Workbook

Sheet Resumen
J1: SCHNEIDER | K1: sigma-eta-1 | L1: M
F2: Sin corregir | H2: Corregido | L2: b
C3: High-mass SF regions | F3: P75 | G3: M | H3: P75 | I3: M | L3: 0.33 | M3: 0.5 | N3: 1
D4: D-15 (Cygnus South) | F4: ='dr15'!N14 -> 0.2613531 | G4: =3.7368269-F4*3.715115 -> 2.7658701 | H4: ='dr15'!T14 -> 0.24911126 | I4: =3.7368269-H4*3.715115 -> 2.8113499 | K4: 0.29 | L4: =((EXP(K4^2)-1)/($L$3^2))^0.5 -> 0.89759224 | M4: =((EXP(K4^2)-1)/($M$3^2))^0.5 -> 0.59241088 | N4: =((EXP(K4^2)-1)/($N$3^2))^0.5 -> 0.29620544
D5: M16 | F5: ='m16'!N14 -> 0.28548987 | G5: =3.7368269-F5*3.715115 -> 2.6761992 | H5: ='m16'!T14 -> 0.33890613 | I5: =3.7368269-H5*3.715115 -> 2.4777517 | K5: 0.33 | L5: =((EXP(K5^2)-1)/($L$3^2))^0.5 -> 1.0278529 | M5: =((EXP(K5^2)-1)/($M$3^2))^0.5 -> 0.6783829 | N5: =((EXP(K5^2)-1)/($N$3^2))^0.5 -> 0.33919145
D6: M17 | F6: ='m17'!N14 -> 0.65837325 | G6: =3.7368269-F6*3.715115 -> 1.2908946 | H6: ='m17'!T14 -> 0.34156787 | I6: =3.7368269-H6*3.715115 -> 2.467863 | K6: 0.79 | L6: =((EXP(K6^2)-1)/($L$3^2))^0.5 -> 2.8208936 | M6: =((EXP(K6^2)-1)/($M$3^2))^0.5 -> 1.8617898 | N6: =((EXP(K6^2)-1)/($N$3^2))^0.5 -> 0.93089489
D7: NGC6334 | F7: ='ngc6334'!N14 -> 0.37735849 | G7: =3.7368269-F7*3.715115 -> 2.3348967 | H7: ='ngc6334'!T14 -> 0.19230769 | I7: =3.7368269-H7*3.715115 -> 3.0223817 | K7: 0.81 | L7: =((EXP(K7^2)-1)/($L$3^2))^0.5 -> 2.9180124 | M7: =((EXP(K7^2)-1)/($M$3^2))^0.5 -> 1.9258882 | N7: =((EXP(K7^2)-1)/($N$3^2))^0.5 -> 0.9629441
D8: NGC6357 | F8: ='ngc6357'!N14 -> 0.4641922 | G8: =3.7368269-F8*3.715115 -> 2.0122995 | H8: ='ngc6357'!T14 -> 0.26147025 | I8: =3.7368269-H8*3.715115 -> 2.7654348 | K8: 0.74 | L8: =((EXP(K8^2)-1)/($L$3^2))^0.5 -> 2.5874923 | M8: =((EXP(K8^2)-1)/($M$3^2))^0.5 -> 1.7077449 | N8: =((EXP(K8^2)-1)/($N$3^2))^0.5 -> 0.85387247
D9: NGC7538 | F9: ='ngc7538'!N14 -> 0.52531379 | G9: =3.7368269-F9*3.715115 -> 1.7852258 | H9: ='ngc7538'!T14 -> 0.39957461 | I9: =3.7368269-H9*3.715115 -> 2.2523613 | K9: 0.33 | L9: =((EXP(K9^2)-1)/($L$3^2))^0.5 -> 1.0278529 | M9: =((EXP(K9^2)-1)/($M$3^2))^0.5 -> 0.6783829 | N9: =((EXP(K9^2)-1)/($N$3^2))^0.5 -> 0.33919145
D10: Rosette | F10: =rosette!N14 -> 0.42006825 | G10: =3.7368269-F10*3.715115 -> 2.176225 | H10: =rosette!T14 -> 0.21476919 | I10: =3.7368269-H10*3.715115 -> 2.9389347 | K10: 0.63 | L10: =((EXP(K10^2)-1)/($L$3^2))^0.5 -> 2.1151585 | M10: =((EXP(K10^2)-1)/($M$3^2))^0.5 -> 1.3960046 | N10: =((EXP(K10^2)-1)/($N$3^2))^0.5 -> 0.69800229
D11: Vela C | F11: =velac!N14 -> 0.55455421 | G11: =3.7368269-F11*3.715115 -> 1.6765942 | H11: =velac!T14 -> 0.30328749 | I11: =3.7368269-H11*3.715115 -> 2.610079 | K11: 0.25 | L11: =((EXP(K11^2)-1)/($L$3^2))^0.5 -> 0.76956846 | M11: =((EXP(K11^2)-1)/($M$3^2))^0.5 -> 0.50791519 | N11: =((EXP(K11^2)-1)/($N$3^2))^0.5 -> 0.25395759
E12: Media | F12: =AVERAGE(F4:F11) -> 0.4433379 | G12: =AVERAGE(G4:G11) -> 2.0897756 | H12: =AVERAGE(H4:H11) -> 0.28762431 | I12: =AVERAGE(I4:I11) -> 2.6682695
C13: Intermediate-mass SF regions
D14: Monr2 | F14: =monr2!N14 -> 0.54095558 | G14: =3.7368269-F14*3.715115 -> 1.7271147 | H14: =monr2!T14 -> 0.36202783 | I14: =3.7368269-H14*3.715115 -> 2.3918519 | K14: 0.36 | L14: =((EXP(K14^2)-1)/($L$3^2))^0.5 -> 1.1272277 | M14: =((EXP(K14^2)-1)/($M$3^2))^0.5 -> 0.74397028 | N14: =((EXP(K14^2)-1)/($N$3^2))^0.5 -> 0.37198514
D15: Monob1 | F15: =monob1!N14 -> 0.5677814 | G15: =3.7368269-F15*3.715115 -> 1.6274537 | H15: =monob1!T14 -> 0.31624569 | I15: =3.7368269-H15*3.715115 -> 2.5619378 | K15: 0.49 | L15: =((EXP(K15^2)-1)/($L$3^2))^0.5 -> 1.5785997 | M15: =((EXP(K15^2)-1)/($M$3^2))^0.5 -> 1.0418758 | N15: =((EXP(K15^2)-1)/($N$3^2))^0.5 -> 0.52093789
D16: NGC2264 | F16: ='ngc2264'!N14 -> 0.46844118 | G16: =3.7368269-F16*3.715115 -> 1.9965141 | H16: ='ngc2264'!T14 -> 0.34064825 | I16: =3.7368269-H16*3.715115 -> 2.4712795 | K16: 0.47 | L16: =((EXP(K16^2)-1)/($L$3^2))^0.5 -> 1.5066388 | M16: =((EXP(K16^2)-1)/($M$3^2))^0.5 -> 0.99438163 | N16: =((EXP(K16^2)-1)/($N$3^2))^0.5 -> 0.49719081
E17: Media | F17: =AVERAGE(F14:F16) -> 0.52572605 | G17: =AVERAGE(G14:G16) -> 1.7836942 | H17: =AVERAGE(H14:H16) -> 0.33964059 | I17: =AVERAGE(I14:I16) -> 2.475023
J18: High Mass | K18: R2 (sin corregir) | L18: =RSQ(L4:L11,G4:G11) -> 0.088538042 | M18: =RSQ(M4:M11,G4:G11) -> 0.088538042 | N18: =RSQ(N4:N11,G4:G11) -> 0.088538042
K19: R2 (corregido) | L19: =RSQ(I4:I11,L4:L11) -> 0.19353962 | M19: =RSQ(I4:I11,M4:M11) -> 0.19353962 | N19: =RSQ(I4:I11,N4:N11) -> 0.19353962
J20: Inter Mass | K20: R2 (sin corregir) | L20: =RSQ(G14:G16,L14:L16) -> 0.012189029 | M20: =RSQ(G14:G16,M14:M16) -> 0.012189029 | N20: =RSQ(G14:G16,N14:N16) -> 0.012189029
K21: R2 (corregido) | L21: =RSQ(I14:I16,L14:L16) -> 0.83906805 | M21: =RSQ(I14:I16,M14:M16) -> 0.83906805 | N21: =RSQ(I14:I16,N14:N16) -> 0.83906805

Sheet velac
A1: eta | B1: pdf_original | C1: error_original | D1: counts_original | E1: pdf_corregido | F1: error_corregido | G1: counts_corregido
A2: -4.95 | B2: 0 | C2: 0 | D2: 0 | E2: 0.0024019191 | F2: 8.2240142e-05 | G2: 853
A3: -4.85 | B3: 0 | C3: 0 | D3: 0 | E3: 0.0027088466 | F3: 8.7336719e-05 | G3: 962 | J3: PDF ORIGINAL | P3: PDF CORREGIDO
A4: -4.75 | B4: 0 | C4: 0 | D4: 0 | E4: 0.0030720911 | F4: 9.3008301e-05 | G4: 1091 | J4: PERCENTILES | P4: PERCENTILES
A5: -4.65 | B5: 0 | C5: 0 | D5: 0 | E5: 0.003502916 | F5: 9.931607e-05 | G5: 1244 | J5: 0.001 | K5: =J5 -> 0.001 | L5: =_xlfn.PERCENTILE.INC($B$2:$B$101,E9) -> 0 | N5: P95 | P5: 0.001 | Q5: =P5 -> 0.001 | R5: =_xlfn.PERCENTILE.INC($E$2:$E$101,K9) -> 0 | T5: P95
A6: -4.55 | B6: 0 | C6: 0 | D6: 0 | E6: 0.0039956895 | F6: 0.00010607195 | G6: 1419 | J6: 0.002 | K6: =J6 -> 0.002 | L6: =_xlfn.PERCENTILE.INC($B$2:$B$61,J6) -> 0 | N6: =L979-L29 -> 0.71928492 | P6: 0.002 | Q6: =P6 -> 0.002 | R6: =_xlfn.PERCENTILE.INC($E$2:$E$101,K10) -> 0 | T6: =R979-R29 -> 0.36450332
A7: -4.45 | B7: 0 | C7: 0 | D7: 0 | E7: 0.004471568 | F7: 0.00011221078 | G7: 1588 | J7: 0.003 | K7: =J7 -> 0.003 | L7: =_xlfn.PERCENTILE.INC($B$2:$B$61,J7) -> 0 | N7: P90 | P7: 0.003 | Q7: =P7 -> 0.003 | R7: =_xlfn.PERCENTILE.INC($E$2:$E$101,K11) -> 0 | T7: P90
A8: -4.35 | B8: 0 | C8: 0 | D8: 0 | E8: 0.0050713438 | F8: 0.00011949953 | G8: 1801 | J8: 0.004 | K8: =J8 -> 0.004 | L8: =_xlfn.PERCENTILE.INC($B$2:$B$61,J8) -> 0 | N8: =L954-L54 -> 0.66073552 | P8: 0.004 | Q8: =P8 -> 0.004 | R8: =_xlfn.PERCENTILE.INC($E$2:$E$101,K12) -> 0 | T8: =R954-R54 -> 0.35189737
A9: -4.25 | B9: 0 | C9: 0 | D9: 0 | E9: 0.0060118373 | F9: 0.00013010928 | G9: 2135 | J9: 0.005 | K9: =J9 -> 0.005 | L9: =_xlfn.PERCENTILE.INC($B$2:$B$61,J9) -> 0 | N9: P85 | P9: 0.005 | Q9: =P9 -> 0.005 | R9: =_xlfn.PERCENTILE.INC($E$2:$E$101,K13) -> 0 | T9: P85
A10: -4.15 | B10: 0 | C10: 0 | D10: 0 | E10: 0.0066059814 | F10: 0.00013638711 | G10: 2346 | J10: 0.006 | K10: =J10 -> 0.006 | L10: =_xlfn.PERCENTILE.INC($B$2:$B$61,J10) -> 0 | N10: =L929-L79 -> 0.60938582 | P10: 0.006 | Q10: =P10 -> 0.006 | R10: =_xlfn.PERCENTILE.INC($E$2:$E$101,K14) -> 0 | T10: =R929-R79 -> 0.33956067
A11: -4.05 | B11: 0 | C11: 0 | D11: 0 | E11: 0.0082081994 | F11: 0.00015202976 | G11: 2915 | J11: 0.007 | K11: =J11 -> 0.007 | L11: =_xlfn.PERCENTILE.INC($B$2:$B$61,J11) -> 0 | N11: P80 | P11: 0.007 | Q11: =P11 -> 0.007 | R11: =_xlfn.PERCENTILE.INC($E$2:$E$101,K15) -> 0 | T11: P80
A12: -3.95 | B12: 0 | C12: 0 | D12: 0 | E12: 0.0090416906 | F12: 0.00015956201 | G12: 3211 | J12: 0.008 | K12: =J12 -> 0.008 | L12: =_xlfn.PERCENTILE.INC($B$2:$B$61,J12) -> 0 | N12: =L904-L104 -> 0.58823019 | P12: 0.008 | Q12: =P12 -> 0.008 | R12: =_xlfn.PERCENTILE.INC($E$2:$E$101,K16) -> 0 | T12: =R904-R104 -> 0.3227514
A13: -3.85 | B13: 0 | C13: 0 | D13: 0 | E13: 0.010384851 | F13: 0.00017100342 | G13: 3688 | J13: 0.009 | K13: =J13 -> 0.009 | L13: =_xlfn.PERCENTILE.INC($B$2:$B$61,J13) -> 0 | N13: P75 | P13: 0.009 | Q13: =P13 -> 0.009 | R13: =_xlfn.PERCENTILE.INC($E$2:$E$101,K17) -> 0 | T13: P75
A14: -3.75 | B14: 0 | C14: 0 | D14: 0 | E14: 0.012167283 | F14: 0.00018509789 | G14: 4321 | J14: 0.01 | K14: =J14 -> 0.01 | L14: =_xlfn.PERCENTILE.INC($B$2:$B$61,J14) -> 0 | N14: =L879-L129 -> 0.55455421 | P14: 0.01 | Q14: =P14 -> 0.01 | R14: =_xlfn.PERCENTILE.INC($E$2:$E$101,K18) -> 0 | T14: =R879-R129 -> 0.30328749
A15: -3.65 | B15: 0 | C15: 0 | D15: 0 | E15: 0.014152456 | F15: 0.0001996276 | G15: 5026 | J15: 0.011 | K15: =J15 -> 0.011 | L15: =_xlfn.PERCENTILE.INC($B$2:$B$61,J15) -> 0 | N15: P70 | P15: 0.011 | Q15: =P15 -> 0.011 | R15: =_xlfn.PERCENTILE.INC($E$2:$E$101,K19) -> 0 | T15: P70
A16: -3.55 | B16: 0 | C16: 0 | D16: 0 | E16: 0.016633219 | F16: 0.00021641772 | G16: 5907 | J16: 0.012 | K16: =J16 -> 0.012 | L16: =_xlfn.PERCENTILE.INC($B$2:$B$61,J16) -> 0 | N16: =L854-L154 -> 0.50133983 | P16: 0.012 | Q16: =P16 -> 0.012 | R16: =_xlfn.PERCENTILE.INC($E$2:$E$101,K20) -> 0 | T16: =R854-R154 -> 0.28987954
A17: -3.45 | B17: 0 | C17: 0 | D17: 0 | E17: 0.020144583 | F17: 0.00023816822 | G17: 7154 | J17: 0.013 | K17: =J17 -> 0.013 | L17: =_xlfn.PERCENTILE.INC($B$2:$B$61,J17) -> 0 | N17: P65 | P17: 0.013 | Q17: =P17 -> 0.013 | R17: =_xlfn.PERCENTILE.INC($E$2:$E$101,K21) -> 0 | T17: P65
A18: -3.35 | B18: 0 | C18: 0 | D18: 0 | E18: 0.02338844 | F18: 0.00025662875 | G18: 8306 | J18: 0.014 | K18: =J18 -> 0.014 | L18: =_xlfn.PERCENTILE.INC($B$2:$B$61,J18) -> 0 | N18: =L829-L179 -> 0.43028063 | P18: 0.014 | Q18: =P18 -> 0.014 | R18: =_xlfn.PERCENTILE.INC($E$2:$E$101,K22) -> 0 | T18: =R829-R179 -> 0.26081193
A19: -3.25 | B19: 0 | C19: 0 | D19: 0 | E19: 0.028735737 | F19: 0.00028445649 | G19: 10205 | J19: 0.015 | K19: =J19 -> 0.015 | L19: =_xlfn.PERCENTILE.INC($B$2:$B$61,J19) -> 0 | N19: P60 | P19: 0.015 | Q19: =P19 -> 0.015 | R19: =_xlfn.PERCENTILE.INC($E$2:$E$101,K23) -> 0 | T19: P60
A20: -3.15 | B20: 0 | C20: 0 | D20: 0 | E20: 0.033750764 | F20: 0.0003082808 | G20: 11986 | J20: 0.016 | K20: =J20 -> 0.016 | L20: =_xlfn.PERCENTILE.INC($B$2:$B$61,J20) -> 0 | N20: =L804-L204 -> 0.40932833 | P20: 0.016 | Q20: =P20 -> 0.016 | R20: =_xlfn.PERCENTILE.INC($E$2:$E$101,K24) -> 0 | T20: =R804-R204 -> 0.22712542
A21: -3.05 | B21: 0 | C21: 0 | D21: 0 | E21: 0.041257817 | F21: 0.00034084568 | G21: 14652 | J21: 0.017 | K21: =J21 -> 0.017 | L21: =_xlfn.PERCENTILE.INC($B$2:$B$61,J21) -> 0 | N21: P55 | P21: 0.017 | Q21: =P21 -> 0.017 | R21: =_xlfn.PERCENTILE.INC($E$2:$E$101,K25) -> 0 | T21: P55
A22: -2.95 | B22: 0 | C22: 0 | D22: 0 | E22: 0.048015854 | F22: 0.00036770285 | G22: 17052 | J22: 0.018 | K22: =J22 -> 0.018 | L22: =_xlfn.PERCENTILE.INC($B$2:$B$61,J22) -> 0 | N22: =L779-L229 -> 0.35870376 | P22: 0.018 | Q22: =P22 -> 0.018 | R22: =_xlfn.PERCENTILE.INC($E$2:$E$101,K26) -> 0 | T22: =R779-R229 -> 0.18902721
A23: -2.85 | B23: 0 | C23: 0 | D23: 0 | E23: 0.053929137 | F23: 0.00038968744 | G23: 19152 | J23: 0.019 | K23: =J23 -> 0.019 | L23: =_xlfn.PERCENTILE.INC($B$2:$B$61,J23) -> 0 | N23: P50 | P23: 0.019 | Q23: =P23 -> 0.019 | R23: =_xlfn.PERCENTILE.INC($E$2:$E$101,K27) -> 0 | T23: P50
A24: -2.75 | B24: 0 | C24: 0 | D24: 0 | E24: 0.059498886 | F24: 0.00040931634 | G24: 21130 | J24: 0.02 | K24: =J24 -> 0.02 | L24: =_xlfn.PERCENTILE.INC($B$2:$B$61,J24) -> 0 | N24: =L754-L254 -> 0.28813536 | P24: 0.02 | Q24: =P24 -> 0.02 | R24: =_xlfn.PERCENTILE.INC($E$2:$E$101,K28) -> 0 | T24: =R754-R254 -> 0.17069771
A25: -2.65 | B25: 0 | C25: 0 | D25: 0 | E25: 0.068385705 | F25: 0.00043882093 | G25: 24286 | J25: 0.021 | K25: =J25 -> 0.021 | L25: =_xlfn.PERCENTILE.INC($B$2:$B$61,J25) -> 0 | P25: 0.021 | Q25: =P25 -> 0.021 | R25: =_xlfn.PERCENTILE.INC($E$2:$E$101,K29) -> 0
A26: -2.55 | B26: 0 | C26: 0 | D26: 0 | E26: 0.077863852 | F26: 0.00046824442 | G26: 27652 | J26: 0.022 | K26: =J26 -> 0.022 | L26: =_xlfn.PERCENTILE.INC($B$2:$B$61,J26) -> 0 | P26: 0.022 | Q26: =P26 -> 0.022 | R26: =_xlfn.PERCENTILE.INC($E$2:$E$101,K30) -> 0
A27: -2.45 | B27: 0 | C27: 0 | D27: 0 | E27: 0.088471155 | F27: 0.00049912062 | G27: 31419 | J27: 0.023 | K27: =J27 -> 0.023 | L27: =_xlfn.PERCENTILE.INC($B$2:$B$61,J27) -> 0 | P27: 0.023 | Q27: =P27 -> 0.023 | R27: =_xlfn.PERCENTILE.INC($E$2:$E$101,K31) -> 0
A28: -2.35 | B28: 0 | C28: 0 | D28: 0 | E28: 0.096752566 | F28: 0.00052195843 | G28: 34360 | J28: 0.024 | K28: =J28 -> 0.024 | L28: =_xlfn.PERCENTILE.INC($B$2:$B$61,J28) -> 0 | P28: 0.024 | Q28: =P28 -> 0.024 | R28: =_xlfn.PERCENTILE.INC($E$2:$E$101,K32) -> 0
A29: -2.25 | B29: 0 | C29: 0 | D29: 0 | E29: 0.10616595 | F29: 0.0005467607 | G29: 37703 | J29: 0.025 | K29: =J29 -> 0.025 | L29: =_xlfn.PERCENTILE.INC($B$2:$B$61,J29) -> 0 | P29: 0.025 | Q29: =P29 -> 0.025 | R29: =_xlfn.PERCENTILE.INC($E$2:$E$101,K33) -> 0
A30: -2.15 | B30: 0 | C30: 0 | D30: 0 | E30: 0.11886824 | F30: 0.00057854559 | G30: 42214 | J30: 0.026 | K30: =J30 -> 0.026 | L30: =_xlfn.PERCENTILE.INC($B$2:$B$61,J30) -> 0 | P30: 0.026 | Q30: =P30 -> 0.026 | R30: =_xlfn.PERCENTILE.INC($E$2:$E$101,K34) -> 0
A31: -2.05 | B31: 0 | C31: 0 | D31: 0 | E31: 0.13169725 | F31: 0.00060896597 | G31: 46770 | J31: 0.027 | K31: =J31 -> 0.027 | L31: =_xlfn.PERCENTILE.INC($B$2:$B$61,J31) -> 0 | P31: 0.027 | Q31: =P31 -> 0.027 | R31: =_xlfn.PERCENTILE.INC($E$2:$E$101,K35) -> 0
A32: -1.95 | B32: 0 | C32: 0 | D32: 0 | E32: 0.15246695 | F32: 0.00065522812 | G32: 54146 | J32: 0.028 | K32: =J32 -> 0.028 | L32: =_xlfn.PERCENTILE.INC($B$2:$B$61,J32) -> 0 | P32: 0.028 | Q32: =P32 -> 0.028 | R32: =_xlfn.PERCENTILE.INC($E$2:$E$101,K36) -> 0
A33: -1.85 | B33: 0 | C33: 0 | D33: 0 | E33: 0.15749887 | F33: 0.00066595271 | G33: 55933 | J33: 0.029 | K33: =J33 -> 0.029 | L33: =_xlfn.PERCENTILE.INC($B$2:$B$61,J33) -> 0 | P33: 0.029 | Q33: =P33 -> 0.029 | R33: =_xlfn.PERCENTILE.INC($E$2:$E$101,K37) -> 0
A34: -1.75 | B34: 0 | C34: 0 | D34: 0 | E34: 0.17175833 | F34: 0.00069544626 | G34: 60997 | J34: 0.03 | K34: =J34 -> 0.03 | L34: =_xlfn.PERCENTILE.INC($B$2:$B$61,J34) -> 0 | P34: 0.03 | Q34: =P34 -> 0.03 | R34: =_xlfn.PERCENTILE.INC($E$2:$E$101,K38) -> 0
A35: -1.65 | B35: 0 | C35: 0 | D35: 0 | E35: 0.17390401 | F35: 0.00069977668 | G35: 61759 | J35: 0.031 | K35: =J35 -> 0.031 | L35: =_xlfn.PERCENTILE.INC($B$2:$B$61,J35) -> 0 | P35: 0.031 | Q35: =P35 -> 0.031 | R35: =_xlfn.PERCENTILE.INC($E$2:$E$101,K39) -> 0
A36: -1.55 | B36: 0 | C36: 0 | D36: 0 | E36: 0.17753927 | F36: 0.00070705286 | G36: 63050 | J36: 0.032 | K36: =J36 -> 0.032 | L36: =_xlfn.PERCENTILE.INC($B$2:$B$61,J36) -> 0 | P36: 0.032 | Q36: =P36 -> 0.032 | R36: =_xlfn.PERCENTILE.INC($E$2:$E$101,K40) -> 0
... A101: 4.95 | B101: 0 | C101: 0 | D101: 0 | E101: 0 | F101: 0 | G101: 0 | J101: 0.097 | K101: =J101 -> 0.097 | L101: =_xlfn.PERCENTILE.INC($B$2:$B$61,J101) -> 0 | P101: 0.097 | Q101: =P101 -> 0.097 | R101: =_xlfn.PERCENTILE.INC($E$2:$E$101,K105) -> 0
J102: 0.098 | K102: =J102 -> 0.098 | L102: =_xlfn.PERCENTILE.INC($B$2:$B$61,J102) -> 0 | P102: 0.098 | Q102: =P102 -> 0.098 | R102: =_xlfn.PERCENTILE.INC($E$2:$E$101,K106) -> 0
J103: 0.099 | K103: =J103 -> 0.099 | L103: =_xlfn.PERCENTILE.INC($B$2:$B$61,J103) -> 0 | P103: 0.099 | Q103: =P103 -> 0.099 | R103: =_xlfn.PERCENTILE.INC($E$2:$E$101,K107) -> 0
J104: 0.1 | K104: =J104 -> 0.1 | L104: =_xlfn.PERCENTILE.INC($B$2:$B$61,J104) -> 0 | P104: 0.1 | Q104: =P104 -> 0.1 | R104: =_xlfn.PERCENTILE.INC($E$2:$E$101,K108) -> 0
...

Sheet dr15
A1: eta | B1: pdf_original | C1: error_original | D1: counts_original | E1: pdf_corregido | F1: error_corregido | G1: counts_corregido
A2: -4.95 | B2: 0 | C2: 0 | D2: 0 | E2: 4.7774793e-06 | F2: 3.378188e-06 | G2: 2
A3: -4.85 | B3: 0 | C3: 0 | D3: 0 | E3: 4.7774793e-06 | F3: 3.378188e-06 | G3: 2 | J3: PDF ORIGINAL | P3: PDF CORREGIDO
A4: -4.75 | B4: 0 | C4: 0 | D4: 0 | E4: 4.7774793e-06 | F4: 3.378188e-06 | G4: 2 | J4: PERCENTILES | P4: PERCENTILES
A5: -4.65 | B5: 0 | C5: 0 | D5: 0 | E5: 2.3887397e-06 | F5: 2.3887397e-06 | G5: 1 | J5: 0.001 | K5: =J5 -> 0.001 | L5: =_xlfn.PERCENTILE.INC($B$2:$B$101,E9) -> 0 | N5: P95 | P5: 0.001 | Q5: =P5 -> 0.001 | R5: =_xlfn.PERCENTILE.INC($E$2:$E$101,K9) -> 0 | T5: P95
A6: -4.55 | B6: 0 | C6: 0 | D6: 0 | E6: 1.1943698e-05 | F6: 5.3413843e-06 | G6: 5 | J6: 0.002 | K6: =J6 -> 0.002 | L6: =_xlfn.PERCENTILE.INC($B$2:$B$61,J6) -> 0 | N6: =L979-L29 -> 1.8647735 | P6: 0.002 | Q6: =P6 -> 0.002 | R6: =_xlfn.PERCENTILE.INC($E$2:$E$101,K10) -> 0 | T6: =R979-R29 -> 1.0495147
A7: -4.45 | B7: 0 | C7: 0 | D7: 0 | E7: 0 | F7: 0 | G7: 0 | J7: 0.003 | K7: =J7 -> 0.003 | L7: =_xlfn.PERCENTILE.INC($B$2:$B$61,J7) -> 0 | N7: P90 | P7: 0.003 | Q7: =P7 -> 0.003 | R7: =_xlfn.PERCENTILE.INC($E$2:$E$101,K11) -> 0 | T7: P90
A8: -4.35 | B8: 0 | C8: 0 | D8: 0 | E8: 7.166219e-06 | F8: 4.1374185e-06 | G8: 3 | J8: 0.004 | K8: =J8 -> 0.004 | L8: =_xlfn.PERCENTILE.INC($B$2:$B$61,J8) -> 0 | N8: =L954-L54 -> 1.2823673 | P8: 0.004 | Q8: =P8 -> 0.004 | R8: =_xlfn.PERCENTILE.INC($E$2:$E$101,K12) -> 0 | T8: =R954-R54 -> 0.84968567
A9: -4.25 | B9: 0 | C9: 0 | D9: 0 | E9: 1.4332438e-05 | F9: 5.8511933e-06 | G9: 6 | J9: 0.005 | K9: =J9 -> 0.005 | L9: =_xlfn.PERCENTILE.INC($B$2:$B$61,J9) -> 0 | N9: P85 | P9: 0.005 | Q9: =P9 -> 0.005 | R9: =_xlfn.PERCENTILE.INC($E$2:$E$101,K13) -> 0 | T9: P85
A10: -4.15 | B10: 0 | C10: 0 | D10: 0 | E10: 1.1943698e-05 | F10: 5.3413843e-06 | G10: 5 | J10: 0.006 | K10: =J10 -> 0.006 | L10: =_xlfn.PERCENTILE.INC($B$2:$B$61,J10) -> 0 | N10: =L929-L79 -> 0.89280142 | P10: 0.006 | Q10: =P10 -> 0.006 | R10: =_xlfn.PERCENTILE.INC($E$2:$E$101,K14) -> 0 | T10: =R929-R79 -> 0.66735303
A11: -4.05 | B11: 0 | C11: 0 | D11: 0 | E11: 7.166219e-06 | F11: 4.1374185e-06 | G11: 3 | J11: 0.007 | K11: =J11 -> 0.007 | L11: =_xlfn.PERCENTILE.INC($B$2:$B$61,J11) -> 0 | N11: P80 | P11: 0.007 | Q11: =P11 -> 0.007 | R11: =_xlfn.PERCENTILE.INC($E$2:$E$101,K15) -> 0 | T11: P80
A12: -3.95 | B12: 0 | C12: 0 | D12: 0 | E12: 4.7774793e-06 | F12: 3.378188e-06 | G12: 2 | J12: 0.008 | K12: =J12 -> 0.008 | L12: =_xlfn.PERCENTILE.INC($B$2:$B$61,J12) -> 0 | N12: =L904-L104 -> 0.47091833 | P12: 0.008 | Q12: =P12 -> 0.008 | R12: =_xlfn.PERCENTILE.INC($E$2:$E$101,K16) -> 0 | T12: =R904-R104 -> 0.41232995
A13: -3.85 | B13: 0 | C13: 0 | D13: 0 | E13: 1.6721178e-05 | F13: 6.3200111e-06 | G13: 7 | J13: 0.009 | K13: =J13 -> 0.009 | L13: =_xlfn.PERCENTILE.INC($B$2:$B$61,J13) -> 0 | N13: P75 | P13: 0.009 | Q13: =P13 -> 0.009 | R13: =_xlfn.PERCENTILE.INC($E$2:$E$101,K17) -> 0 | T13: P75
A14: -3.75 | B14: 0 | C14: 0 | D14: 0 | E14: 2.3887397e-06 | F14: 2.3887397e-06 | G14: 1 | J14: 0.01 | K14: =J14 -> 0.01 | L14: =_xlfn.PERCENTILE.INC($B$2:$B$61,J14) -> 0 | N14: =L879-L129 -> 0.2613531 | P14: 0.01 | Q14: =P14 -> 0.01 | R14: =_xlfn.PERCENTILE.INC($E$2:$E$101,K18) -> 0 | T14: =R879-R129 -> 0.24911126
A15: -3.65 | B15: 0 | C15: 0 | D15: 0 | E15: 1.9109917e-05 | F15: 6.7563761e-06 | G15: 8 | J15: 0.011 | K15: =J15 -> 0.011 | L15: =_xlfn.PERCENTILE.INC($B$2:$B$61,J15) -> 0 | N15: P70 | P15: 0.011 | Q15: =P15 -> 0.011 | R15: =_xlfn.PERCENTILE.INC($E$2:$E$101,K19) -> 0 | T15: P70
A16: -3.55 | B16: 0 | C16: 0 | D16: 0 | E16: 9.5549587e-06 | F16: 4.7774793e-06 | G16: 4 | J16: 0.012 | K16: =J16 -> 0.012 | L16: =_xlfn.PERCENTILE.INC($B$2:$B$61,J16) -> 0 | N16: =L854-L154 -> 0.066545842 | P16: 0.012 | Q16: =P16 -> 0.012 | R16: =_xlfn.PERCENTILE.INC($E$2:$E$101,K20) -> 0 | T16: =R854-R154 -> 0.12777965
A17: -3.45 | B17: 0 | C17: 0 | D17: 0 | E17: 1.6721178e-05 | F17: 6.3200111e-06 | G17: 7 | J17: 0.013 | K17: =J17 -> 0.013 | L17: =_xlfn.PERCENTILE.INC($B$2:$B$61,J17) -> 0 | N17: P65 | P17: 0.013 | Q17: =P17 -> 0.013 | R17: =_xlfn.PERCENTILE.INC($E$2:$E$101,K21) -> 0 | T17: P65
A18: -3.35 | B18: 0 | C18: 0 | D18: 0 | E18: 2.1498657e-05 | F18: 7.166219e-06 | G18: 9 | J18: 0.014 | K18: =J18 -> 0.014 | L18: =_xlfn.PERCENTILE.INC($B$2:$B$61,J18) -> 0 | N18: =L829-L179 -> 0.033287432 | P18: 0.014 | Q18: =P18 -> 0.014 | R18: =_xlfn.PERCENTILE.INC($E$2:$E$101,K22) -> 0 | T18: =R829-R179 -> 0.042379299
A19: -3.25 | B19: 0 | C19: 0 | D19: 0 | E19: 1.9109917e-05 | F19: 6.7563761e-06 | G19: 8 | J19: 0.015 | K19: =J19 -> 0.015 | L19: =_xlfn.PERCENTILE.INC($B$2:$B$61,J19) -> 0 | N19: P60 | P19: 0.015 | Q19: =P19 -> 0.015 | R19: =_xlfn.PERCENTILE.INC($E$2:$E$101,K23) -> 0 | T19: P60
A20: -3.15 | B20: 0 | C20: 0 | D20: 0 | E20: 3.1053616e-05 | F20: 8.6127234e-06 | G20: 13 | J20: 0.016 | K20: =J20 -> 0.016 | L20: =_xlfn.PERCENTILE.INC($B$2:$B$61,J20) -> 0 | N20: =L804-L204 -> 0.018214651 | P20: 0.016 | Q20: =P20 -> 0.016 | R20: =_xlfn.PERCENTILE.INC($E$2:$E$101,K24) -> 0 | T20: =R804-R204 -> 0.020960665
A21: -3.05 | B21: 0 | C21: 0 | D21: 0 | E21: 2.3887397e-05 | F21: 7.5538581e-06 | G21: 10 | J21: 0.017 | K21: =J21 -> 0.017 | L21: =_xlfn.PERCENTILE.INC($B$2:$B$61,J21) -> 0 | N21: P55 | P21: 0.017 | Q21: =P21 -> 0.017 | R21: =_xlfn.PERCENTILE.INC($E$2:$E$101,K25) -> 0 | T21: P55
A22: -2.95 | B22: 0 | C22: 0 | D22: 0 | E22: 1.9109917e-05 | F22: 6.7563761e-06 | G22: 8 | J22: 0.018 | K22: =J22 -> 0.018 | L22: =_xlfn.PERCENTILE.INC($B$2:$B$61,J22) -> 0 | N22: =L779-L229 -> 0.010137895 | P22: 0.018 | Q22: =P22 -> 0.018 | R22: =_xlfn.PERCENTILE.INC($E$2:$E$101,K26) -> 0 | T22: =R779-R229 -> 0.0093740093
A23: -2.85 | B23: 2.3886187e-06 | C23: 2.3886187e-06 | D23: 1 | E23: 3.1053616e-05 | F23: 8.6127234e-06 | G23: 13 | J23: 0.019 | K23: =J23 -> 0.019 | L23: =_xlfn.PERCENTILE.INC($B$2:$B$61,J23) -> 0 | N23: P50 | P23: 0.019 | Q23: =P23 -> 0.019 | R23: =_xlfn.PERCENTILE.INC($E$2:$E$101,K27) -> 0 | T23: P50
A24: -2.75 | B24: 0 | C24: 0 | D24: 0 | E24: 3.1053616e-05 | F24: 8.6127234e-06 | G24: 13 | J24: 0.02 | K24: =J24 -> 0.02 | L24: =_xlfn.PERCENTILE.INC($B$2:$B$61,J24) -> 0 | N24: =L754-L254 -> 0.003675487 | P24: 0.02 | Q24: =P24 -> 0.02 | R24: =_xlfn.PERCENTILE.INC($E$2:$E$101,K28) -> 0 | T24: =R754-R254 -> 0.006078922
A25: -2.65 | B25: 0 | C25: 0 | D25: 0 | E25: 3.8219835e-05 | F25: 9.5549587e-06 | G25: 16 | J25: 0.021 | K25: =J25 -> 0.021 | L25: =_xlfn.PERCENTILE.INC($B$2:$B$61,J25) -> 0 | P25: 0.021 | Q25: =P25 -> 0.021 | R25: =_xlfn.PERCENTILE.INC($E$2:$E$101,K29) -> 0
A26: -2.55 | B26: 0 | C26: 0 | D26: 0 | E26: 6.4495971e-05 | F26: 1.2412255e-05 | G26: 27 | J26: 0.022 | K26: =J26 -> 0.022 | L26: =_xlfn.PERCENTILE.INC($B$2:$B$61,J26) -> 0 | P26: 0.022 | Q26: =P26 -> 0.022 | R26: =_xlfn.PERCENTILE.INC($E$2:$E$101,K30) -> 0
A27: -2.45 | B27: 2.3886187e-06 | C27: 2.3886187e-06 | D27: 1 | E27: 3.8219835e-05 | F27: 9.5549587e-06 | G27: 16 | J27: 0.023 | K27: =J27 -> 0.023 | L27: =_xlfn.PERCENTILE.INC($B$2:$B$61,J27) -> 0 | P27: 0.023 | Q27: =P27 -> 0.023 | R27: =_xlfn.PERCENTILE.INC($E$2:$E$101,K31) -> 0
A28: -2.35 | B28: 0 | C28: 0 | D28: 0 | E28: 9.0772108e-05 | F28: 1.472518e-05 | G28: 38 | J28: 0.024 | K28: =J28 -> 0.024 | L28: =_xlfn.PERCENTILE.INC($B$2:$B$61,J28) -> 0 | P28: 0.024 | Q28: =P28 -> 0.024 | R28: =_xlfn.PERCENTILE.INC($E$2:$E$101,K32) -> 0
A29: -2.25 | B29: 0 | C29: 0 | D29: 0 | E29: 7.166219e-05 | F29: 1.3083666e-05 | G29: 30 | J29: 0.025 | K29: =J29 -> 0.025 | L29: =_xlfn.PERCENTILE.INC($B$2:$B$61,J29) -> 0 | P29: 0.025 | Q29: =P29 -> 0.025 | R29: =_xlfn.PERCENTILE.INC($E$2:$E$101,K33) -> 0
A30: -2.15 | B30: 0 | C30: 0 | D30: 0 | E30: 9.0772108e-05 | F30: 1.472518e-05 | G30: 38 | J30: 0.026 | K30: =J30 -> 0.026 | L30: =_xlfn.PERCENTILE.INC($B$2:$B$61,J30) -> 0 | P30: 0.026 | Q30: =P30 -> 0.026 | R30: =_xlfn.PERCENTILE.INC($E$2:$E$101,K34) -> 0
A31: -2.05 | B31: 0 | C31: 0 | D31: 0 | E31: 0.00012421446 | F31: 1.7225447e-05 | G31: 52 | J31: 0.027 | K31: =J31 -> 0.027 | L31: =_xlfn.PERCENTILE.INC($B$2:$B$61,J31) -> 0 | P31: 0.027 | Q31: =P31 -> 0.027 | R31: =_xlfn.PERCENTILE.INC($E$2:$E$101,K35) -> 0
A32: -1.95 | B32: 0 | C32: 0 | D32: 0 | E32: 0.00010749329 | F32: 1.6024153e-05 | G32: 45 | J32: 0.028 | K32: =J32 -> 0.028 | L32: =_xlfn.PERCENTILE.INC($B$2:$B$61,J32) -> 0 | P32: 0.028 | Q32: =P32 -> 0.028 | R32: =_xlfn.PERCENTILE.INC($E$2:$E$101,K36) -> 0
A33: -1.85 | B33: 2.3886187e-06 | C33: 2.3886187e-06 | D33: 1 | E33: 0.0001146595 | F33: 1.6549674e-05 | G33: 48 | J33: 0.029 | K33: =J33 -> 0.029 | L33: =_xlfn.PERCENTILE.INC($B$2:$B$61,J33) -> 0 | P33: 0.029 | Q33: =P33 -> 0.029 | R33: =_xlfn.PERCENTILE.INC($E$2:$E$101,K37) -> 0
A34: -1.75 | B34: 0 | C34: 0 | D34: 0 | E34: 0.00018871043 | F34: 2.1231583e-05 | G34: 79 | J34: 0.03 | K34: =J34 -> 0.03 | L34: =_xlfn.PERCENTILE.INC($B$2:$B$61,J34) -> 0 | P34: 0.03 | Q34: =P34 -> 0.03 | R34: =_xlfn.PERCENTILE.INC($E$2:$E$101,K38) -> 0
A35: -1.65 | B35: 0 | C35: 0 | D35: 0 | E35: 0.00026276136 | F35: 2.5053313e-05 | G35: 110 | J35: 0.031 | K35: =J35 -> 0.031 | L35: =_xlfn.PERCENTILE.INC($B$2:$B$61,J35) -> 0 | P35: 0.031 | Q35: =P35 -> 0.031 | R35: =_xlfn.PERCENTILE.INC($E$2:$E$101,K39) -> 0
A36: -1.55 | B36: 0 | C36: 0 | D36: 0 | E36: 0.00042280692 | F36: 3.1780114e-05 | G36: 177 | J36: 0.032 | K36: =J36 -> 0.032 | L36: =_xlfn.PERCENTILE.INC($B$2:$B$61,J36) -> 0 | P36: 0.032 | Q36: =P36 -> 0.032 | R36: =_xlfn.PERCENTILE.INC($E$2:$E$101,K40) -> 0
... A101: 4.95 | B101: 0 | C101: 0 | D101: 0 | E101: 0 | F101: 0 | G101: 0 | J101: 0.097 | K101: =J101 -> 0.097 | L101: =_xlfn.PERCENTILE.INC($B$2:$B$61,J101) -> 0 | P101: 0.097 | Q101: =P101 -> 0.097 | R101: =_xlfn.PERCENTILE.INC($E$2:$E$101,K105) -> 0
J102: 0.098 | K102: =J102 -> 0.098 | L102: =_xlfn.PERCENTILE.INC($B$2:$B$61,J102) -> 0 | P102: 0.098 | Q102: =P102 -> 0.098 | R102: =_xlfn.PERCENTILE.INC($E$2:$E$101,K106) -> 0
J103: 0.099 | K103: =J103 -> 0.099 | L103: =_xlfn.PERCENTILE.INC($B$2:$B$61,J103) -> 0 | P103: 0.099 | Q103: =P103 -> 0.099 | R103: =_xlfn.PERCENTILE.INC($E$2:$E$101,K107) -> 0
J104: 0.1 | K104: =J104 -> 0.1 | L104: =_xlfn.PERCENTILE.INC($B$2:$B$61,J104) -> 0 | P104: 0.1 | Q104: =P104 -> 0.1 | R104: =_xlfn.PERCENTILE.INC($E$2:$E$101,K108) -> 0
...

Sheet m16
A1: eta | B1: pdf_original | C1: error_original | D1: counts_original | E1: pdf_corregido | F1: error_corregido | G1: counts_corregido
A2: -4.95 | B2: 0 | C2: 0 | D2: 0 | E2: 0.0033470974 | F2: 0.00019421829 | G2: 297
A3: -4.85 | B3: 0 | C3: 0 | D3: 0 | E3: 0.0030878946 | F3: 0.00018654653 | G3: 274 | J3: PDF ORIGINAL | P3: PDF CORREGIDO
A4: -4.75 | B4: 0 | C4: 0 | D4: 0 | E4: 0.0036626486 | F4: 0.00020316719 | G4: 325 | J4: PERCENTILES | P4: PERCENTILES
A5: -4.65 | B5: 0 | C5: 0 | D5: 0 | E5: 0.0042486724 | F5: 0.00021881776 | G5: 377 | J5: 0.001 | K5: =J5 -> 0.001 | L5: =_xlfn.PERCENTILE.INC($B$2:$B$101,E9) -> 0 | N5: P95 | P5: 0.001 | Q5: =P5 -> 0.001 | R5: =_xlfn.PERCENTILE.INC($E$2:$E$101,K9) -> 0 | T5: P95
A6: -4.55 | B6: 0 | C6: 0 | D6: 0 | E6: 0.0042261331 | F6: 0.00021823657 | G6: 375 | J6: 0.002 | K6: =J6 -> 0.002 | L6: =_xlfn.PERCENTILE.INC($B$2:$B$61,J6) -> 0 | N6: =L979-L29 -> 1.7479943 | P6: 0.002 | Q6: =P6 -> 0.002 | R6: =_xlfn.PERCENTILE.INC($E$2:$E$101,K10) -> 0 | T6: =R979-R29 -> 0.46131976
A7: -4.45 | B7: 0 | C7: 0 | D7: 0 | E7: 0.0052178656 | F7: 0.00024249478 | G7: 463 | J7: 0.003 | K7: =J7 -> 0.003 | L7: =_xlfn.PERCENTILE.INC($B$2:$B$61,J7) -> 0 | N7: P90 | P7: 0.003 | Q7: =P7 -> 0.003 | R7: =_xlfn.PERCENTILE.INC($E$2:$E$101,K11) -> 0 | T7: P90
A8: -4.35 | B8: 0 | C8: 0 | D8: 0 | E8: 0.00578135 | F8: 0.00025525284 | G8: 513 | J8: 0.004 | K8: =J8 -> 0.004 | L8: =_xlfn.PERCENTILE.INC($B$2:$B$61,J8) -> 0 | N8: =L954-L54 -> 1.1065099 | P8: 0.004 | Q8: =P8 -> 0.004 | R8: =_xlfn.PERCENTILE.INC($E$2:$E$101,K12) -> 0 | T8: =R954-R54 -> 0.44453817
A9: -4.25 | B9: 0 | C9: 0 | D9: 0 | E9: 0.0063110254 | F9: 0.0002666895 | G9: 560 | J9: 0.005 | K9: =J9 -> 0.005 | L9: =_xlfn.PERCENTILE.INC($B$2:$B$61,J9) -> 0 | N9: P85 | P9: 0.005 | Q9: =P9 -> 0.005 | R9: =_xlfn.PERCENTILE.INC($E$2:$E$101,K13) -> 0 | T9: P85
A10: -4.15 | B10: 0 | C10: 0 | D10: 0 | E10: 0.007190061 | F10: 0.00028465724 | G10: 638 | J10: 0.006 | K10: =J10 -> 0.006 | L10: =_xlfn.PERCENTILE.INC($B$2:$B$61,J10) -> 0 | N10: =L929-L79 -> 0.87774211 | P10: 0.006 | Q10: =P10 -> 0.006 | R10: =_xlfn.PERCENTILE.INC($E$2:$E$101,K14) -> 0 | T10: =R929-R79 -> 0.43288256
A11: -4.05 | B11: 0 | C11: 0 | D11: 0 | E11: 0.0083508389 | F11: 0.00030677573 | G11: 741 | J11: 0.007 | K11: =J11 -> 0.007 | L11: =_xlfn.PERCENTILE.INC($B$2:$B$61,J11) -> 0 | N11: P80 | P11: 0.007 | Q11: =P11 -> 0.007 | R11: =_xlfn.PERCENTILE.INC($E$2:$E$101,K15) -> 0 | T11: P80
A12: -3.95 | B12: 0 | C12: 0 | D12: 0 | E12: 0.0094214593 | F12: 0.00032584798 | G12: 836 | J12: 0.008 | K12: =J12 -> 0.008 | L12: =_xlfn.PERCENTILE.INC($B$2:$B$61,J12) -> 0 | N12: =L904-L104 -> 0.44769326 | P12: 0.008 | Q12: =P12 -> 0.008 | R12: =_xlfn.PERCENTILE.INC($E$2:$E$101,K16) -> 0 | T12: =R904-R104 -> 0.40047053
A13: -3.85 | B13: 0 | C13: 0 | D13: 0 | E13: 0.0096355834 | F13: 0.00032953 | G13: 855 | J13: 0.009 | K13: =J13 -> 0.009 | L13: =_xlfn.PERCENTILE.INC($B$2:$B$61,J13) -> 0 | N13: P75 | P13: 0.009 | Q13: =P13 -> 0.009 | R13: =_xlfn.PERCENTILE.INC($E$2:$E$101,K17) -> 0 | T13: P75
A14: -3.75 | B14: 0 | C14: 0 | D14: 0 | E14: 0.011731745 | F14: 0.00036361121 | G14: 1041 | J14: 0.01 | K14: =J14 -> 0.01 | L14: =_xlfn.PERCENTILE.INC($B$2:$B$61,J14) -> 0 | N14: =L879-L129 -> 0.28548987 | P14: 0.01 | Q14: =P14 -> 0.01 | R14: =_xlfn.PERCENTILE.INC($E$2:$E$101,K18) -> 0 | T14: =R879-R129 -> 0.33890613
A15: -3.65 | B15: 0 | C15: 0 | D15: 0 | E15: 0.012351578 | F15: 0.00037309306 | G15: 1096 | J15: 0.011 | K15: =J15 -> 0.011 | L15: =_xlfn.PERCENTILE.INC($B$2:$B$61,J15) -> 0 | N15: P70 | P15: 0.011 | Q15: =P15 -> 0.011 | R15: =_xlfn.PERCENTILE.INC($E$2:$E$101,K19) -> 0 | T15: P70
A16: -3.55 | B16: 0 | C16: 0 | D16: 0 | E16: 0.014413931 | F16: 0.00040303909 | G16: 1279 | J16: 0.012 | K16: =J16 -> 0.012 | L16: =_xlfn.PERCENTILE.INC($B$2:$B$61,J16) -> 0 | N16: =L854-L154 -> 0.20994226 | P16: 0.012 | Q16: =P16 -> 0.012 | R16: =_xlfn.PERCENTILE.INC($E$2:$E$101,K20) -> 0 | T16: =R854-R154 -> 0.29033045
A17: -3.45 | B17: 0 | C17: 0 | D17: 0 | E17: 0.016318508 | F17: 0.00042884088 | G17: 1448 | J17: 0.013 | K17: =J17 -> 0.013 | L17: =_xlfn.PERCENTILE.INC($B$2:$B$61,J17) -> 0 | N17: P65 | P17: 0.013 | Q17: =P17 -> 0.013 | R17: =_xlfn.PERCENTILE.INC($E$2:$E$101,K21) -> 0 | T17: P65
A18: -3.35 | B18: 0 | C18: 0 | D18: 0 | E18: 0.017772298 | F18: 0.00044753576 | G18: 1577 | J18: 0.014 | K18: =J18 -> 0.014 | L18: =_xlfn.PERCENTILE.INC($B$2:$B$61,J18) -> 0 | N18: =L829-L179 -> 0.13772665 | P18: 0.014 | Q18: =P18 -> 0.014 | R18: =_xlfn.PERCENTILE.INC($E$2:$E$101,K22) -> 0 | T18: =R829-R179 -> 0.24489589
A19: -3.25 | B19: 0 | C19: 0 | D19: 0 | E19: 0.020296708 | F19: 0.00047826517 | G19: 1801 | J19: 0.015 | K19: =J19 -> 0.015 | L19: =_xlfn.PERCENTILE.INC($B$2:$B$61,J19) -> 0 | N19: P60 | P19: 0.015 | Q19: =P19 -> 0.015 | R19: =_xlfn.PERCENTILE.INC($E$2:$E$101,K23) -> 0 | T19: P60
A20: -3.15 | B20: 0 | C20: 0 | D20: 0 | E20: 0.022325252 | F20: 0.00050159608 | G20: 1981 | J20: 0.016 | K20: =J20 -> 0.016 | L20: =_xlfn.PERCENTILE.INC($B$2:$B$61,J20) -> 0 | N20: =L804-L204 -> 0.070595106 | P20: 0.016 | Q20: =P20 -> 0.016 | R20: =_xlfn.PERCENTILE.INC($E$2:$E$101,K24) -> 0 | T20: =R804-R204 -> 0.20010828
A21: -3.05 | B21: 0 | C21: 0 | D21: 0 | E21: 0.023970627 | F21: 0.00051975137 | G21: 2127 | J21: 0.017 | K21: =J21 -> 0.017 | L21: =_xlfn.PERCENTILE.INC($B$2:$B$61,J21) -> 0 | N21: P55 | P21: 0.017 | Q21: =P21 -> 0.017 | R21: =_xlfn.PERCENTILE.INC($E$2:$E$101,K25) -> 0 | T21: P55
A22: -2.95 | B22: 0 | C22: 0 | D22: 0 | E22: 0.025920283 | F22: 0.00054047526 | G22: 2300 | J22: 0.018 | K22: =J22 -> 0.018 | L22: =_xlfn.PERCENTILE.INC($B$2:$B$61,J22) -> 0 | N22: =L779-L229 -> 0.038413806 | P22: 0.018 | Q22: =P22 -> 0.018 | R22: =_xlfn.PERCENTILE.INC($E$2:$E$101,K26) -> 0 | T22: =R779-R229 -> 0.16238019
A23: -2.85 | B23: 0 | C23: 0 | D23: 0 | E23: 0.028715165 | F23: 0.00056886814 | G23: 2548 | J23: 0.019 | K23: =J23 -> 0.019 | L23: =_xlfn.PERCENTILE.INC($B$2:$B$61,J23) -> 0 | N23: P50 | P23: 0.019 | Q23: =P23 -> 0.019 | R23: =_xlfn.PERCENTILE.INC($E$2:$E$101,K27) -> 0 | T23: P50
A24: -2.75 | B24: 0 | C24: 0 | D24: 0 | E24: 0.033482243 | F24: 0.00061427554 | G24: 2971 | J24: 0.02 | K24: =J24 -> 0.02 | L24: =_xlfn.PERCENTILE.INC($B$2:$B$61,J24) -> 0 | N24: =L754-L254 -> 0.009958933 | P24: 0.02 | Q24: =P24 -> 0.02 | R24: =_xlfn.PERCENTILE.INC($E$2:$E$101,K28) -> 0 | T24: =R754-R254 -> 0.13818301
A25: -2.65 | B25: 0 | C25: 0 | D25: 0 | E25: 0.036682835 | F25: 0.00064296509 | G25: 3255 | J25: 0.021 | K25: =J25 -> 0.021 | L25: =_xlfn.PERCENTILE.INC($B$2:$B$61,J25) -> 0 | P25: 0.021 | Q25: =P25 -> 0.021 | R25: =_xlfn.PERCENTILE.INC($E$2:$E$101,K29) -> 0
A26: -2.55 | B26: 0 | C26: 0 | D26: 0 | E26: 0.041742925 | F26: 0.00068587881 | G26: 3704 | J26: 0.022 | K26: =J26 -> 0.022 | L26: =_xlfn.PERCENTILE.INC($B$2:$B$61,J26) -> 0 | P26: 0.022 | Q26: =P26 -> 0.022 | R26: =_xlfn.PERCENTILE.INC($E$2:$E$101,K30) -> 0
A27: -2.45 | B27: 0 | C27: 0 | D27: 0 | E27: 0.04518018 | F27: 0.00071355906 | G27: 4009 | J27: 0.023 | K27: =J27 -> 0.023 | L27: =_xlfn.PERCENTILE.INC($B$2:$B$61,J27) -> 0 | P27: 0.023 | Q27: =P27 -> 0.023 | R27: =_xlfn.PERCENTILE.INC($E$2:$E$101,K31) -> 0
A28: -2.35 | B28: 0 | C28: 0 | D28: 0 | E28: 0.048392041 | F28: 0.00073848711 | G28: 4294 | J28: 0.024 | K28: =J28 -> 0.024 | L28: =_xlfn.PERCENTILE.INC($B$2:$B$61,J28) -> 0 | P28: 0.024 | Q28: =P28 -> 0.024 | R28: =_xlfn.PERCENTILE.INC($E$2:$E$101,K32) -> 0
A29: -2.25 | B29: 0 | C29: 0 | D29: 0 | E29: 0.054184661 | F29: 0.00078143728 | G29: 4808 | J29: 0.025 | K29: =J29 -> 0.025 | L29: =_xlfn.PERCENTILE.INC($B$2:$B$61,J29) -> 0 | P29: 0.025 | Q29: =P29 -> 0.025 | R29: =_xlfn.PERCENTILE.INC($E$2:$E$101,K33) -> 0
A30: -2.15 | B30: 0 | C30: 0 | D30: 0 | E30: 0.060946473 | F30: 0.00082876278 | G30: 5408 | J30: 0.026 | K30: =J30 -> 0.026 | L30: =_xlfn.PERCENTILE.INC($B$2:$B$61,J30) -> 0 | P30: 0.026 | Q30: =P30 -> 0.026 | R30: =_xlfn.PERCENTILE.INC($E$2:$E$101,K34) -> 0
A31: -2.05 | B31: 0 | C31: 0 | D31: 0 | E31: 0.067167341 | F31: 0.0008700316 | G31: 5960 | J31: 0.027 | K31: =J31 -> 0.027 | L31: =_xlfn.PERCENTILE.INC($B$2:$B$61,J31) -> 0 | P31: 0.027 | Q31: =P31 -> 0.027 | R31: =_xlfn.PERCENTILE.INC($E$2:$E$101,K35) -> 0
A32: -1.95 | B32: 0 | C32: 0 | D32: 0 | E32: 0.077174824 | F32: 0.00093259649 | G32: 6848 | J32: 0.028 | K32: =J32 -> 0.028 | L32: =_xlfn.PERCENTILE.INC($B$2:$B$61,J32) -> 0 | P32: 0.028 | Q32: =P32 -> 0.028 | R32: =_xlfn.PERCENTILE.INC($E$2:$E$101,K36) -> 0
A33: -1.85 | B33: 0 | C33: 0 | D33: 0 | E33: 0.091025271 | F33: 0.0010128309 | G33: 8077 | J33: 0.029 | K33: =J33 -> 0.029 | L33: =_xlfn.PERCENTILE.INC($B$2:$B$61,J33) -> 0 | P33: 0.029 | Q33: =P33 -> 0.029 | R33: =_xlfn.PERCENTILE.INC($E$2:$E$101,K37) -> 0
A34: -1.75 | B34: 0 | C34: 0 | D34: 0 | E34: 0.1068141 | F34: 0.0010971607 | G34: 9478 | J34: 0.03 | K34: =J34 -> 0.03 | L34: =_xlfn.PERCENTILE.INC($B$2:$B$61,J34) -> 0 | P34: 0.03 | Q34: =P34 -> 0.03 | R34: =_xlfn.PERCENTILE.INC($E$2:$E$101,K38) -> 0
A35: -1.65 | B35: 0 | C35: 0 | D35: 0 | E35: 0.12392149 | F35: 0.0011817599 | G35: 10996 | J35: 0.031 | K35: =J35 -> 0.031 | L35: =_xlfn.PERCENTILE.INC($B$2:$B$61,J35) -> 0 | P35: 0.031 | Q35: =P35 -> 0.031 | R35: =_xlfn.PERCENTILE.INC($E$2:$E$101,K39) -> 0
A36: -1.55 | B36: 0 | C36: 0 | D36: 0 | E36: 0.14211077 | F36: 0.0012655212 | G36: 12610 | J36: 0.032 | K36: =J36 -> 0.032 | L36: =_xlfn.PERCENTILE.INC($B$2:$B$61,J36) -> 0 | P36: 0.032 | Q36: =P36 -> 0.032 | R36: =_xlfn.PERCENTILE.INC($E$2:$E$101,K40) -> 0
... A101: 4.95 | B101: 0 | C101: 0 | D101: 0 | E101: 0 | F101: 0 | G101: 0 | J101: 0.097 | K101: =J101 -> 0.097 | L101: =_xlfn.PERCENTILE.INC($B$2:$B$61,J101) -> 0 | P101: 0.097 | Q101: =P101 -> 0.097 | R101: =_xlfn.PERCENTILE.INC($E$2:$E$101,K105) -> 0.00013519118
J102: 0.098 | K102: =J102 -> 0.098 | L102: =_xlfn.PERCENTILE.INC($B$2:$B$61,J102) -> 0 | P102: 0.098 | Q102: =P102 -> 0.098 | R102: =_xlfn.PERCENTILE.INC($E$2:$E$101,K106) -> 0.00013744512
J103: 0.099 | K103: =J103 -> 0.099 | L103: =_xlfn.PERCENTILE.INC($B$2:$B$61,J103) -> 0 | P103: 0.099 | Q103: =P103 -> 0.099 | R103: =_xlfn.PERCENTILE.INC($E$2:$E$101,K107) -> 0.00013967651
J104: 0.1 | K104: =J104 -> 0.1 | L104: =_xlfn.PERCENTILE.INC($B$2:$B$61,J104) -> 0 | P104: 0.1 | Q104: =P104 -> 0.1 | R104: =_xlfn.PERCENTILE.INC($E$2:$E$101,K108) -> 0.00014190791
...

Sheet m17
A1: eta | B1: pdf_original | C1: error_original | D1: counts_original | E1: pdf_corregido | F1: error_corregido | G1: counts_corregido
A2: -4.95 | B2: 0 | C2: 0 | D2: 0 | E2: 0.0020370808 | F2: 0.00011031411 | G2: 341
A3: -4.85 | B3: 0 | C3: 0 | D3: 0 | E3: 0.0024313546 | F3: 0.00012051777 | G3: 407 | J3: PDF ORIGINAL | P3: PDF CORREGIDO
A4: -4.75 | B4: 0 | C4: 0 | D4: 0 | E4: 0.0026942037 | F4: 0.0001268651 | G4: 451 | J4: PERCENTILES | P4: PERCENTILES
A5: -4.65 | B5: 0 | C5: 0 | D5: 0 | E5: 0.002795759 | F5: 0.00012923401 | G5: 468 | J5: 0.001 | K5: =J5 -> 0.001 | L5: =_xlfn.PERCENTILE.INC($B$2:$B$101,E9) -> 0 | N5: P95 | P5: 0.001 | Q5: =P5 -> 0.001 | R5: =_xlfn.PERCENTILE.INC($E$2:$E$101,K9) -> 0 | T5: P95
A6: -4.55 | B6: 0 | C6: 0 | D6: 0 | E6: 0.0033632742 | F6: 0.00014174511 | G6: 563 | J6: 0.002 | K6: =J6 -> 0.002 | L6: =_xlfn.PERCENTILE.INC($B$2:$B$61,J6) -> 0 | N6: =L979-L29 -> 0.96360398 | P6: 0.002 | Q6: =P6 -> 0.002 | R6: =_xlfn.PERCENTILE.INC($E$2:$E$101,K10) -> 0 | T6: =R979-R29 -> 0.62239348
A7: -4.45 | B7: 0 | C7: 0 | D7: 0 | E7: 0.0040084494 | F7: 0.00015474447 | G7: 671 | J7: 0.003 | K7: =J7 -> 0.003 | L7: =_xlfn.PERCENTILE.INC($B$2:$B$61,J7) -> 0 | N7: P90 | P7: 0.003 | Q7: =P7 -> 0.003 | R7: =_xlfn.PERCENTILE.INC($E$2:$E$101,K11) -> 0 | T7: P90
A8: -4.35 | B8: 0 | C8: 0 | D8: 0 | E8: 0.003871051 | F8: 0.00015206924 | G8: 648 | J8: 0.004 | K8: =J8 -> 0.004 | L8: =_xlfn.PERCENTILE.INC($B$2:$B$61,J8) -> 0 | N8: =L954-L54 -> 0.82229441 | P8: 0.004 | Q8: =P8 -> 0.004 | R8: =_xlfn.PERCENTILE.INC($E$2:$E$101,K12) -> 0 | T8: =R954-R54 -> 0.53876536
A9: -4.25 | B9: 5.8960735e-06 | C9: 5.8960735e-06 | D9: 1 | E9: 0.0041996124 | F9: 0.00015839138 | G9: 703 | J9: 0.005 | K9: =J9 -> 0.005 | L9: =_xlfn.PERCENTILE.INC($B$2:$B$61,J9) -> 0 | N9: P85 | P9: 0.005 | Q9: =P9 -> 0.005 | R9: =_xlfn.PERCENTILE.INC($E$2:$E$101,K13) -> 0 | T9: P85
A10: -4.15 | B10: 0 | C10: 0 | D10: 0 | E10: 0.0046476507 | F10: 0.00016662635 | G10: 778 | J10: 0.006 | K10: =J10 -> 0.006 | L10: =_xlfn.PERCENTILE.INC($B$2:$B$61,J10) -> 0 | N10: =L929-L79 -> 0.77883298 | P10: 0.006 | Q10: =P10 -> 0.006 | R10: =_xlfn.PERCENTILE.INC($E$2:$E$101,K14) -> 0 | T10: =R929-R79 -> 0.42573209
A11: -4.05 | B11: 0 | C11: 0 | D11: 0 | E11: 0.0055317797 | F11: 0.00018178556 | G11: 926 | J11: 0.007 | K11: =J11 -> 0.007 | L11: =_xlfn.PERCENTILE.INC($B$2:$B$61,J11) -> 0 | N11: P80 | P11: 0.007 | Q11: =P11 -> 0.007 | R11: =_xlfn.PERCENTILE.INC($E$2:$E$101,K15) -> 0 | T11: P80
A12: -3.95 | B12: 0 | C12: 0 | D12: 0 | E12: 0.006248641 | F12: 0.00019320561 | G12: 1046 | J12: 0.008 | K12: =J12 -> 0.008 | L12: =_xlfn.PERCENTILE.INC($B$2:$B$61,J12) -> 0 | N12: =L904-L104 -> 0.68645684 | P12: 0.008 | Q12: =P12 -> 0.008 | R12: =_xlfn.PERCENTILE.INC($E$2:$E$101,K16) -> 0 | T12: =R904-R104 -> 0.35147231
A13: -3.85 | B13: 0 | C13: 0 | D13: 0 | E13: 0.0068758946 | F13: 0.00020267097 | G13: 1151 | J13: 0.009 | K13: =J13 -> 0.009 | L13: =_xlfn.PERCENTILE.INC($B$2:$B$61,J13) -> 0 | N13: P75 | P13: 0.009 | Q13: =P13 -> 0.009 | R13: =_xlfn.PERCENTILE.INC($E$2:$E$101,K17) -> 0 | T13: P75
A14: -3.75 | B14: 0 | C14: 0 | D14: 0 | E14: 0.0078854742 | F14: 0.00021704054 | G14: 1320 | J14: 0.01 | K14: =J14 -> 0.01 | L14: =_xlfn.PERCENTILE.INC($B$2:$B$61,J14) -> 0 | N14: =L879-L129 -> 0.65837325 | P14: 0.01 | Q14: =P14 -> 0.01 | R14: =_xlfn.PERCENTILE.INC($E$2:$E$101,K18) -> 0 | T14: =R879-R129 -> 0.34156787
A15: -3.65 | B15: 5.8960735e-06 | C15: 5.8960735e-06 | D15: 1 | E15: 0.0084350679 | F15: 0.00022447668 | G15: 1412 | J15: 0.011 | K15: =J15 -> 0.011 | L15: =_xlfn.PERCENTILE.INC($B$2:$B$61,J15) -> 0 | N15: P70 | P15: 0.011 | Q15: =P15 -> 0.011 | R15: =_xlfn.PERCENTILE.INC($E$2:$E$101,K19) -> 0 | T15: P70
A16: -3.55 | B16: 0 | C16: 0 | D16: 0 | E16: 0.0098448951 | F16: 0.00024251158 | G16: 1648 | J16: 0.012 | K16: =J16 -> 0.012 | L16: =_xlfn.PERCENTILE.INC($B$2:$B$61,J16) -> 0 | N16: =L854-L154 -> 0.52155487 | P16: 0.012 | Q16: =P16 -> 0.012 | R16: =_xlfn.PERCENTILE.INC($E$2:$E$101,K20) -> 0 | T16: =R854-R154 -> 0.3272113
A17: -3.45 | B17: 0 | C17: 0 | D17: 0 | E17: 0.010543835 | F17: 0.00025097256 | G17: 1765 | J17: 0.013 | K17: =J17 -> 0.013 | L17: =_xlfn.PERCENTILE.INC($B$2:$B$61,J17) -> 0 | N17: P65 | P17: 0.013 | Q17: =P17 -> 0.013 | R17: =_xlfn.PERCENTILE.INC($E$2:$E$101,K21) -> 0 | T17: P65
A18: -3.35 | B18: 0 | C18: 0 | D18: 0 | E18: 0.011929767 | F18: 0.00026695799 | G18: 1997 | J18: 0.014 | K18: =J18 -> 0.014 | L18: =_xlfn.PERCENTILE.INC($B$2:$B$61,J18) -> 0 | N18: =L829-L179 -> 0.40285703 | P18: 0.014 | Q18: =P18 -> 0.014 | R18: =_xlfn.PERCENTILE.INC($E$2:$E$101,K22) -> 0 | T18: =R829-R179 -> 0.25188877
A19: -3.25 | B19: 0 | C19: 0 | D19: 0 | E19: 0.013363489 | F19: 0.00028254451 | G19: 2237 | J19: 0.015 | K19: =J19 -> 0.015 | L19: =_xlfn.PERCENTILE.INC($B$2:$B$61,J19) -> 0 | N19: P60 | P19: 0.015 | Q19: =P19 -> 0.015 | R19: =_xlfn.PERCENTILE.INC($E$2:$E$101,K23) -> 0 | T19: P60
A20: -3.15 | B20: 0 | C20: 0 | D20: 0 | E20: 0.013727894 | F20: 0.00028637091 | G20: 2298 | J20: 0.016 | K20: =J20 -> 0.016 | L20: =_xlfn.PERCENTILE.INC($B$2:$B$61,J20) -> 0 | N20: =L804-L204 -> 0.29609609 | P20: 0.016 | Q20: =P20 -> 0.016 | R20: =_xlfn.PERCENTILE.INC($E$2:$E$101,K24) -> 0 | T20: =R804-R204 -> 0.17451044
A21: -3.05 | B21: 0 | C21: 0 | D21: 0 | E21: 0.015878478 | F21: 0.00030798628 | G21: 2658 | J21: 0.017 | K21: =J21 -> 0.017 | L21: =_xlfn.PERCENTILE.INC($B$2:$B$61,J21) -> 0 | N21: P55 | P21: 0.017 | Q21: =P21 -> 0.017 | R21: =_xlfn.PERCENTILE.INC($E$2:$E$101,K25) -> 0 | T21: P55
A22: -2.95 | B22: 0 | C22: 0 | D22: 0 | E22: 0.018620472 | F22: 0.00033352031 | G22: 3117 | J22: 0.018 | K22: =J22 -> 0.018 | L22: =_xlfn.PERCENTILE.INC($B$2:$B$61,J22) -> 0 | N22: =L779-L229 -> 0.20458446 | P22: 0.018 | Q22: =P22 -> 0.018 | R22: =_xlfn.PERCENTILE.INC($E$2:$E$101,K26) -> 0 | T22: =R779-R229 -> 0.12950086
A23: -2.85 | B23: 0 | C23: 0 | D23: 0 | E23: 0.018638394 | F23: 0.00033368077 | G23: 3120 | J23: 0.019 | K23: =J23 -> 0.019 | L23: =_xlfn.PERCENTILE.INC($B$2:$B$61,J23) -> 0 | N23: P50 | P23: 0.019 | Q23: =P23 -> 0.019 | R23: =_xlfn.PERCENTILE.INC($E$2:$E$101,K27) -> 0 | T23: P50
A24: -2.75 | B24: 0 | C24: 0 | D24: 0 | E24: 0.019665895 | F24: 0.000342755 | G24: 3292 | J24: 0.02 | K24: =J24 -> 0.02 | L24: =_xlfn.PERCENTILE.INC($B$2:$B$61,J24) -> 0 | N24: =L754-L254 -> 0.19434932 | P24: 0.02 | Q24: =P24 -> 0.02 | R24: =_xlfn.PERCENTILE.INC($E$2:$E$101,K28) -> 0 | T24: =R754-R254 -> 0.094522965
A25: -2.65 | B25: 0 | C25: 0 | D25: 0 | E25: 0.021254937 | F25: 0.00035633367 | G25: 3558 | J25: 0.021 | K25: =J25 -> 0.021 | L25: =_xlfn.PERCENTILE.INC($B$2:$B$61,J25) -> 0 | P25: 0.021 | Q25: =P25 -> 0.021 | R25: =_xlfn.PERCENTILE.INC($E$2:$E$101,K29) -> 0
A26: -2.55 | B26: 5.8960735e-06 | C26: 5.8960735e-06 | D26: 1 | E26: 0.021726871 | F26: 0.00036026787 | G26: 3637 | J26: 0.022 | K26: =J26 -> 0.022 | L26: =_xlfn.PERCENTILE.INC($B$2:$B$61,J26) -> 0 | P26: 0.022 | Q26: =P26 -> 0.022 | R26: =_xlfn.PERCENTILE.INC($E$2:$E$101,K30) -> 0
A27: -2.45 | B27: 5.8960735e-06 | C27: 5.8960735e-06 | D27: 1 | E27: 0.022383994 | F27: 0.00036567539 | G27: 3747 | J27: 0.023 | K27: =J27 -> 0.023 | L27: =_xlfn.PERCENTILE.INC($B$2:$B$61,J27) -> 0 | P27: 0.023 | Q27: =P27 -> 0.023 | R27: =_xlfn.PERCENTILE.INC($E$2:$E$101,K31) -> 0
A28: -2.35 | B28: 5.8960735e-06 | C28: 5.8960735e-06 | D28: 1 | E28: 0.025394811 | F28: 0.0003894928 | G28: 4251 | J28: 0.024 | K28: =J28 -> 0.024 | L28: =_xlfn.PERCENTILE.INC($B$2:$B$61,J28) -> 0 | P28: 0.024 | Q28: =P28 -> 0.024 | R28: =_xlfn.PERCENTILE.INC($E$2:$E$101,K32) -> 0
A29: -2.25 | B29: 0 | C29: 0 | D29: 0 | E29: 0.031374629 | F29: 0.00043292857 | G29: 5252 | J29: 0.025 | K29: =J29 -> 0.025 | L29: =_xlfn.PERCENTILE.INC($B$2:$B$61,J29) -> 0 | P29: 0.025 | Q29: =P29 -> 0.025 | R29: =_xlfn.PERCENTILE.INC($E$2:$E$101,K33) -> 0
A30: -2.15 | B30: 0 | C30: 0 | D30: 0 | E30: 0.038770248 | F30: 0.00048125609 | G30: 6490 | J30: 0.026 | K30: =J30 -> 0.026 | L30: =_xlfn.PERCENTILE.INC($B$2:$B$61,J30) -> 0 | P30: 0.026 | Q30: =P30 -> 0.026 | R30: =_xlfn.PERCENTILE.INC($E$2:$E$101,K34) -> 0
A31: -2.05 | B31: 0 | C31: 0 | D31: 0 | E31: 0.040693826 | F31: 0.00049305028 | G31: 6812 | J31: 0.027 | K31: =J31 -> 0.027 | L31: =_xlfn.PERCENTILE.INC($B$2:$B$61,J31) -> 0 | P31: 0.027 | Q31: =P31 -> 0.027 | R31: =_xlfn.PERCENTILE.INC($E$2:$E$101,K35) -> 0
A32: -1.95 | B32: 1.1792147e-05 | C32: 8.338307e-06 | D32: 2 | E32: 0.051823098 | F32: 0.00055640193 | G32: 8675 | J32: 0.028 | K32: =J32 -> 0.028 | L32: =_xlfn.PERCENTILE.INC($B$2:$B$61,J32) -> 0 | P32: 0.028 | Q32: =P32 -> 0.028 | R32: =_xlfn.PERCENTILE.INC($E$2:$E$101,K36) -> 0
A33: -1.85 | B33: 0 | C33: 0 | D33: 0 | E33: 0.059350141 | F33: 0.00059543975 | G33: 9935 | J33: 0.029 | K33: =J33 -> 0.029 | L33: =_xlfn.PERCENTILE.INC($B$2:$B$61,J33) -> 0 | P33: 0.029 | Q33: =P33 -> 0.029 | R33: =_xlfn.PERCENTILE.INC($E$2:$E$101,K37) -> 0
A34: -1.75 | B34: 5.8960735e-06 | C34: 5.8960735e-06 | D34: 1 | E34: 0.075413808 | F34: 0.00067120067 | G34: 12624 | J34: 0.03 | K34: =J34 -> 0.03 | L34: =_xlfn.PERCENTILE.INC($B$2:$B$61,J34) -> 0 | P34: 0.03 | Q34: =P34 -> 0.03 | R34: =_xlfn.PERCENTILE.INC($E$2:$E$101,K38) -> 0
A35: -1.65 | B35: 1.1792147e-05 | C35: 8.338307e-06 | D35: 2 | E35: 0.08791109 | F35: 0.00072468417 | G35: 14716 | J35: 0.031 | K35: =J35 -> 0.031 | L35: =_xlfn.PERCENTILE.INC($B$2:$B$61,J35) -> 0 | P35: 0.031 | Q35: =P35 -> 0.031 | R35: =_xlfn.PERCENTILE.INC($E$2:$E$101,K39) -> 0
A36: -1.55 | B36: 5.8960735e-06 | C36: 5.8960735e-06 | D36: 1 | E36: 0.10194365 | F36: 0.00078038162 | G36: 17065 | J36: 0.032 | K36: =J36 -> 0.032 | L36: =_xlfn.PERCENTILE.INC($B$2:$B$61,J36) -> 0 | P36: 0.032 | Q36: =P36 -> 0.032 | R36: =_xlfn.PERCENTILE.INC($E$2:$E$101,K40) -> 0
... A101: 4.95 | B101: 0 | C101: 0 | D101: 0 | E101: 0 | F101: 0 | G101: 0 | J101: 0.097 | K101: =J101 -> 0.097 | L101: =_xlfn.PERCENTILE.INC($B$2:$B$61,J101) -> 0 | P101: 0.097 | Q101: =P101 -> 0.097 | R101: =_xlfn.PERCENTILE.INC($E$2:$E$101,K105) -> 0
J102: 0.098 | K102: =J102 -> 0.098 | L102: =_xlfn.PERCENTILE.INC($B$2:$B$61,J102) -> 0 | P102: 0.098 | Q102: =P102 -> 0.098 | R102: =_xlfn.PERCENTILE.INC($E$2:$E$101,K106) -> 4.6834938e-06
J103: 0.099 | K103: =J103 -> 0.099 | L103: =_xlfn.PERCENTILE.INC($B$2:$B$61,J103) -> 0 | P103: 0.099 | Q103: =P103 -> 0.099 | R103: =_xlfn.PERCENTILE.INC($E$2:$E$101,K107) -> 9.4147783e-06
J104: 0.1 | K104: =J104 -> 0.1 | L104: =_xlfn.PERCENTILE.INC($B$2:$B$61,J104) -> 0 | P104: 0.1 | Q104: =P104 -> 0.1 | R104: =_xlfn.PERCENTILE.INC($E$2:$E$101,K108) -> 1.4146063e-05
...

Sheet monob1
A1: eta | B1: pdf_original | C1: error_original | D1: counts_original | E1: pdf_corregido | F1: error_corregido | G1: counts_corregido
A2: -4.95 | B2: 0 | C2: 0 | D2: 0 | E2: 0.0048933299 | F2: 0.00027101648 | G2: 326
A3: -4.85 | B3: 0 | C3: 0 | D3: 0 | E3: 0.0048332891 | F3: 0.00026934867 | G3: 322 | J3: PDF ORIGINAL | P3: PDF CORREGIDO
A4: -4.75 | B4: 0 | C4: 0 | D4: 0 | E4: 0.0062142288 | F4: 0.00030541268 | G4: 414 | J4: PERCENTILES | P4: PERCENTILES
A5: -4.65 | B5: 0 | C5: 0 | D5: 0 | E5: 0.0064694024 | F5: 0.00031162015 | G5: 431 | J5: 0.001 | K5: =J5 -> 0.001 | L5: =_xlfn.PERCENTILE.INC($B$2:$B$101,E9) -> 0 | N5: P95 | P5: 0.001 | Q5: =P5 -> 0.001 | R5: =_xlfn.PERCENTILE.INC($E$2:$E$101,K9) -> 0 | T5: P95
A6: -4.55 | B6: 0 | C6: 0 | D6: 0 | E6: 0.0084957814 | F6: 0.00035710433 | G6: 566 | J6: 0.002 | K6: =J6 -> 0.002 | L6: =_xlfn.PERCENTILE.INC($B$2:$B$61,J6) -> 0 | N6: =L979-L29 -> 0.85587136 | P6: 0.002 | Q6: =P6 -> 0.002 | R6: =_xlfn.PERCENTILE.INC($E$2:$E$101,K10) -> 0 | T6: =R979-R29 -> 0.40516935
A7: -4.45 | B7: 0 | C7: 0 | D7: 0 | E7: 0.0090211389 | F7: 0.00036797993 | G7: 601 | J7: 0.003 | K7: =J7 -> 0.003 | L7: =_xlfn.PERCENTILE.INC($B$2:$B$61,J7) -> 0 | N7: P90 | P7: 0.003 | Q7: =P7 -> 0.003 | R7: =_xlfn.PERCENTILE.INC($E$2:$E$101,K11) -> 0 | T7: P90
A8: -4.35 | B8: 0 | C8: 0 | D8: 0 | E8: 0.010717293 | F8: 0.00040108461 | G8: 714 | J8: 0.004 | K8: =J8 -> 0.004 | L8: =_xlfn.PERCENTILE.INC($B$2:$B$61,J8) -> 0 | N8: =L954-L54 -> 0.81449446 | P8: 0.004 | Q8: =P8 -> 0.004 | R8: =_xlfn.PERCENTILE.INC($E$2:$E$101,K12) -> 0 | T8: =R954-R54 -> 0.38214004
A9: -4.25 | B9: 0 | C9: 0 | D9: 0 | E9: 0.011422773 | F9: 0.0004140752 | G9: 761 | J9: 0.005 | K9: =J9 -> 0.005 | L9: =_xlfn.PERCENTILE.INC($B$2:$B$61,J9) -> 0 | N9: P85 | P9: 0.005 | Q9: =P9 -> 0.005 | R9: =_xlfn.PERCENTILE.INC($E$2:$E$101,K13) -> 0 | T9: P85
A10: -4.15 | B10: 0 | C10: 0 | D10: 0 | E10: 0.012878764 | F10: 0.00043967375 | G10: 858 | J10: 0.006 | K10: =J10 -> 0.006 | L10: =_xlfn.PERCENTILE.INC($B$2:$B$61,J10) -> 0 | N10: =L929-L79 -> 0.74172706 | P10: 0.006 | Q10: =P10 -> 0.006 | R10: =_xlfn.PERCENTILE.INC($E$2:$E$101,K14) -> 0 | T10: =R929-R79 -> 0.36627022
A11: -4.05 | B11: 0 | C11: 0 | D11: 0 | E11: 0.01332907 | F11: 0.00044729432 | G11: 888 | J11: 0.007 | K11: =J11 -> 0.007 | L11: =_xlfn.PERCENTILE.INC($B$2:$B$61,J11) -> 0 | N11: P80 | P11: 0.007 | Q11: =P11 -> 0.007 | R11: =_xlfn.PERCENTILE.INC($E$2:$E$101,K15) -> 0 | T11: P80
A12: -3.95 | B12: 0 | C12: 0 | D12: 0 | E12: 0.016976553 | F12: 0.00050479867 | G12: 1131 | J12: 0.008 | K12: =J12 -> 0.008 | L12: =_xlfn.PERCENTILE.INC($B$2:$B$61,J12) -> 0 | N12: =L904-L104 -> 0.62091173 | P12: 0.008 | Q12: =P12 -> 0.008 | R12: =_xlfn.PERCENTILE.INC($E$2:$E$101,K16) -> 0 | T12: =R904-R104 -> 0.34115732
A13: -3.85 | B13: 0 | C13: 0 | D13: 0 | E13: 0.018537615 | F13: 0.00052749746 | G13: 1235 | J13: 0.009 | K13: =J13 -> 0.009 | L13: =_xlfn.PERCENTILE.INC($B$2:$B$61,J13) -> 0 | N13: P75 | P13: 0.009 | Q13: =P13 -> 0.009 | R13: =_xlfn.PERCENTILE.INC($E$2:$E$101,K17) -> 0 | T13: P75
A14: -3.75 | B14: 0 | C14: 0 | D14: 0 | E14: 0.021314505 | F14: 0.00056562822 | G14: 1420 | J14: 0.01 | K14: =J14 -> 0.01 | L14: =_xlfn.PERCENTILE.INC($B$2:$B$61,J14) -> 0 | N14: =L879-L129 -> 0.5677814 | P14: 0.01 | Q14: =P14 -> 0.01 | R14: =_xlfn.PERCENTILE.INC($E$2:$E$101,K18) -> 0 | T14: =R879-R129 -> 0.31624569
A15: -3.65 | B15: 0 | C15: 0 | D15: 0 | E15: 0.025442313 | F15: 0.0006179762 | G15: 1695 | J15: 0.011 | K15: =J15 -> 0.011 | L15: =_xlfn.PERCENTILE.INC($B$2:$B$61,J15) -> 0 | N15: P70 | P15: 0.011 | Q15: =P15 -> 0.011 | R15: =_xlfn.PERCENTILE.INC($E$2:$E$101,K19) -> 0 | T15: P70
A16: -3.55 | B16: 0 | C16: 0 | D16: 0 | E16: 0.026282886 | F16: 0.0006281017 | G16: 1751 | J16: 0.012 | K16: =J16 -> 0.012 | L16: =_xlfn.PERCENTILE.INC($B$2:$B$61,J16) -> 0 | N16: =L854-L154 -> 0.56136265 | P16: 0.012 | Q16: =P16 -> 0.012 | R16: =_xlfn.PERCENTILE.INC($E$2:$E$101,K20) -> 0 | T16: =R854-R154 -> 0.29655879
A17: -3.45 | B17: 0 | C17: 0 | D17: 0 | E17: 0.03078595 | F17: 0.0006797821 | G17: 2051 | J17: 0.013 | K17: =J17 -> 0.013 | L17: =_xlfn.PERCENTILE.INC($B$2:$B$61,J17) -> 0 | N17: P65 | P17: 0.013 | Q17: =P17 -> 0.013 | R17: =_xlfn.PERCENTILE.INC($E$2:$E$101,K21) -> 0 | T17: P65
A18: -3.35 | B18: 0 | C18: 0 | D18: 0 | E18: 0.034868728 | F18: 0.00072345497 | G18: 2323 | J18: 0.014 | K18: =J18 -> 0.014 | L18: =_xlfn.PERCENTILE.INC($B$2:$B$61,J18) -> 0 | N18: =L829-L179 -> 0.49605227 | P18: 0.014 | Q18: =P18 -> 0.014 | R18: =_xlfn.PERCENTILE.INC($E$2:$E$101,K22) -> 0 | T18: =R829-R179 -> 0.26629563
A19: -3.25 | B19: 0 | C19: 0 | D19: 0 | E19: 0.038576251 | F19: 0.00076094533 | G19: 2570 | J19: 0.015 | K19: =J19 -> 0.015 | L19: =_xlfn.PERCENTILE.INC($B$2:$B$61,J19) -> 0 | N19: P60 | P19: 0.015 | Q19: =P19 -> 0.015 | R19: =_xlfn.PERCENTILE.INC($E$2:$E$101,K23) -> 0 | T19: P60
A20: -3.15 | B20: 0 | C20: 0 | D20: 0 | E20: 0.043559642 | F20: 0.00080860347 | G20: 2902 | J20: 0.016 | K20: =J20 -> 0.016 | L20: =_xlfn.PERCENTILE.INC($B$2:$B$61,J20) -> 0 | N20: =L804-L204 -> 0.34380988 | P20: 0.016 | Q20: =P20 -> 0.016 | R20: =_xlfn.PERCENTILE.INC($E$2:$E$101,K24) -> 0 | T20: =R804-R204 -> 0.22390437
A21: -3.05 | B21: 0 | C21: 0 | D21: 0 | E21: 0.047762502 | F21: 0.00084671448 | G21: 3182 | J21: 0.017 | K21: =J21 -> 0.017 | L21: =_xlfn.PERCENTILE.INC($B$2:$B$61,J21) -> 0 | N21: P55 | P21: 0.017 | Q21: =P21 -> 0.017 | R21: =_xlfn.PERCENTILE.INC($E$2:$E$101,K25) -> 0 | T21: P55
A22: -2.95 | B22: 0 | C22: 0 | D22: 0 | E22: 0.051229862 | F22: 0.00087691004 | G22: 3413 | J22: 0.018 | K22: =J22 -> 0.018 | L22: =_xlfn.PERCENTILE.INC($B$2:$B$61,J22) -> 0 | N22: =L779-L229 -> 0.27702428 | P22: 0.018 | Q22: =P22 -> 0.018 | R22: =_xlfn.PERCENTILE.INC($E$2:$E$101,K26) -> 0 | T22: =R779-R229 -> 0.18747184
A23: -2.85 | B23: 0 | C23: 0 | D23: 0 | E23: 0.054276935 | F23: 0.00090261201 | G23: 3616 | J23: 0.019 | K23: =J23 -> 0.019 | L23: =_xlfn.PERCENTILE.INC($B$2:$B$61,J23) -> 0 | N23: P50 | P23: 0.019 | Q23: =P23 -> 0.019 | R23: =_xlfn.PERCENTILE.INC($E$2:$E$101,K27) -> 0 | T23: P50
A24: -2.75 | B24: 0 | C24: 0 | D24: 0 | E24: 0.057864377 | F24: 0.0009319639 | G24: 3855 | J24: 0.02 | K24: =J24 -> 0.02 | L24: =_xlfn.PERCENTILE.INC($B$2:$B$61,J24) -> 0 | N24: =L754-L254 -> 0.22748931 | P24: 0.02 | Q24: =P24 -> 0.02 | R24: =_xlfn.PERCENTILE.INC($E$2:$E$101,K28) -> 0 | T24: =R754-R254 -> 0.16268911
A25: -2.65 | B25: 0 | C25: 0 | D25: 0 | E25: 0.061887114 | F25: 0.00096381474 | G25: 4123 | J25: 0.021 | K25: =J25 -> 0.021 | L25: =_xlfn.PERCENTILE.INC($B$2:$B$61,J25) -> 0 | P25: 0.021 | Q25: =P25 -> 0.021 | R25: =_xlfn.PERCENTILE.INC($E$2:$E$101,K29) -> 0
A26: -2.55 | B26: 0 | C26: 0 | D26: 0 | E26: 0.064513902 | F26: 0.00098405665 | G26: 4298 | J26: 0.022 | K26: =J26 -> 0.022 | L26: =_xlfn.PERCENTILE.INC($B$2:$B$61,J26) -> 0 | P26: 0.022 | Q26: =P26 -> 0.022 | R26: =_xlfn.PERCENTILE.INC($E$2:$E$101,K30) -> 0
A27: -2.45 | B27: 0 | C27: 0 | D27: 0 | E27: 0.065384494 | F27: 0.00099067415 | G27: 4356 | J27: 0.023 | K27: =J27 -> 0.023 | L27: =_xlfn.PERCENTILE.INC($B$2:$B$61,J27) -> 0 | P27: 0.023 | Q27: =P27 -> 0.023 | R27: =_xlfn.PERCENTILE.INC($E$2:$E$101,K31) -> 0
A28: -2.35 | B28: 0 | C28: 0 | D28: 0 | E28: 0.068356517 | F28: 0.0010129393 | G28: 4554 | J28: 0.024 | K28: =J28 -> 0.024 | L28: =_xlfn.PERCENTILE.INC($B$2:$B$61,J28) -> 0 | P28: 0.024 | Q28: =P28 -> 0.024 | R28: =_xlfn.PERCENTILE.INC($E$2:$E$101,K32) -> 0
A29: -2.25 | B29: 0 | C29: 0 | D29: 0 | E29: 0.070578028 | F29: 0.0010292674 | G29: 4702 | J29: 0.025 | K29: =J29 -> 0.025 | L29: =_xlfn.PERCENTILE.INC($B$2:$B$61,J29) -> 0 | P29: 0.025 | Q29: =P29 -> 0.025 | R29: =_xlfn.PERCENTILE.INC($E$2:$E$101,K33) -> 0
A30: -2.15 | B30: 0 | C30: 0 | D30: 0 | E30: 0.070953284 | F30: 0.001032 | G30: 4727 | J30: 0.026 | K30: =J30 -> 0.026 | L30: =_xlfn.PERCENTILE.INC($B$2:$B$61,J30) -> 0 | P30: 0.026 | Q30: =P30 -> 0.026 | R30: =_xlfn.PERCENTILE.INC($E$2:$E$101,K34) -> 0
A31: -2.05 | B31: 0 | C31: 0 | D31: 0 | E31: 0.074525715 | F31: 0.0010576611 | G31: 4965 | J31: 0.027 | K31: =J31 -> 0.027 | L31: =_xlfn.PERCENTILE.INC($B$2:$B$61,J31) -> 0 | P31: 0.027 | Q31: =P31 -> 0.027 | R31: =_xlfn.PERCENTILE.INC($E$2:$E$101,K35) -> 0
A32: -1.95 | B32: 0 | C32: 0 | D32: 0 | E32: 0.078098146 | F32: 0.0010827141 | G32: 5203 | J32: 0.028 | K32: =J32 -> 0.028 | L32: =_xlfn.PERCENTILE.INC($B$2:$B$61,J32) -> 0 | P32: 0.028 | Q32: =P32 -> 0.028 | R32: =_xlfn.PERCENTILE.INC($E$2:$E$101,K36) -> 0
A33: -1.85 | B33: 0 | C33: 0 | D33: 0 | E33: 0.094129055 | F33: 0.0011886536 | G33: 6271 | J33: 0.029 | K33: =J33 -> 0.029 | L33: =_xlfn.PERCENTILE.INC($B$2:$B$61,J33) -> 0 | P33: 0.029 | Q33: =P33 -> 0.029 | R33: =_xlfn.PERCENTILE.INC($E$2:$E$101,K37) -> 0
A34: -1.75 | B34: 0 | C34: 0 | D34: 0 | E34: 0.11365734 | F34: 0.0013061474 | G34: 7572 | J34: 0.03 | K34: =J34 -> 0.03 | L34: =_xlfn.PERCENTILE.INC($B$2:$B$61,J34) -> 0 | P34: 0.03 | Q34: =P34 -> 0.03 | R34: =_xlfn.PERCENTILE.INC($E$2:$E$101,K38) -> 0
A35: -1.65 | B35: 0 | C35: 0 | D35: 0 | E35: 0.12598073 | F35: 0.0013751355 | G35: 8393 | J35: 0.031 | K35: =J35 -> 0.031 | L35: =_xlfn.PERCENTILE.INC($B$2:$B$61,J35) -> 0 | P35: 0.031 | Q35: =P35 -> 0.031 | R35: =_xlfn.PERCENTILE.INC($E$2:$E$101,K39) -> 0
A36: -1.55 | B36: 0 | C36: 0 | D36: 0 | E36: 0.14993703 | F36: 0.0015001957 | G36: 9989 | J36: 0.032 | K36: =J36 -> 0.032 | L36: =_xlfn.PERCENTILE.INC($B$2:$B$61,J36) -> 0 | P36: 0.032 | Q36: =P36 -> 0.032 | R36: =_xlfn.PERCENTILE.INC($E$2:$E$101,K40) -> 0
... A101: 4.95 | B101: 0 | C101: 0 | D101: 0 | E101: 0 | F101: 0 | G101: 0 | J101: 0.097 | K101: =J101 -> 0.097 | L101: =_xlfn.PERCENTILE.INC($B$2:$B$61,J101) -> 0 | P101: 0.097 | Q101: =P101 -> 0.097 | R101: =_xlfn.PERCENTILE.INC($E$2:$E$101,K105) -> 0
J102: 0.098 | K102: =J102 -> 0.098 | L102: =_xlfn.PERCENTILE.INC($B$2:$B$61,J102) -> 0 | P102: 0.098 | Q102: =P102 -> 0.098 | R102: =_xlfn.PERCENTILE.INC($E$2:$E$101,K106) -> 0
J103: 0.099 | K103: =J103 -> 0.099 | L103: =_xlfn.PERCENTILE.INC($B$2:$B$61,J103) -> 0 | P103: 0.099 | Q103: =P103 -> 0.099 | R103: =_xlfn.PERCENTILE.INC($E$2:$E$101,K107) -> 0
J104: 0.1 | K104: =J104 -> 0.1 | L104: =_xlfn.PERCENTILE.INC($B$2:$B$61,J104) -> 0 | P104: 0.1 | Q104: =P104 -> 0.1 | R104: =_xlfn.PERCENTILE.INC($E$2:$E$101,K108) -> 0
...

Sheet monr2
A1: eta | B1: pdf_original | C1: error_original | D1: counts_original | E1: pdf_corregido | F1: error_corregido | G1: counts_corregido
A2: -4.95 | B2: 0 | C2: 0 | D2: 0 | E2: 0.00029338488 | F2: 5.8676975e-05 | G2: 25
A3: -4.85 | B3: 0 | C3: 0 | D3: 0 | E3: 0.00041073883 | F3: 6.9427533e-05 | G3: 35 | J3: PDF ORIGINAL | P3: PDF CORREGIDO
A4: -4.75 | B4: 0 | C4: 0 | D4: 0 | E4: 0.00044594501 | F4: 7.2341833e-05 | G4: 38 | J4: PERCENTILES | P4: PERCENTILES
A5: -4.65 | B5: 0 | C5: 0 | D5: 0 | E5: 0.00062197594 | F5: 8.5434965e-05 | G5: 53 | J5: 0.001 | K5: =J5 -> 0.001 | L5: =_xlfn.PERCENTILE.INC($B$2:$B$101,E9) -> 0 | N5: P95 | P5: 0.001 | Q5: =P5 -> 0.001 | R5: =_xlfn.PERCENTILE.INC($E$2:$E$101,K9) -> 0 | T5: P95
A6: -4.55 | B6: 0 | C6: 0 | D6: 0 | E6: 0.00068065291 | F6: 8.9374106e-05 | G6: 58 | J6: 0.002 | K6: =J6 -> 0.002 | L6: =_xlfn.PERCENTILE.INC($B$2:$B$61,J6) -> 0 | N6: =L979-L29 -> 1.2109742 | P6: 0.002 | Q6: =P6 -> 0.002 | R6: =_xlfn.PERCENTILE.INC($E$2:$E$101,K10) -> 0 | T6: =R979-R29 -> 0.53920684
A7: -4.45 | B7: 0 | C7: 0 | D7: 0 | E7: 0.00079800686 | F7: 9.6772546e-05 | G7: 68 | J7: 0.003 | K7: =J7 -> 0.003 | L7: =_xlfn.PERCENTILE.INC($B$2:$B$61,J7) -> 0 | N7: P90 | P7: 0.003 | Q7: =P7 -> 0.003 | R7: =_xlfn.PERCENTILE.INC($E$2:$E$101,K11) -> 0 | T7: P90
A8: -4.35 | B8: 0 | C8: 0 | D8: 0 | E8: 0.00077453607 | F8: 9.53388e-05 | G8: 66 | J8: 0.004 | K8: =J8 -> 0.004 | L8: =_xlfn.PERCENTILE.INC($B$2:$B$61,J8) -> 0 | N8: =L954-L54 -> 0.97189285 | P8: 0.004 | Q8: =P8 -> 0.004 | R8: =_xlfn.PERCENTILE.INC($E$2:$E$101,K12) -> 0 | T8: =R954-R54 -> 0.51384671
A9: -4.25 | B9: 0 | C9: 0 | D9: 0 | E9: 0.0012322165 | F9: 0.00012025201 | G9: 105 | J9: 0.005 | K9: =J9 -> 0.005 | L9: =_xlfn.PERCENTILE.INC($B$2:$B$61,J9) -> 0 | N9: P85 | P9: 0.005 | Q9: =P9 -> 0.005 | R9: =_xlfn.PERCENTILE.INC($E$2:$E$101,K13) -> 0 | T9: P85
A10: -4.15 | B10: 0 | C10: 0 | D10: 0 | E10: 0.0014199828 | F10: 0.00012908935 | G10: 121 | J10: 0.006 | K10: =J10 -> 0.006 | L10: =_xlfn.PERCENTILE.INC($B$2:$B$61,J10) -> 0 | N10: =L929-L79 -> 0.8860573 | P10: 0.006 | Q10: =P10 -> 0.006 | R10: =_xlfn.PERCENTILE.INC($E$2:$E$101,K14) -> 0 | T10: =R929-R79 -> 0.47282383
A11: -4.05 | B11: 0 | C11: 0 | D11: 0 | E11: 0.0017955154 | F11: 0.00014515882 | G11: 153 | J11: 0.007 | K11: =J11 -> 0.007 | L11: =_xlfn.PERCENTILE.INC($B$2:$B$61,J11) -> 0 | N11: P80 | P11: 0.007 | Q11: =P11 -> 0.007 | R11: =_xlfn.PERCENTILE.INC($E$2:$E$101,K15) -> 0 | T11: P80
A12: -3.95 | B12: 0 | C12: 0 | D12: 0 | E12: 0.0024526976 | F12: 0.00016965664 | G12: 209 | J12: 0.008 | K12: =J12 -> 0.008 | L12: =_xlfn.PERCENTILE.INC($B$2:$B$61,J12) -> 0 | N12: =L904-L104 -> 0.65252085 | P12: 0.008 | Q12: =P12 -> 0.008 | R12: =_xlfn.PERCENTILE.INC($E$2:$E$101,K16) -> 0 | T12: =R904-R104 -> 0.42984161
A13: -3.85 | B13: 0 | C13: 0 | D13: 0 | E13: 0.0025231099 | F13: 0.00017207467 | G13: 215 | J13: 0.009 | K13: =J13 -> 0.009 | L13: =_xlfn.PERCENTILE.INC($B$2:$B$61,J13) -> 0 | N13: P75 | P13: 0.009 | Q13: =P13 -> 0.009 | R13: =_xlfn.PERCENTILE.INC($E$2:$E$101,K17) -> 0 | T13: P75
A14: -3.75 | B14: 0 | C14: 0 | D14: 0 | E14: 0.0033915292 | F14: 0.00019950172 | G14: 289 | J14: 0.01 | K14: =J14 -> 0.01 | L14: =_xlfn.PERCENTILE.INC($B$2:$B$61,J14) -> 0 | N14: =L879-L129 -> 0.54095558 | P14: 0.01 | Q14: =P14 -> 0.01 | R14: =_xlfn.PERCENTILE.INC($E$2:$E$101,K18) -> 0 | T14: =R879-R129 -> 0.36202783
