Workbook

Sheet Summary
Q2: VALORES CENTRALES
B3: Archivo | C3: H | D3: pend 3-10 | E3: desv est 3-10 | F3: pend 3-20 | G3: desv est 3-20 | H3: pend 3-30 | I3: desv est 3-30 | J3: pend 3-40 | K3: desv est 3-40 | L3: pend 3-50 | M3: desv est 3-50 | O3: H=alpha/2 (stutzki et al. 1998) | P3: H | Q3: alpha teorica | R3: 3-10 | S3: 3-20 | T3: 3-30 | U3: 3-40 | V3: 3-50
B4: =efbm_H0.5Mach1_0!$E$2 -> efbm_H0.5Mach1_0.fits | C4: =efbm_H0.5Mach1_0!$F$2 -> 0.5 | D4: =efbm_H0.5Mach1_0!$H$6 -> 0.9580466 | E4: =efbm_H0.5Mach1_0!$I$6 -> 0.0024116814 | F4: =efbm_H0.5Mach1_0!$H$7 -> 0.88461503 | G4: =efbm_H0.5Mach1_0!$I$7 -> 0.002226311 | H4: =efbm_H0.5Mach1_0!$H$8 -> 0.88086556 | I4: =efbm_H0.5Mach1_0!$I$8 -> 0.0015485243 | J4: =efbm_H0.5Mach1_0!$H$9 -> 0.8872357 | K4: =efbm_H0.5Mach1_0!$I$9 -> 0.0012852058 | L4: =efbm_H0.5Mach1_0!$H$10 -> 0.89361472 | M4: =efbm_H0.5Mach1_0!$I$10 -> 0.0011744346 | P4: 0.5 | Q4: =2*P4 -> 1 | R4: =D24 -> 0.97032735 | S4: =F24 -> 0.97180517 | T4: =H24 -> 0.98350892 | U4: =J24 -> 0.99337896 | V4: =L24 -> 0.99862252
B5: =efbm_H0.5Mach1_1!$E$2 -> efbm_H0.5Mach1_1.fits | C5: =efbm_H0.5Mach1_1!$F$2 -> 0.5 | D5: =efbm_H0.5Mach1_1!$H$6 -> 0.92804484 | E5: =efbm_H0.5Mach1_1!$I$6 -> 0.0020128057 | F5: =efbm_H0.5Mach1_1!$H$7 -> 0.92715633 | G5: =efbm_H0.5Mach1_1!$I$7 -> 0.00086368125 | H5: =efbm_H0.5Mach1_1!$H$8 -> 0.94064046 | I5: =efbm_H0.5Mach1_1!$I$8 -> 0.0010080158 | J5: =efbm_H0.5Mach1_1!$H$9 -> 0.96653433 | K5: =efbm_H0.5Mach1_1!$I$9 -> 0.0017468105 | L5: =efbm_H0.5Mach1_1!$H$10 -> 0.9875694 | M5: =efbm_H0.5Mach1_1!$I$10 -> 0.0020682259 | P5: 1 | Q5: =2*P5 -> 2 | R5: =D45 -> 2.0685634 | S5: =F45 -> 2.1229141 | T5: =H45 -> 2.1465978 | U5: =J45 -> 2.1483258 | V5: =L45 -> 2.1386274
B6: =efbm_H0.5Mach1_2!$E$2 -> efbm_H0.5Mach1_2.fits | C6: =efbm_H0.5Mach1_2!$F$2 -> 0.5 | D6: =efbm_H0.5Mach1_2!$H$6 -> 1.0105329 | E6: =efbm_H0.5Mach1_2!$I$6 -> 0.0020283534 | F6: =efbm_H0.5Mach1_2!$H$7 -> 1.0025464 | G6: =efbm_H0.5Mach1_2!$I$7 -> 0.0010427444 | H6: =efbm_H0.5Mach1_2!$H$8 -> 0.99609452 | I6: =efbm_H0.5Mach1_2!$I$8 -> 0.00078972256 | J6: =efbm_H0.5Mach1_2!$H$9 -> 0.99464736 | K6: =efbm_H0.5Mach1_2!$I$9 -> 0.00064594262 | L6: =efbm_H0.5Mach1_2!$H$10 -> 0.98345968 | M6: =efbm_H0.5Mach1_2!$I$10 -> 0.0010024529
B7: =efbm_H0.5Mach1_3!$E$2 -> efbm_H0.5Mach1_3.fits | C7: =efbm_H0.5Mach1_3!$F$2 -> 0.5 | D7: =efbm_H0.5Mach1_3!$H$6 -> 1.0551075 | E7: =efbm_H0.5Mach1_3!$I$6 -> 0.0020364661 | F7: =efbm_H0.5Mach1_3!$H$7 -> 1.1195966 | G7: =efbm_H0.5Mach1_3!$I$7 -> 0.0024553816 | H7: =efbm_H0.5Mach1_3!$H$8 -> 1.1854681 | I7: =efbm_H0.5Mach1_3!$I$8 -> 0.0035527919 | J7: =efbm_H0.5Mach1_3!$H$9 -> 1.2341771 | K7: =efbm_H0.5Mach1_3!$I$9 -> 0.0040072866 | L7: =efbm_H0.5Mach1_3!$H$10 -> 1.2621833 | M7: =efbm_H0.5Mach1_3!$I$10 -> 0.0039013972 | Q7: DESVIACIONES TÍPICAS
B8: =efbm_H0.5Mach1_4!$E$2 -> efbm_H0.5Mach1_4.fits | C8: =efbm_H0.5Mach1_4!$F$2 -> 0.5 | D8: =efbm_H0.5Mach1_4!$H$6 -> 1.0234232 | E8: =efbm_H0.5Mach1_4!$I$6 -> 0.0019830017 | F8: =efbm_H0.5Mach1_4!$H$7 -> 1.0054079 | G8: =efbm_H0.5Mach1_4!$I$7 -> 0.0012860793 | H8: =efbm_H0.5Mach1_4!$H$8 -> 0.95302787 | I8: =efbm_H0.5Mach1_4!$I$8 -> 0.0027210534 | J8: =efbm_H0.5Mach1_4!$H$9 -> 0.907819 | K8: =efbm_H0.5Mach1_4!$I$9 -> 0.0034173268 | L8: =efbm_H0.5Mach1_4!$H$10 -> 0.87852242 | M8: =efbm_H0.5Mach1_4!$I$10 -> 0.0035256767 | P8: H | Q8: alpha teorica | R8: 3-10 | S8: 3-20 | T8: 3-30 | U8: 3-40 | V8: 3-50
B9: =efbm_H0.5Mach1_5!$E$2 -> efbm_H0.5Mach1_5.fits | C9: =efbm_H0.5Mach1_5!$F$2 -> 0.5 | D9: =efbm_H0.5Mach1_5!$H$6 -> 1.0370632 | E9: =efbm_H0.5Mach1_5!$I$6 -> 0.0019859629 | F9: =efbm_H0.5Mach1_5!$H$7 -> 1.0932597 | G9: =efbm_H0.5Mach1_5!$I$7 -> 0.0021691304 | H9: =efbm_H0.5Mach1_5!$H$8 -> 1.1224191 | I9: =efbm_H0.5Mach1_5!$I$8 -> 0.0019900168 | J9: =efbm_H0.5Mach1_5!$H$9 -> 1.1266311 | K9: =efbm_H0.5Mach1_5!$I$9 -> 0.0016190481 | L9: =efbm_H0.5Mach1_5!$H$10 -> 1.113334 | M9: =efbm_H0.5Mach1_5!$I$10 -> 0.0017044925 | P9: 0.5 | Q9: =2*P9 -> 1 | R9: =E24 -> 0.00054257892 | S9: =G24 -> 0.00095665397 | T9: =I24 -> 0.0011087934 | U9: =K24 -> 0.0013248064 | V9: =M24 -> 0.001272099
B10: =efbm_H0.5Mach1_6!$E$2 -> efbm_H0.5Mach1_6.fits | C10: =efbm_H0.5Mach1_6!$F$2 -> 0.5 | D10: =efbm_H0.5Mach1_6!$H$6 -> 0.82240712 | E10: =efbm_H0.5Mach1_6!$I$6 -> 0.0022318867 | F10: =efbm_H0.5Mach1_6!$H$7 -> 0.82911931 | G10: =efbm_H0.5Mach1_6!$I$7 -> 0.0014647347 | H10: =efbm_H0.5Mach1_6!$H$8 -> 0.88720833 | I10: =efbm_H0.5Mach1_6!$I$8 -> 0.0029828029 | J10: =efbm_H0.5Mach1_6!$H$9 -> 0.92858185 | K10: =efbm_H0.5Mach1_6!$I$9 -> 0.0033791611 | L10: =efbm_H0.5Mach1_6!$H$10 -> 0.94665408 | M10: =efbm_H0.5Mach1_6!$I$10 -> 0.0031267878 | P10: 1 | Q10: =2*P10 -> 2 | R10: =E45 -> 0.00057692973 | S10: =G45 -> 0.00097326211 | T10: =I45 -> 0.0012222479 | U10: =K45 -> 0.001311367 | V10: =M45 -> 0.0014096581
B11: =efbm_H0.5Mach1_7!$E$2 -> efbm_H0.5Mach1_7.fits | C11: =efbm_H0.5Mach1_7!$F$2 -> 0.5 | D11: =efbm_H0.5Mach1_7!$H$6 -> 0.95229709 | E11: =efbm_H0.5Mach1_7!$I$6 -> 0.0023136799 | F11: =efbm_H0.5Mach1_7!$H$7 -> 0.94505825 | G11: =efbm_H0.5Mach1_7!$I$7 -> 0.0011221926 | H11: =efbm_H0.5Mach1_7!$H$8 -> 0.969679 | I11: =efbm_H0.5Mach1_7!$I$8 -> 0.0014509689 | J11: =efbm_H0.5Mach1_7!$H$9 -> 0.99924778 | K11: =efbm_H0.5Mach1_7!$I$9 -> 0.0021213459 | L11: =efbm_H0.5Mach1_7!$H$10 -> 1.0308855 | M11: =efbm_H0.5Mach1_7!$I$10 -> 0.0028393916
B12: =efbm_H0.5Mach1_8!$E$2 -> efbm_H0.5Mach1_8.fits | C12: =efbm_H0.5Mach1_8!$F$2 -> 0.5 | D12: =efbm_H0.5Mach1_8!$H$6 -> 1.0061867 | E12: =efbm_H0.5Mach1_8!$I$6 -> 0.0026804941 | F12: =efbm_H0.5Mach1_8!$H$7 -> 1.0756293 | G12: =efbm_H0.5Mach1_8!$I$7 -> 0.0022570971 | H12: =efbm_H0.5Mach1_8!$H$8 -> 1.1315482 | I12: =efbm_H0.5Mach1_8!$I$8 -> 0.0031674599 | J12: =efbm_H0.5Mach1_8!$H$9 -> 1.1889131 | K12: =efbm_H0.5Mach1_8!$I$9 -> 0.00422215 | L12: =efbm_H0.5Mach1_8!$H$10 -> 1.2314436 | M12: =efbm_H0.5Mach1_8!$I$10 -> 0.0046178853
B13: =efbm_H0.5Mach1_9!$E$2 -> efbm_H0.5Mach1_9.fits | C13: =efbm_H0.5Mach1_9!$F$2 -> 0.5 | D13: =efbm_H0.5Mach1_9!$H$6 -> 1.0329239 | E13: =efbm_H0.5Mach1_9!$I$6 -> 0.0020217781 | F13: =efbm_H0.5Mach1_9!$H$7 -> 1.0445401 | G13: =efbm_H0.5Mach1_9!$I$7 -> 0.00094102389 | H13: =efbm_H0.5Mach1_9!$H$8 -> 1.0671955 | I13: =efbm_H0.5Mach1_9!$I$8 -> 0.001327043 | J13: =efbm_H0.5Mach1_9!$H$9 -> 1.0942281 | K13: =efbm_H0.5Mach1_9!$I$9 -> 0.0019275377 | L13: =efbm_H0.5Mach1_9!$H$10 -> 1.1197761 | M13: =efbm_H0.5Mach1_9!$I$10 -> 0.0024074781
B14: ='efbm_H0.5Mach2.5_0'!$E$2 -> efbm_H0.5Mach2.5_0.fits | C14: ='efbm_H0.5Mach2.5_0'!$F$2 -> 0.5 | D14: ='efbm_H0.5Mach2.5_0'!$H$6 -> 0.93450301 | E14: ='efbm_H0.5Mach2.5_0'!$I$6 -> 0.0032921638 | F14: ='efbm_H0.5Mach2.5_0'!$H$7 -> 0.77487799 | G14: ='efbm_H0.5Mach2.5_0'!$I$7 -> 0.0047289439 | H14: ='efbm_H0.5Mach2.5_0'!$H$8 -> 0.7285672 | I14: ='efbm_H0.5Mach2.5_0'!$I$8 -> 0.0038509084 | J14: ='efbm_H0.5Mach2.5_0'!$H$9 -> 0.71826339 | K14: ='efbm_H0.5Mach2.5_0'!$I$9 -> 0.0031083875 | L14: ='efbm_H0.5Mach2.5_0'!$H$10 -> 0.71819172 | M14: ='efbm_H0.5Mach2.5_0'!$I$10 -> 0.0026342024
B15: ='efbm_H0.5Mach2.5_1'!$E$2 -> efbm_H0.5Mach2.5_1.fits | C15: ='efbm_H0.5Mach2.5_1'!$F$2 -> 0.5 | D15: ='efbm_H0.5Mach2.5_1'!$H$6 -> 0.92100389 | E15: ='efbm_H0.5Mach2.5_1'!$I$6 -> 0.0024225545 | F15: ='efbm_H0.5Mach2.5_1'!$H$7 -> 0.88614512 | G15: ='efbm_H0.5Mach2.5_1'!$I$7 -> 0.001445111 | H15: ='efbm_H0.5Mach2.5_1'!$H$8 -> 0.8726152 | I15: ='efbm_H0.5Mach2.5_1'!$I$8 -> 0.0011764875 | J15: ='efbm_H0.5Mach2.5_1'!$H$9 -> 0.87510658 | K15: ='efbm_H0.5Mach2.5_1'!$I$9 -> 0.00094794864 | L15: ='efbm_H0.5Mach2.5_1'!$H$10 -> 0.87512077 | M15: ='efbm_H0.5Mach2.5_1'!$I$10 -> 0.00081308487
B16: ='efbm_H0.5Mach2.5_2'!$E$2 -> efbm_H0.5Mach2.5_2.fits | C16: =efbm_H0.5Mach1_2!$F$2 -> 0.5 | D16: ='efbm_H0.5Mach2.5_2'!$H$6 -> 0.95996826 | E16: ='efbm_H0.5Mach2.5_2'!$I$6 -> 0.0020023392 | F16: ='efbm_H0.5Mach2.5_2'!$H$7 -> 0.90299878 | G16: ='efbm_H0.5Mach2.5_2'!$I$7 -> 0.0019895706 | H16: ='efbm_H0.5Mach2.5_2'!$H$8 -> 0.87753707 | I16: ='efbm_H0.5Mach2.5_2'!$I$8 -> 0.001785963 | J16: ='efbm_H0.5Mach2.5_2'!$H$9 -> 0.8619487 | K16: ='efbm_H0.5Mach2.5_2'!$I$9 -> 0.0017057391 | L16: ='efbm_H0.5Mach2.5_2'!$H$10 -> 0.83666053 | M16: ='efbm_H0.5Mach2.5_2'!$I$10 -> 0.0023144538
B17: ='efbm_H0.5Mach2.5_3'!$E$2 -> efbm_H0.5Mach2.5_3.fits | C17: ='efbm_H0.5Mach2.5_3'!$F$2 -> 0.5 | D17: ='efbm_H0.5Mach2.5_3'!$H$6 -> 1.1038881 | E17: ='efbm_H0.5Mach2.5_3'!$I$6 -> 0.0020910133 | F17: ='efbm_H0.5Mach2.5_3'!$H$7 -> 1.1280629 | G17: ='efbm_H0.5Mach2.5_3'!$I$7 -> 0.0011553507 | H17: ='efbm_H0.5Mach2.5_3'!$H$8 -> 1.1461039 | I17: ='efbm_H0.5Mach2.5_3'!$I$8 -> 0.0012351316 | J17: ='efbm_H0.5Mach2.5_3'!$H$9 -> 1.1678186 | K17: ='efbm_H0.5Mach2.5_3'!$I$9 -> 0.0016098844 | L17: ='efbm_H0.5Mach2.5_3'!$H$10 -> 1.1770878 | M17: ='efbm_H0.5Mach2.5_3'!$I$10 -> 0.0015173203
B18: ='efbm_H0.5Mach2.5_4'!$E$2 -> efbm_H0.5Mach2.5_4.fits | C18: ='efbm_H0.5Mach2.5_4'!$F$2 -> 0.5 | D18: ='efbm_H0.5Mach2.5_4'!$H$6 -> 1.0179557 | E18: ='efbm_H0.5Mach2.5_4'!$I$6 -> 0.0020763122 | F18: ='efbm_H0.5Mach2.5_4'!$H$7 -> 0.9534189 | G18: ='efbm_H0.5Mach2.5_4'!$I$7 -> 0.0024128378 | H18: ='efbm_H0.5Mach2.5_4'!$H$8 -> 0.86707737 | I18: ='efbm_H0.5Mach2.5_4'!$I$8 -> 0.0045178182 | J18: ='efbm_H0.5Mach2.5_4'!$H$9 -> 0.79120076 | K18: ='efbm_H0.5Mach2.5_4'!$I$9 -> 0.0057189394 | L18: ='efbm_H0.5Mach2.5_4'!$H$10 -> 0.73982544 | M18: ='efbm_H0.5Mach2.5_4'!$I$10 -> 0.0059934322
B19: ='efbm_H0.5Mach2.5_5'!$E$2 -> efbm_H0.5Mach2.5_5.fits | C19: ='efbm_H0.5Mach2.5_5'!$F$2 -> 0.5 | D19: ='efbm_H0.5Mach2.5_5'!$H$6 -> 1.001553 | E19: ='efbm_H0.5Mach2.5_5'!$I$6 -> 0.0022147488 | F19: ='efbm_H0.5Mach2.5_5'!$H$7 -> 1.0828441 | G19: ='efbm_H0.5Mach2.5_5'!$I$7 -> 0.0029030573 | H19: ='efbm_H0.5Mach2.5_5'!$H$8 -> 1.0949652 | I19: ='efbm_H0.5Mach2.5_5'!$I$8 -> 0.0021647565 | J19: ='efbm_H0.5Mach2.5_5'!$H$9 -> 1.0672189 | K19: ='efbm_H0.5Mach2.5_5'!$I$9 -> 0.0024742114 | L19: ='efbm_H0.5Mach2.5_5'!$H$10 -> 1.0227508 | M19: ='efbm_H0.5Mach2.5_5'!$I$10 -> 0.0037700813
B20: ='efbm_H0.5Mach2.5_6'!$E$2 -> efbm_H0.5Mach2.5_6.fits | C20: ='efbm_H0.5Mach2.5_6'!$F$2 -> 0.5 | D20: ='efbm_H0.5Mach2.5_6'!$H$6 -> 0.73546488 | E20: ='efbm_H0.5Mach2.5_6'!$I$6 -> 0.0022369957 | F20: ='efbm_H0.5Mach2.5_6'!$H$7 -> 0.72980323 | G20: ='efbm_H0.5Mach2.5_6'!$I$7 -> 0.0011965238 | H20: ='efbm_H0.5Mach2.5_6'!$H$8 -> 0.78226366 | I20: ='efbm_H0.5Mach2.5_6'!$I$8 -> 0.0027291724 | J20: ='efbm_H0.5Mach2.5_6'!$H$9 -> 0.82304195 | K20: ='efbm_H0.5Mach2.5_6'!$I$9 -> 0.003216348 | L20: ='efbm_H0.5Mach2.5_6'!$H$10 -> 0.83853911 | M20: ='efbm_H0.5Mach2.5_6'!$I$10 -> 0.0029395063
B21: ='efbm_H0.5Mach2.5_7'!$E$2 -> efbm_H0.5Mach2.5_7.fits | C21: ='efbm_H0.5Mach2.5_7'!$F$2 -> 0.5 | D21: ='efbm_H0.5Mach2.5_7'!$H$6 -> 0.89054989 | E21: ='efbm_H0.5Mach2.5_7'!$I$6 -> 0.0034895161 | F21: ='efbm_H0.5Mach2.5_7'!$H$7 -> 0.90150756 | G21: ='efbm_H0.5Mach2.5_7'!$I$7 -> 0.0022421948 | H21: ='efbm_H0.5Mach2.5_7'!$H$8 -> 0.94772083 | I21: ='efbm_H0.5Mach2.5_7'!$I$8 -> 0.0026264023 | J21: ='efbm_H0.5Mach2.5_7'!$H$9 -> 0.96916925 | K21: ='efbm_H0.5Mach2.5_7'!$I$9 -> 0.0024252357 | L21: ='efbm_H0.5Mach2.5_7'!$H$10 -> 0.98143548 | M21: ='efbm_H0.5Mach2.5_7'!$I$10 -> 0.0022207529
B22: ='efbm_H0.5Mach2.5_8'!$E$2 -> efbm_H0.5Mach2.5_8.fits | C22: ='efbm_H0.5Mach2.5_8'!$F$2 -> 0.5 | D22: ='efbm_H0.5Mach2.5_8'!$H$6 -> 0.99188549 | E22: ='efbm_H0.5Mach2.5_8'!$I$6 -> 0.0038501039 | F22: ='efbm_H0.5Mach2.5_8'!$H$7 -> 1.0932434 | G22: ='efbm_H0.5Mach2.5_8'!$I$7 -> 0.0032466963 | H22: ='efbm_H0.5Mach2.5_8'!$H$8 -> 1.1556781 | I22: ='efbm_H0.5Mach2.5_8'!$I$8 -> 0.0036980125 | J22: ='efbm_H0.5Mach2.5_8'!$H$9 -> 1.1976021 | K22: ='efbm_H0.5Mach2.5_8'!$I$9 -> 0.0038158991 | L22: ='efbm_H0.5Mach2.5_8'!$H$10 -> 1.2156201 | M22: ='efbm_H0.5Mach2.5_8'!$I$10 -> 0.0034682498
B23: ='efbm_H0.5Mach2.5_9'!$E$2 -> efbm_H0.5Mach2.5_9.fits | C23: ='efbm_H0.5Mach2.5_9'!$F$2 -> 0.5 | D23: ='efbm_H0.5Mach2.5_9'!$H$6 -> 1.0237417 | E23: ='efbm_H0.5Mach2.5_9'!$I$6 -> 0.0021223974 | F23: ='efbm_H0.5Mach2.5_9'!$H$7 -> 1.0562723 | G23: ='efbm_H0.5Mach2.5_9'!$I$7 -> 0.0012558194 | H23: ='efbm_H0.5Mach2.5_9'!$H$8 -> 1.0635032 | I23: ='efbm_H0.5Mach2.5_9'!$I$8 -> 0.0009232121 | J23: ='efbm_H0.5Mach2.5_9'!$H$9 -> 1.0681937 | K23: ='efbm_H0.5Mach2.5_9'!$I$9 -> 0.00078125009 | L23: =efbm_H0.5Mach1_9!$H$10 -> 1.1197761 | M23: =efbm_H0.5Mach1_9!$I$10 -> 0.0024074781
B24: Medias | C24: 0.5 | D24: =AVERAGE(D4:D23) -> 0.97032735 | E24: =_xlfn.STDEV.S(E4:E23) -> 0.00054257892 | F24: =AVERAGE(F4:F23) -> 0.97180517 | G24: =_xlfn.STDEV.S(G4:G23) -> 0.00095665397 | H24: =AVERAGE(H4:H23) -> 0.98350892 | I24: =_xlfn.STDEV.S(I4:I23) -> 0.0011087934 | J24: =AVERAGE(J4:J23) -> 0.99337896 | K24: =_xlfn.STDEV.S(K4:K23) -> 0.0013248064 | L24: =AVERAGE(L4:L23) -> 0.99862252 | M24: =_xlfn.STDEV.S(M4:M23) -> 0.001272099
B25: =efbm_H1Mach1_0!$E$2 -> efbm_H1Mach1_0.fits | C25: =efbm_H1Mach1_0!$F$2 -> 1 | D25: =efbm_H1Mach1_0!$H$6 -> 1.9566376 | E25: =efbm_H1Mach1_0!$I$6 -> 0.0031297757 | F25: =efbm_H1Mach1_0!$H$7 -> 1.9482526 | G25: =efbm_H1Mach1_0!$I$7 -> 0.0014960478 | H25: =efbm_H1Mach1_0!$H$8 -> 1.9730264 | I25: =efbm_H1Mach1_0!$I$8 -> 0.0015774777 | J25: =efbm_H1Mach1_0!$H$9 -> 1.9917461 | K25: =efbm_H1Mach1_0!$I$9 -> 0.0016624163 | L25: =efbm_H1Mach1_0!$H$10 -> 2.0011474 | M25: =efbm_H1Mach1_0!$I$10 -> 0.001551554
B26: =efbm_H1Mach1_1!$E$2 -> efbm_H1Mach1_1.fits | C26: =efbm_H1Mach1_1!$F$2 -> 1 | D26: =efbm_H1Mach1_1!$H$6 -> 2.0135284 | E26: =efbm_H1Mach1_1!$I$6 -> 0.0031996668 | F26: =efbm_H1Mach1_1!$H$7 -> 2.0914356 | G26: =efbm_H1Mach1_1!$I$7 -> 0.0028582158 | H26: =efbm_H1Mach1_1!$H$8 -> 2.1546104 | I26: =efbm_H1Mach1_1!$I$8 -> 0.003559929 | J26: =efbm_H1Mach1_1!$H$9 -> 2.1951798 | K26: =efbm_H1Mach1_1!$I$9 -> 0.003681916 | L26: =efbm_H1Mach1_1!$H$10 -> 2.2143555 | M26: =efbm_H1Mach1_1!$I$10 -> 0.0033887258
B27: =efbm_H1Mach1_2!$E$2 -> efbm_H1Mach1_2.fits | C27: =efbm_H1Mach1_2!$F$2 -> 1 | D27: =efbm_H1Mach1_2!$H$6 -> 2.0439725 | E27: =efbm_H1Mach1_2!$I$6 -> 0.0030793179 | F27: =efbm_H1Mach1_2!$H$7 -> 2.044274 | G27: =efbm_H1Mach1_2!$I$7 -> 0.001323512 | H27: =efbm_H1Mach1_2!$H$8 -> 2.0421247 | I27: =efbm_H1Mach1_2!$I$8 -> 0.00092551371 | J27: =efbm_H1Mach1_2!$H$9 -> 2.0279937 | K27: =efbm_H1Mach1_2!$I$9 -> 0.0011865004 | L27: =efbm_H1Mach1_2!$H$10 -> 2.0017773 | M27: =efbm_H1Mach1_2!$I$10 -> 0.0021113483
B28: =efbm_H1Mach1_3!$E$2 -> efbm_H1Mach1_3.fits | C28: =efbm_H1Mach1_3!$F$2 -> 1 | D28: =efbm_H1Mach1_3!$H$6 -> 2.1946832 | E28: =efbm_H1Mach1_3!$I$6 -> 0.0038673055 | F28: =efbm_H1Mach1_3!$H$7 -> 2.3147402 | G28: =efbm_H1Mach1_3!$I$7 -> 0.0040187412 | H28: =efbm_H1Mach1_3!$H$8 -> 2.3764527 | I28: =efbm_H1Mach1_3!$I$8 -> 0.0039429599 | J28: =efbm_H1Mach1_3!$H$9 -> 2.4003182 | K28: =efbm_H1Mach1_3!$I$9 -> 0.003420248 | L28: =efbm_H1Mach1_3!$H$10 -> 2.4018425 | M28: =efbm_H1Mach1_3!$I$10 -> 0.0029156336
B29: =efbm_H1Mach1_4!$E$2 -> efbm_H1Mach1_4.fits | C29: =efbm_H1Mach1_4!$F$2 -> 1 | D29: =efbm_H1Mach1_4!$H$6 -> 2.0256422 | E29: =efbm_H1Mach1_4!$I$6 -> 0.0030499337 | F29: =efbm_H1Mach1_4!$H$7 -> 1.9864254 | G29: =efbm_H1Mach1_4!$I$7 -> 0.0020422443 | H29: =efbm_H1Mach1_4!$H$8 -> 1.9295269 | I29: =efbm_H1Mach1_4!$I$8 -> 0.0030584313 | J29: =efbm_H1Mach1_4!$H$9 -> 1.884066 | K29: =efbm_H1Mach1_4!$I$9 -> 0.003609857 | L29: =efbm_H1Mach1_4!$H$10 -> 1.8475637 | M29: =efbm_H1Mach1_4!$I$10 -> 0.0039645638
B30: =efbm_H1Mach1_5!$E$2 -> efbm_H1Mach1_5.fits | C30: =efbm_H1Mach1_5!$F$2 -> 1 | D30: =efbm_H1Mach1_5!$H$6 -> 2.1129294 | E30: =efbm_H1Mach1_5!$I$6 -> 0.0034026844 | F30: =efbm_H1Mach1_5!$H$7 -> 2.1771618 | G30: =efbm_H1Mach1_5!$I$7 -> 0.0023278019 | H30: =efbm_H1Mach1_5!$H$8 -> 2.1843068 | I30: =efbm_H1Mach1_5!$I$8 -> 0.0016585964 | J30: =efbm_H1Mach1_5!$H$9 -> 2.1679591 | K30: =efbm_H1Mach1_5!$I$9 -> 0.0016958414 | L30: =efbm_H1Mach1_5!$H$10 -> 2.1390325 | M30: =efbm_H1Mach1_5!$I$10 -> 0.0024999235
B31: =efbm_H1Mach1_6!$E$2 -> efbm_H1Mach1_6.fits | C31: =efbm_H1Mach1_6!$F$2 -> 1 | D31: =efbm_H1Mach1_6!$H$6 -> 1.87338 | E31: =efbm_H1Mach1_6!$I$6 -> 0.003012257 | F31: =efbm_H1Mach1_6!$H$7 -> 1.9676559 | G31: =efbm_H1Mach1_6!$I$7 -> 0.003482991 | H31: =efbm_H1Mach1_6!$H$8 -> 2.0378148 | I31: =efbm_H1Mach1_6!$I$8 -> 0.004013848 | J31: =efbm_H1Mach1_6!$H$9 -> 2.0657416 | K31: =efbm_H1Mach1_6!$I$9 -> 0.003575549 | L31: =efbm_H1Mach1_6!$H$10 -> 2.0672852 | M31: =efbm_H1Mach1_6!$I$10 -> 0.0030524898
B32: =efbm_H1Mach1_7!$E$2 -> efbm_H1Mach1_7.fits | C32: =efbm_H1Mach1_7!$F$2 -> 1 | D32: =efbm_H1Mach1_7!$H$6 -> 2.0299268 | E32: =efbm_H1Mach1_7!$I$6 -> 0.0031573453 | F32: =efbm_H1Mach1_7!$H$7 -> 2.1151661 | G32: =efbm_H1Mach1_7!$I$7 -> 0.0032031177 | H32: =efbm_H1Mach1_7!$H$8 -> 2.185495 | I32: =efbm_H1Mach1_7!$I$8 -> 0.0039557711 | J32: =efbm_H1Mach1_7!$H$9 -> 2.2326728 | K32: =efbm_H1Mach1_7!$I$9 -> 0.004177502 | L32: =efbm_H1Mach1_7!$H$10 -> 2.2620833 | M32: =efbm_H1Mach1_7!$I$10 -> 0.004073999
B33: =efbm_H1Mach1_8!$E$2 -> efbm_H1Mach1_8.fits | C33: =efbm_H1Mach1_8!$F$2 -> 1 | D33: =efbm_H1Mach1_8!$H$6 -> 2.1512023 | E33: =efbm_H1Mach1_8!$I$6 -> 0.0043633392 | F33: =efbm_H1Mach1_8!$H$7 -> 2.285147 | G33: =efbm_H1Mach1_8!$I$7 -> 0.0043922609 | H33: =efbm_H1Mach1_8!$H$8 -> 2.3587729 | I33: =efbm_H1Mach1_8!$I$8 -> 0.0045389948 | J33: =efbm_H1Mach1_8!$H$9 -> 2.3970514 | K33: =efbm_H1Mach1_8!$I$9 -> 0.0042285441 | L33: =efbm_H1Mach1_8!$H$10 -> 2.4112282 | M33: =efbm_H1Mach1_8!$I$10 -> 0.0037189965
B34: =efbm_H1Mach1_9!$E$2 -> efbm_H1Mach1_9.fits | C34: =efbm_H1Mach1_9!$F$2 -> 1 | D34: =efbm_H1Mach1_9!$H$6 -> 2.1301932 | E34: =efbm_H1Mach1_9!$I$6 -> 0.0035785689 | F34: =efbm_H1Mach1_9!$H$7 -> 2.2189783 | G34: =efbm_H1Mach1_9!$I$7 -> 0.003166964 | H34: =efbm_H1Mach1_9!$H$8 -> 2.2810769 | I34: =efbm_H1Mach1_9!$I$8 -> 0.0036231149 | J34: =efbm_H1Mach1_9!$H$9 -> 2.3213779 | K34: =efbm_H1Mach1_9!$I$9 -> 0.003713589 | L34: =efbm_H1Mach1_9!$H$10 -> 2.3452968 | M34: =efbm_H1Mach1_9!$I$10 -> 0.0035485156
B35: =efbm_H1Mach2.5_0!$E$2 -> efbm_H1Mach2.5_0.fits | C35: =efbm_H1Mach2.5_0!$F$2 -> 1 | D35: =efbm_H1Mach2.5_0!$H$6 -> 1.9361291 | E35: =efbm_H1Mach2.5_0!$I$6 -> 0.0035603132 | F35: =efbm_H1Mach2.5_0!$H$7 -> 1.8774471 | G35: =efbm_H1Mach2.5_0!$I$7 -> 0.0021520485 | H35: =efbm_H1Mach2.5_0!$H$8 -> 1.88222 | I35: =efbm_H1Mach2.5_0!$I$8 -> 0.0015150446 | J35: =efbm_H1Mach2.5_0!$H$9 -> 1.889529 | K35: =efbm_H1Mach2.5_0!$I$9 -> 0.0012734325 | L35: =efbm_H1Mach2.5_0!$H$10 -> 1.8884228 | M35: =efbm_H1Mach2.5_0!$I$10 -> 0.0011002327
B36: =efbm_H1Mach2.5_1!$E$2 -> efbm_H1Mach2.5_1.fits | C36: =efbm_H1Mach2.5_1!$F$2 -> 1 | D36: =efbm_H1Mach2.5_1!$H$6 -> 2.021979 | E36: =efbm_H1Mach2.5_1!$I$6 -> 0.0031395275 | F36: =efbm_H1Mach2.5_1!$H$7 -> 2.0824021 | G36: =efbm_H1Mach2.5_1!$I$7 -> 0.0022881456 | H36: =efbm_H1Mach2.5_1!$H$8 -> 2.1193344 | I36: =efbm_H1Mach2.5_1!$I$8 -> 0.0023200769 | J36: =efbm_H1Mach2.5_1!$H$9 -> 2.133378 | K36: =efbm_H1Mach2.5_1!$I$9 -> 0.0020220659 | L36: =efbm_H1Mach2.5_1!$H$10 -> 2.1276848 | M36: =efbm_H1Mach2.5_1!$I$10 -> 0.0017973116
B37: =efbm_H1Mach2.5_2!$E$2 -> efbm_H1Mach2.5_2.fits | C37: =efbm_H1Mach1_2!$F$2 -> 1 | D37: =efbm_H1Mach2.5_2!$H$6 -> 2.0291341 | E37: =efbm_H1Mach2.5_2!$I$6 -> 0.0030472496 | F37: =efbm_H1Mach2.5_2!$H$7 -> 1.9963306 | G37: =efbm_H1Mach2.5_2!$I$7 -> 0.0016425698 | H37: =efbm_H1Mach2.5_2!$H$8 -> 1.9717432 | I37: =efbm_H1Mach2.5_2!$I$8 -> 0.0016521345 | J37: =efbm_H1Mach2.5_2!$H$9 -> 1.9353631 | K37: =efbm_H1Mach2.5_2!$I$9 -> 0.0025990183 | L37: =efbm_H1Mach2.5_2!$H$10 -> 1.8865488 | M37: =efbm_H1Mach2.5_2!$I$10 -> 0.0040695669
B38: =efbm_H1Mach2.5_3!$E$2 -> efbm_H1Mach2.5_3.fits | C38: =efbm_H1Mach2.5_3!$F$2 -> 1 | D38: =efbm_H1Mach2.5_3!$H$6 -> 2.2772252 | E38: =efbm_H1Mach2.5_3!$I$6 -> 0.0037306636 | F38: =efbm_H1Mach2.5_3!$H$7 -> 2.3539848 | G38: =efbm_H1Mach2.5_3!$I$7 -> 0.0027386377 | H38: =efbm_H1Mach2.5_3!$H$8 -> 2.379392 | I38: =efbm_H1Mach2.5_3!$I$8 -> 0.002204521 | J38: =efbm_H1Mach2.5_3!$H$9 -> 2.3735609 | K38: =efbm_H1Mach2.5_3!$I$9 -> 0.0018483599 | L38: =efbm_H1Mach2.5_3!$H$10 -> 2.3480146 | M38: =efbm_H1Mach2.5_3!$I$10 -> 0.0024167447
B39: =efbm_H1Mach2.5_4!$E$2 -> efbm_H1Mach2.5_4.fits | C39: =efbm_H1Mach2.5_4!$F$2 -> 1 | D39: =efbm_H1Mach2.5_4!$H$6 -> 2.0727378 | E39: =efbm_H1Mach2.5_4!$I$6 -> 0.0032082575 | F39: =efbm_H1Mach2.5_4!$H$7 -> 1.9811648 | G39: =efbm_H1Mach2.5_4!$I$7 -> 0.0035128372 | H39: =efbm_H1Mach2.5_4!$H$8 -> 1.8782123 | I39: =efbm_H1Mach2.5_4!$I$8 -> 0.0054677257 | J39: =efbm_H1Mach2.5_4!$H$9 -> 1.79545 | K39: =efbm_H1Mach2.5_4!$I$9 -> 0.0065191962 | L39: =efbm_H1Mach2.5_4!$H$10 -> 1.7312482 | M39: =efbm_H1Mach2.5_4!$I$10 -> 0.0070781087
B40: =efbm_H1Mach2.5_5!$E$2 -> efbm_H1Mach2.5_5.fits | C40: =efbm_H1Mach2.5_5!$F$2 -> 1 | D40: =efbm_H1Mach2.5_5!$H$6 -> 2.1853264 | E40: =efbm_H1Mach2.5_5!$I$6 -> 0.0038376277 | F40: =efbm_H1Mach2.5_5!$H$7 -> 2.2454378 | G40: =efbm_H1Mach2.5_5!$I$7 -> 0.0023357964 | H40: =efbm_H1Mach2.5_5!$H$8 -> 2.2054422 | I40: =efbm_H1Mach2.5_5!$I$8 -> 0.0027017816 | J40: =efbm_H1Mach2.5_5!$H$9 -> 2.1421277 | K40: =efbm_H1Mach2.5_5!$I$9 -> 0.004386773 | L40: =efbm_H1Mach2.5_5!$H$10 -> 2.0727914 | M40: =efbm_H1Mach2.5_5!$I$10 -> 0.0060896127
B41: =efbm_H1Mach2.5_6!$E$2 -> efbm_H1Mach2.5_6.fits | C41: =efbm_H1Mach2.5_6!$F$2 -> 1 | D41: =efbm_H1Mach2.5_6!$H$6 -> 1.8296118 | E41: =efbm_H1Mach2.5_6!$I$6 -> 0.0032182071 | F41: =efbm_H1Mach2.5_6!$H$7 -> 1.9476416 | G41: =efbm_H1Mach2.5_6!$I$7 -> 0.0040816842 | H41: =efbm_H1Mach2.5_6!$H$8 -> 2.021338 | I41: =efbm_H1Mach2.5_6!$I$8 -> 0.0043778288 | J41: =efbm_H1Mach2.5_6!$H$9 -> 2.0409038 | K41: =efbm_H1Mach2.5_6!$I$9 -> 0.0036773318 | L41: =efbm_H1Mach2.5_6!$H$10 -> 2.027652 | M41: =efbm_H1Mach2.5_6!$I$10 -> 0.0033019809
...

Sheet efbm_H0.5Mach1_0
A1: L | B1: Delta2(L) | C1: log(L) | D1: Log(Delta2(L)) | E1: Archivo | F1: H | G1: Mach | H1: dv_slope | I1: dv_slope_err
A2: 3 | B2: 0.0012474323 | C2: =LOG10(A2) -> 0.47712125 | D2: =LOG10(B2) -> -2.903983 | E2: efbm_H0.5Mach1_0.fits | F2: 0.5 | G2: 1 | H2: 0.95718468 | I2: 0.0042346577
A3: 3.0112212 | B3: 0.0012504984 | C3: =LOG10(A3) -> 0.47874266 | D3: =LOG10(B3) -> -2.9029169
A4: 3.0224844 | B4: 0.0012535335 | C4: =LOG10(A4) -> 0.48036408 | D4: =LOG10(B4) -> -2.901864
A5: 3.0337898 | B5: 0.0012565369 | C5: =LOG10(A5) -> 0.48198549 | D5: =LOG10(B5) -> -2.9008248 | H5: valor central | I5: desv tip
A6: 3.0451374 | B6: 0.0012595076 | C6: =LOG10(A6) -> 0.4836069 | D6: =LOG10(B6) -> -2.8997992 | F6: Pendiente 3-10 | H6: =SLOPE(D2:D324,C2:C324) -> 0.9580466 | I6: =INDEX(LINEST(D2:D324,C2:C324,TRUE,TRUE),2,1) -> 0.0024116814
A7: 3.0565275 | B7: 0.001262445 | C7: =LOG10(A7) -> 0.48522831 | D7: =LOG10(B7) -> -2.8987875 | F7: Pendiente 3-20 | H7: =SLOPE(D2:D510,C2:C510) -> 0.88461503 | I7: =INDEX(LINEST(D2:D510,C2:C510,TRUE,TRUE),2,1) -> 0.002226311
A8: 3.0679602 | B8: 0.0012653481 | C8: =LOG10(A8) -> 0.48684972 | D8: =LOG10(B8) -> -2.89779 | F8: Pendiente 3-30 | H8: =SLOPE(D2:D618,C2:C618) -> 0.88086556 | I8: =INDEX(LINEST(D2:D618,C2:C618,TRUE,TRUE),2,1) -> 0.0015485243
A9: 3.0794356 | B9: 0.0012682161 | C9: =LOG10(A9) -> 0.48847113 | D9: =LOG10(B9) -> -2.8968068 | F9: Pendiente 3-40 | H9: =SLOPE(D2:D695,C2:C695) -> 0.8872357 | I9: =INDEX(LINEST(D2:D695,C2:C695,TRUE,TRUE),2,1) -> 0.0012852058
A10: 3.090954 | B10: 0.0012710482 | C10: =LOG10(A10) -> 0.49009254 | D10: =LOG10(B10) -> -2.895838 | F10: Pendiente 3-50 | H10: =SLOPE(D2:D755,C2:C755) -> 0.89361472 | I10: =INDEX(LINEST(D2:D755,C2:C755,TRUE,TRUE),2,1) -> 0.0011744346
A11: 3.1025154 | B11: 0.0012738436 | C11: =LOG10(A11) -> 0.49171395 | D11: =LOG10(B11) -> -2.8948839
A12: 3.1141201 | B12: 0.0012766014 | C12: =LOG10(A12) -> 0.49333536 | D12: =LOG10(B12) -> -2.8939447
A13: 3.1257682 | B13: 0.001279321 | C13: =LOG10(A13) -> 0.49495677 | D13: =LOG10(B13) -> -2.8930205
A14: 3.1374598 | B14: 0.0012820014 | C14: =LOG10(A14) -> 0.49657818 | D14: =LOG10(B14) -> -2.8921115
A15: 3.1491952 | B15: 0.0012846419 | C15: =LOG10(A15) -> 0.49819959 | D15: =LOG10(B15) -> -2.8912179
A16: 3.1609745 | B16: 0.0012872416 | C16: =LOG10(A16) -> 0.499821 | D16: =LOG10(B16) -> -2.8903399
A17: 3.1727979 | B17: 0.0012897998 | C17: =LOG10(A17) -> 0.50144241 | D17: =LOG10(B17) -> -2.8894777
A18: 3.1846655 | B18: 0.0013601978 | C18: =LOG10(A18) -> 0.50306382 | D18: =LOG10(B18) -> -2.8663979
A19: 3.1965774 | B19: 0.0013646718 | C19: =LOG10(A19) -> 0.50468523 | D19: =LOG10(B19) -> -2.8649718
A20: 3.2085339 | B20: 0.0013691412 | C20: =LOG10(A20) -> 0.50630664 | D20: =LOG10(B20) -> -2.8635518
A21: 3.2205352 | B21: 0.0013736052 | C21: =LOG10(A21) -> 0.50792805 | D21: =LOG10(B21) -> -2.8621381
A22: 3.2325813 | B22: 0.0013780632 | C22: =LOG10(A22) -> 0.50954946 | D22: =LOG10(B22) -> -2.8607309
... A1001: 125 | B1001: 0.015921627 | C1001: =LOG10(A1001) -> 2.09691 | D1001: =LOG10(B1001) -> -1.7980126

Sheet efbm_H0.5Mach1_1
A1: L | B1: Delta2(L) | C1: log(L) | D1: Log(Delta2(L)) | E1: Archivo | F1: H | G1: Mach | H1: dv_slope | I1: dv_slope_err
A2: 3 | B2: 0.0020507559 | C2: =LOG10(A2) -> 0.47712125 | D2: =LOG10(B2) -> -2.688086 | E2: efbm_H0.5Mach1_1.fits | F2: 0.5 | G2: 1 | H2: 0.9469654 | I2: 0.0041389119
A3: 3.0112212 | B3: 0.0020557529 | C3: =LOG10(A3) -> 0.47874266 | D3: =LOG10(B3) -> -2.6870291
A4: 3.0224844 | B4: 0.0020607 | C4: =LOG10(A4) -> 0.48036408 | D4: =LOG10(B4) -> -2.6859852
A5: 3.0337898 | B5: 0.0020655958 | C5: =LOG10(A5) -> 0.48198549 | D5: =LOG10(B5) -> -2.6849547 | H5: valor central | I5: desv tip
A6: 3.0451374 | B6: 0.002070439 | C6: =LOG10(A6) -> 0.4836069 | D6: =LOG10(B6) -> -2.6839376 | F6: Pendiente 3-10 | H6: =SLOPE(D2:D324,C2:C324) -> 0.92804484 | I6: =INDEX(LINEST(D2:D324,C2:C324,TRUE,TRUE),2,1) -> 0.0020128057
A7: 3.0565275 | B7: 0.0020752281 | C7: =LOG10(A7) -> 0.48522831 | D7: =LOG10(B7) -> -2.6829342 | F7: Pendiente 3-20 | H7: =SLOPE(D2:D510,C2:C510) -> 0.92715633 | I7: =INDEX(LINEST(D2:D510,C2:C510,TRUE,TRUE),2,1) -> 0.00086368125
A8: 3.0679602 | B8: 0.002079962 | C8: =LOG10(A8) -> 0.48684972 | D8: =LOG10(B8) -> -2.6819446 | F8: Pendiente 3-30 | H8: =SLOPE(D2:D618,C2:C618) -> 0.94064046 | I8: =INDEX(LINEST(D2:D618,C2:C618,TRUE,TRUE),2,1) -> 0.0010080158
A9: 3.0794356 | B9: 0.0020846392 | C9: =LOG10(A9) -> 0.48847113 | D9: =LOG10(B9) -> -2.6809691 | F9: Pendiente 3-40 | H9: =SLOPE(D2:D695,C2:C695) -> 0.96653433 | I9: =INDEX(LINEST(D2:D695,C2:C695,TRUE,TRUE),2,1) -> 0.0017468105
A10: 3.090954 | B10: 0.0020892584 | C10: =LOG10(A10) -> 0.49009254 | D10: =LOG10(B10) -> -2.6800079 | F10: Pendiente 3-50 | H10: =SLOPE(D2:D755,C2:C755) -> 0.9875694 | I10: =INDEX(LINEST(D2:D755,C2:C755,TRUE,TRUE),2,1) -> 0.0020682259
A11: 3.1025154 | B11: 0.0020938183 | C11: =LOG10(A11) -> 0.49171395 | D11: =LOG10(B11) -> -2.679061
A12: 3.1141201 | B12: 0.0020983175 | C12: =LOG10(A12) -> 0.49333536 | D12: =LOG10(B12) -> -2.6781288
A13: 3.1257682 | B13: 0.0021027548 | C13: =LOG10(A13) -> 0.49495677 | D13: =LOG10(B13) -> -2.6772114
A14: 3.1374598 | B14: 0.0021071289 | C14: =LOG10(A14) -> 0.49657818 | D14: =LOG10(B14) -> -2.6763089
A15: 3.1491952 | B15: 0.0021114384 | C15: =LOG10(A15) -> 0.49819959 | D15: =LOG10(B15) -> -2.6754216
A16: 3.1609745 | B16: 0.002115682 | C16: =LOG10(A16) -> 0.499821 | D16: =LOG10(B16) -> -2.6745496
A17: 3.1727979 | B17: 0.0021198584 | C17: =LOG10(A17) -> 0.50144241 | D17: =LOG10(B17) -> -2.6736931
A18: 3.1846655 | B18: 0.002233454 | C18: =LOG10(A18) -> 0.50306382 | D18: =LOG10(B18) -> -2.651023
A19: 3.1965774 | B19: 0.0022407203 | C19: =LOG10(A19) -> 0.50468523 | D19: =LOG10(B19) -> -2.6496124
A20: 3.2085339 | B20: 0.0022479787 | C20: =LOG10(A20) -> 0.50630664 | D20: =LOG10(B20) -> -2.6482078
A21: 3.2205352 | B21: 0.0022552283 | C21: =LOG10(A21) -> 0.50792805 | D21: =LOG10(B21) -> -2.6468095
A22: 3.2325813 | B22: 0.0022624679 | C22: =LOG10(A22) -> 0.50954946 | D22: =LOG10(B22) -> -2.6454176
... A1001: 125 | B1001: 0.066317015 | C1001: =LOG10(A1001) -> 2.09691 | D1001: =LOG10(B1001) -> -1.178375

Sheet efbm_H0.5Mach1_2
A1: L | B1: Delta2(L) | C1: log(L) | D1: Log(Delta2(L)) | E1: Archivo | F1: H | G1: Mach | H1: dv_slope | I1: dv_slope_err
A2: 3 | B2: 0.0012584736 | C2: =LOG10(A2) -> 0.47712125 | D2: =LOG10(B2) -> -2.9001559 | E2: efbm_H0.5Mach1_2.fits | F2: 0.5 | G2: 1 | H2: 0.99966464 | I2: 0.0033354209
A3: 3.0112212 | B3: 0.0012615453 | C3: =LOG10(A3) -> 0.47874266 | D3: =LOG10(B3) -> -2.8990971
A4: 3.0224844 | B4: 0.0012645872 | C4: =LOG10(A4) -> 0.48036408 | D4: =LOG10(B4) -> -2.8980512
A5: 3.0337898 | B5: 0.0012675984 | C5: =LOG10(A5) -> 0.48198549 | D5: =LOG10(B5) -> -2.8970183 | H5: valor central | I5: desv tip
A6: 3.0451374 | B6: 0.001270578 | C6: =LOG10(A6) -> 0.4836069 | D6: =LOG10(B6) -> -2.8959987 | F6: Pendiente 3-10 | H6: =SLOPE(D2:D324,C2:C324) -> 1.0105329 | I6: =INDEX(LINEST(D2:D324,C2:C324,TRUE,TRUE),2,1) -> 0.0020283534
A7: 3.0565275 | B7: 0.0012735254 | C7: =LOG10(A7) -> 0.48522831 | D7: =LOG10(B7) -> -2.8949924 | F7: Pendiente 3-20 | H7: =SLOPE(D2:D510,C2:C510) -> 1.0025464 | I7: =INDEX(LINEST(D2:D510,C2:C510,TRUE,TRUE),2,1) -> 0.0010427444
A8: 3.0679602 | B8: 0.0012764395 | C8: =LOG10(A8) -> 0.48684972 | D8: =LOG10(B8) -> -2.8939998 | F8: Pendiente 3-30 | H8: =SLOPE(D2:D618,C2:C618) -> 0.99609452 | I8: =INDEX(LINEST(D2:D618,C2:C618,TRUE,TRUE),2,1) -> 0.00078972256
A9: 3.0794356 | B9: 0.0012793197 | C9: =LOG10(A9) -> 0.48847113 | D9: =LOG10(B9) -> -2.8930209 | F9: Pendiente 3-40 | H9: =SLOPE(D2:D695,C2:C695) -> 0.99464736 | I9: =INDEX(LINEST(D2:D695,C2:C695,TRUE,TRUE),2,1) -> 0.00064594262
A10: 3.090954 | B10: 0.0012821651 | C10: =LOG10(A10) -> 0.49009254 | D10: =LOG10(B10) -> -2.8920561 | F10: Pendiente 3-50 | H10: =SLOPE(D2:D755,C2:C755) -> 0.98345968 | I10: =INDEX(LINEST(D2:D755,C2:C755,TRUE,TRUE),2,1) -> 0.0010024529
A11: 3.1025154 | B11: 0.0012849748 | C11: =LOG10(A11) -> 0.49171395 | D11: =LOG10(B11) -> -2.8911054
A12: 3.1141201 | B12: 0.001287748 | C12: =LOG10(A12) -> 0.49333536 | D12: =LOG10(B12) -> -2.8901691
A13: 3.1257682 | B13: 0.001290484 | C13: =LOG10(A13) -> 0.49495677 | D13: =LOG10(B13) -> -2.8892474
A14: 3.1374598 | B14: 0.0012931819 | C14: =LOG10(A14) -> 0.49657818 | D14: =LOG10(B14) -> -2.8883404
A15: 3.1491952 | B15: 0.0012958409 | C15: =LOG10(A15) -> 0.49819959 | D15: =LOG10(B15) -> -2.8874483
A16: 3.1609745 | B16: 0.0012984602 | C16: =LOG10(A16) -> 0.499821 | D16: =LOG10(B16) -> -2.8865714
A17: 3.1727979 | B17: 0.0013010389 | C17: =LOG10(A17) -> 0.50144241 | D17: =LOG10(B17) -> -2.8857097
A18: 3.1846655 | B18: 0.0013706685 | C18: =LOG10(A18) -> 0.50306382 | D18: =LOG10(B18) -> -2.8630676
A19: 3.1965774 | B19: 0.0013751472 | C19: =LOG10(A19) -> 0.50468523 | D19: =LOG10(B19) -> -2.8616508
A20: 3.2085339 | B20: 0.001379622 | C20: =LOG10(A20) -> 0.50630664 | D20: =LOG10(B20) -> -2.8602399
A21: 3.2205352 | B21: 0.0013840924 | C21: =LOG10(A21) -> 0.50792805 | D21: =LOG10(B21) -> -2.8588349
A22: 3.2325813 | B22: 0.0013885577 | C22: =LOG10(A22) -> 0.50954946 | D22: =LOG10(B22) -> -2.8574361
... A1001: 125 | B1001: 0.025305915 | C1001: =LOG10(A1001) -> 2.09691 | D1001: =LOG10(B1001) -> -1.596778

Sheet efbm_H0.5Mach1_3
A1: L | B1: Delta2(L) | C1: log(L) | D1: Log(Delta2(L)) | E1: Archivo | F1: H | G1: Mach | H1: dv_slope | I1: dv_slope_err
A2: 3 | B2: 0.00073967327 | C2: =LOG10(A2) -> 0.47712125 | D2: =LOG10(B2) -> -3.1309601 | E2: efbm_H0.5Mach1_3.fits | F2: 0.5 | G2: 1 | H2: 1.0625933 | I2: 0.0041997873
A3: 3.0112212 | B3: 0.00074162917 | C3: =LOG10(A3) -> 0.47874266 | D3: =LOG10(B3) -> -3.1298132
A4: 3.0224844 | B4: 0.00074356808 | C4: =LOG10(A4) -> 0.48036408 | D4: =LOG10(B4) -> -3.1286793
A5: 3.0337898 | B5: 0.00074548948 | C5: =LOG10(A5) -> 0.48198549 | D5: =LOG10(B5) -> -3.1275585 | H5: valor central | I5: desv tip
A6: 3.0451374 | B6: 0.00074739284 | C6: =LOG10(A6) -> 0.4836069 | D6: =LOG10(B6) -> -3.1264511 | F6: Pendiente 3-10 | H6: =SLOPE(D2:D324,C2:C324) -> 1.0551075 | I6: =INDEX(LINEST(D2:D324,C2:C324,TRUE,TRUE),2,1) -> 0.0020364661
A7: 3.0565275 | B7: 0.00074927764 | C7: =LOG10(A7) -> 0.48522831 | D7: =LOG10(B7) -> -3.1253572 | F7: Pendiente 3-20 | H7: =SLOPE(D2:D510,C2:C510) -> 1.1195966 | I7: =INDEX(LINEST(D2:D510,C2:C510,TRUE,TRUE),2,1) -> 0.0024553816
A8: 3.0679602 | B8: 0.00075114337 | C8: =LOG10(A8) -> 0.48684972 | D8: =LOG10(B8) -> -3.1242772 | F8: Pendiente 3-30 | H8: =SLOPE(D2:D618,C2:C618) -> 1.1854681 | I8: =INDEX(LINEST(D2:D618,C2:C618,TRUE,TRUE),2,1) -> 0.0035527919
A9: 3.0794356 | B9: 0.00075298949 | C9: =LOG10(A9) -> 0.48847113 | D9: =LOG10(B9) -> -3.1232111 | F9: Pendiente 3-40 | H9: =SLOPE(D2:D695,C2:C695) -> 1.2341771 | I9: =INDEX(LINEST(D2:D695,C2:C695,TRUE,TRUE),2,1) -> 0.0040072866
A10: 3.090954 | B10: 0.00075481549 | C10: =LOG10(A10) -> 0.49009254 | D10: =LOG10(B10) -> -3.1221592 | F10: Pendiente 3-50 | H10: =SLOPE(D2:D755,C2:C755) -> 1.2621833 | I10: =INDEX(LINEST(D2:D755,C2:C755,TRUE,TRUE),2,1) -> 0.0039013972
A11: 3.1025154 | B11: 0.00075662084 | C11: =LOG10(A11) -> 0.49171395 | D11: =LOG10(B11) -> -3.1211217
A12: 3.1141201 | B12: 0.00075840504 | C12: =LOG10(A12) -> 0.49333536 | D12: =LOG10(B12) -> -3.1200988
A13: 3.1257682 | B13: 0.00076016756 | C13: =LOG10(A13) -> 0.49495677 | D13: =LOG10(B13) -> -3.1190907
A14: 3.1374598 | B14: 0.00076190788 | C14: =LOG10(A14) -> 0.49657818 | D14: =LOG10(B14) -> -3.1180975
A15: 3.1491952 | B15: 0.00076362549 | C15: =LOG10(A15) -> 0.49819959 | D15: =LOG10(B15) -> -3.1171196
A16: 3.1609745 | B16: 0.00076531989 | C16: =LOG10(A16) -> 0.499821 | D16: =LOG10(B16) -> -3.116157
A17: 3.1727979 | B17: 0.00076699057 | C17: =LOG10(A17) -> 0.50144241 | D17: =LOG10(B17) -> -3.11521
A18: 3.1846655 | B18: 0.00081012355 | C18: =LOG10(A18) -> 0.50306382 | D18: =LOG10(B18) -> -3.0914487
A19: 3.1965774 | B19: 0.00081297383 | C19: =LOG10(A19) -> 0.50468523 | D19: =LOG10(B19) -> -3.0899234
A20: 3.2085339 | B20: 0.00081582309 | C20: =LOG10(A20) -> 0.50630664 | D20: =LOG10(B20) -> -3.088404
A21: 3.2205352 | B21: 0.00081867091 | C21: =LOG10(A21) -> 0.50792805 | D21: =LOG10(B21) -> -3.0868906
A22: 3.2325813 | B22: 0.00082151686 | C22: =LOG10(A22) -> 0.50954946 | D22: =LOG10(B22) -> -3.0853835
... A1001: 125 | B1001: 0.064745563 | C1001: =LOG10(A1001) -> 2.09691 | D1001: =LOG10(B1001) -> -1.18879

Sheet efbm_H0.5Mach1_4
A1: L | B1: Delta2(L) | C1: log(L) | D1: Log(Delta2(L)) | E1: Archivo | F1: H | G1: Mach | H1: dv_slope | I1: dv_slope_err
A2: 3 | B2: 0.0017249152 | C2: =LOG10(A2) -> 0.47712125 | D2: =LOG10(B2) -> -2.7632323 | E2: efbm_H0.5Mach1_4.fits | F2: 0.5 | G2: 1 | H2: 1.0098618 | I2: 0.0040043123
A3: 3.0112212 | B3: 0.0017292877 | C3: =LOG10(A3) -> 0.47874266 | D3: =LOG10(B3) -> -2.7621328
A4: 3.0224844 | B4: 0.0017336178 | C4: =LOG10(A4) -> 0.48036408 | D4: =LOG10(B4) -> -2.7610467
A5: 3.0337898 | B5: 0.0017379042 | C5: =LOG10(A5) -> 0.48198549 | D5: =LOG10(B5) -> -2.7599742 | H5: valor central | I5: desv tip
A6: 3.0451374 | B6: 0.0017421459 | C6: =LOG10(A6) -> 0.4836069 | D6: =LOG10(B6) -> -2.7589155 | F6: Pendiente 3-10 | H6: =SLOPE(D2:D324,C2:C324) -> 1.0234232 | I6: =INDEX(LINEST(D2:D324,C2:C324,TRUE,TRUE),2,1) -> 0.0019830017
A7: 3.0565275 | B7: 0.0017463416 | C7: =LOG10(A7) -> 0.48522831 | D7: =LOG10(B7) -> -2.7578708 | F7: Pendiente 3-20 | H7: =SLOPE(D2:D510,C2:C510) -> 1.0054079 | I7: =INDEX(LINEST(D2:D510,C2:C510,TRUE,TRUE),2,1) -> 0.0012860793
A8: 3.0679602 | B8: 0.0017504901 | C8: =LOG10(A8) -> 0.48684972 | D8: =LOG10(B8) -> -2.7568403 | F8: Pendiente 3-30 | H8: =SLOPE(D2:D618,C2:C618) -> 0.95302787 | I8: =INDEX(LINEST(D2:D618,C2:C618,TRUE,TRUE),2,1) -> 0.0027210534
A9: 3.0794356 | B9: 0.0017545903 | C9: =LOG10(A9) -> 0.48847113 | D9: =LOG10(B9) -> -2.7558243 | F9: Pendiente 3-40 | H9: =SLOPE(D2:D695,C2:C695) -> 0.907819 | I9: =INDEX(LINEST(D2:D695,C2:C695,TRUE,TRUE),2,1) -> 0.0034173268
A10: 3.090954 | B10: 0.0017586411 | C10: =LOG10(A10) -> 0.49009254 | D10: =LOG10(B10) -> -2.7548228 | F10: Pendiente 3-50 | H10: =SLOPE(D2:D755,C2:C755) -> 0.87852242 | I10: =INDEX(LINEST(D2:D755,C2:C755,TRUE,TRUE),2,1) -> 0.0035256767
A11: 3.1025154 | B11: 0.0017626411 | C11: =LOG10(A11) -> 0.49171395 | D11: =LOG10(B11) -> -2.7538361
A12: 3.1141201 | B12: 0.0017665894 | C12: =LOG10(A12) -> 0.49333536 | D12: =LOG10(B12) -> -2.7528644
A13: 3.1257682 | B13: 0.0017704847 | C13: =LOG10(A13) -> 0.49495677 | D13: =LOG10(B13) -> -2.7519078
A14: 3.1374598 | B14: 0.0017743258 | C14: =LOG10(A14) -> 0.49657818 | D14: =LOG10(B14) -> -2.7509666
A15: 3.1491952 | B15: 0.0017781117 | C15: =LOG10(A15) -> 0.49819959 | D15: =LOG10(B15) -> -2.750041
A16: 3.1609745 | B16: 0.0017818412 | C16: =LOG10(A16) -> 0.499821 | D16: =LOG10(B16) -> -2.749131
A17: 3.1727979 | B17: 0.0017855131 | C17: =LOG10(A17) -> 0.50144241 | D17: =LOG10(B17) -> -2.748237
A18: 3.1846655 | B18: 0.0018845897 | C18: =LOG10(A18) -> 0.50306382 | D18: =LOG10(B18) -> -2.7247832
A19: 3.1965774 | B19: 0.0018909589 | C19: =LOG10(A19) -> 0.50468523 | D19: =LOG10(B19) -> -2.7233179
A20: 3.2085339 | B20: 0.0018973224 | C20: =LOG10(A20) -> 0.50630664 | D20: =LOG10(B20) -> -2.7218589
A21: 3.2205352 | B21: 0.0019036792 | C21: =LOG10(A21) -> 0.50792805 | D21: =LOG10(B21) -> -2.7204062
A22: 3.2325813 | B22: 0.0019100283 | C22: =LOG10(A22) -> 0.50954946 | D22: =LOG10(B22) -> -2.7189602
... A1001: 125 | B1001: 0.017212922 | C1001: =LOG10(A1001) -> 2.09691 | D1001: =LOG10(B1001) -> -1.7641454

Sheet efbm_H0.5Mach1_5
A1: L | B1: Delta2(L) | C1: log(L) | D1: Log(Delta2(L)) | E1: Archivo | F1: H | G1: Mach | H1: dv_slope | I1: dv_slope_err
A2: 3 | B2: 0.0026054123 | C2: =LOG10(A2) -> 0.47712125 | D2: =LOG10(B2) -> -2.5841235 | E2: efbm_H0.5Mach1_5.fits | F2: 0.5 | G2: 1 | H2: 1.0475696 | I2: 0.0040170492
A3: 3.0112212 | B3: 0.0026121328 | C3: =LOG10(A3) -> 0.47874266 | D3: =LOG10(B3) -> -2.5830048
A4: 3.0224844 | B4: 0.0026187915 | C4: =LOG10(A4) -> 0.48036408 | D4: =LOG10(B4) -> -2.5818991
A5: 3.0337898 | B5: 0.0026253866 | C5: =LOG10(A5) -> 0.48198549 | D5: =LOG10(B5) -> -2.5808067 | H5: valor central | I5: desv tip
A6: 3.0451374 | B6: 0.0026319165 | C6: =LOG10(A6) -> 0.4836069 | D6: =LOG10(B6) -> -2.5797279 | F6: Pendiente 3-10 | H6: =SLOPE(D2:D324,C2:C324) -> 1.0370632 | I6: =INDEX(LINEST(D2:D324,C2:C324,TRUE,TRUE),2,1) -> 0.0019859629
A7: 3.0565275 | B7: 0.0026383793 | C7: =LOG10(A7) -> 0.48522831 | D7: =LOG10(B7) -> -2.5786628 | F7: Pendiente 3-20 | H7: =SLOPE(D2:D510,C2:C510) -> 1.0932597 | I7: =INDEX(LINEST(D2:D510,C2:C510,TRUE,TRUE),2,1) -> 0.0021691304
A8: 3.0679602 | B8: 0.0026447733 | C8: =LOG10(A8) -> 0.48684972 | D8: =LOG10(B8) -> -2.5776115 | F8: Pendiente 3-30 | H8: =SLOPE(D2:D618,C2:C618) -> 1.1224191 | I8: =INDEX(LINEST(D2:D618,C2:C618,TRUE,TRUE),2,1) -> 0.0019900168
A9: 3.0794356 | B9: 0.0026510968 | C9: =LOG10(A9) -> 0.48847113 | D9: =LOG10(B9) -> -2.5765744 | F9: Pendiente 3-40 | H9: =SLOPE(D2:D695,C2:C695) -> 1.1266311 | I9: =INDEX(LINEST(D2:D695,C2:C695,TRUE,TRUE),2,1) -> 0.0016190481
A10: 3.090954 | B10: 0.002657348 | C10: =LOG10(A10) -> 0.49009254 | D10: =LOG10(B10) -> -2.5755516 | F10: Pendiente 3-50 | H10: =SLOPE(D2:D755,C2:C755) -> 1.113334 | I10: =INDEX(LINEST(D2:D755,C2:C755,TRUE,TRUE),2,1) -> 0.0017044925
A11: 3.1025154 | B11: 0.0026635251 | C11: =LOG10(A11) -> 0.49171395 | D11: =LOG10(B11) -> -2.5745432
A12: 3.1141201 | B12: 0.0026696264 | C12: =LOG10(A12) -> 0.49333536 | D12: =LOG10(B12) -> -2.5735495
A13: 3.1257682 | B13: 0.0026756502 | C13: =LOG10(A13) -> 0.49495677 | D13: =LOG10(B13) -> -2.5725707
A14: 3.1374598 | B14: 0.0026815947 | C14: =LOG10(A14) -> 0.49657818 | D14: =LOG10(B14) -> -2.5716069
A15: 3.1491952 | B15: 0.0026874582 | C15: =LOG10(A15) -> 0.49819959 | D15: =LOG10(B15) -> -2.5706583
A16: 3.1609745 | B16: 0.0026932391 | C16: =LOG10(A16) -> 0.499821 | D16: =LOG10(B16) -> -2.5697251
A17: 3.1727979 | B17: 0.0026989355 | C17: =LOG10(A17) -> 0.50144241 | D17: =LOG10(B17) -> -2.5688075
A18: 3.1846655 | B18: 0.0028494398 | C18: =LOG10(A18) -> 0.50306382 | D18: =LOG10(B18) -> -2.5452405
A19: 3.1965774 | B19: 0.0028592558 | C19: =LOG10(A19) -> 0.50468523 | D19: =LOG10(B19) -> -2.543747
A20: 3.2085339 | B20: 0.0028690673 | C20: =LOG10(A20) -> 0.50630664 | D20: =LOG10(B20) -> -2.5422593
A21: 3.2205352 | B21: 0.0028788728 | C21: =LOG10(A21) -> 0.50792805 | D21: =LOG10(B21) -> -2.5407775
A22: 3.2325813 | B22: 0.0028886709 | C22: =LOG10(A22) -> 0.50954946 | D22: =LOG10(B22) -> -2.5393019
... A1001: 125 | B1001: 0.052262043 | C1001: =LOG10(A1001) -> 2.09691 | D1001: =LOG10(B1001) -> -1.2818136

Sheet efbm_H0.5Mach1_6
A1: L | B1: Delta2(L) | C1: log(L) | D1: Log(Delta2(L)) | E1: Archivo | F1: H | G1: Mach | H1: dv_slope | I1: dv_slope_err
A2: 3 | B2: 0.00067189778 | C2: =LOG10(A2) -> 0.47712125 | D2: =LOG10(B2) -> -3.1726968 | E2: efbm_H0.5Mach1_6.fits | F2: 0.5 | G2: 1 | H2: 0.84977915 | I2: 0.0041770153
A3: 3.0112212 | B3: 0.00067347771 | C3: =LOG10(A3) -> 0.47874266 | D3: =LOG10(B3) -> -3.1716768
A4: 3.0224844 | B4: 0.00067504027 | C4: =LOG10(A4) -> 0.48036408 | D4: =LOG10(B4) -> -3.1706703
A5: 3.0337898 | B5: 0.00067658502 | C5: =LOG10(A5) -> 0.48198549 | D5: =LOG10(B5) -> -3.1696776 | H5: valor central | I5: desv tip
A6: 3.0451374 | B6: 0.00067811153 | C6: =LOG10(A6) -> 0.4836069 | D6: =LOG10(B6) -> -3.1686989 | F6: Pendiente 3-10 | H6: =SLOPE(D2:D324,C2:C324) -> 0.82240712 | I6: =INDEX(LINEST(D2:D324,C2:C324,TRUE,TRUE),2,1) -> 0.0022318867
A7: 3.0565275 | B7: 0.00067961934 | C7: =LOG10(A7) -> 0.48522831 | D7: =LOG10(B7) -> -3.1677343 | F7: Pendiente 3-20 | H7: =SLOPE(D2:D510,C2:C510) -> 0.82911931 | I7: =INDEX(LINEST(D2:D510,C2:C510,TRUE,TRUE),2,1) -> 0.0014647347
A8: 3.0679602 | B8: 0.00068110802 | C8: =LOG10(A8) -> 0.48684972 | D8: =LOG10(B8) -> -3.166784 | F8: Pendiente 3-30 | H8: =SLOPE(D2:D618,C2:C618) -> 0.88720833 | I8: =INDEX(LINEST(D2:D618,C2:C618,TRUE,TRUE),2,1) -> 0.0029828029
A9: 3.0794356 | B9: 0.00068257714 | C9: =LOG10(A9) -> 0.48847113 | D9: =LOG10(B9) -> -3.1658483 | F9: Pendiente 3-40 | H9: =SLOPE(D2:D695,C2:C695) -> 0.92858185 | I9: =INDEX(LINEST(D2:D695,C2:C695,TRUE,TRUE),2,1) -> 0.0033791611
A10: 3.090954 | B10: 0.00068402624 | C10: =LOG10(A10) -> 0.49009254 | D10: =LOG10(B10) -> -3.1649272 | F10: Pendiente 3-50 | H10: =SLOPE(D2:D755,C2:C755) -> 0.94665408 | I10: =INDEX(LINEST(D2:D755,C2:C755,TRUE,TRUE),2,1) -> 0.0031267878
A11: 3.1025154 | B11: 0.0006854549 | C11: =LOG10(A11) -> 0.49171395 | D11: =LOG10(B11) -> -3.1640211
A12: 3.1141201 | B12: 0.00068686269 | C12: =LOG10(A12) -> 0.49333536 | D12: =LOG10(B12) -> -3.1631301
A13: 3.1257682 | B13: 0.00068824917 | C13: =LOG10(A13) -> 0.49495677 | D13: =LOG10(B13) -> -3.1622543
A14: 3.1374598 | B14: 0.00068961391 | C14: =LOG10(A14) -> 0.49657818 | D14: =LOG10(B14) -> -3.161394
A15: 3.1491952 | B15: 0.00069095649 | C15: =LOG10(A15) -> 0.49819959 | D15: =LOG10(B15) -> -3.1605493
A16: 3.1609745 | B16: 0.00069227648 | C16: =LOG10(A16) -> 0.499821 | D16: =LOG10(B16) -> -3.1597204
A17: 3.1727979 | B17: 0.00069357348 | C17: =LOG10(A17) -> 0.50144241 | D17: =LOG10(B17) -> -3.1589075
A18: 3.1846655 | B18: 0.00072980864 | C18: =LOG10(A18) -> 0.50306382 | D18: =LOG10(B18) -> -3.136791
A19: 3.1965774 | B19: 0.00073207948 | C19: =LOG10(A19) -> 0.50468523 | D19: =LOG10(B19) -> -3.1354418
A20: 3.2085339 | B20: 0.00073434566 | C20: =LOG10(A20) -> 0.50630664 | D20: =LOG10(B20) -> -3.1340995
A21: 3.2205352 | B21: 0.00073660684 | C21: =LOG10(A21) -> 0.50792805 | D21: =LOG10(B21) -> -3.1327643
A22: 3.2325813 | B22: 0.00073886263 | C22: =LOG10(A22) -> 0.50954946 | D22: =LOG10(B22) -> -3.1314363
... A1001: 125 | B1001: 0.01395075 | C1001: =LOG10(A1001) -> 2.09691 | D1001: =LOG10(B1001) -> -1.8554024

Sheet efbm_H0.5Mach1_7
A1: L | B1: Delta2(L) | C1: log(L) | D1: Log(Delta2(L)) | E1: Archivo | F1: H | G1: Mach | H1: dv_slope | I1: dv_slope_err
A2: 3 | B2: 0.00054058963 | C2: =LOG10(A2) -> 0.47712125 | D2: =LOG10(B2) -> -3.2671323 | E2: efbm_H0.5Mach1_7.fits | F2: 0.5 | G2: 1 | H2: 0.97528765 | I2: 0.004432257
A3: 3.0112212 | B3: 0.00054200501 | C3: =LOG10(A3) -> 0.47874266 | D3: =LOG10(B3) -> -3.2659967
A4: 3.0224844 | B4: 0.00054340684 | C4: =LOG10(A4) -> 0.48036408 | D4: =LOG10(B4) -> -3.2648749
A5: 3.0337898 | B5: 0.00054479472 | C5: =LOG10(A5) -> 0.48198549 | D5: =LOG10(B5) -> -3.2637671 | H5: valor central | I5: desv tip
A6: 3.0451374 | B6: 0.00054616828 | C6: =LOG10(A6) -> 0.4836069 | D6: =LOG10(B6) -> -3.2626735 | F6: Pendiente 3-10 | H6: =SLOPE(D2:D324,C2:C324) -> 0.95229709 | I6: =INDEX(LINEST(D2:D324,C2:C324,TRUE,TRUE),2,1) -> 0.0023136799
A7: 3.0565275 | B7: 0.00054752715 | C7: =LOG10(A7) -> 0.48522831 | D7: =LOG10(B7) -> -3.2615943 | F7: Pendiente 3-20 | H7: =SLOPE(D2:D510,C2:C510) -> 0.94505825 | I7: =INDEX(LINEST(D2:D510,C2:C510,TRUE,TRUE),2,1) -> 0.0011221926
A8: 3.0679602 | B8: 0.00054887095 | C8: =LOG10(A8) -> 0.48684972 | D8: =LOG10(B8) -> -3.2605298 | F8: Pendiente 3-30 | H8: =SLOPE(D2:D618,C2:C618) -> 0.969679 | I8: =INDEX(LINEST(D2:D618,C2:C618,TRUE,TRUE),2,1) -> 0.0014509689
A9: 3.0794356 | B9: 0.00055019929 | C9: =LOG10(A9) -> 0.48847113 | D9: =LOG10(B9) -> -3.25948 | F9: Pendiente 3-40 | H9: =SLOPE(D2:D695,C2:C695) -> 0.99924778 | I9: =INDEX(LINEST(D2:D695,C2:C695,TRUE,TRUE),2,1) -> 0.0021213459
A10: 3.090954 | B10: 0.00055151181 | C10: =LOG10(A10) -> 0.49009254 | D10: =LOG10(B10) -> -3.2584452 | F10: Pendiente 3-50 | H10: =SLOPE(D2:D755,C2:C755) -> 1.0308855 | I10: =INDEX(LINEST(D2:D755,C2:C755,TRUE,TRUE),2,1) -> 0.0028393916
A11: 3.1025154 | B11: 0.00055280812 | C11: =LOG10(A11) -> 0.49171395 | D11: =LOG10(B11) -> -3.2574256
A12: 3.1141201 | B12: 0.00055408785 | C12: =LOG10(A12) -> 0.49333536 | D12: =LOG10(B12) -> -3.2564214
A13: 3.1257682 | B13: 0.00055535064 | C13: =LOG10(A13) -> 0.49495677 | D13: =LOG10(B13) -> -3.2554327
A14: 3.1374598 | B14: 0.00055659611 | C14: =LOG10(A14) -> 0.49657818 | D14: =LOG10(B14) -> -3.2544598
A15: 3.1491952 | B15: 0.00055782389 | C15: =LOG10(A15) -> 0.49819959 | D15: =LOG10(B15) -> -3.2535029
A16: 3.1609745 | B16: 0.00055903362 | C16: =LOG10(A16) -> 0.499821 | D16: =LOG10(B16) -> -3.2525621
A17: 3.1727979 | B17: 0.00056022493 | C17: =LOG10(A17) -> 0.50144241 | D17: =LOG10(B17) -> -3.2516376
A18: 3.1846655 | B18: 0.00059151264 | C18: =LOG10(A18) -> 0.50306382 | D18: =LOG10(B18) -> -3.228036
A19: 3.1965774 | B19: 0.00059355217 | C19: =LOG10(A19) -> 0.50468523 | D19: =LOG10(B19) -> -3.2265411
A20: 3.2085339 | B20: 0.00059558945 | C20: =LOG10(A20) -> 0.50630664 | D20: =LOG10(B20) -> -3.225053
A21: 3.2205352 | B21: 0.00059762418 | C21: =LOG10(A21) -> 0.50792805 | D21: =LOG10(B21) -> -3.2235718
A22: 3.2325813 | B22: 0.00059965604 | C22: =LOG10(A22) -> 0.50954946 | D22: =LOG10(B22) -> -3.2220978
... A1001: 125 | B1001: 0.029408234 | C1001: =LOG10(A1001) -> 2.09691 | D1001: =LOG10(B1001) -> -1.5315311

Sheet efbm_H0.5Mach1_8
A1: L | B1: Delta2(L) | C1: log(L) | D1: Log(Delta2(L)) | E1: Archivo | F1: H | G1: Mach | H1: dv_slope | I1: dv_slope_err
A2: 3 | B2: 0.0007629771 | C2: =LOG10(A2) -> 0.47712125 | D2: =LOG10(B2) -> -3.1174885 | E2: efbm_H0.5Mach1_8.fits | F2: 0.5 | G2: 1 | H2: 0.98865269 | I2: 0.0037500835
A3: 3.0112212 | B3: 0.00076475255 | C3: =LOG10(A3) -> 0.47874266 | D3: =LOG10(B3) -> -3.1164791
A4: 3.0224844 | B4: 0.00076650925 | C4: =LOG10(A4) -> 0.48036408 | D4: =LOG10(B4) -> -3.1154826
A5: 3.0337898 | B5: 0.00076824669 | C5: =LOG10(A5) -> 0.48198549 | D5: =LOG10(B5) -> -3.1144993 | H5: valor central | I5: desv tip
A6: 3.0451374 | B6: 0.00076996439 | C6: =LOG10(A6) -> 0.4836069 | D6: =LOG10(B6) -> -3.1135294 | F6: Pendiente 3-10 | H6: =SLOPE(D2:D324,C2:C324) -> 1.0061867 | I6: =INDEX(LINEST(D2:D324,C2:C324,TRUE,TRUE),2,1) -> 0.0026804941
A7: 3.0565275 | B7: 0.00077166186 | C7: =LOG10(A7) -> 0.48522831 | D7: =LOG10(B7) -> -3.112573 | F7: Pendiente 3-20 | H7: =SLOPE(D2:D510,C2:C510) -> 1.0756293 | I7: =INDEX(LINEST(D2:D510,C2:C510,TRUE,TRUE),2,1) -> 0.0022570971
A8: 3.0679602 | B8: 0.00077333861 | C8: =LOG10(A8) -> 0.48684972 | D8: =LOG10(B8) -> -3.1116303 | F8: Pendiente 3-30 | H8: =SLOPE(D2:D618,C2:C618) -> 1.1315482 | I8: =INDEX(LINEST(D2:D618,C2:C618,TRUE,TRUE),2,1) -> 0.0031674599
A9: 3.0794356 | B9: 0.00077499415 | C9: =LOG10(A9) -> 0.48847113 | D9: =LOG10(B9) -> -3.1107016 | F9: Pendiente 3-40 | H9: =SLOPE(D2:D695,C2:C695) -> 1.1889131 | I9: =INDEX(LINEST(D2:D695,C2:C695,TRUE,TRUE),2,1) -> 0.00422215
A10: 3.090954 | B10: 0.000776628 | C10: =LOG10(A10) -> 0.49009254 | D10: =LOG10(B10) -> -3.109787 | F10: Pendiente 3-50 | H10: =SLOPE(D2:D755,C2:C755) -> 1.2314436 | I10: =INDEX(LINEST(D2:D755,C2:C755,TRUE,TRUE),2,1) -> 0.0046178853
A11: 3.1025154 | B11: 0.00077823967 | C11: =LOG10(A11) -> 0.49171395 | D11: =LOG10(B11) -> -3.1088866
A12: 3.1141201 | B12: 0.00077982869 | C12: =LOG10(A12) -> 0.49333536 | D12: =LOG10(B12) -> -3.1080008
A13: 3.1257682 | B13: 0.00078139456 | C13: =LOG10(A13) -> 0.49495677 | D13: =LOG10(B13) -> -3.1071296
A14: 3.1374598 | B14: 0.00078293682 | C14: =LOG10(A14) -> 0.49657818 | D14: =LOG10(B14) -> -3.1062733
A15: 3.1491952 | B15: 0.00078445497 | C15: =LOG10(A15) -> 0.49819959 | D15: =LOG10(B15) -> -3.105432
A16: 3.1609745 | B16: 0.00078594857 | C16: =LOG10(A16) -> 0.499821 | D16: =LOG10(B16) -> -3.1046059
A17: 3.1727979 | B17: 0.00078741712 | C17: =LOG10(A17) -> 0.50144241 | D17: =LOG10(B17) -> -3.1037951
A18: 3.1846655 | B18: 0.00082962787 | C18: =LOG10(A18) -> 0.50306382 | D18: =LOG10(B18) -> -3.0811167
A19: 3.1965774 | B19: 0.00083224529 | C19: =LOG10(A19) -> 0.50468523 | D19: =LOG10(B19) -> -3.0797487
A20: 3.2085339 | B20: 0.0008348597 | C20: =LOG10(A20) -> 0.50630664 | D20: =LOG10(B20) -> -3.0783865
A21: 3.2205352 | B21: 0.00083747071 | C21: =LOG10(A21) -> 0.50792805 | D21: =LOG10(B21) -> -3.0770304
A22: 3.2325813 | B22: 0.00084007793 | C22: =LOG10(A22) -> 0.50954946 | D22: =LOG10(B22) -> -3.0756804
... A1001: 125 | B1001: 0.052641687 | C1001: =LOG10(A1001) -> 2.09691 | D1001: =LOG10(B1001) -> -1.2786702

Sheet efbm_H0.5Mach1_9
A1: L | B1: Delta2(L) | C1: log(L) | D1: Log(Delta2(L)) | E1: Archivo | F1: H | G1: Mach | H1: dv_slope | I1: dv_slope_err
A2: 3 | B2: 0.00041077729 | C2: =LOG10(A2) -> 0.47712125 | D2: =LOG10(B2) -> -3.3863936 | E2: efbm_H0.5Mach1_9.fits | F2: 0.5 | G2: 1 | H2: 1.0304632 | I2: 0.0039257242
A3: 3.0112212 | B3: 0.00041182841 | C3: =LOG10(A3) -> 0.47874266 | D3: =LOG10(B3) -> -3.3852837
A4: 3.0224844 | B4: 0.00041286952 | C4: =LOG10(A4) -> 0.48036408 | D4: =LOG10(B4) -> -3.3841872
A5: 3.0337898 | B5: 0.00041390036 | C5: =LOG10(A5) -> 0.48198549 | D5: =LOG10(B5) -> -3.3831042 | H5: valor central | I5: desv tip
A6: 3.0451374 | B6: 0.00041492062 | C6: =LOG10(A6) -> 0.4836069 | D6: =LOG10(B6) -> -3.382035 | F6: Pendiente 3-10 | H6: =SLOPE(D2:D324,C2:C324) -> 1.0329239 | I6: =INDEX(LINEST(D2:D324,C2:C324,TRUE,TRUE),2,1) -> 0.0020217781
A7: 3.0565275 | B7: 0.00041593005 | C7: =LOG10(A7) -> 0.48522831 | D7: =LOG10(B7) -> -3.3809797 | F7: Pendiente 3-20 | H7: =SLOPE(D2:D510,C2:C510) -> 1.0445401 | I7: =INDEX(LINEST(D2:D510,C2:C510,TRUE,TRUE),2,1) -> 0.00094102389
A8: 3.0679602 | B8: 0.00041692834 | C8: =LOG10(A8) -> 0.48684972 | D8: =LOG10(B8) -> -3.3799386 | F8: Pendiente 3-30 | H8: =SLOPE(D2:D618,C2:C618) -> 1.0671955 | I8: =INDEX(LINEST(D2:D618,C2:C618,TRUE,TRUE),2,1) -> 0.001327043
A9: 3.0794356 | B9: 0.00041791524 | C9: =LOG10(A9) -> 0.48847113 | D9: =LOG10(B9) -> -3.3789118 | F9: Pendiente 3-40 | H9: =SLOPE(D2:D695,C2:C695) -> 1.0942281 | I9: =INDEX(LINEST(D2:D695,C2:C695,TRUE,TRUE),2,1) -> 0.0019275377
A10: 3.090954 | B10: 0.00041889045 | C10: =LOG10(A10) -> 0.49009254 | D10: =LOG10(B10) -> -3.3778995 | F10: Pendiente 3-50 | H10: =SLOPE(D2:D755,C2:C755) -> 1.1197761 | I10: =INDEX(LINEST(D2:D755,C2:C755,TRUE,TRUE),2,1) -> 0.0024074781
A11: 3.1025154 | B11: 0.0004198537 | C11: =LOG10(A11) -> 0.49171395 | D11: =LOG10(B11) -> -3.376902
A12: 3.1141201 | B12: 0.00042080471 | C12: =LOG10(A12) -> 0.49333536 | D12: =LOG10(B12) -> -3.3759194
A13: 3.1257682 | B13: 0.0004217432 | C13: =LOG10(A13) -> 0.49495677 | D13: =LOG10(B13) -> -3.3749519
A14: 3.1374598 | B14: 0.00042266891 | C14: =LOG10(A14) -> 0.49657818 | D14: =LOG10(B14) -> -3.3739997
A15: 3.1491952 | B15: 0.00042358156 | C15: =LOG10(A15) -> 0.49819959 | D15: =LOG10(B15) -> -3.373063
A16: 3.1609745 | B16: 0.00042448087 | C16: =LOG10(A16) -> 0.499821 | D16: =LOG10(B16) -> -3.3721419
A17: 3.1727979 | B17: 0.00042536659 | C17: =LOG10(A17) -> 0.50144241 | D17: =LOG10(B17) -> -3.3712366
A18: 3.1846655 | B18: 0.00044883388 | C18: =LOG10(A18) -> 0.50306382 | D18: =LOG10(B18) -> -3.3479144
A19: 3.1965774 | B19: 0.00045035914 | C19: =LOG10(A19) -> 0.50468523 | D19: =LOG10(B19) -> -3.346441
A20: 3.2085339 | B20: 0.00045188312 | C20: =LOG10(A20) -> 0.50630664 | D20: =LOG10(B20) -> -3.3449739
A21: 3.2205352 | B21: 0.00045340559 | C21: =LOG10(A21) -> 0.50792805 | D21: =LOG10(B21) -> -3.3435131
A22: 3.2325813 | B22: 0.00045492633 | C22: =LOG10(A22) -> 0.50954946 | D22: =LOG10(B22) -> -3.3420589
... A1001: 125 | B1001: 0.026630161 | C1001: =LOG10(A1001) -> 2.09691 | D1001: =LOG10(B1001) -> -1.5746262

Sheet efbm_H0.5Mach2.5_0
A1: L | B1: Delta2(L) | C1: log(L) | D1: Log(Delta2(L)) | E1: Archivo | F1: H | G1: Mach | H1: dv_slope | I1: dv_slope_err
A2: 3 | B2: 0.010447533 | C2: =LOG10(A2) -> 0.47712125 | D2: =LOG10(B2) -> -1.9809863 | E2: efbm_H0.5Mach2.5_0.fits | F2: 0.5 | G2: 2.5 | H2: 0.88899816 | I2: 0.0060863508
A3: 3.0112212 | B3: 0.010473445 | C3: =LOG10(A3) -> 0.47874266 | D3: =LOG10(B3) -> -1.9799104
A4: 3.0224844 | B4: 0.010499097 | C4: =LOG10(A4) -> 0.48036408 | D4: =LOG10(B4) -> -1.978848
A5: 3.0337898 | B5: 0.010524482 | C5: =LOG10(A5) -> 0.48198549 | D5: =LOG10(B5) -> -1.9777993 | H5: valor central | I5: desv tip
A6: 3.0451374 | B6: 0.010549592 | C6: =LOG10(A6) -> 0.4836069 | D6: =LOG10(B6) -> -1.9767643 | F6: Pendiente 3-10 | H6: =SLOPE(D2:D324,C2:C324) -> 0.93450301 | I6: =INDEX(LINEST(D2:D324,C2:C324,TRUE,TRUE),2,1) -> 0.0032921638
A7: 3.0565275 | B7: 0.010574421 | C7: =LOG10(A7) -> 0.48522831 | D7: =LOG10(B7) -> -1.9757434 | F7: Pendiente 3-20 | H7: =SLOPE(D2:D510,C2:C510) -> 0.77487799 | I7: =INDEX(LINEST(D2:D510,C2:C510,TRUE,TRUE),2,1) -> 0.0047289439
A8: 3.0679602 | B8: 0.010598962 | C8: =LOG10(A8) -> 0.48684972 | D8: =LOG10(B8) -> -1.9747367 | F8: Pendiente 3-30 | H8: =SLOPE(D2:D618,C2:C618) -> 0.7285672 | I8: =INDEX(LINEST(D2:D618,C2:C618,TRUE,TRUE),2,1) -> 0.0038509084
A9: 3.0794356 | B9: 0.010623207 | C9: =LOG10(A9) -> 0.48847113 | D9: =LOG10(B9) -> -1.9737443 | F9: Pendiente 3-40 | H9: =SLOPE(D2:D695,C2:C695) -> 0.71826339 | I9: =INDEX(LINEST(D2:D695,C2:C695,TRUE,TRUE),2,1) -> 0.0031083875
A10: 3.090954 | B10: 0.010647151 | C10: =LOG10(A10) -> 0.49009254 | D10: =LOG10(B10) -> -1.9727666 | F10: Pendiente 3-50 | H10: =SLOPE(D2:D755,C2:C755) -> 0.71819172 | I10: =INDEX(LINEST(D2:D755,C2:C755,TRUE,TRUE),2,1) -> 0.0026342024
A11: 3.1025154 | B11: 0.010670786 | C11: =LOG10(A11) -> 0.49171395 | D11: =LOG10(B11) -> -1.9718036
A12: 3.1141201 | B12: 0.010694105 | C12: =LOG10(A12) -> 0.49333536 | D12: =LOG10(B12) -> -1.9708556
A13: 3.1257682 | B13: 0.010717101 | C13: =LOG10(A13) -> 0.49495677 | D13: =LOG10(B13) -> -1.9699227
A14: 3.1374598 | B14: 0.010739768 | C14: =LOG10(A14) -> 0.49657818 | D14: =LOG10(B14) -> -1.9690051
A15: 3.1491952 | B15: 0.010762099 | C15: =LOG10(A15) -> 0.49819959 | D15: =LOG10(B15) -> -1.968103
A16: 3.1609745 | B16: 0.010784088 | C16: =LOG10(A16) -> 0.499821 | D16: =LOG10(B16) -> -1.9672166
A17: 3.1727979 | B17: 0.010805727 | C17: =LOG10(A17) -> 0.50144241 | D17: =LOG10(B17) -> -1.966346
A18: 3.1846655 | B18: 0.011401041 | C18: =LOG10(A18) -> 0.50306382 | D18: =LOG10(B18) -> -1.9430555
A19: 3.1965774 | B19: 0.01143888 | C19: =LOG10(A19) -> 0.50468523 | D19: =LOG10(B19) -> -1.9416165
A20: 3.2085339 | B20: 0.01147668 | C20: =LOG10(A20) -> 0.50630664 | D20: =LOG10(B20) -> -1.9401837
A21: 3.2205352 | B21: 0.011514437 | C21: =LOG10(A21) -> 0.50792805 | D21: =LOG10(B21) -> -1.9387573
A22: 3.2325813 | B22: 0.011552145 | C22: =LOG10(A22) -> 0.50954946 | D22: =LOG10(B22) -> -1.9373374
... A1001: 125 | B1001: 0.079790973 | C1001: =LOG10(A1001) -> 2.09691 | D1001: =LOG10(B1001) -> -1.0980462

Sheet efbm_H0.5Mach2.5_1
A1: L | B1: Delta2(L) | C1: log(L) | D1: Log(Delta2(L)) | E1: Archivo | F1: H | G1: Mach | H1: dv_slope | I1: dv_slope_err
A2: 3 | B2: 0.040810521 | C2: =LOG10(A2) -> 0.47712125 | D2: =LOG10(B2) -> -1.3892279 | E2: efbm_H0.5Mach2.5_1.fits | F2: 0.5 | G2: 2.5 | H2: 0.93667251 | I2: 0.0045352154
A3: 3.0112212 | B3: 0.040908606 | C3: =LOG10(A3) -> 0.47874266 | D3: =LOG10(B3) -> -1.3881853
A4: 3.0224844 | B4: 0.041005731 | C4: =LOG10(A4) -> 0.48036408 | D4: =LOG10(B4) -> -1.3871554
A5: 3.0337898 | B5: 0.041101869 | C5: =LOG10(A5) -> 0.48198549 | D5: =LOG10(B5) -> -1.3861384 | H5: valor central | I5: desv tip
A6: 3.0451374 | B6: 0.041196993 | C6: =LOG10(A6) -> 0.4836069 | D6: =LOG10(B6) -> -1.3851345 | F6: Pendiente 3-10 | H6: =SLOPE(D2:D324,C2:C324) -> 0.92100389 | I6: =INDEX(LINEST(D2:D324,C2:C324,TRUE,TRUE),2,1) -> 0.0024225545
A7: 3.0565275 | B7: 0.041291078 | C7: =LOG10(A7) -> 0.48522831 | D7: =LOG10(B7) -> -1.3841438 | F7: Pendiente 3-20 | H7: =SLOPE(D2:D510,C2:C510) -> 0.88614512 | I7: =INDEX(LINEST(D2:D510,C2:C510,TRUE,TRUE),2,1) -> 0.001445111
A8: 3.0679602 | B8: 0.041384097 | C8: =LOG10(A8) -> 0.48684972 | D8: =LOG10(B8) -> -1.3831665 | F8: Pendiente 3-30 | H8: =SLOPE(D2:D618,C2:C618) -> 0.8726152 | I8: =INDEX(LINEST(D2:D618,C2:C618,TRUE,TRUE),2,1) -> 0.0011764875
A9: 3.0794356 | B9: 0.041476025 | C9: =LOG10(A9) -> 0.48847113 | D9: =LOG10(B9) -> -1.3822029 | F9: Pendiente 3-40 | H9: =SLOPE(D2:D695,C2:C695) -> 0.87510658 | I9: =INDEX(LINEST(D2:D695,C2:C695,TRUE,TRUE),2,1) -> 0.00094794864
A10: 3.090954 | B10: 0.041566834 | C10: =LOG10(A10) -> 0.49009254 | D10: =LOG10(B10) -> -1.3812531 | F10: Pendiente 3-50 | H10: =SLOPE(D2:D755,C2:C755) -> 0.87512077 | I10: =INDEX(LINEST(D2:D755,C2:C755,TRUE,TRUE),2,1) -> 0.00081308487
A11: 3.1025154 | B11: 0.041656498 | C11: =LOG10(A11) -> 0.49171395 | D11: =LOG10(B11) -> -1.3803172
A12: 3.1141201 | B12: 0.041744993 | C12: =LOG10(A12) -> 0.49333536 | D12: =LOG10(B12) -> -1.3793956
A13: 3.1257682 | B13: 0.041832291 | C13: =LOG10(A13) -> 0.49495677 | D13: =LOG10(B13) -> -1.3784884
A14: 3.1374598 | B14: 0.041918366 | C14: =LOG10(A14) -> 0.49657818 | D14: =LOG10(B14) -> -1.3775957
A15: 3.1491952 | B15: 0.042003193 | C15: =LOG10(A15) -> 0.49819959 | D15: =LOG10(B15) -> -1.3767177
A16: 3.1609745 | B16: 0.042086747 | C16: =LOG10(A16) -> 0.499821 | D16: =LOG10(B16) -> -1.3758546
A17: 3.1727979 | B17: 0.042169001 | C17: =LOG10(A17) -> 0.50144241 | D17: =LOG10(B17) -> -1.3750067
A18: 3.1846655 | B18: 0.044441028 | C18: =LOG10(A18) -> 0.50306382 | D18: =LOG10(B18) -> -1.3522159
A19: 3.1965774 | B19: 0.044585369 | C19: =LOG10(A19) -> 0.50468523 | D19: =LOG10(B19) -> -1.3508076
A20: 3.2085339 | B20: 0.044729608 | C20: =LOG10(A20) -> 0.50630664 | D20: =LOG10(B20) -> -1.3494049
A21: 3.2205352 | B21: 0.044873725 | C21: =LOG10(A21) -> 0.50792805 | D21: =LOG10(B21) -> -1.3480079
A22: 3.2325813 | B22: 0.045017698 | C22: =LOG10(A22) -> 0.50954946 | D22: =LOG10(B22) -> -1.3466167
... A1001: 125 | B1001: 0.64033713 | C1001: =LOG10(A1001) -> 2.09691 | D1001: =LOG10(B1001) -> -0.19359132

Sheet efbm_H0.5Mach2.5_2
A1: L | B1: Delta2(L) | C1: log(L) | D1: Log(Delta2(L)) | E1: Archivo | F1: H | G1: Mach | H1: dv_slope | I1: dv_slope_err
A2: 3 | B2: 0.012061211 | C2: =LOG10(A2) -> 0.47712125 | D2: =LOG10(B2) -> -1.9186091 | E2: efbm_H0.5Mach2.5_2.fits | F2: 0.5 | G2: 2.5 | H2: 0.92761242 | I2: 0.0039679032
A3: 3.0112212 | B3: 0.01209037 | C3: =LOG10(A3) -> 0.47874266 | D3: =LOG10(B3) -> -1.9175604
A4: 3.0224844 | B4: 0.012119246 | C4: =LOG10(A4) -> 0.48036408 | D4: =LOG10(B4) -> -1.9165244
A5: 3.0337898 | B5: 0.012147831 | C5: =LOG10(A5) -> 0.48198549 | D5: =LOG10(B5) -> -1.9155013 | H5: valor central | I5: desv tip
A6: 3.0451374 | B6: 0.012176116 | C6: =LOG10(A6) -> 0.4836069 | D6: =LOG10(B6) -> -1.9144912 | F6: Pendiente 3-10 | H6: =SLOPE(D2:D324,C2:C324) -> 0.95996826 | I6: =INDEX(LINEST(D2:D324,C2:C324,TRUE,TRUE),2,1) -> 0.0020023392
A7: 3.0565275 | B7: 0.012204095 | C7: =LOG10(A7) -> 0.48522831 | D7: =LOG10(B7) -> -1.9134944 | F7: Pendiente 3-20 | H7: =SLOPE(D2:D510,C2:C510) -> 0.90299878 | I7: =INDEX(LINEST(D2:D510,C2:C510,TRUE,TRUE),2,1) -> 0.0019895706
