Workbook

Sheet Summary
B1: SUMMARY | Z1: Aproximación clásica:
S2: P75 | Z2: Schneider, etc. | AD2: b entre 1/3 y 1
B3: File | C3: H | D3: ℳ | E3: Skewness | F3: Kurtosis | G3: Sigma | H3: P95 | I3: P90 | J3: P85 | K3: P80 | L3: P75 | M3: P70 | N3: P65 | O3: P60 | P3: P55 | Q3: P50 | S3: M | U3: P75 | V3: M estimado | W3: Residuo | X3: % residuo | Z3: M | AA3: sigma | AB3: b
B4: =efbm_H0.5Mach1_0!$C$2 -> efbm_H0.5Mach1_0.fits | C4: =efbm_H0.5Mach1_0!D2 -> 0.5 | D4: =efbm_H0.5Mach1_0!E2 -> 1 | E4: {=INDIRECT("'"&SUBSTITUTE($B4,".fits","")&"'!$I$2")} -> 0.072205595 | F4: {=INDIRECT("'"&SUBSTITUTE($B4,".fits","")&"'!$J$2")} -> -0.54554104 | G4: =efbm_H0.5Mach1_0!$G$2 -> 0.47238073 | H4: =efbm_H0.5Mach1_0!I14 -> 0.83114875 | I4: =efbm_H0.5Mach1_0!I16 -> 0.79261868 | J4: =efbm_H0.5Mach1_0!I18 -> 0.77060149 | K4: =efbm_H0.5Mach1_0!I20 -> 0.74363044 | L4: =efbm_H0.5Mach1_0!I22 -> 0.72656712 | M4: =efbm_H0.5Mach1_0!I24 -> 0.70454993 | N4: =efbm_H0.5Mach1_0!I26 -> 0.68803705 | O4: =efbm_H0.5Mach1_0!I28 -> 0.64950697 | P4: =efbm_H0.5Mach1_0!I30 -> 0.61648119 | Q4: =efbm_H0.5Mach1_0!I32 -> 0.56143823 | S4: =D4 -> 1 | T4: 0 | U4: =L4 -> 0.72656712 | V4: =$L$45+$L$46*L4 -> 1.0375464 | W4: =S4-V4 -> -0.037546431 | X4: =W4/V4 -> -0.036187711 | Z4: =D4 -> 1 | AA4: =G4 -> 0.47238073 | AB4: =SQRT(EXP(AA4^2)-1)/Z4 -> 0.5
B5: =efbm_H0.5Mach1_1!$C$2 -> efbm_H0.5Mach1_1.fits | C5: =efbm_H0.5Mach1_1!D2 -> 0.5 | D5: =efbm_H0.5Mach1_1!E2 -> 1 | E5: {=INDIRECT("'"&SUBSTITUTE($B5,".fits","")&"'!$I$2")} -> -0.36060418 | F5: {=INDIRECT("'"&SUBSTITUTE($B5,".fits","")&"'!$J$2")} -> -0.15326012 | G5: =efbm_H0.5Mach1_1!$G$2 -> 0.47238073 | H5: {=INDIRECT("'"&SUBSTITUTE($B5,".fits","")&"'!I14")} -> 0.89346739 | I5: {=INDIRECT("'"&SUBSTITUTE($B5,".fits","")&"'!I16")} -> 0.86057902 | J5: {=INDIRECT("'"&SUBSTITUTE($B5,".fits","")&"'!I18")} -> 0.81672786 | K5: {=INDIRECT("'"&SUBSTITUTE($B5,".fits","")&"'!I20")} -> 0.7783581 | L5: {=INDIRECT("'"&SUBSTITUTE($B5,".fits","")&"'!I22")} -> 0.75095112 | M5: {=INDIRECT("'"&SUBSTITUTE($B5,".fits","")&"'!I24")} -> 0.71806275 | N5: {=INDIRECT("'"&SUBSTITUTE($B5,".fits","")&"'!I26")} -> 0.67421159 | O5: {=INDIRECT("'"&SUBSTITUTE($B5,".fits","")&"'!I28")} -> 0.62597531 | P5: {=INDIRECT("'"&SUBSTITUTE($B5,".fits","")&"'!I30")} -> 0.57253171 | Q5: {=INDIRECT("'"&SUBSTITUTE($B5,".fits","")&"'!I32")} -> 0.53717671 | S5: =D5 -> 1 | T5: 1 | U5: =L5 -> 0.75095112 | V5: =$L$45+$L$46*L5 -> 0.94695707 | W5: =S5-V5 -> 0.053042934 | X5: =W5/V5 -> 0.056014086 | Z5: =D5 -> 1 | AA5: =G5 -> 0.47238073 | AB5: =SQRT(EXP(AA5^2)-1)/Z5 -> 0.5
B6: =efbm_H0.5Mach1_2!$C$2 -> efbm_H0.5Mach1_2.fits | C6: =efbm_H0.5Mach1_2!D2 -> 0.5 | D6: =efbm_H0.5Mach1_2!E2 -> 1 | E6: {=INDIRECT("'"&SUBSTITUTE($B6,".fits","")&"'!$I$2")} -> -0.10198019 | F6: {=INDIRECT("'"&SUBSTITUTE($B6,".fits","")&"'!$J$2")} -> -0.71606429 | G6: =efbm_H0.5Mach1_2!$G$2 -> 0.47238073 | H6: {=INDIRECT("'"&SUBSTITUTE($B6,".fits","")&"'!I14")} -> 0.76395626 | I6: {=INDIRECT("'"&SUBSTITUTE($B6,".fits","")&"'!I16")} -> 0.74684115 | J6: {=INDIRECT("'"&SUBSTITUTE($B6,".fits","")&"'!I18")} -> 0.7242096 | K6: {=INDIRECT("'"&SUBSTITUTE($B6,".fits","")&"'!I20")} -> 0.70723593 | L6: {=INDIRECT("'"&SUBSTITUTE($B6,".fits","")&"'!I22")} -> 0.69026227 | M6: {=INDIRECT("'"&SUBSTITUTE($B6,".fits","")&"'!I24")} -> 0.67328861 | N6: {=INDIRECT("'"&SUBSTITUTE($B6,".fits","")&"'!I26")} -> 0.65631495 | O6: {=INDIRECT("'"&SUBSTITUTE($B6,".fits","")&"'!I28")} -> 0.63934128 | P6: {=INDIRECT("'"&SUBSTITUTE($B6,".fits","")&"'!I30")} -> 0.61232487 | Q6: {=INDIRECT("'"&SUBSTITUTE($B6,".fits","")&"'!I32")} -> 0.5884203 | S6: =D6 -> 1 | T6: 2 | U6: =L6 -> 0.69026227 | V6: =$L$45+$L$46*L6 -> 1.1724231 | W6: =S6-V6 -> -0.17242312 | X6: =W6/V6 -> -0.14706561 | Y6: >15% | Z6: =D6 -> 1 | AA6: =G6 -> 0.47238073 | AB6: =SQRT(EXP(AA6^2)-1)/Z6 -> 0.5
B7: =efbm_H0.5Mach1_3!$C$2 -> efbm_H0.5Mach1_3.fits | C7: =efbm_H0.5Mach1_3!D2 -> 0.5 | D7: =efbm_H0.5Mach1_3!E2 -> 1 | E7: {=INDIRECT("'"&SUBSTITUTE($B7,".fits","")&"'!$I$2")} -> 0.58056948 | F7: {=INDIRECT("'"&SUBSTITUTE($B7,".fits","")&"'!$J$2")} -> -0.46379137 | G7: =efbm_H0.5Mach1_3!$G$2 -> 0.47238073 | H7: {=INDIRECT("'"&SUBSTITUTE($B7,".fits","")&"'!I14")} -> 1.1573012 | I7: {=INDIRECT("'"&SUBSTITUTE($B7,".fits","")&"'!I16")} -> 1.0639704 | J7: {=INDIRECT("'"&SUBSTITUTE($B7,".fits","")&"'!I18")} -> 0.97732839 | K7: {=INDIRECT("'"&SUBSTITUTE($B7,".fits","")&"'!I20")} -> 0.86548706 | L7: {=INDIRECT("'"&SUBSTITUTE($B7,".fits","")&"'!I22")} -> 0.79642231 | M7: {=INDIRECT("'"&SUBSTITUTE($B7,".fits","")&"'!I24")} -> 0.71646898 | N7: {=INDIRECT("'"&SUBSTITUTE($B7,".fits","")&"'!I26")} -> 0.65440404 | O7: {=INDIRECT("'"&SUBSTITUTE($B7,".fits","")&"'!I28")} -> 0.57367295 | P7: {=INDIRECT("'"&SUBSTITUTE($B7,".fits","")&"'!I30")} -> 0.50398599 | Q7: {=INDIRECT("'"&SUBSTITUTE($B7,".fits","")&"'!I32")} -> 0.44798755 | S7: =D7 -> 1 | T7: 3 | U7: =L7 -> 0.79642231 | V7: =$L$45+$L$46*L7 -> 0.77802636 | W7: =S7-V7 -> 0.22197364 | X7: =W7/V7 -> 0.28530349 | Z7: =D7 -> 1 | AA7: =G7 -> 0.47238073 | AB7: =SQRT(EXP(AA7^2)-1)/Z7 -> 0.5
B8: =efbm_H0.5Mach1_4!$C$2 -> efbm_H0.5Mach1_4.fits | C8: =efbm_H0.5Mach1_4!D2 -> 0.5 | D8: =efbm_H0.5Mach1_4!E2 -> 1 | E8: {=INDIRECT("'"&SUBSTITUTE($B8,".fits","")&"'!$I$2")} -> -0.25375646 | F8: {=INDIRECT("'"&SUBSTITUTE($B8,".fits","")&"'!$J$2")} -> -0.3259587 | G8: =efbm_H0.5Mach1_4!$G$2 -> 0.47238073 | H8: {=INDIRECT("'"&SUBSTITUTE($B8,".fits","")&"'!I14")} -> 0.9129928 | I8: {=INDIRECT("'"&SUBSTITUTE($B8,".fits","")&"'!I16")} -> 0.87378452 | J8: {=INDIRECT("'"&SUBSTITUTE($B8,".fits","")&"'!I18")} -> 0.82939515 | K8: {=INDIRECT("'"&SUBSTITUTE($B8,".fits","")&"'!I20")} -> 0.80096915 | L8: {=INDIRECT("'"&SUBSTITUTE($B8,".fits","")&"'!I22")} -> 0.76736205 | M8: {=INDIRECT("'"&SUBSTITUTE($B8,".fits","")&"'!I24")} -> 0.73459513 | N8: {=INDIRECT("'"&SUBSTITUTE($B8,".fits","")&"'!I26")} -> 0.69454667 | O8: {=INDIRECT("'"&SUBSTITUTE($B8,".fits","")&"'!I28")} -> 0.63517413 | P8: {=INDIRECT("'"&SUBSTITUTE($B8,".fits","")&"'!I30")} -> 0.58938446 | Q8: {=INDIRECT("'"&SUBSTITUTE($B8,".fits","")&"'!I32")} -> 0.53911385 | S8: =D8 -> 1 | T8: 4 | U8: =L8 -> 0.76736205 | V8: =$L$45+$L$46*L8 -> 0.88598858 | W8: =S8-V8 -> 0.11401142 | X8: =W8/V8 -> 0.12868272 | Y8: >15% | Z8: =D8 -> 1 | AA8: =G8 -> 0.47238073 | AB8: =SQRT(EXP(AA8^2)-1)/Z8 -> 0.5
B9: =efbm_H0.5Mach1_5!$C$2 -> efbm_H0.5Mach1_5.fits | C9: =efbm_H0.5Mach1_5!D2 -> 0.5 | D9: =efbm_H0.5Mach1_5!E2 -> 1 | E9: {=INDIRECT("'"&SUBSTITUTE($B9,".fits","")&"'!$I$2")} -> -0.49174519 | F9: {=INDIRECT("'"&SUBSTITUTE($B9,".fits","")&"'!$J$2")} -> 0.56315614 | G9: =efbm_H0.5Mach1_5!$G$2 -> 0.47238073 | H9: {=INDIRECT("'"&SUBSTITUTE($B9,".fits","")&"'!I14")} -> 1.0057779 | I9: {=INDIRECT("'"&SUBSTITUTE($B9,".fits","")&"'!I16")} -> 0.9466145 | J9: {=INDIRECT("'"&SUBSTITUTE($B9,".fits","")&"'!I18")} -> 0.91210251 | K9: {=INDIRECT("'"&SUBSTITUTE($B9,".fits","")&"'!I20")} -> 0.88301384 | L9: {=INDIRECT("'"&SUBSTITUTE($B9,".fits","")&"'!I22")} -> 0.83814825 | M9: {=INDIRECT("'"&SUBSTITUTE($B9,".fits","")&"'!I24")} -> 0.764194 | N9: {=INDIRECT("'"&SUBSTITUTE($B9,".fits","")&"'!I26")} -> 0.70589339 | O9: {=INDIRECT("'"&SUBSTITUTE($B9,".fits","")&"'!I28")} -> 0.62713211 | P9: {=INDIRECT("'"&SUBSTITUTE($B9,".fits","")&"'!I30")} -> 0.54726151 | Q9: {=INDIRECT("'"&SUBSTITUTE($B9,".fits","")&"'!I32")} -> 0.47330725 | S9: =D9 -> 1 | T9: 5 | U9: =L9 -> 0.83814825 | V9: =$L$45+$L$46*L9 -> 0.62300968 | W9: =S9-V9 -> 0.37699032 | X9: =W9/V9 -> 0.6051115 | Y9: >15% | Z9: =D9 -> 1 | AA9: =G9 -> 0.47238073 | AB9: =SQRT(EXP(AA9^2)-1)/Z9 -> 0.5
B10: =efbm_H0.5Mach1_6!$C$2 -> efbm_H0.5Mach1_6.fits | C10: =efbm_H0.5Mach1_6!$D$2 -> 0.5 | D10: =efbm_H0.5Mach1_6!$E$2 -> 1 | E10: {=INDIRECT("'"&SUBSTITUTE($B10,".fits","")&"'!$I$2")} -> -0.40201208 | F10: {=INDIRECT("'"&SUBSTITUTE($B10,".fits","")&"'!$J$2")} -> -0.44223323 | G10: =efbm_H0.5Mach1_6!$G$2 -> 0.47238073 | H10: {=INDIRECT("'"&SUBSTITUTE($B10,".fits","")&"'!I14")} -> 0.89874361 | I10: {=INDIRECT("'"&SUBSTITUTE($B10,".fits","")&"'!I16")} -> 0.86191362 | J10: {=INDIRECT("'"&SUBSTITUTE($B10,".fits","")&"'!I18")} -> 0.8313493 | K10: {=INDIRECT("'"&SUBSTITUTE($B10,".fits","")&"'!I20")} -> 0.80078499 | L10: {=INDIRECT("'"&SUBSTITUTE($B10,".fits","")&"'!I22")} -> 0.76410782 | M10: {=INDIRECT("'"&SUBSTITUTE($B10,".fits","")&"'!I24")} -> 0.7335435 | N10: {=INDIRECT("'"&SUBSTITUTE($B10,".fits","")&"'!I26")} -> 0.69075347 | O10: {=INDIRECT("'"&SUBSTITUTE($B10,".fits","")&"'!I28")} -> 0.64796343 | P10: {=INDIRECT("'"&SUBSTITUTE($B10,".fits","")&"'!I30")} -> 0.5882102 | Q10: {=INDIRECT("'"&SUBSTITUTE($B10,".fits","")&"'!I32")} -> 0.52112153 | S10: =D10 -> 1 | T10: 6 | U10: =L10 -> 0.76410782 | V10: =$L$45+$L$46*L10 -> 0.89807842 | W10: =S10-V10 -> 0.10192158 | X10: =W10/V10 -> 0.1134885 | Z10: =D10 -> 1 | AA10: =G10 -> 0.47238073 | AB10: =SQRT(EXP(AA10^2)-1)/Z10 -> 0.5
B11: =efbm_H0.5Mach1_7!$C$2 -> efbm_H0.5Mach1_7.fits | C11: =efbm_H0.5Mach1_7!$D$2 -> 0.5 | D11: =efbm_H0.5Mach1_7!$E$2 -> 1 | E11: {=INDIRECT("'"&SUBSTITUTE($B11,".fits","")&"'!$I$2")} -> -0.2659248 | F11: {=INDIRECT("'"&SUBSTITUTE($B11,".fits","")&"'!$J$2")} -> -0.44122871 | G11: =efbm_H0.5Mach1_7!$G$2 -> 0.47238073 | H11: {=INDIRECT("'"&SUBSTITUTE($B11,".fits","")&"'!I14")} -> 0.84943957 | I11: {=INDIRECT("'"&SUBSTITUTE($B11,".fits","")&"'!I16")} -> 0.81599488 | J11: {=INDIRECT("'"&SUBSTITUTE($B11,".fits","")&"'!I18")} -> 0.79379094 | K11: {=INDIRECT("'"&SUBSTITUTE($B11,".fits","")&"'!I20")} -> 0.76659111 | L11: {=INDIRECT("'"&SUBSTITUTE($B11,".fits","")&"'!I22")} -> 0.74938305 | M11: {=INDIRECT("'"&SUBSTITUTE($B11,".fits","")&"'!I24")} -> 0.72162813 | N11: {=INDIRECT("'"&SUBSTITUTE($B11,".fits","")&"'!I26")} -> 0.69942418 | O11: {=INDIRECT("'"&SUBSTITUTE($B11,".fits","")&"'!I28")} -> 0.67166926 | P11: {=INDIRECT("'"&SUBSTITUTE($B11,".fits","")&"'!I30")} -> 0.63961231 | Q11: {=INDIRECT("'"&SUBSTITUTE($B11,".fits","")&"'!I32")} -> 0.58979222 | S11: =D11 -> 1 | T11: 7 | U11: =L11 -> 0.74938305 | V11: =$L$45+$L$46*L11 -> 0.95278261 | W11: =S11-V11 -> 0.04721739 | X11: =W11/V11 -> 0.049557359 | Z11: =D11 -> 1 | AA11: =G11 -> 0.47238073 | AB11: =SQRT(EXP(AA11^2)-1)/Z11 -> 0.5
B12: =efbm_H0.5Mach1_8!$C$2 -> efbm_H0.5Mach1_8.fits | C12: =efbm_H0.5Mach1_8!$D$2 -> 0.5 | D12: =efbm_H0.5Mach1_8!$E$2 -> 1 | E12: {=INDIRECT("'"&SUBSTITUTE($B12,".fits","")&"'!$I$2")} -> 0.12094689 | F12: {=INDIRECT("'"&SUBSTITUTE($B12,".fits","")&"'!$J$2")} -> -0.0057501124 | G12: =efbm_H0.5Mach1_8!$G$2 -> 0.47238073 | H12: {=INDIRECT("'"&SUBSTITUTE($B12,".fits","")&"'!I14")} -> 1.0395949 | I12: {=INDIRECT("'"&SUBSTITUTE($B12,".fits","")&"'!I16")} -> 0.94923015 | J12: {=INDIRECT("'"&SUBSTITUTE($B12,".fits","")&"'!I18")} -> 0.89565102 | K12: {=INDIRECT("'"&SUBSTITUTE($B12,".fits","")&"'!I20")} -> 0.8055528 | L12: {=INDIRECT("'"&SUBSTITUTE($B12,".fits","")&"'!I22")} -> 0.75237352 | M12: {=INDIRECT("'"&SUBSTITUTE($B12,".fits","")&"'!I24")} -> 0.68853172 | N12: {=INDIRECT("'"&SUBSTITUTE($B12,".fits","")&"'!I26")} -> 0.63975073 | O12: {=INDIRECT("'"&SUBSTITUTE($B12,".fits","")&"'!I28")} -> 0.58643817 | P12: {=INDIRECT("'"&SUBSTITUTE($B12,".fits","")&"'!I30")} -> 0.52779435 | Q12: {=INDIRECT("'"&SUBSTITUTE($B12,".fits","")&"'!I32")} -> 0.48114586 | S12: =D12 -> 1 | T12: 8 | U12: =L12 -> 0.75237352 | V12: =$L$45+$L$46*L12 -> 0.9416727 | W12: =S12-V12 -> 0.058327297 | X12: =W12/V12 -> 0.061940095 | Z12: =D12 -> 1 | AA12: =G12 -> 0.47238073 | AB12: =SQRT(EXP(AA12^2)-1)/Z12 -> 0.5
B13: =efbm_H0.5Mach1_9!$C$2 -> efbm_H0.5Mach1_9.fits | C13: =efbm_H0.5Mach1_9!$D$2 -> 0.5 | D13: =efbm_H0.5Mach1_9!$E$2 -> 1 | E13: {=INDIRECT("'"&SUBSTITUTE($B13,".fits","")&"'!$I$2")} -> -0.15613434 | F13: {=INDIRECT("'"&SUBSTITUTE($B13,".fits","")&"'!$J$2")} -> -0.74998719 | G13: =efbm_H0.5Mach1_9!$G$2 -> 0.47238073 | H13: {=INDIRECT("'"&SUBSTITUTE($B13,".fits","")&"'!I14")} -> 0.94317816 | I13: {=INDIRECT("'"&SUBSTITUTE($B13,".fits","")&"'!I16")} -> 0.88373136 | J13: {=INDIRECT("'"&SUBSTITUTE($B13,".fits","")&"'!I18")} -> 0.82362036 | K13: {=INDIRECT("'"&SUBSTITUTE($B13,".fits","")&"'!I20")} -> 0.77048356 | L13: {=INDIRECT("'"&SUBSTITUTE($B13,".fits","")&"'!I22")} -> 0.70489283 | M13: {=INDIRECT("'"&SUBSTITUTE($B13,".fits","")&"'!I24")} -> 0.65092577 | N13: {=INDIRECT("'"&SUBSTITUTE($B13,".fits","")&"'!I26")} -> 0.59230924 | O13: {=INDIRECT("'"&SUBSTITUTE($B13,".fits","")&"'!I28")} -> 0.54465217 | P13: {=INDIRECT("'"&SUBSTITUTE($B13,".fits","")&"'!I30")} -> 0.49151538 | Q13: {=INDIRECT("'"&SUBSTITUTE($B13,".fits","")&"'!I32")} -> 0.4466812 | S13: =D13 -> 1 | T13: 9 | U13: =L13 -> 0.70489283 | V13: =$L$45+$L$46*L13 -> 1.1180689 | W13: =S13-V13 -> -0.11806892 | X13: =W13/V13 -> -0.10560075 | Z13: =D13 -> 1 | AA13: =G13 -> 0.47238073 | AB13: =SQRT(EXP(AA13^2)-1)/Z13 -> 0.5
B14: ='efbm_H0.5Mach2.5_0'!$C$2 -> efbm_H0.5Mach2.5_0.fits | C14: ='efbm_H0.5Mach2.5_0'!$D$2 -> 0.5 | D14: ='efbm_H0.5Mach2.5_0'!$E$2 -> 2.5 | E14: {=INDIRECT("'"&SUBSTITUTE($B14,".fits","")&"'!$I$2")} -> 0.072205595 | F14: {=INDIRECT("'"&SUBSTITUTE($B14,".fits","")&"'!$J$2")} -> -0.54554104 | G14: ='efbm_H0.5Mach2.5_0'!$G$2 -> 0.97004296 | H14: {=INDIRECT("'"&SUBSTITUTE($B14,".fits","")&"'!I14")} -> 0.40474357 | I14: {=INDIRECT("'"&SUBSTITUTE($B14,".fits","")&"'!I16")} -> 0.38598062 | J14: {=INDIRECT("'"&SUBSTITUTE($B14,".fits","")&"'!I18")} -> 0.37525894 | K14: {=INDIRECT("'"&SUBSTITUTE($B14,".fits","")&"'!I20")} -> 0.36212488 | L14: {=INDIRECT("'"&SUBSTITUTE($B14,".fits","")&"'!I22")} -> 0.35381557 | M14: {=INDIRECT("'"&SUBSTITUTE($B14,".fits","")&"'!I24")} -> 0.34309389 | N14: {=INDIRECT("'"&SUBSTITUTE($B14,".fits","")&"'!I26")} -> 0.33505262 | O14: {=INDIRECT("'"&SUBSTITUTE($B14,".fits","")&"'!I28")} -> 0.31628968 | P14: {=INDIRECT("'"&SUBSTITUTE($B14,".fits","")&"'!I30")} -> 0.30020715 | Q14: {=INDIRECT("'"&SUBSTITUTE($B14,".fits","")&"'!I32")} -> 0.27340294 | S14: =D14 -> 2.5 | T14: 0 | U14: =L14 -> 0.35381557 | V14: =$L$45+$L$46*L14 -> 2.4223613 | W14: =S14-V14 -> 0.07763869 | X14: =W14/V14 -> 0.03205083 | Z14: =D14 -> 2.5 | AA14: =G14 -> 0.97004296 | AB14: =SQRT(EXP(AA14^2)-1)/Z14 -> 0.5
B15: ='efbm_H0.5Mach2.5_1'!$C$2 -> efbm_H0.5Mach2.5_1.fits | C15: ='efbm_H0.5Mach2.5_1'!$D$2 -> 0.5 | D15: ='efbm_H0.5Mach2.5_1'!$E$2 -> 2.5 | E15: {=INDIRECT("'"&SUBSTITUTE($B15,".fits","")&"'!$I$2")} -> -0.36060418 | F15: {=INDIRECT("'"&SUBSTITUTE($B15,".fits","")&"'!$J$2")} -> -0.15326012 | G15: ='efbm_H0.5Mach2.5_0'!$G$2 -> 0.97004296 | H15: {=INDIRECT("'"&SUBSTITUTE($B15,".fits","")&"'!I14")} -> 0.43509081 | I15: {=INDIRECT("'"&SUBSTITUTE($B15,".fits","")&"'!I16")} -> 0.4190752 | J15: {=INDIRECT("'"&SUBSTITUTE($B15,".fits","")&"'!I18")} -> 0.39772105 | K15: {=INDIRECT("'"&SUBSTITUTE($B15,".fits","")&"'!I20")} -> 0.37903616 | L15: {=INDIRECT("'"&SUBSTITUTE($B15,".fits","")&"'!I22")} -> 0.36568982 | M15: {=INDIRECT("'"&SUBSTITUTE($B15,".fits","")&"'!I24")} -> 0.34967421 | N15: {=INDIRECT("'"&SUBSTITUTE($B15,".fits","")&"'!I26")} -> 0.32832006 | O15: {=INDIRECT("'"&SUBSTITUTE($B15,".fits","")&"'!I28")} -> 0.30483049 | P15: {=INDIRECT("'"&SUBSTITUTE($B15,".fits","")&"'!I30")} -> 0.27880512 | Q15: {=INDIRECT("'"&SUBSTITUTE($B15,".fits","")&"'!I32")} -> 0.26158834 | S15: =D15 -> 2.5 | T15: 1 | U15: =L15 -> 0.36568982 | V15: =$L$45+$L$46*L15 -> 2.3782471 | W15: =S15-V15 -> 0.12175289 | X15: =W15/V15 -> 0.051194382 | Z15: =D15 -> 2.5 | AA15: =G15 -> 0.97004296 | AB15: =SQRT(EXP(AA15^2)-1)/Z15 -> 0.5
B16: ='efbm_H0.5Mach2.5_2'!$C$2 -> efbm_H0.5Mach2.5_2.fits | C16: ='efbm_H0.5Mach2.5_2'!$D$2 -> 0.5 | D16: ='efbm_H0.5Mach2.5_2'!$E$2 -> 2.5 | E16: {=INDIRECT("'"&SUBSTITUTE($B16,".fits","")&"'!$I$2")} -> -0.10198019 | F16: {=INDIRECT("'"&SUBSTITUTE($B16,".fits","")&"'!$J$2")} -> -0.71606429 | G16: ='efbm_H0.5Mach2.5_0'!$G$2 -> 0.97004296 | H16: {=INDIRECT("'"&SUBSTITUTE($B16,".fits","")&"'!I14")} -> 0.37202292 | I16: {=INDIRECT("'"&SUBSTITUTE($B16,".fits","")&"'!I16")} -> 0.36368839 | J16: {=INDIRECT("'"&SUBSTITUTE($B16,".fits","")&"'!I18")} -> 0.35266753 | K16: {=INDIRECT("'"&SUBSTITUTE($B16,".fits","")&"'!I20")} -> 0.34440189 | L16: {=INDIRECT("'"&SUBSTITUTE($B16,".fits","")&"'!I22")} -> 0.33613624 | M16: {=INDIRECT("'"&SUBSTITUTE($B16,".fits","")&"'!I24")} -> 0.32787059 | N16: {=INDIRECT("'"&SUBSTITUTE($B16,".fits","")&"'!I26")} -> 0.31960495 | O16: {=INDIRECT("'"&SUBSTITUTE($B16,".fits","")&"'!I28")} -> 0.3113393 | P16: {=INDIRECT("'"&SUBSTITUTE($B16,".fits","")&"'!I30")} -> 0.29818315 | Q16: {=INDIRECT("'"&SUBSTITUTE($B16,".fits","")&"'!I32")} -> 0.28654237 | S16: =D16 -> 2.5 | T16: 2 | U16: =L16 -> 0.33613624 | V16: =$L$45+$L$46*L16 -> 2.4880421 | W16: =S16-V16 -> 0.01195794 | X16: =W16/V16 -> 0.0048061648 | Z16: =D16 -> 2.5 | AA16: =G16 -> 0.97004296 | AB16: =SQRT(EXP(AA16^2)-1)/Z16 -> 0.5
B17: ='efbm_H0.5Mach2.5_3'!$C$2 -> efbm_H0.5Mach2.5_3.fits | C17: ='efbm_H0.5Mach2.5_3'!$D$2 -> 0.5 | D17: ='efbm_H0.5Mach2.5_3'!$E$2 -> 2.5 | E17: {=INDIRECT("'"&SUBSTITUTE($B17,".fits","")&"'!$I$2")} -> 0.58056948 | F17: {=INDIRECT("'"&SUBSTITUTE($B17,".fits","")&"'!$J$2")} -> -0.46379137 | G17: ='efbm_H0.5Mach2.5_0'!$G$2 -> 0.97004296 | H17: {=INDIRECT("'"&SUBSTITUTE($B17,".fits","")&"'!I14")} -> 0.56356965 | I17: {=INDIRECT("'"&SUBSTITUTE($B17,".fits","")&"'!I16")} -> 0.51812048 | J17: {=INDIRECT("'"&SUBSTITUTE($B17,".fits","")&"'!I18")} -> 0.47592851 | K17: {=INDIRECT("'"&SUBSTITUTE($B17,".fits","")&"'!I20")} -> 0.42146526 | L17: {=INDIRECT("'"&SUBSTITUTE($B17,".fits","")&"'!I22")} -> 0.38783287 | M17: {=INDIRECT("'"&SUBSTITUTE($B17,".fits","")&"'!I24")} -> 0.34889809 | N17: {=INDIRECT("'"&SUBSTITUTE($B17,".fits","")&"'!I26")} -> 0.3186744 | O17: {=INDIRECT("'"&SUBSTITUTE($B17,".fits","")&"'!I28")} -> 0.27936087 | P17: {=INDIRECT("'"&SUBSTITUTE($B17,".fits","")&"'!I30")} -> 0.24542549 | Q17: {=INDIRECT("'"&SUBSTITUTE($B17,".fits","")&"'!I32")} -> 0.21815599 | S17: =D17 -> 2.5 | T17: 3 | U17: =L17 -> 0.38783287 | V17: =$L$45+$L$46*L17 -> 2.2959831 | W17: =S17-V17 -> 0.20401689 | X17: =W17/V17 -> 0.088858182 | Z17: =D17 -> 2.5 | AA17: =G17 -> 0.97004296 | AB17: =SQRT(EXP(AA17^2)-1)/Z17 -> 0.5
B18: ='efbm_H0.5Mach2.5_4'!$C$2 -> efbm_H0.5Mach2.5_4.fits | C18: ='efbm_H0.5Mach2.5_4'!$D$2 -> 0.5 | D18: ='efbm_H0.5Mach2.5_4'!$E$2 -> 2.5 | E18: {=INDIRECT("'"&SUBSTITUTE($B18,".fits","")&"'!$I$2")} -> -0.25375646 | F18: {=INDIRECT("'"&SUBSTITUTE($B18,".fits","")&"'!$J$2")} -> -0.3259587 | G18: ='efbm_H0.5Mach2.5_0'!$G$2 -> 0.97004296 | H18: {=INDIRECT("'"&SUBSTITUTE($B18,".fits","")&"'!I14")} -> 0.44459908 | I18: {=INDIRECT("'"&SUBSTITUTE($B18,".fits","")&"'!I16")} -> 0.42550586 | J18: {=INDIRECT("'"&SUBSTITUTE($B18,".fits","")&"'!I18")} -> 0.40388962 | K18: {=INDIRECT("'"&SUBSTITUTE($B18,".fits","")&"'!I20")} -> 0.39004704 | L18: {=INDIRECT("'"&SUBSTITUTE($B18,".fits","")&"'!I22")} -> 0.37368143 | M18: {=INDIRECT("'"&SUBSTITUTE($B18,".fits","")&"'!I24")} -> 0.35772496 | N18: {=INDIRECT("'"&SUBSTITUTE($B18,".fits","")&"'!I26")} -> 0.33822261 | O18: {=INDIRECT("'"&SUBSTITUTE($B18,".fits","")&"'!I28")} -> 0.30931003 | P18: {=INDIRECT("'"&SUBSTITUTE($B18,".fits","")&"'!I30")} -> 0.28701189 | Q18: {=INDIRECT("'"&SUBSTITUTE($B18,".fits","")&"'!I32")} -> 0.26253166 | S18: =D18 -> 2.5 | T18: 4 | U18: =L18 -> 0.37368143 | V18: =$L$45+$L$46*L18 -> 2.3485574 | W18: =S18-V18 -> 0.15144265 | X18: =W18/V18 -> 0.064483265 | Z18: =D18 -> 2.5 | AA18: =G18 -> 0.97004296 | AB18: =SQRT(EXP(AA18^2)-1)/Z18 -> 0.5
B19: ='efbm_H0.5Mach2.5_5'!$C$2 -> efbm_H0.5Mach2.5_5.fits | C19: ='efbm_H0.5Mach2.5_5'!$D$2 -> 0.5 | D19: ='efbm_H0.5Mach2.5_5'!$E$2 -> 2.5 | E19: {=INDIRECT("'"&SUBSTITUTE($B19,".fits","")&"'!$I$2")} -> -0.49174519 | F19: {=INDIRECT("'"&SUBSTITUTE($B19,".fits","")&"'!$J$2")} -> 0.56315614 | G19: ='efbm_H0.5Mach2.5_0'!$G$2 -> 0.97004296 | H19: {=INDIRECT("'"&SUBSTITUTE($B19,".fits","")&"'!I14")} -> 0.48978253 | I19: {=INDIRECT("'"&SUBSTITUTE($B19,".fits","")&"'!I16")} -> 0.4609718 | J19: {=INDIRECT("'"&SUBSTITUTE($B19,".fits","")&"'!I18")} -> 0.44416553 | K19: {=INDIRECT("'"&SUBSTITUTE($B19,".fits","")&"'!I20")} -> 0.43000025 | L19: {=INDIRECT("'"&SUBSTITUTE($B19,".fits","")&"'!I22")} -> 0.40815211 | M19: {=INDIRECT("'"&SUBSTITUTE($B19,".fits","")&"'!I24")} -> 0.37213869 | N19: {=INDIRECT("'"&SUBSTITUTE($B19,".fits","")&"'!I26")} -> 0.34374811 | O19: {=INDIRECT("'"&SUBSTITUTE($B19,".fits","")&"'!I28")} -> 0.30539381 | P19: {=INDIRECT("'"&SUBSTITUTE($B19,".fits","")&"'!I30")} -> 0.26649932 | Q19: {=INDIRECT("'"&SUBSTITUTE($B19,".fits","")&"'!I32")} -> 0.2304859 | S19: =D19 -> 2.5 | T19: 5 | U19: =L19 -> 0.40815211 | V19: =$L$45+$L$46*L19 -> 2.2204948 | W19: =S19-V19 -> 0.27950518 | X19: =W19/V19 -> 0.12587518 | Z19: =D19 -> 2.5 | AA19: =G19 -> 0.97004296 | AB19: =SQRT(EXP(AA19^2)-1)/Z19 -> 0.5
B20: ='efbm_H0.5Mach2.5_6'!$C$2 -> efbm_H0.5Mach2.5_6.fits | C20: ='efbm_H0.5Mach2.5_6'!$D$2 -> 0.5 | D20: ='efbm_H0.5Mach2.5_6'!$E$2 -> 2.5 | E20: {=INDIRECT("'"&SUBSTITUTE($B20,".fits","")&"'!$I$2")} -> -0.40201208 | F20: {=INDIRECT("'"&SUBSTITUTE($B20,".fits","")&"'!$J$2")} -> -0.44223323 | G20: ='efbm_H0.5Mach2.5_0'!$G$2 -> 0.97004296 | H20: {=INDIRECT("'"&SUBSTITUTE($B20,".fits","")&"'!I14")} -> 0.43766016 | I20: {=INDIRECT("'"&SUBSTITUTE($B20,".fits","")&"'!I16")} -> 0.4197251 | J20: {=INDIRECT("'"&SUBSTITUTE($B20,".fits","")&"'!I18")} -> 0.40484123 | K20: {=INDIRECT("'"&SUBSTITUTE($B20,".fits","")&"'!I20")} -> 0.38995737 | L20: {=INDIRECT("'"&SUBSTITUTE($B20,".fits","")&"'!I22")} -> 0.37209672 | M20: {=INDIRECT("'"&SUBSTITUTE($B20,".fits","")&"'!I24")} -> 0.35721285 | N20: {=INDIRECT("'"&SUBSTITUTE($B20,".fits","")&"'!I26")} -> 0.33637544 | O20: {=INDIRECT("'"&SUBSTITUTE($B20,".fits","")&"'!I28")} -> 0.31553802 | P20: {=INDIRECT("'"&SUBSTITUTE($B20,".fits","")&"'!I30")} -> 0.28644006 | Q20: {=INDIRECT("'"&SUBSTITUTE($B20,".fits","")&"'!I32")} -> 0.25376996 | S20: =D20 -> 2.5 | T20: 6 | U20: =L20 -> 0.37209672 | V20: =$L$45+$L$46*L20 -> 2.3544447 | W20: =S20-V20 -> 0.14555527 | X20: =W20/V20 -> 0.061821485 | Z20: =D20 -> 2.5 | AA20: =G20 -> 0.97004296 | AB20: =SQRT(EXP(AA20^2)-1)/Z20 -> 0.5
B21: ='efbm_H0.5Mach2.5_7'!$C$2 -> efbm_H0.5Mach2.5_7.fits | C21: ='efbm_H0.5Mach2.5_7'!$D$2 -> 0.5 | D21: ='efbm_H0.5Mach2.5_7'!$E$2 -> 2.5 | E21: {=INDIRECT("'"&SUBSTITUTE($B21,".fits","")&"'!$I$2")} -> -0.2659248 | F21: {=INDIRECT("'"&SUBSTITUTE($B21,".fits","")&"'!$J$2")} -> -0.44122871 | G21: ='efbm_H0.5Mach2.5_0'!$G$2 -> 0.97004296 | H21: {=INDIRECT("'"&SUBSTITUTE($B21,".fits","")&"'!I14")} -> 0.41365063 | I21: {=INDIRECT("'"&SUBSTITUTE($B21,".fits","")&"'!I16")} -> 0.39736411 | J21: {=INDIRECT("'"&SUBSTITUTE($B21,".fits","")&"'!I18")} -> 0.38655148 | K21: {=INDIRECT("'"&SUBSTITUTE($B21,".fits","")&"'!I20")} -> 0.37330601 | L21: {=INDIRECT("'"&SUBSTITUTE($B21,".fits","")&"'!I22")} -> 0.36492622 | M21: {=INDIRECT("'"&SUBSTITUTE($B21,".fits","")&"'!I24")} -> 0.35141044 | N21: {=INDIRECT("'"&SUBSTITUTE($B21,".fits","")&"'!I26")} -> 0.34059781 | O21: {=INDIRECT("'"&SUBSTITUTE($B21,".fits","")&"'!I28")} -> 0.32708202 | P21: {=INDIRECT("'"&SUBSTITUTE($B21,".fits","")&"'!I30")} -> 0.31147129 | Q21: {=INDIRECT("'"&SUBSTITUTE($B21,".fits","")&"'!I32")} -> 0.28721045 | S21: =D21 -> 2.5 | T21: 7 | U21: =L21 -> 0.36492622 | V21: =$L$45+$L$46*L21 -> 2.381084 | W21: =S21-V21 -> 0.11891603 | X21: =W21/V21 -> 0.049941974 | Z21: =D21 -> 2.5 | AA21: =G21 -> 0.97004296 | AB21: =SQRT(EXP(AA21^2)-1)/Z21 -> 0.5
B22: ='efbm_H0.5Mach2.5_8'!$C$2 -> efbm_H0.5Mach2.5_8.fits | C22: ='efbm_H0.5Mach2.5_8'!$D$2 -> 0.5 | D22: ='efbm_H0.5Mach2.5_8'!$E$2 -> 2.5 | E22: {=INDIRECT("'"&SUBSTITUTE($B22,".fits","")&"'!$I$2")} -> 0.12094689 | F22: {=INDIRECT("'"&SUBSTITUTE($B22,".fits","")&"'!$J$2")} -> -0.0057501124 | G22: ='efbm_H0.5Mach2.5_0'!$G$2 -> 0.97004296 | H22: {=INDIRECT("'"&SUBSTITUTE($B22,".fits","")&"'!I14")} -> 0.50625038 | I22: {=INDIRECT("'"&SUBSTITUTE($B22,".fits","")&"'!I16")} -> 0.46224553 | J22: {=INDIRECT("'"&SUBSTITUTE($B22,".fits","")&"'!I18")} -> 0.43615417 | K22: {=INDIRECT("'"&SUBSTITUTE($B22,".fits","")&"'!I20")} -> 0.39227914 | L22: {=INDIRECT("'"&SUBSTITUTE($B22,".fits","")&"'!I22")} -> 0.36638248 | M22: {=INDIRECT("'"&SUBSTITUTE($B22,".fits","")&"'!I24")} -> 0.33529352 | N22: {=INDIRECT("'"&SUBSTITUTE($B22,".fits","")&"'!I26")} -> 0.31153869 | O22: {=INDIRECT("'"&SUBSTITUTE($B22,".fits","")&"'!I28")} -> 0.28557713 | P22: {=INDIRECT("'"&SUBSTITUTE($B22,".fits","")&"'!I30")} -> 0.25701942 | Q22: {=INDIRECT("'"&SUBSTITUTE($B22,".fits","")&"'!I32")} -> 0.23430306 | S22: =D22 -> 2.5 | T22: 8 | U22: =L22 -> 0.36638248 | V22: =$L$45+$L$46*L22 -> 2.3756738 | W22: =S22-V22 -> 0.12432621 | X22: =W22/V22 -> 0.052333032 | Z22: =D22 -> 2.5 | AA22: =G22 -> 0.97004296 | AB22: =SQRT(EXP(AA22^2)-1)/Z22 -> 0.5
B23: ='efbm_H0.5Mach2.5_9'!$C$2 -> efbm_H0.5Mach2.5_9.fits | C23: ='efbm_H0.5Mach2.5_9'!$D$2 -> 0.5 | D23: ='efbm_H0.5Mach2.5_9'!$E$2 -> 2.5 | E23: {=INDIRECT("'"&SUBSTITUTE($B23,".fits","")&"'!$I$2")} -> -0.15613434 | F23: {=INDIRECT("'"&SUBSTITUTE($B23,".fits","")&"'!$J$2")} -> -0.74998719 | G23: ='efbm_H0.5Mach2.5_0'!$G$2 -> 0.97004296 | H23: {=INDIRECT("'"&SUBSTITUTE($B23,".fits","")&"'!I14")} -> 0.4592984 | I23: {=INDIRECT("'"&SUBSTITUTE($B23,".fits","")&"'!I16")} -> 0.43034967 | J23: {=INDIRECT("'"&SUBSTITUTE($B23,".fits","")&"'!I18")} -> 0.40107748 | K23: {=INDIRECT("'"&SUBSTITUTE($B23,".fits","")&"'!I20")} -> 0.37520151 | L23: {=INDIRECT("'"&SUBSTITUTE($B23,".fits","")&"'!I22")} -> 0.34326087 | M23: {=INDIRECT("'"&SUBSTITUTE($B23,".fits","")&"'!I24")} -> 0.31698059 | N23: {=INDIRECT("'"&SUBSTITUTE($B23,".fits","")&"'!I26")} -> 0.28843616 | O23: {=INDIRECT("'"&SUBSTITUTE($B23,".fits","")&"'!I28")} -> 0.26522866 | P23: {=INDIRECT("'"&SUBSTITUTE($B23,".fits","")&"'!I30")} -> 0.23935269 | Q23: {=INDIRECT("'"&SUBSTITUTE($B23,".fits","")&"'!I32")} -> 0.21751984 | S23: =D23 -> 2.5 | T23: 9 | U23: =L23 -> 0.34326087 | V23: =$L$45+$L$46*L23 -> 2.4615733 | W23: =S23-V23 -> 0.038426747 | X23: =W23/V23 -> 0.015610645 | Z23: =D23 -> 2.5 | AA23: =G23 -> 0.97004296 | AB23: =SQRT(EXP(AA23^2)-1)/Z23 -> 0.5
B24: =efbm_H1Mach1_0!$C$2 -> efbm_H1Mach1_0.fits | C24: =efbm_H1Mach1_0!$D$2 -> 1 | D24: =efbm_H1Mach1_0!$E$2 -> 1 | E24: {=INDIRECT("'"&SUBSTITUTE($B24,".fits","")&"'!$I$2")} -> 0.22885028 | F24: {=INDIRECT("'"&SUBSTITUTE($B24,".fits","")&"'!$J$2")} -> -0.80673475 | G24: =efbm_H1Mach1_0!$G$2 -> 0.47238073 | H24: {=INDIRECT("'"&SUBSTITUTE($B24,".fits","")&"'!I14")} -> 0.8474233 | I24: {=INDIRECT("'"&SUBSTITUTE($B24,".fits","")&"'!I16")} -> 0.78093345 | J24: {=INDIRECT("'"&SUBSTITUTE($B24,".fits","")&"'!I18")} -> 0.72936237 | K24: {=INDIRECT("'"&SUBSTITUTE($B24,".fits","")&"'!I20")} -> 0.67852802 | L24: {=INDIRECT("'"&SUBSTITUTE($B24,".fits","")&"'!I22")} -> 0.63358752 | M24: {=INDIRECT("'"&SUBSTITUTE($B24,".fits","")&"'!I24")} -> 0.59675103 | N24: {=INDIRECT("'"&SUBSTITUTE($B24,".fits","")&"'!I26")} -> 0.55991455 | O24: {=INDIRECT("'"&SUBSTITUTE($B24,".fits","")&"'!I28")} -> 0.52307806 | P24: {=INDIRECT("'"&SUBSTITUTE($B24,".fits","")&"'!I30")} -> 0.46413969 | Q24: {=INDIRECT("'"&SUBSTITUTE($B24,".fits","")&"'!I32")} -> 0.42177774 | S24: =D24 -> 1 | T24: 0 | U24: =L24 -> 0.63358752 | V24: =$L$45+$L$46*L24 -> 1.3829764 | W24: =S24-V24 -> -0.38297636 | X24: =W24/V24 -> -0.27692184 | Y24: >15% | Z24: =D24 -> 1 | AA24: =G24 -> 0.47238073 | AB24: =SQRT(EXP(AA24^2)-1)/Z24 -> 0.5
B25: =efbm_H1Mach1_1!$C$2 -> efbm_H1Mach1_1.fits | C25: =efbm_H1Mach1_1!$D$2 -> 1 | D25: =efbm_H1Mach1_1!$E$2 -> 1 | E25: {=INDIRECT("'"&SUBSTITUTE($B25,".fits","")&"'!$I$2")} -> -0.39734918 | F25: {=INDIRECT("'"&SUBSTITUTE($B25,".fits","")&"'!$J$2")} -> -0.45420755 | G25: =efbm_H1Mach1_1!$G$2 -> 0.47238073 | H25: {=INDIRECT("'"&SUBSTITUTE($B25,".fits","")&"'!I14")} -> 0.90980852 | I25: {=INDIRECT("'"&SUBSTITUTE($B25,".fits","")&"'!I16")} -> 0.79241387 | J25: {=INDIRECT("'"&SUBSTITUTE($B25,".fits","")&"'!I18")} -> 0.73371655 | K25: {=INDIRECT("'"&SUBSTITUTE($B25,".fits","")&"'!I20")} -> 0.69703072 | L25: {=INDIRECT("'"&SUBSTITUTE($B25,".fits","")&"'!I22")} -> 0.64567056 | M25: {=INDIRECT("'"&SUBSTITUTE($B25,".fits","")&"'!I24")} -> 0.6163219 | N25: {=INDIRECT("'"&SUBSTITUTE($B25,".fits","")&"'!I26")} -> 0.57229891 | O25: {=INDIRECT("'"&SUBSTITUTE($B25,".fits","")&"'!I28")} -> 0.55028741 | P25: {=INDIRECT("'"&SUBSTITUTE($B25,".fits","")&"'!I30")} -> 0.50791528 | Q25: {=INDIRECT("'"&SUBSTITUTE($B25,".fits","")&"'!I32")} -> 0.47691576 | S25: =D25 -> 1 | T25: 1 | U25: =L25 -> 0.64567056 | V25: =$L$45+$L$46*L25 -> 1.3380865 | W25: =S25-V25 -> -0.33808645 | X25: =W25/V25 -> -0.25266413 | Y25: >15% | Z25: =D25 -> 1 | AA25: =G25 -> 0.47238073 | AB25: =SQRT(EXP(AA25^2)-1)/Z25 -> 0.5
B26: =efbm_H1Mach1_2!$C$2 -> efbm_H1Mach1_2.fits | C26: =efbm_H1Mach1_2!$D$2 -> 1 | D26: =efbm_H1Mach1_2!$E$2 -> 1 | E26: {=INDIRECT("'"&SUBSTITUTE($B26,".fits","")&"'!$I$2")} -> -0.10823695 | F26: {=INDIRECT("'"&SUBSTITUTE($B26,".fits","")&"'!$J$2")} -> -1.0918272 | G26: =efbm_H1Mach1_2!$G$2 -> 0.47238073 | H26: {=INDIRECT("'"&SUBSTITUTE($B26,".fits","")&"'!I14")} -> 0.82708808 | I26: {=INDIRECT("'"&SUBSTITUTE($B26,".fits","")&"'!I16")} -> 0.77246905 | J26: {=INDIRECT("'"&SUBSTITUTE($B26,".fits","")&"'!I18")} -> 0.71785003 | K26: {=INDIRECT("'"&SUBSTITUTE($B26,".fits","")&"'!I20")} -> 0.67103372 | L26: {=INDIRECT("'"&SUBSTITUTE($B26,".fits","")&"'!I22")} -> 0.64079819 | M26: {=INDIRECT("'"&SUBSTITUTE($B26,".fits","")&"'!I24")} -> 0.60080926 | N26: {=INDIRECT("'"&SUBSTITUTE($B26,".fits","")&"'!I26")} -> 0.51497937 | O26: {=INDIRECT("'"&SUBSTITUTE($B26,".fits","")&"'!I28")} -> 0.45411817 | P26: {=INDIRECT("'"&SUBSTITUTE($B26,".fits","")&"'!I30")} -> 0.41354404 | Q26: {=INDIRECT("'"&SUBSTITUTE($B26,".fits","")&"'!I32")} -> 0.3511223 | S26: =D26 -> 1 | T26: 2 | U26: =L26 -> 0.64079819 | V26: =$L$45+$L$46*L26 -> 1.3561879 | W26: =S26-V26 -> -0.35618787 | X26: =W26/V26 -> -0.26263903 | Y26: >15% | Z26: =D26 -> 1 | AA26: =G26 -> 0.47238073 | AB26: =SQRT(EXP(AA26^2)-1)/Z26 -> 0.5
B27: =efbm_H1Mach1_3!$C$2 -> efbm_H1Mach1_3.fits | C27: =efbm_H1Mach1_3!$D$2 -> 1 | D27: =efbm_H1Mach1_3!$E$2 -> 1 | E27: {=INDIRECT("'"&SUBSTITUTE($B27,".fits","")&"'!$I$2")} -> 0.55802179 | F27: {=INDIRECT("'"&SUBSTITUTE($B27,".fits","")&"'!$J$2")} -> -0.80947274 | G27: =efbm_H1Mach1_0!$G$2 -> 0.47238073 | H27: {=INDIRECT("'"&SUBSTITUTE($B27,".fits","")&"'!I14")} -> 1.418686 | I27: {=INDIRECT("'"&SUBSTITUTE($B27,".fits","")&"'!I16")} -> 1.2672533 | J27: {=INDIRECT("'"&SUBSTITUTE($B27,".fits","")&"'!I18")} -> 1.0691951 | K27: {=INDIRECT("'"&SUBSTITUTE($B27,".fits","")&"'!I20")} -> 0.8934534 | L27: {=INDIRECT("'"&SUBSTITUTE($B27,".fits","")&"'!I22")} -> 0.73325346 | M27: {=INDIRECT("'"&SUBSTITUTE($B27,".fits","")&"'!I24")} -> 0.56588039 | N27: {=INDIRECT("'"&SUBSTITUTE($B27,".fits","")&"'!I26")} -> 0.47023863 | O27: {=INDIRECT("'"&SUBSTITUTE($B27,".fits","")&"'!I28")} -> 0.41444761 | P27: {=INDIRECT("'"&SUBSTITUTE($B27,".fits","")&"'!I30")} -> 0.36662673 | Q27: {=INDIRECT("'"&SUBSTITUTE($B27,".fits","")&"'!I32")} -> 0.32079839 | S27: =D27 -> 1 | T27: 3 | U27: =L27 -> 0.73325346 | V27: =$L$45+$L$46*L27 -> 1.0127059 | W27: =S27-V27 -> -0.012705918 | X27: =W27/V27 -> -0.012546503 | Z27: =D27 -> 1 | AA27: =G27 -> 0.47238073 | AB27: =SQRT(EXP(AA27^2)-1)/Z27 -> 0.5
B28: =efbm_H1Mach1_4!$C$2 -> efbm_H1Mach1_4.fits | C28: =efbm_H1Mach1_4!$D$2 -> 1 | D28: =efbm_H1Mach1_4!$E$2 -> 1 | E28: {=INDIRECT("'"&SUBSTITUTE($B28,".fits","")&"'!$I$2")} -> -0.60582574 | F28: {=INDIRECT("'"&SUBSTITUTE($B28,".fits","")&"'!$J$2")} -> -0.46603174 | G28: =efbm_H1Mach1_0!$G$2 -> 0.47238073 | H28: {=INDIRECT("'"&SUBSTITUTE($B28,".fits","")&"'!I14")} -> 1.1113928 | I28: {=INDIRECT("'"&SUBSTITUTE($B28,".fits","")&"'!I16")} -> 1.0340173 | J28: {=INDIRECT("'"&SUBSTITUTE($B28,".fits","")&"'!I18")} -> 0.98477842 | K28: {=INDIRECT("'"&SUBSTITUTE($B28,".fits","")&"'!I20")} -> 0.91443711 | L28: {=INDIRECT("'"&SUBSTITUTE($B28,".fits","")&"'!I22")} -> 0.81683853 | M28: {=INDIRECT("'"&SUBSTITUTE($B28,".fits","")&"'!I24")} -> 0.71150241 | N28: {=INDIRECT("'"&SUBSTITUTE($B28,".fits","")&"'!I26")} -> 0.63307184 | O28: {=INDIRECT("'"&SUBSTITUTE($B28,".fits","")&"'!I28")} -> 0.57117148 | P28: {=INDIRECT("'"&SUBSTITUTE($B28,".fits","")&"'!I30")} -> 0.47990363 | Q28: {=INDIRECT("'"&SUBSTITUTE($B28,".fits","")&"'!I32")} -> 0.40797963 | S28: =D28 -> 1 | T28: 4 | U28: =L28 -> 0.81683853 | V28: =$L$45+$L$46*L28 -> 0.70217776 | W28: =S28-V28 -> 0.29782224 | X28: =W28/V28 -> 0.42414081 | Y28: >15% | Z28: =D28 -> 1 | AA28: =G28 -> 0.47238073 | AB28: =SQRT(EXP(AA28^2)-1)/Z28 -> 0.5
B29: =efbm_H1Mach1_5!$C$2 -> efbm_H1Mach1_5.fits | C29: =efbm_H1Mach1_5!$D$2 -> 1 | D29: =efbm_H1Mach1_5!$E$2 -> 1 | E29: {=INDIRECT("'"&SUBSTITUTE($B29,".fits","")&"'!$I$2")} -> -0.77708798 | F29: {=INDIRECT("'"&SUBSTITUTE($B29,".fits","")&"'!$J$2")} -> 0.49027506 | G29: =efbm_H1Mach1_0!$G$2 -> 0.47238073 | H29: {=INDIRECT("'"&SUBSTITUTE($B29,".fits","")&"'!I14")} -> 1.0496309 | I29: {=INDIRECT("'"&SUBSTITUTE($B29,".fits","")&"'!I16")} -> 0.96400308 | J29: {=INDIRECT("'"&SUBSTITUTE($B29,".fits","")&"'!I18")} -> 0.90845244 | K29: {=INDIRECT("'"&SUBSTITUTE($B29,".fits","")&"'!I20")} -> 0.85320871 | L29: {=INDIRECT("'"&SUBSTITUTE($B29,".fits","")&"'!I22")} -> 0.81637956 | M29: {=INDIRECT("'"&SUBSTITUTE($B29,".fits","")&"'!I24")} -> 0.77955041 | N29: {=INDIRECT("'"&SUBSTITUTE($B29,".fits","")&"'!I26")} -> 0.73658306 | O29: {=INDIRECT("'"&SUBSTITUTE($B29,".fits","")&"'!I28")} -> 0.70098155 | P29: {=INDIRECT("'"&SUBSTITUTE($B29,".fits","")&"'!I30")} -> 0.66292476 | Q29: {=INDIRECT("'"&SUBSTITUTE($B29,".fits","")&"'!I32")} -> 0.60921557 | S29: =D29 -> 1 | T29: 5 | U29: =L29 -> 0.81637956 | V29: =$L$45+$L$46*L29 -> 0.70388288 | W29: =S29-V29 -> 0.29611712 | X29: =W29/V29 -> 0.42069089 | Y29: >15% | Z29: =D29 -> 1 | AA29: =G29 -> 0.47238073 | AB29: =SQRT(EXP(AA29^2)-1)/Z29 -> 0.5
B30: =efbm_H1Mach1_6!$C$2 -> efbm_H1Mach1_6.fits | C30: =efbm_H1Mach1_6!$D$2 -> 1 | D30: =efbm_H1Mach1_6!$E$2 -> 1 | E30: {=INDIRECT("'"&SUBSTITUTE($B30,".fits","")&"'!$I$2")} -> -0.4114514 | F30: {=INDIRECT("'"&SUBSTITUTE($B30,".fits","")&"'!$J$2")} -> -0.62315483 | G30: =efbm_H1Mach1_0!$G$2 -> 0.47238073 | H30: {=INDIRECT("'"&SUBSTITUTE($B30,".fits","")&"'!I14")} -> 0.91831934 | I30: {=INDIRECT("'"&SUBSTITUTE($B30,".fits","")&"'!I16")} -> 0.84287455 | J30: {=INDIRECT("'"&SUBSTITUTE($B30,".fits","")&"'!I18")} -> 0.76065665 | K30: {=INDIRECT("'"&SUBSTITUTE($B30,".fits","")&"'!I20")} -> 0.68558813 | L30: {=INDIRECT("'"&SUBSTITUTE($B30,".fits","")&"'!I22")} -> 0.62557095 | M30: {=INDIRECT("'"&SUBSTITUTE($B30,".fits","")&"'!I24")} -> 0.56442492 | N30: {=INDIRECT("'"&SUBSTITUTE($B30,".fits","")&"'!I26")} -> 0.53432226 | O30: {=INDIRECT("'"&SUBSTITUTE($B30,".fits","")&"'!I28")} -> 0.51174526 | P30: {=INDIRECT("'"&SUBSTITUTE($B30,".fits","")&"'!I30")} -> 0.4816426 | Q30: {=INDIRECT("'"&SUBSTITUTE($B30,".fits","")&"'!I32")} -> 0.4364886 | S30: =D30 -> 1 | T30: 6 | U30: =L30 -> 0.62557095 | V30: =$L$45+$L$46*L30 -> 1.4127588 | W30: =S30-V30 -> -0.41275881 | X30: =W30/V30 -> -0.2921651 | Y30: >15% | Z30: =D30 -> 1 | AA30: =G30 -> 0.47238073 | AB30: =SQRT(EXP(AA30^2)-1)/Z30 -> 0.5
B31: =efbm_H1Mach1_7!$C$2 -> efbm_H1Mach1_7.fits | C31: =efbm_H1Mach1_7!$D$2 -> 1 | D31: =efbm_H1Mach1_7!$E$2 -> 1 | E31: {=INDIRECT("'"&SUBSTITUTE($B31,".fits","")&"'!$I$2")} -> -0.23788079 | F31: {=INDIRECT("'"&SUBSTITUTE($B31,".fits","")&"'!$J$2")} -> -0.58065061 | G31: =efbm_H1Mach1_0!$G$2 -> 0.47238073 | H31: {=INDIRECT("'"&SUBSTITUTE($B31,".fits","")&"'!I14")} -> 0.99172895 | I31: {=INDIRECT("'"&SUBSTITUTE($B31,".fits","")&"'!I16")} -> 0.88045998 | J31: {=INDIRECT("'"&SUBSTITUTE($B31,".fits","")&"'!I18")} -> 0.80516238 | K31: {=INDIRECT("'"&SUBSTITUTE($B31,".fits","")&"'!I20")} -> 0.7231551 | L31: {=INDIRECT("'"&SUBSTITUTE($B31,".fits","")&"'!I22")} -> 0.64953493 | M31: {=INDIRECT("'"&SUBSTITUTE($B31,".fits","")&"'!I24")} -> 0.58150617 | N31: {=INDIRECT("'"&SUBSTITUTE($B31,".fits","")&"'!I26")} -> 0.52316917 | O31: {=INDIRECT("'"&SUBSTITUTE($B31,".fits","")&"'!I28")} -> 0.47713326 | P31: {=INDIRECT("'"&SUBSTITUTE($B31,".fits","")&"'!I30")} -> 0.42494681 | Q31: {=INDIRECT("'"&SUBSTITUTE($B31,".fits","")&"'!I32")} -> 0.38767078 | S31: =D31 -> 1 | T31: 7 | U31: =L31 -> 0.64953493 | V31: =$L$45+$L$46*L31 -> 1.3237299 | W31: =S31-V31 -> -0.32372987 | X31: =W31/V31 -> -0.24455886 | Y31: >15% | Z31: =D31 -> 1 | AA31: =G31 -> 0.47238073 | AB31: =SQRT(EXP(AA31^2)-1)/Z31 -> 0.5
B32: =efbm_H1Mach1_8!$C$2 -> efbm_H1Mach1_8.fits | C32: =efbm_H1Mach1_8!$D$2 -> 1 | D32: =efbm_H1Mach1_8!$E$2 -> 1 | E32: {=INDIRECT("'"&SUBSTITUTE($B32,".fits","")&"'!$I$2")} -> 0.08537529 | F32: {=INDIRECT("'"&SUBSTITUTE($B32,".fits","")&"'!$J$2")} -> -0.37741886 | G32: =efbm_H1Mach1_0!$G$2 -> 0.47238073 | H32: {=INDIRECT("'"&SUBSTITUTE($B32,".fits","")&"'!I14")} -> 0.98850873 | I32: {=INDIRECT("'"&SUBSTITUTE($B32,".fits","")&"'!I16")} -> 0.92080265 | J32: {=INDIRECT("'"&SUBSTITUTE($B32,".fits","")&"'!I18")} -> 0.84057095 | K32: {=INDIRECT("'"&SUBSTITUTE($B32,".fits","")&"'!I20")} -> 0.77184928 | L32: {=INDIRECT("'"&SUBSTITUTE($B32,".fits","")&"'!I22")} -> 0.71768442 | M32: {=INDIRECT("'"&SUBSTITUTE($B32,".fits","")&"'!I24")} -> 0.67029016 | N32: {=INDIRECT("'"&SUBSTITUTE($B32,".fits","")&"'!I26")} -> 0.6161253 | O32: {=INDIRECT("'"&SUBSTITUTE($B32,".fits","")&"'!I28")} -> 0.55518983 | P32: {=INDIRECT("'"&SUBSTITUTE($B32,".fits","")&"'!I30")} -> 0.48748376 | Q32: {=INDIRECT("'"&SUBSTITUTE($B32,".fits","")&"'!I32")} -> 0.42824094 | S32: =D32 -> 1 | T32: 8 | U32: =L32 -> 0.71768442 | V32: =$L$45+$L$46*L32 -> 1.0705467 | W32: =S32-V32 -> -0.070546694 | X32: =W32/V32 -> -0.06589782 | Z32: =D32 -> 1 | AA32: =G32 -> 0.47238073 | AB32: =SQRT(EXP(AA32^2)-1)/Z32 -> 0.5
B33: =efbm_H1Mach1_9!$C$2 -> efbm_H1Mach1_9.fits | C33: =efbm_H1Mach1_9!$D$2 -> 1 | D33: =efbm_H1Mach1_9!$E$2 -> 1 | E33: {=INDIRECT("'"&SUBSTITUTE($B33,".fits","")&"'!$I$2")} -> -0.23024651 | F33: {=INDIRECT("'"&SUBSTITUTE($B33,".fits","")&"'!$J$2")} -> -0.84501581 | G33: =efbm_H1Mach1_0!$G$2 -> 0.47238073 | H33: {=INDIRECT("'"&SUBSTITUTE($B33,".fits","")&"'!I14")} -> 1.0849432 | I33: {=INDIRECT("'"&SUBSTITUTE($B33,".fits","")&"'!I16")} -> 0.85399388 | J33: {=INDIRECT("'"&SUBSTITUTE($B33,".fits","")&"'!I18")} -> 0.72595463 | K33: {=INDIRECT("'"&SUBSTITUTE($B33,".fits","")&"'!I20")} -> 0.64697715 | L33: {=INDIRECT("'"&SUBSTITUTE($B33,".fits","")&"'!I22")} -> 0.56640416 | M33: {=INDIRECT("'"&SUBSTITUTE($B33,".fits","")&"'!I24")} -> 0.46269636 | N33: {=INDIRECT("'"&SUBSTITUTE($B33,".fits","")&"'!I26")} -> 0.38292112 | O33: {=INDIRECT("'"&SUBSTITUTE($B33,".fits","")&"'!I28")} -> 0.33505598 | P33: {=INDIRECT("'"&SUBSTITUTE($B33,".fits","")&"'!I30")} -> 0.27921332 | Q33: {=INDIRECT("'"&SUBSTITUTE($B33,".fits","")&"'!I32")} -> 0.2393257 | S33: =D33 -> 1 | T33: 9 | U33: =L33 -> 0.56640416 | V33: =$L$45+$L$46*L33 -> 1.6325702 | W33: =S33-V33 -> -0.63257025 | X33: =W33/V33 -> -0.38746893 | Y33: >15% | Z33: =D33 -> 1 | AA33: =G33 -> 0.47238073 | AB33: =SQRT(EXP(AA33^2)-1)/Z33 -> 0.5
B34: =efbm_H1Mach2.5_0!$C$2 -> efbm_H1Mach2.5_0.fits | C34: =efbm_H1Mach2.5_0!$D$2 -> 1 | D34: =efbm_H1Mach2.5_0!$E$2 -> 2.5 | E34: {=INDIRECT("'"&SUBSTITUTE($B34,".fits","")&"'!$I$2")} -> 0.22885028 | F34: {=INDIRECT("'"&SUBSTITUTE($B34,".fits","")&"'!$J$2")} -> -0.80673475 | G34: =efbm_H1Mach2.5_0!$G$2 -> 0.97004296 | H34: {=INDIRECT("'"&SUBSTITUTE($B34,".fits","")&"'!I14")} -> 0.41266877 | I34: {=INDIRECT("'"&SUBSTITUTE($B34,".fits","")&"'!I16")} -> 0.38029028 | J34: {=INDIRECT("'"&SUBSTITUTE($B34,".fits","")&"'!I18")} -> 0.35517677 | K34: {=INDIRECT("'"&SUBSTITUTE($B34,".fits","")&"'!I20")} -> 0.33042203 | L34: {=INDIRECT("'"&SUBSTITUTE($B34,".fits","")&"'!I22")} -> 0.3085374 | M34: {=INDIRECT("'"&SUBSTITUTE($B34,".fits","")&"'!I24")} -> 0.29059918 | N34: {=INDIRECT("'"&SUBSTITUTE($B34,".fits","")&"'!I26")} -> 0.27266096 | O34: {=INDIRECT("'"&SUBSTITUTE($B34,".fits","")&"'!I28")} -> 0.25472274 | P34: {=INDIRECT("'"&SUBSTITUTE($B34,".fits","")&"'!I30")} -> 0.22602158 | Q34: {=INDIRECT("'"&SUBSTITUTE($B34,".fits","")&"'!I32")} -> 0.20539263 | S34: =D34 -> 2.5 | T34: 0 | U34: =L34 -> 0.3085374 | V34: =$L$45+$L$46*L34 -> 2.5905749 | W34: =S34-V34 -> -0.090574932 | X34: =W34/V34 -> -0.034963255 | Z34: =D34 -> 2.5 | AA34: =G34 -> 0.97004296 | AB34: =SQRT(EXP(AA34^2)-1)/Z34 -> 0.5
B35: =efbm_H1Mach2.5_1!$C$2 -> efbm_H1Mach2.5_1.fits | C35: =efbm_H1Mach2.5_1!$D$2 -> 1 | D35: =efbm_H1Mach2.5_1!$E$2 -> 2.5 | E35: {=INDIRECT("'"&SUBSTITUTE($B35,".fits","")&"'!$I$2")} -> -0.39734918 | F35: {=INDIRECT("'"&SUBSTITUTE($B35,".fits","")&"'!$J$2")} -> -0.45420755 | G35: =efbm_H1Mach2.5_0!$G$2 -> 0.97004296 | H35: {=INDIRECT("'"&SUBSTITUTE($B35,".fits","")&"'!I14")} -> 0.44304843 | I35: {=INDIRECT("'"&SUBSTITUTE($B35,".fits","")&"'!I16")} -> 0.38588089 | J35: {=INDIRECT("'"&SUBSTITUTE($B35,".fits","")&"'!I18")} -> 0.35729712 | K35: {=INDIRECT("'"&SUBSTITUTE($B35,".fits","")&"'!I20")} -> 0.33943226 | L35: {=INDIRECT("'"&SUBSTITUTE($B35,".fits","")&"'!I22")} -> 0.31442147 | M35: {=INDIRECT("'"&SUBSTITUTE($B35,".fits","")&"'!I24")} -> 0.30012958 | N35: {=INDIRECT("'"&SUBSTITUTE($B35,".fits","")&"'!I26")} -> 0.27869175 | O35: {=INDIRECT("'"&SUBSTITUTE($B35,".fits","")&"'!I28")} -> 0.26797284 | P35: {=INDIRECT("'"&SUBSTITUTE($B35,".fits","")&"'!I30")} -> 0.24733893 | Q35: {=INDIRECT("'"&SUBSTITUTE($B35,".fits","")&"'!I32")} -> 0.23224313 | S35: =D35 -> 2.5 | T35: 1 | U35: =L35 -> 0.31442147 | V35: =$L$45+$L$46*L35 -> 2.5687149 | W35: =S35-V35 -> -0.068714945 | X35: =W35/V35 -> -0.026750709 | Z35: =D35 -> 2.5 | AA35: =G35 -> 0.97004296 | AB35: =SQRT(EXP(AA35^2)-1)/Z35 -> 0.5
B36: =efbm_H1Mach2.5_2!$C$2 -> efbm_H1Mach2.5_2.fits | C36: =efbm_H1Mach2.5_2!$D$2 -> 1 | D36: =efbm_H1Mach2.5_2!$E$2 -> 2.5 | E36: {=INDIRECT("'"&SUBSTITUTE($B36,".fits","")&"'!$I$2")} -> -0.10823695 | F36: {=INDIRECT("'"&SUBSTITUTE($B36,".fits","")&"'!$J$2")} -> -1.0918272 | G36: =efbm_H1Mach2.5_0!$G$2 -> 0.97004296 | H36: {=INDIRECT("'"&SUBSTITUTE($B36,".fits","")&"'!I14")} -> 0.40276615 | I36: {=INDIRECT("'"&SUBSTITUTE($B36,".fits","")&"'!I16")} -> 0.37616838 | J36: {=INDIRECT("'"&SUBSTITUTE($B36,".fits","")&"'!I18")} -> 0.34957062 | K36: {=INDIRECT("'"&SUBSTITUTE($B36,".fits","")&"'!I20")} -> 0.32677254 | L36: {=INDIRECT("'"&SUBSTITUTE($B36,".fits","")&"'!I22")} -> 0.31204877 | M36: {=INDIRECT("'"&SUBSTITUTE($B36,".fits","")&"'!I24")} -> 0.29257541 | N36: {=INDIRECT("'"&SUBSTITUTE($B36,".fits","")&"'!I26")} -> 0.25077892 | O36: {=INDIRECT("'"&SUBSTITUTE($B36,".fits","")&"'!I28")} -> 0.22114141 | P36: {=INDIRECT("'"&SUBSTITUTE($B36,".fits","")&"'!I30")} -> 0.20138307 | Q36: {=INDIRECT("'"&SUBSTITUTE($B36,".fits","")&"'!I32")} -> 0.17098563 | S36: =D36 -> 2.5 | T36: 2 | U36: =L36 -> 0.31204877 | V36: =$L$45+$L$46*L36 -> 2.5775298 | W36: =S36-V36 -> -0.07752977 | X36: =W36/V36 -> -0.030079098 | Z36: =D36 -> 2.5 | AA36: =G36 -> 0.97004296 | AB36: =SQRT(EXP(AA36^2)-1)/Z36 -> 0.5
B37: =efbm_H1Mach2.5_3!$C$2 -> efbm_H1Mach2.5_3.fits | C37: =efbm_H1Mach2.5_3!$D$2 -> 1 | D37: =efbm_H1Mach2.5_3!$E$2 -> 2.5 | E37: {=INDIRECT("'"&SUBSTITUTE($B37,".fits","")&"'!$I$2")} -> 0.55802179 | F37: {=INDIRECT("'"&SUBSTITUTE($B37,".fits","")&"'!$J$2")} -> -0.80947274 | G37: =efbm_H1Mach2.5_0!$G$2 -> 0.97004296 | H37: {=INDIRECT("'"&SUBSTITUTE($B37,".fits","")&"'!I14")} -> 0.69085594 | I37: {=INDIRECT("'"&SUBSTITUTE($B37,".fits","")&"'!I16")} -> 0.61711289 | J37: {=INDIRECT("'"&SUBSTITUTE($B37,".fits","")&"'!I18")} -> 0.52066474 | K37: {=INDIRECT("'"&SUBSTITUTE($B37,".fits","")&"'!I20")} -> 0.43508399 | L37: {=INDIRECT("'"&SUBSTITUTE($B37,".fits","")&"'!I22")} -> 0.35707161 | M37: {=INDIRECT("'"&SUBSTITUTE($B37,".fits","")&"'!I24")} -> 0.27556613 | N37: {=INDIRECT("'"&SUBSTITUTE($B37,".fits","")&"'!I26")} -> 0.22899158 | O37: {=INDIRECT("'"&SUBSTITUTE($B37,".fits","")&"'!I28")} -> 0.20182308 | P37: {=INDIRECT("'"&SUBSTITUTE($B37,".fits","")&"'!I30")} -> 0.1785358 | Q37: {=INDIRECT("'"&SUBSTITUTE($B37,".fits","")&"'!I32")} -> 0.15621883 | S37: =D37 -> 2.5 | T37: 3 | U37: =L37 -> 0.35707161 | V37: =$L$45+$L$46*L37 -> 2.4102648 | W37: =S37-V37 -> 0.089735247 | X37: =W37/V37 -> 0.037230452 | Z37: =D37 -> 2.5 | AA37: =G37 -> 0.97004296 | AB37: =SQRT(EXP(AA37^2)-1)/Z37 -> 0.5
B38: =efbm_H1Mach2.5_4!$C$2 -> efbm_H1Mach2.5_4.fits | C38: =efbm_H1Mach2.5_4!$D$2 -> 1 | D38: =efbm_H1Mach2.5_4!$E$2 -> 2.5 | E38: {=INDIRECT("'"&SUBSTITUTE($B38,".fits","")&"'!$I$2")} -> -0.60582574 | F38: {=INDIRECT("'"&SUBSTITUTE($B38,".fits","")&"'!$J$2")} -> -0.46603174 | G38: =efbm_H1Mach2.5_0!$G$2 -> 0.97004296 | H38: {=INDIRECT("'"&SUBSTITUTE($B38,".fits","")&"'!I14")} -> 0.54121369 | I38: {=INDIRECT("'"&SUBSTITUTE($B38,".fits","")&"'!I16")} -> 0.50353426 | J38: {=INDIRECT("'"&SUBSTITUTE($B38,".fits","")&"'!I18")} -> 0.47955644 | K38: {=INDIRECT("'"&SUBSTITUTE($B38,".fits","")&"'!I20")} -> 0.44530241 | L38: {=INDIRECT("'"&SUBSTITUTE($B38,".fits","")&"'!I22")} -> 0.39777494 | M38: {=INDIRECT("'"&SUBSTITUTE($B38,".fits","")&"'!I24")} -> 0.34647953 | N38: {=INDIRECT("'"&SUBSTITUTE($B38,".fits","")&"'!I26")} -> 0.30828628 | O38: {=INDIRECT("'"&SUBSTITUTE($B38,".fits","")&"'!I28")} -> 0.27814273 | P38: {=INDIRECT("'"&SUBSTITUTE($B38,".fits","")&"'!I30")} -> 0.23369813 | Q38: {=INDIRECT("'"&SUBSTITUTE($B38,".fits","")&"'!I32")} -> 0.19867338 | S38: =D38 -> 2.5 | T38: 4 | U38: =L38 -> 0.39777494 | V38: =$L$45+$L$46*L38 -> 2.2590472 | W38: =S38-V38 -> 0.24095279 | X38: =W38/V38 -> 0.10666125 | Z38: =D38 -> 2.5 | AA38: =G38 -> 0.97004296 | AB38: =SQRT(EXP(AA38^2)-1)/Z38 -> 0.5
B39: =efbm_H1Mach2.5_5!$C$2 -> efbm_H1Mach2.5_5.fits | C39: =efbm_H1Mach2.5_5!$D$2 -> 1 | D39: =efbm_H1Mach2.5_5!$E$2 -> 2.5 | E39: {=INDIRECT("'"&SUBSTITUTE($B39,".fits","")&"'!$I$2")} -> -0.77708798 | F39: {=INDIRECT("'"&SUBSTITUTE($B39,".fits","")&"'!$J$2")} -> 0.49027506 | G39: =efbm_H1Mach2.5_0!$G$2 -> 0.97004296 | H39: {=INDIRECT("'"&SUBSTITUTE($B39,".fits","")&"'!I14")} -> 0.51113756 | I39: {=INDIRECT("'"&SUBSTITUTE($B39,".fits","")&"'!I16")} -> 0.46943949 | J39: {=INDIRECT("'"&SUBSTITUTE($B39,".fits","")&"'!I18")} -> 0.44238806 | K39: {=INDIRECT("'"&SUBSTITUTE($B39,".fits","")&"'!I20")} -> 0.41548609 | L39: {=INDIRECT("'"&SUBSTITUTE($B39,".fits","")&"'!I22")} -> 0.39755143 | M39: {=INDIRECT("'"&SUBSTITUTE($B39,".fits","")&"'!I24")} -> 0.37961678 | N39: {=INDIRECT("'"&SUBSTITUTE($B39,".fits","")&"'!I26")} -> 0.35869302 | O39: {=INDIRECT("'"&SUBSTITUTE($B39,".fits","")&"'!I28")} -> 0.34135619 | P39: {=INDIRECT("'"&SUBSTITUTE($B39,".fits","")&"'!I30")} -> 0.32282372 | Q39: {=INDIRECT("'"&SUBSTITUTE($B39,".fits","")&"'!I32")} -> 0.29666902 | S39: =D39 -> 2.5 | T39: 5 | U39: =L39 -> 0.39755143 | V39: =$L$45+$L$46*L39 -> 2.2598775 | W39: =S39-V39 -> 0.24012245 | X39: =W39/V39 -> 0.10625463 | Z39: =D39 -> 2.5 | AA39: =G39 -> 0.97004296 | AB39: =SQRT(EXP(AA39^2)-1)/Z39 -> 0.5
B40: =efbm_H1Mach2.5_6!$C$2 -> efbm_H1Mach2.5_6.fits | C40: =efbm_H1Mach2.5_6!$D$2 -> 1 | D40: =efbm_H1Mach2.5_6!$E$2 -> 2.5 | E40: {=INDIRECT("'"&SUBSTITUTE($B40,".fits","")&"'!$I$2")} -> -0.4114514 | F40: {=INDIRECT("'"&SUBSTITUTE($B40,".fits","")&"'!$J$2")} -> -0.62315483 | G40: =efbm_H1Mach2.5_0!$G$2 -> 0.97004296 | H40: {=INDIRECT("'"&SUBSTITUTE($B40,".fits","")&"'!I14")} -> 0.44719294 | I40: {=INDIRECT("'"&SUBSTITUTE($B40,".fits","")&"'!I16")} -> 0.41045367 | J40: {=INDIRECT("'"&SUBSTITUTE($B40,".fits","")&"'!I18")} -> 0.37041611 | K40: {=INDIRECT("'"&SUBSTITUTE($B40,".fits","")&"'!I20")} -> 0.33386008 | L40: {=INDIRECT("'"&SUBSTITUTE($B40,".fits","")&"'!I22")} -> 0.30463358 | M40: {=INDIRECT("'"&SUBSTITUTE($B40,".fits","")&"'!I24")} -> 0.27485737 | N40: {=INDIRECT("'"&SUBSTITUTE($B40,".fits","")&"'!I26")} -> 0.26019831 | O40: {=INDIRECT("'"&SUBSTITUTE($B40,".fits","")&"'!I28")} -> 0.24920401 | P40: {=INDIRECT("'"&SUBSTITUTE($B40,".fits","")&"'!I30")} -> 0.23454495 | Q40: {=INDIRECT("'"&SUBSTITUTE($B40,".fits","")&"'!I32")} -> 0.21255636 | S40: =D40 -> 2.5 | T40: 6 | U40: =L40 -> 0.30463358 | V40: =$L$45+$L$46*L40 -> 2.6050781 | W40: =S40-V40 -> -0.10507806 | X40: =W40/V40 -> -0.040335859 | Z40: =D40 -> 2.5 | AA40: =G40 -> 0.97004296 | AB40: =SQRT(EXP(AA40^2)-1)/Z40 -> 0.5
...

Sheet efbm_H0.5Mach1_0
A1: eta | B1: PDF | C1: Archivo | D1: H | E1: Mach_real | F1: PDF_tipo | G1: pdf_sigma | H1: pdf_sigma_core | I1: pdf_skewness | J1: pdf_kurtosis | K1: Mach_inferido_PDF
A2: -1.531757 | B2: 0.0055042964 | C2: efbm_H0.5Mach1_0.fits | D2: 0.5 | E2: 1 | F2: A_lognormal | G2: 0.47238073 | H2: 0.26019694 | I2: 0.072205595 | J2: -0.54554104 | K2: 1.25
A3: -1.5288502 | B3: 0
A4: -1.5259434 | B4: 0
A5: -1.5230365 | B5: 0
A6: -1.5201297 | B6: 0 | E6: CUARTILES | I6: P50%
A7: -1.5172229 | B7: 0 | E7: 1 | F7: 0.25 | G7: =_xlfn.QUARTILE.INC($B$2:$B$1001,E7) -> 0.049538667 | I7: =G9-G7 -> 0.56143823
A8: -1.5143161 | B8: 0.0055042964 | E8: 2 | F8: 0.5 | G8: =_xlfn.QUARTILE.INC($B$2:$B$1001,E8) -> 0.3027363
A9: -1.5114093 | B9: 0 | E9: 3 | F9: 0.75 | G9: =_xlfn.QUARTILE.INC($B$2:$B$1001,E9) -> 0.6109769
A10: -1.5085024 | B10: 0.011008593
A11: -1.5055956 | B11: 0
A12: -1.5026888 | B12: 0.0055042964 | E12: PERCENTILES
A13: -1.499782 | B13: 0 | E13: 0.001 | F13: =E13 -> 0.001 | G13: =_xlfn.PERCENTILE.INC($B$2:$B$1001,E13) -> 0 | I13: P95
A14: -1.4968752 | B14: 0 | E14: 0.002 | F14: =E14 -> 0.002 | G14: =_xlfn.PERCENTILE.INC($B$2:$B$1001,E14) -> 0 | I14: =G987-G37 -> 0.83114875
A15: -1.4939683 | B15: 0 | E15: 0.003 | F15: =E15 -> 0.003 | G15: =_xlfn.PERCENTILE.INC($B$2:$B$1001,E15) -> 0 | I15: P90
A16: -1.4910615 | B16: 0 | E16: 0.004 | F16: =E16 -> 0.004 | G16: =_xlfn.PERCENTILE.INC($B$2:$B$1001,E16) -> 0 | I16: =G962-G62 -> 0.79261868
A17: -1.4881547 | B17: 0.0055042964 | E17: 0.005 | F17: =E17 -> 0.005 | G17: =_xlfn.PERCENTILE.INC($B$2:$B$1001,E17) -> 0 | I17: P85
A18: -1.4852479 | B18: 0 | E18: 0.006 | F18: =E18 -> 0.006 | G18: =_xlfn.PERCENTILE.INC($B$2:$B$1001,E18) -> 0 | I18: =G937-G87 -> 0.77060149
A19: -1.4823411 | B19: 0.0055042964 | E19: 0.007 | F19: =E19 -> 0.007 | G19: =_xlfn.PERCENTILE.INC($B$2:$B$1001,E19) -> 0 | I19: P80
A20: -1.4794342 | B20: 0 | E20: 0.008 | F20: =E20 -> 0.008 | G20: =_xlfn.PERCENTILE.INC($B$2:$B$1001,E20) -> 0 | I20: =G912-G112 -> 0.74363044
A21: -1.4765274 | B21: 0.0055042964 | E21: 0.009 | F21: =E21 -> 0.009 | G21: =_xlfn.PERCENTILE.INC($B$2:$B$1001,E21) -> 0 | I21: P75
A22: -1.4736206 | B22: 0.0055042964 | E22: 0.01 | F22: =E22 -> 0.01 | G22: =_xlfn.PERCENTILE.INC($B$2:$B$1001,E22) -> 0 | I22: =G887-G137 -> 0.72656712
A23: -1.4707138 | B23: 0 | E23: 0.011 | F23: =E23 -> 0.011 | G23: =_xlfn.PERCENTILE.INC($B$2:$B$1001,E23) -> 0 | I23: P70
A24: -1.467807 | B24: 0 | E24: 0.012 | F24: =E24 -> 0.012 | G24: =_xlfn.PERCENTILE.INC($B$2:$B$1001,E24) -> 0 | I24: =G862-G162 -> 0.70454993
A25: -1.4649001 | B25: 0.0055042964 | E25: 0.013 | F25: =E25 -> 0.013 | G25: =_xlfn.PERCENTILE.INC($B$2:$B$1001,E25) -> 0 | I25: P65
A26: -1.4619933 | B26: 0.011008593 | E26: 0.014 | F26: =E26 -> 0.014 | G26: =_xlfn.PERCENTILE.INC($B$2:$B$1001,E26) -> 0 | I26: =G837-G187 -> 0.68803705
A27: -1.4590865 | B27: 0 | E27: 0.015 | F27: =E27 -> 0.015 | G27: =_xlfn.PERCENTILE.INC($B$2:$B$1001,E27) -> 0 | I27: P60
A28: -1.4561797 | B28: 0 | E28: 0.016 | F28: =E28 -> 0.016 | G28: =_xlfn.PERCENTILE.INC($B$2:$B$1001,E28) -> 0 | I28: =G812-G212 -> 0.64950697
A29: -1.4532729 | B29: 0 | E29: 0.017 | F29: =E29 -> 0.017 | G29: =_xlfn.PERCENTILE.INC($B$2:$B$1001,E29) -> 0 | I29: P55
A30: -1.450366 | B30: 0 | E30: 0.018 | F30: =E30 -> 0.018 | G30: =_xlfn.PERCENTILE.INC($B$2:$B$1001,E30) -> 0 | I30: =G787-G237 -> 0.61648119
A31: -1.4474592 | B31: 0.0055042964 | E31: 0.019 | F31: =E31 -> 0.019 | G31: =_xlfn.PERCENTILE.INC($B$2:$B$1001,E31) -> 0 | I31: P50
A32: -1.4445524 | B32: 0 | E32: 0.02 | F32: =E32 -> 0.02 | G32: =_xlfn.PERCENTILE.INC($B$2:$B$1001,E32) -> 0 | I32: =G762-G262 -> 0.56143823
A33: -1.4416456 | B33: 0 | E33: 0.021 | F33: =E33 -> 0.021 | G33: =_xlfn.PERCENTILE.INC($B$2:$B$1001,E33) -> 0
A34: -1.4387388 | B34: 0.0055042964 | E34: 0.022 | F34: =E34 -> 0.022 | G34: =_xlfn.PERCENTILE.INC($B$2:$B$1001,E34) -> 0
A35: -1.4358319 | B35: 0 | E35: 0.023 | F35: =E35 -> 0.023 | G35: =_xlfn.PERCENTILE.INC($B$2:$B$1001,E35) -> 0
A36: -1.4329251 | B36: 0 | E36: 0.024 | F36: =E36 -> 0.024 | G36: =_xlfn.PERCENTILE.INC($B$2:$B$1001,E36) -> 0
A37: -1.4300183 | B37: 0 | E37: 0.025 | F37: =E37 -> 0.025 | G37: =_xlfn.PERCENTILE.INC($B$2:$B$1001,E37) -> 0
A38: -1.4271115 | B38: 0 | E38: 0.026 | F38: =E38 -> 0.026 | G38: =_xlfn.PERCENTILE.INC($B$2:$B$1001,E38) -> 0
A39: -1.4242047 | B39: 0 | E39: 0.027 | F39: =E39 -> 0.027 | G39: =_xlfn.PERCENTILE.INC($B$2:$B$1001,E39) -> 0
A40: -1.4212978 | B40: 0 | E40: 0.028 | F40: =E40 -> 0.028 | G40: =_xlfn.PERCENTILE.INC($B$2:$B$1001,E40) -> 0
...

Sheet efbm_H0.5Mach1_1
A1: eta | B1: PDF | C1: Archivo | D1: H | E1: Mach_real | F1: PDF_tipo | G1: pdf_sigma | H1: pdf_sigma_core | I1: pdf_skewness | J1: pdf_kurtosis | K1: Mach_inferido_PDF
A2: -1.7094962 | B2: 0.005481395 | C2: efbm_H0.5Mach1_1.fits | D2: 0.5 | E2: 1 | F2: B_intermitente | G2: 0.47238073 | H2: 0.25391196 | I2: -0.36060418 | J2: -0.15326012 | K2: 0.64514993
A3: -1.7065772 | B3: 0
A4: -1.7036583 | B4: 0
A5: -1.7007393 | B5: 0
A6: -1.6978204 | B6: 0 | E6: CUARTILES | I6: P50%
A7: -1.6949014 | B7: 0 | E7: 1 | F7: 0.25 | G7: =_xlfn.QUARTILE.INC($B$2:$B$1001,E7) -> 0.060295345 | I7: =G9-G7 -> 0.53717671
A8: -1.6919824 | B8: 0.005481395 | E8: 2 | F8: 0.5 | G8: =_xlfn.QUARTILE.INC($B$2:$B$1001,E8) -> 0.27955115
A9: -1.6890635 | B9: 0.005481395 | E9: 3 | F9: 0.75 | G9: =_xlfn.QUARTILE.INC($B$2:$B$1001,E9) -> 0.59747206
A10: -1.6861445 | B10: 0
A11: -1.6832255 | B11: 0
A12: -1.6803066 | B12: 0 | E12: PERCENTILES
A13: -1.6773876 | B13: 0 | E13: 0.001 | F13: =E13 -> 0.001 | G13: =_xlfn.PERCENTILE.INC($B$2:$B$1001,E13) -> 0 | I13: P95
A14: -1.6744686 | B14: 0 | E14: 0.002 | F14: =E14 -> 0.002 | G14: =_xlfn.PERCENTILE.INC($B$2:$B$1001,E14) -> 0 | I14: =G987-G37 -> 0.89346739
A15: -1.6715497 | B15: 0 | E15: 0.003 | F15: =E15 -> 0.003 | G15: =_xlfn.PERCENTILE.INC($B$2:$B$1001,E15) -> 0 | I15: P90
A16: -1.6686307 | B16: 0 | E16: 0.004 | F16: =E16 -> 0.004 | G16: =_xlfn.PERCENTILE.INC($B$2:$B$1001,E16) -> 0 | I16: =G962-G62 -> 0.86057902
A17: -1.6657117 | B17: 0.005481395 | E17: 0.005 | F17: =E17 -> 0.005 | G17: =_xlfn.PERCENTILE.INC($B$2:$B$1001,E17) -> 0 | I17: P85
A18: -1.6627928 | B18: 0 | E18: 0.006 | F18: =E18 -> 0.006 | G18: =_xlfn.PERCENTILE.INC($B$2:$B$1001,E18) -> 0 | I18: =G937-G87 -> 0.81672786
A19: -1.6598738 | B19: 0 | E19: 0.007 | F19: =E19 -> 0.007 | G19: =_xlfn.PERCENTILE.INC($B$2:$B$1001,E19) -> 0 | I19: P80
A20: -1.6569548 | B20: 0.005481395 | E20: 0.008 | F20: =E20 -> 0.008 | G20: =_xlfn.PERCENTILE.INC($B$2:$B$1001,E20) -> 0 | I20: =G912-G112 -> 0.7783581
A21: -1.6540359 | B21: 0.005481395 | E21: 0.009 | F21: =E21 -> 0.009 | G21: =_xlfn.PERCENTILE.INC($B$2:$B$1001,E21) -> 0 | I21: P75
A22: -1.6511169 | B22: 0 | E22: 0.01 | F22: =E22 -> 0.01 | G22: =_xlfn.PERCENTILE.INC($B$2:$B$1001,E22) -> 0 | I22: =G887-G137 -> 0.75095112
A23: -1.6481979 | B23: 0 | E23: 0.011 | F23: =E23 -> 0.011 | G23: =_xlfn.PERCENTILE.INC($B$2:$B$1001,E23) -> 0 | I23: P70
A24: -1.645279 | B24: 0.005481395 | E24: 0.012 | F24: =E24 -> 0.012 | G24: =_xlfn.PERCENTILE.INC($B$2:$B$1001,E24) -> 0 | I24: =G862-G162 -> 0.71806275
A25: -1.64236 | B25: 0 | E25: 0.013 | F25: =E25 -> 0.013 | G25: =_xlfn.PERCENTILE.INC($B$2:$B$1001,E25) -> 0 | I25: P65
A26: -1.6394411 | B26: 0 | E26: 0.014 | F26: =E26 -> 0.014 | G26: =_xlfn.PERCENTILE.INC($B$2:$B$1001,E26) -> 0 | I26: =G837-G187 -> 0.67421159
A27: -1.6365221 | B27: 0.016444185 | E27: 0.015 | F27: =E27 -> 0.015 | G27: =_xlfn.PERCENTILE.INC($B$2:$B$1001,E27) -> 0 | I27: P60
A28: -1.6336031 | B28: 0.016444185 | E28: 0.016 | F28: =E28 -> 0.016 | G28: =_xlfn.PERCENTILE.INC($B$2:$B$1001,E28) -> 0 | I28: =G812-G212 -> 0.62597531
A29: -1.6306842 | B29: 0.016444185 | E29: 0.017 | F29: =E29 -> 0.017 | G29: =_xlfn.PERCENTILE.INC($B$2:$B$1001,E29) -> 0 | I29: P55
A30: -1.6277652 | B30: 0 | E30: 0.018 | F30: =E30 -> 0.018 | G30: =_xlfn.PERCENTILE.INC($B$2:$B$1001,E30) -> 0 | I30: =G787-G237 -> 0.57253171
A31: -1.6248462 | B31: 0.01096279 | E31: 0.019 | F31: =E31 -> 0.019 | G31: =_xlfn.PERCENTILE.INC($B$2:$B$1001,E31) -> 0 | I31: P50
A32: -1.6219273 | B32: 0 | E32: 0.02 | F32: =E32 -> 0.02 | G32: =_xlfn.PERCENTILE.INC($B$2:$B$1001,E32) -> 0 | I32: =G762-G262 -> 0.53717671
A33: -1.6190083 | B33: 0.016444185 | E33: 0.021 | F33: =E33 -> 0.021 | G33: =_xlfn.PERCENTILE.INC($B$2:$B$1001,E33) -> 0
A34: -1.6160893 | B34: 0.005481395 | E34: 0.022 | F34: =E34 -> 0.022 | G34: =_xlfn.PERCENTILE.INC($B$2:$B$1001,E34) -> 0
A35: -1.6131704 | B35: 0.005481395 | E35: 0.023 | F35: =E35 -> 0.023 | G35: =_xlfn.PERCENTILE.INC($B$2:$B$1001,E35) -> 0
A36: -1.6102514 | B36: 0.016444185 | E36: 0.024 | F36: =E36 -> 0.024 | G36: =_xlfn.PERCENTILE.INC($B$2:$B$1001,E36) -> 0
A37: -1.6073324 | B37: 0.005481395 | E37: 0.025 | F37: =E37 -> 0.025 | G37: =_xlfn.PERCENTILE.INC($B$2:$B$1001,E37) -> 0
A38: -1.6044135 | B38: 0.005481395 | E38: 0.026 | F38: =E38 -> 0.026 | G38: =_xlfn.PERCENTILE.INC($B$2:$B$1001,E38) -> 0
A39: -1.6014945 | B39: 0.016444185 | E39: 0.027 | F39: =E39 -> 0.027 | G39: =_xlfn.PERCENTILE.INC($B$2:$B$1001,E39) -> 0
A40: -1.5985755 | B40: 0.01096279 | E40: 0.028 | F40: =E40 -> 0.028 | G40: =_xlfn.PERCENTILE.INC($B$2:$B$1001,E40) -> 0
...

Sheet efbm_H0.5Mach1_2
A1: eta | B1: PDF | C1: Archivo | D1: H | E1: Mach_real | F1: PDF_tipo | G1: pdf_sigma | H1: pdf_sigma_core | I1: pdf_skewness | J1: pdf_kurtosis | K1: Mach_inferido_PDF
A2: -1.5687286 | B2: 0.0056578875 | C2: efbm_H0.5Mach1_2.fits | D2: 0.5 | E2: 1 | F2: A_lognormal | G2: 0.47238073 | H2: 0.2714552 | I2: -0.10198019 | J2: -0.71606429 | K2: 1.25
A3: -1.5659006 | B3: 0
A4: -1.5630727 | B4: 0
A5: -1.5602448 | B5: 0
A6: -1.5574169 | B6: 0 | E6: CUARTILES | I6: P50%
A7: -1.554589 | B7: 0 | E7: 1 | F7: 0.25 | G7: =_xlfn.QUARTILE.INC($B$2:$B$1001,E7) -> 0.0452631 | I7: =G9-G7 -> 0.5884203
A8: -1.5517611 | B8: 0 | E8: 2 | F8: 0.5 | G8: =_xlfn.QUARTILE.INC($B$2:$B$1001,E8) -> 0.3366443
A9: -1.5489332 | B9: 0 | E9: 3 | F9: 0.75 | G9: =_xlfn.QUARTILE.INC($B$2:$B$1001,E9) -> 0.6336834
A10: -1.5461053 | B10: 0
A11: -1.5432774 | B11: 0
A12: -1.5404494 | B12: 0 | E12: PERCENTILES
A13: -1.5376215 | B13: 0 | E13: 0.001 | F13: =E13 -> 0.001 | G13: =_xlfn.PERCENTILE.INC($B$2:$B$1001,E13) -> 0 | I13: P95
A14: -1.5347936 | B14: 0 | E14: 0.002 | F14: =E14 -> 0.002 | G14: =_xlfn.PERCENTILE.INC($B$2:$B$1001,E14) -> 0 | I14: =G987-G37 -> 0.76395626
A15: -1.5319657 | B15: 0 | E15: 0.003 | F15: =E15 -> 0.003 | G15: =_xlfn.PERCENTILE.INC($B$2:$B$1001,E15) -> 0 | I15: P90
A16: -1.5291378 | B16: 0 | E16: 0.004 | F16: =E16 -> 0.004 | G16: =_xlfn.PERCENTILE.INC($B$2:$B$1001,E16) -> 0 | I16: =G962-G62 -> 0.74684115
A17: -1.5263099 | B17: 0 | E17: 0.005 | F17: =E17 -> 0.005 | G17: =_xlfn.PERCENTILE.INC($B$2:$B$1001,E17) -> 0 | I17: P85
A18: -1.523482 | B18: 0 | E18: 0.006 | F18: =E18 -> 0.006 | G18: =_xlfn.PERCENTILE.INC($B$2:$B$1001,E18) -> 0 | I18: =G937-G87 -> 0.7242096
A19: -1.5206541 | B19: 0 | E19: 0.007 | F19: =E19 -> 0.007 | G19: =_xlfn.PERCENTILE.INC($B$2:$B$1001,E19) -> 0 | I19: P80
A20: -1.5178262 | B20: 0.0056578875 | E20: 0.008 | F20: =E20 -> 0.008 | G20: =_xlfn.PERCENTILE.INC($B$2:$B$1001,E20) -> 0 | I20: =G912-G112 -> 0.70723593
A21: -1.5149983 | B21: 0 | E21: 0.009 | F21: =E21 -> 0.009 | G21: =_xlfn.PERCENTILE.INC($B$2:$B$1001,E21) -> 0 | I21: P75
A22: -1.5121703 | B22: 0 | E22: 0.01 | F22: =E22 -> 0.01 | G22: =_xlfn.PERCENTILE.INC($B$2:$B$1001,E22) -> 0 | I22: =G887-G137 -> 0.69026227
A23: -1.5093424 | B23: 0 | E23: 0.011 | F23: =E23 -> 0.011 | G23: =_xlfn.PERCENTILE.INC($B$2:$B$1001,E23) -> 0 | I23: P70
A24: -1.5065145 | B24: 0 | E24: 0.012 | F24: =E24 -> 0.012 | G24: =_xlfn.PERCENTILE.INC($B$2:$B$1001,E24) -> 0 | I24: =G862-G162 -> 0.67328861
A25: -1.5036866 | B25: 0 | E25: 0.013 | F25: =E25 -> 0.013 | G25: =_xlfn.PERCENTILE.INC($B$2:$B$1001,E25) -> 0 | I25: P65
A26: -1.5008587 | B26: 0 | E26: 0.014 | F26: =E26 -> 0.014 | G26: =_xlfn.PERCENTILE.INC($B$2:$B$1001,E26) -> 0 | I26: =G837-G187 -> 0.65631495
A27: -1.4980308 | B27: 0 | E27: 0.015 | F27: =E27 -> 0.015 | G27: =_xlfn.PERCENTILE.INC($B$2:$B$1001,E27) -> 0 | I27: P60
