Workbook

Sheet Summary
B1: SUMMARY
E2: Ajuste: log P(k)=a+b log(k) | L2: AJUSTE
B3: File | C3: H | D3: ℳ | E3: b(β) | F3: a | H3: Relación H=c*β+d | L3: H | M3: β(media) | N3: sigma(β)
B4: =efbm_H0.5Mach1_0!F2 -> efbm_H0.5Mach1_0.fits | C4: =efbm_H0.5Mach1_0!G2 -> 0.5 | D4: =efbm_H0.5Mach1_0!H2 -> 1 | E4: =efbm_H0.5Mach1_0!H6 -> -2.9471601 | F4: =efbm_H0.5Mach1_0!H8 -> 0.82980827 | H4: Cálculo de la pendiente ( c ) | L4: =0.5 -> 0.5 | M4: =AVERAGE(E4:E23) -> -2.9583973 | N4: =_xlfn.STDEV.S(E4:E23) -> 0.15521654
B5: =efbm_H0.5Mach1_1!F2 -> efbm_H0.5Mach1_1.fits | C5: =efbm_H0.5Mach1_1!G2 -> 0.5 | D5: =efbm_H0.5Mach1_1!H2 -> 1 | E5: =efbm_H0.5Mach1_1!H6 -> -3.0158719 | F5: =efbm_H0.5Mach1_1!H8 -> 0.99824225 | H5: =SLOPE(C4:C43,E4:E43) -> -0.41225892 | J5: 0.5 | L5: 1 | M5: =AVERAGE(E24:E43) -> -4.0857485 | N5: =_xlfn.STDEV.S(E24:E43) -> 0.1631749
B6: =efbm_H0.5Mach1_2!F2 -> efbm_H0.5Mach1_2.fits | C6: =efbm_H0.5Mach1_2!G2 -> 0.5 | D6: =efbm_H0.5Mach1_2!H2 -> 1 | E6: =efbm_H0.5Mach1_2!H6 -> -2.8373476 | F6: =efbm_H0.5Mach1_2!H8 -> 0.95884855 | H6: Cálculo de la intersección-y (d)
B7: =efbm_H0.5Mach1_3!F2 -> efbm_H0.5Mach1_3.fits | C7: =efbm_H0.5Mach1_3!G2 -> 0.5 | D7: =efbm_H0.5Mach1_3!H2 -> 1 | E7: =efbm_H0.5Mach1_3!H6 -> -3.1945703 | F7: =efbm_H0.5Mach1_3!H8 -> 0.4080232 | H7: =INTERCEPT(C4:C43,E4:E43) -> -0.70200597 | J7: 1
B8: =efbm_H0.5Mach1_4!F2 -> efbm_H0.5Mach1_4.fits | C8: =efbm_H0.5Mach1_4!G2 -> 0.5 | D8: =efbm_H0.5Mach1_4!H2 -> 1 | E8: =efbm_H0.5Mach1_4!H6 -> -2.8151567 | F8: =efbm_H0.5Mach1_4!H8 -> 1.101531 | H8: R2
B9: =efbm_H0.5Mach1_5!F2 -> efbm_H0.5Mach1_5.fits | C9: =efbm_H0.5Mach1_5!G2 -> 0.5 | D9: =efbm_H0.5Mach1_5!H2 -> 1 | E9: =efbm_H0.5Mach1_5!H6 -> -3.0285212 | F9: =efbm_H0.5Mach1_5!H8 -> 1.1134838 | H9: =CORREL(E4:E43,C4:C43)^2 -> 0.92952121
B10: =efbm_H0.5Mach1_6!$F$2 -> efbm_H0.5Mach1_6.fits | C10: =efbm_H0.5Mach1_6!$G$2 -> 0.5 | D10: =efbm_H0.5Mach1_6!$H$2 -> 1 | E10: =efbm_H0.5Mach1_6!$H$6 -> -2.871939 | F10: =efbm_H0.5Mach1_6!$H$8 -> 0.62879549 | L10: TEORÍA
B11: =efbm_H0.5Mach1_7!$F$2 -> efbm_H0.5Mach1_7.fits | C11: =efbm_H0.5Mach1_7!$G$2 -> 0.5 | D11: =efbm_H0.5Mach1_7!$H$2 -> 1 | E11: =efbm_H0.5Mach1_7!$H$6 -> -3.0532654 | F11: =efbm_H0.5Mach1_7!$H$8 -> 0.37825941 | H11: Relación clásica en 2D: H=(β-2)/2 | L11: H | M11: β | N11: sigma(β)
B12: =efbm_H0.5Mach1_8!$F$2 -> efbm_H0.5Mach1_8.fits | C12: =efbm_H0.5Mach1_8!$G$2 -> 0.5 | D12: =efbm_H0.5Mach1_8!$H$2 -> 1 | E12: =efbm_H0.5Mach1_8!$H$6 -> -3.162452 | F12: =efbm_H0.5Mach1_8!$H$8 -> 0.44038665 | L12: =0.5 -> 0.5 | M12: =-1*(2*L12+2) -> -3 | N12: N/A
B13: =efbm_H0.5Mach1_9!$F$2 -> efbm_H0.5Mach1_9.fits | C13: =efbm_H0.5Mach1_9!$G$2 -> 0.5 | D13: =efbm_H0.5Mach1_9!$H$2 -> 1 | E13: =efbm_H0.5Mach1_9!$H$6 -> -3.1305248 | F13: =efbm_H0.5Mach1_9!$H$8 -> 0.20338343 | L13: 1 | M13: =-1*(2*L13+2) -> -4 | N13: N/A
B14: ='efbm_H0.5Mach2.5_0'!$F$2 -> efbm_H0.5Mach2.5_0.fits | C14: ='efbm_H0.5Mach2.5_0'!$G$2 -> 0.5 | D14: ='efbm_H0.5Mach2.5_0'!$H$2 -> 2.5 | E14: ='efbm_H0.5Mach2.5_0'!$H$6 -> -2.8211349 | F14: ='efbm_H0.5Mach2.5_0'!$H$8 -> 1.858146
B15: ='efbm_H0.5Mach2.5_1'!$F$2 -> efbm_H0.5Mach2.5_1.fits | C15: ='efbm_H0.5Mach2.5_1'!$G$2 -> 0.5 | D15: ='efbm_H0.5Mach2.5_1'!$H$2 -> 2.5 | E15: ='efbm_H0.5Mach2.5_1'!$H$6 -> -2.9063499 | F15: ='efbm_H0.5Mach2.5_1'!$H$8 -> 2.4020524
B16: ='efbm_H0.5Mach2.5_2'!$F$2 -> efbm_H0.5Mach2.5_2.fits | C16: ='efbm_H0.5Mach2.5_2'!$G$2 -> 0.5 | D16: ='efbm_H0.5Mach2.5_2'!$H$2 -> 2.5 | E16: ='efbm_H0.5Mach2.5_2'!$H$6 -> -2.7129278 | F16: ='efbm_H0.5Mach2.5_2'!$H$8 -> 2.0448324
B17: ='efbm_H0.5Mach2.5_3'!$F$2 -> efbm_H0.5Mach2.5_3.fits | C17: ='efbm_H0.5Mach2.5_3'!$G$2 -> 0.5 | D17: ='efbm_H0.5Mach2.5_3'!$H$2 -> 2.5 | E17: ='efbm_H0.5Mach2.5_3'!$H$6 -> -3.1293645 | F17: ='efbm_H0.5Mach2.5_3'!$H$8 -> 1.701481
B18: ='efbm_H0.5Mach2.5_4'!$F$2 -> efbm_H0.5Mach2.5_4.fits | C18: ='efbm_H0.5Mach2.5_4'!$G$2 -> 0.5 | D18: ='efbm_H0.5Mach2.5_4'!$H$2 -> 2.5 | E18: ='efbm_H0.5Mach2.5_4'!$H$6 -> -2.6879519 | F18: ='efbm_H0.5Mach2.5_4'!$H$8 -> 2.1944086
B19: ='efbm_H0.5Mach2.5_5'!$F$2 -> efbm_H0.5Mach2.5_5.fits | C19: ='efbm_H0.5Mach2.5_5'!$G$2 -> 0.5 | D19: ='efbm_H0.5Mach2.5_5'!$H$2 -> 2.5 | E19: ='efbm_H0.5Mach2.5_5'!$H$6 -> -2.9086614 | F19: ='efbm_H0.5Mach2.5_5'!$H$8 -> 2.6058183
B20: ='efbm_H0.5Mach2.5_6'!$F$2 -> efbm_H0.5Mach2.5_6.fits | C20: ='efbm_H0.5Mach2.5_6'!$G$2 -> 0.5 | D20: ='efbm_H0.5Mach2.5_6'!$H$2 -> 2.5 | E20: ='efbm_H0.5Mach2.5_6'!$H$6 -> -2.7520195 | F20: ='efbm_H0.5Mach2.5_6'!$H$8 -> 1.4252042
B21: ='efbm_H0.5Mach2.5_7'!$F$2 -> efbm_H0.5Mach2.5_7.fits | C21: ='efbm_H0.5Mach2.5_7'!$G$2 -> 0.5 | D21: ='efbm_H0.5Mach2.5_7'!$H$2 -> 2.5 | E21: ='efbm_H0.5Mach2.5_7'!$H$6 -> -3.0020506 | F21: ='efbm_H0.5Mach2.5_7'!$H$8 -> 1.3291194
B22: ='efbm_H0.5Mach2.5_8'!$F$2 -> efbm_H0.5Mach2.5_8.fits | C22: ='efbm_H0.5Mach2.5_8'!$G$2 -> 0.5 | D22: ='efbm_H0.5Mach2.5_8'!$H$2 -> 2.5 | E22: ='efbm_H0.5Mach2.5_8'!$H$6 -> -3.12745 | F22: ='efbm_H0.5Mach2.5_8'!$H$8 -> 1.6492681
B23: ='efbm_H0.5Mach2.5_9'!$F$2 -> efbm_H0.5Mach2.5_9.fits | C23: ='efbm_H0.5Mach2.5_9'!$G$2 -> 0.5 | D23: ='efbm_H0.5Mach2.5_9'!$H$2 -> 2.5 | E23: ='efbm_H0.5Mach2.5_9'!$H$6 -> -3.0632255 | F23: ='efbm_H0.5Mach2.5_9'!$H$8 -> 1.0680086
B24: =efbm_H1Mach1_0!$F$2 -> efbm_H1Mach1_0.fits | C24: =efbm_H1Mach1_0!$G$2 -> 1 | D24: =efbm_H1Mach1_0!$H$2 -> 1 | E24: =efbm_H1Mach1_0!$H$6 -> -4.0496526 | F24: =efbm_H1Mach1_0!$H$8 -> -1.6596522
B25: =efbm_H1Mach1_1!$F$2 -> efbm_H1Mach1_1.fits | C25: =efbm_H1Mach1_1!$G$2 -> 1 | D25: =efbm_H1Mach1_1!$H$2 -> 1 | E25: =efbm_H1Mach1_1!$H$6 -> -4.1647314 | F25: =efbm_H1Mach1_1!$H$8 -> -1.5766048
B26: =efbm_H1Mach1_2!$F$2 -> efbm_H1Mach1_2.fits | C26: =efbm_H1Mach1_2!$G$2 -> 1 | D26: =efbm_H1Mach1_2!$H$2 -> 1 | E26: =efbm_H1Mach1_2!$H$6 -> -3.9223328 | F26: =efbm_H1Mach1_2!$H$8 -> -1.4700649
B27: =efbm_H1Mach1_3!$F$2 -> efbm_H1Mach1_3.fits | C27: =efbm_H1Mach1_3!$G$2 -> 1 | D27: =efbm_H1Mach1_3!$H$2 -> 1 | E27: =efbm_H1Mach1_3!$H$6 -> -4.2938221 | F27: =efbm_H1Mach1_3!$H$8 -> -2.0828325
B28: =efbm_H1Mach1_4!$F$2 -> efbm_H1Mach1_4.fits | C28: =efbm_H1Mach1_4!$G$2 -> 1 | D28: =efbm_H1Mach1_4!$H$2 -> 1 | E28: =efbm_H1Mach1_4!$H$6 -> -3.8617214 | F28: =efbm_H1Mach1_4!$H$8 -> -1.2373553
B29: =efbm_H1Mach1_5!$F$2 -> efbm_H1Mach1_5.fits | C29: =efbm_H1Mach1_5!$G$2 -> 1 | D29: =efbm_H1Mach1_5!$H$2 -> 1 | E29: =efbm_H1Mach1_5!$H$6 -> -4.1202031 | F29: =efbm_H1Mach1_5!$H$8 -> -1.2150529
B30: =efbm_H1Mach1_6!$F$2 -> efbm_H1Mach1_6.fits | C30: =efbm_H1Mach1_6!$G$2 -> 1 | D30: =efbm_H1Mach1_6!$H$2 -> 1 | E30: =efbm_H1Mach1_6!$H$6 -> -3.9809275 | F30: =efbm_H1Mach1_6!$H$8 -> -1.9001325
B31: =efbm_H1Mach1_7!$F$2 -> efbm_H1Mach1_7.fits | C31: =efbm_H1Mach1_7!$G$2 -> 1 | D31: =efbm_H1Mach1_7!$H$2 -> 1 | E31: =efbm_H1Mach1_7!$H$6 -> -4.1740381 | F31: =efbm_H1Mach1_7!$H$8 -> -2.1982317
B32: =efbm_H1Mach1_8!$F$2 -> efbm_H1Mach1_8.fits | C32: =efbm_H1Mach1_8!$G$2 -> 1 | D32: =efbm_H1Mach1_8!$H$2 -> 1 | E32: =efbm_H1Mach1_8!$H$6 -> -4.2619512 | F32: =efbm_H1Mach1_8!$H$8 -> -2.0748717
B33: =efbm_H1Mach1_9!$F$2 -> efbm_H1Mach1_9.fits | C33: =efbm_H1Mach1_9!$G$2 -> 1 | D33: =efbm_H1Mach1_9!$H$2 -> 1 | E33: =efbm_H1Mach1_9!$H$6 -> -4.2482849 | F33: =efbm_H1Mach1_9!$H$8 -> -2.3990965
B34: =efbm_H1Mach2.5_0!$F$2 -> efbm_H1Mach2.5_0.fits | C34: =efbm_H1Mach2.5_0!$G$2 -> 1 | D34: =efbm_H1Mach2.5_0!$H$2 -> 2.5 | E34: =efbm_H1Mach2.5_0!$H$6 -> -3.9739102 | F34: =efbm_H1Mach2.5_0!$H$8 -> -0.72433011
B35: =efbm_H1Mach2.5_1!$F$2 -> efbm_H1Mach2.5_1.fits | C35: =efbm_H1Mach2.5_1!$G$2 -> 1 | D35: =efbm_H1Mach2.5_1!$H$2 -> 2.5 | E35: =efbm_H1Mach2.5_1!$H$6 -> -4.1070578 | F35: =efbm_H1Mach2.5_1!$H$8 -> -0.23048261
B36: =efbm_H1Mach2.5_2!$F$2 -> efbm_H1Mach2.5_2.fits | C36: =efbm_H1Mach2.5_2!$G$2 -> 1 | D36: =efbm_H1Mach2.5_2!$H$2 -> 2.5 | E36: =efbm_H1Mach2.5_2!$H$6 -> -3.8568577 | F36: =efbm_H1Mach2.5_2!$H$8 -> -0.51708498
B37: =efbm_H1Mach2.5_3!$F$2 -> efbm_H1Mach2.5_3.fits | C37: =efbm_H1Mach2.5_3!$G$2 -> 1 | D37: =efbm_H1Mach2.5_3!$H$2 -> 2.5 | E37: =efbm_H1Mach2.5_3!$H$6 -> -4.2812994 | F37: =efbm_H1Mach2.5_3!$H$8 -> -0.88702767
B38: =efbm_H1Mach2.5_4!$F$2 -> efbm_H1Mach2.5_4.fits | C38: =efbm_H1Mach2.5_4!$G$2 -> 1 | D38: =efbm_H1Mach2.5_4!$H$2 -> 2.5 | E38: =efbm_H1Mach2.5_4!$H$6 -> -3.7775712 | F38: =efbm_H1Mach2.5_4!$H$8 -> -0.34163564
B39: =efbm_H1Mach2.5_5!$F$2 -> efbm_H1Mach2.5_5.fits | C39: =efbm_H1Mach2.5_5!$G$2 -> 1 | D39: =efbm_H1Mach2.5_5!$H$2 -> 2.5 | E39: =efbm_H1Mach2.5_5!$H$6 -> -4.056622 | F39: =efbm_H1Mach2.5_5!$H$8 -> 0.22289629
B40: =efbm_H1Mach2.5_6!$F$2 -> efbm_H1Mach2.5_6.fits | C40: =efbm_H1Mach2.5_6!$G$2 -> 1 | D40: =efbm_H1Mach2.5_6!$H$2 -> 2.5 | E40: =efbm_H1Mach2.5_6!$H$6 -> -3.8970741 | F40: =efbm_H1Mach2.5_6!$H$8 -> -1.2382004
...

Sheet efbm_H0.5Mach1_0
A1: k | B1: P(k) | C1: log(k) | D1: log(P(k)) | E1: Residuos | F1: Archivo | G1: H | H1: Mach | I1: beta | J1: beta_err | K1: intercept | L1: intercept_err
A2: 0.0041401922 | B2: 54144807 | C2: =LOG(A2) -> -2.3829795 | D2: =LOG(B2) -> 7.7335568 | E2: =D2-$H$8-$H$6*C2 -> -0.11927352 | F2: efbm_H0.5Mach1_0.fits | G2: 0.5 | H2: 1 | I2: -2.9356345 | J2: 0.018553661 | K2: 0.84527635 | L2: 0.16758168
A3: 0.0041601062 | B3: 53644011 | C3: =LOG(A3) -> -2.3808956 | D3: =LOG(B3) -> 7.7295212 | E3: =D3-$H$8-$H$6*C3 -> -0.11716747
A4: 0.0041801159 | B4: 53147846 | C4: =LOG(A4) -> -2.3788117 | D4: =LOG(B4) -> 7.7254857 | E4: =D4-$H$8-$H$6*C4 -> -0.11506142 | H4: Ajuste: log P(k)=a+b log(k) | L4: H | M4: Est.
A5: 0.0042002219 | B5: 52656270 | C5: =LOG(A5) -> -2.3767278 | D5: =LOG(B5) -> 7.7214501 | E5: =D5-$H$8-$H$6*C5 -> -0.11295537 | H5: Pendiente (b) | L5: =G2 -> 0.5 | M5: =(ABS(H6)-2)/2 -> 0.47358004
A6: 0.0042204246 | B6: 52169241 | C6: =LOG(A6) -> -2.3746439 | D6: =LOG(B6) -> 7.7174145 | E6: =D6-$H$8-$H$6*C6 -> -0.11084933 | H6: =SLOPE(D2:D1001,C2:C1001) -> -2.9471601
A7: 0.0042407245 | B7: 51686717 | C7: =LOG(A7) -> -2.3725599 | D7: =LOG(B7) -> 7.7133789 | E7: =D7-$H$8-$H$6*C7 -> -0.10874328 | H7: Intersección eje y (a)
A8: 0.004261122 | B8: 51208655 | C8: =LOG(A8) -> -2.370476 | D8: =LOG(B8) -> 7.7093434 | E8: =D8-$H$8-$H$6*C8 -> -0.10663723 | H8: =INTERCEPT(D2:D1001,C2:C1001) -> 0.82980827
A9: 0.0042816177 | B9: 50735016 | C9: =LOG(A9) -> -2.3683921 | D9: =LOG(B9) -> 7.7053078 | E9: =D9-$H$8-$H$6*C9 -> -0.10453118 | H9: R2
A10: 0.0043022119 | B10: 50265757 | C10: =LOG(A10) -> -2.3663082 | D10: =LOG(B10) -> 7.7012722 | E10: =D10-$H$8-$H$6*C10 -> -0.10242514 | H10: =CORREL(C2:C1001,D2:D1001)^2 -> 0.99115967
A11: 0.0043229052 | B11: 49800838 | C11: =LOG(A11) -> -2.3642243 | D11: =LOG(B11) -> 7.6972367 | E11: =D11-$H$8-$H$6*C11 -> -0.10031909
A12: 0.004343698 | B12: 49340220 | C12: =LOG(A12) -> -2.3621404 | D12: =LOG(B12) -> 7.6932011 | E12: =D12-$H$8-$H$6*C12 -> -0.09821304
A13: 0.0043645908 | B13: 48883861 | C13: =LOG(A13) -> -2.3600565 | D13: =LOG(B13) -> 7.6891655 | E13: =D13-$H$8-$H$6*C13 -> -0.096106992
A14: 0.0043855841 | B14: 48431724 | C14: =LOG(A14) -> -2.3579726 | D14: =LOG(B14) -> 7.6851299 | E14: =D14-$H$8-$H$6*C14 -> -0.094000944
A15: 0.0044066784 | B15: 47983769 | C15: =LOG(A15) -> -2.3558886 | D15: =LOG(B15) -> 7.6810944 | E15: =D15-$H$8-$H$6*C15 -> -0.091894897
A16: 0.0044278741 | B16: 47539957 | C16: =LOG(A16) -> -2.3538047 | D16: =LOG(B16) -> 7.6770588 | E16: =D16-$H$8-$H$6*C16 -> -0.089788849
A17: 0.0044491718 | B17: 47100250 | C17: =LOG(A17) -> -2.3517208 | D17: =LOG(B17) -> 7.6730232 | E17: =D17-$H$8-$H$6*C17 -> -0.087682801
A18: 0.0044705719 | B18: 46664610 | C18: =LOG(A18) -> -2.3496369 | D18: =LOG(B18) -> 7.6689876 | E18: =D18-$H$8-$H$6*C18 -> -0.085576754
A19: 0.004492075 | B19: 46232999 | C19: =LOG(A19) -> -2.347553 | D19: =LOG(B19) -> 7.6649521 | E19: =D19-$H$8-$H$6*C19 -> -0.083470706
A20: 0.0045136815 | B20: 45805380 | C20: =LOG(A20) -> -2.3454691 | D20: =LOG(B20) -> 7.6609165 | E20: =D20-$H$8-$H$6*C20 -> -0.081364658
A21: 0.0045353919 | B21: 45381716 | C21: =LOG(A21) -> -2.3433852 | D21: =LOG(B21) -> 7.6568809 | E21: =D21-$H$8-$H$6*C21 -> -0.07925861
A22: 0.0045572068 | B22: 44961971 | C22: =LOG(A22) -> -2.3413013 | D22: =LOG(B22) -> 7.6528453 | E22: =D22-$H$8-$H$6*C22 -> -0.077152563
... A1001: 0.49985981 | B1001: 46.312188 | C1001: =LOG(A1001) -> -0.30115178 | D1001: =LOG(B1001) -> 1.6656953 | E1001: =D1001-$H$8-$H$6*C1001 -> -0.051655483

Sheet efbm_H0.5Mach1_1
A1: k | B1: P(k) | C1: log(k) | D1: log(P(k)) | E1: Residuos | F1: Archivo | G1: H | H1: Mach | I1: beta | J1: beta_err | K1: intercept | L1: intercept_err
A2: 0.0041401922 | B2: 1.3507748e+08 | C2: =LOG(A2) -> -2.3829795 | D2: =LOG(B2) -> 8.1305829 | E2: =D2-$H$8-$H$6*C2 -> -0.054420157 | F2: efbm_H0.5Mach1_1.fits | G2: 0.5 | H2: 1 | I2: -2.9643987 | J2: 0.017045817 | K2: 1.0673227 | L2: 0.16120686
A3: 0.0041601062 | B3: 1.3450047e+08 | C3: =LOG(A3) -> -2.3808956 | D3: =LOG(B3) -> 8.1287238 | E3: =D3-$H$8-$H$6*C3 -> -0.049994477
A4: 0.0041801159 | B4: 1.3392593e+08 | C4: =LOG(A4) -> -2.3788117 | D4: =LOG(B4) -> 8.1268647 | E4: =D4-$H$8-$H$6*C4 -> -0.045568796 | H4: Ajuste: log P(k)=a+b log(k)
A5: 0.0042002219 | B5: 1.3335385e+08 | C5: =LOG(A5) -> -2.3767278 | D5: =LOG(B5) -> 8.1250055 | E5: =D5-$H$8-$H$6*C5 -> -0.041143116 | H5: Pendiente (b)
A6: 0.0042204246 | B6: 1.327842e+08 | C6: =LOG(A6) -> -2.3746439 | D6: =LOG(B6) -> 8.1231464 | E6: =D6-$H$8-$H$6*C6 -> -0.036717436 | H6: =SLOPE(D2:D1001,C2:C1001) -> -3.0158719
A7: 0.0042407245 | B7: 1.32217e+08 | C7: =LOG(A7) -> -2.3725599 | D7: =LOG(B7) -> 8.1212873 | E7: =D7-$H$8-$H$6*C7 -> -0.032291755 | H7: Intersección eje y (a)
A8: 0.004261122 | B8: 1.3165221e+08 | C8: =LOG(A8) -> -2.370476 | D8: =LOG(B8) -> 8.1194282 | E8: =D8-$H$8-$H$6*C8 -> -0.027866075 | H8: =INTERCEPT(D2:D1001,C2:C1001) -> 0.99824225
A9: 0.0042816177 | B9: 1.3108984e+08 | C9: =LOG(A9) -> -2.3683921 | D9: =LOG(B9) -> 8.117569 | E9: =D9-$H$8-$H$6*C9 -> -0.023440395 | H9: R2
A10: 0.0043022119 | B10: 1.3052987e+08 | C10: =LOG(A10) -> -2.3663082 | D10: =LOG(B10) -> 8.1157099 | E10: =D10-$H$8-$H$6*C10 -> -0.019014714 | H10: =CORREL(C2:C1001,D2:D1001)^2 -> 0.99245346
A11: 0.0043229052 | B11: 1.2997229e+08 | C11: =LOG(A11) -> -2.3642243 | D11: =LOG(B11) -> 8.1138508 | E11: =D11-$H$8-$H$6*C11 -> -0.014589034
A12: 0.004343698 | B12: 1.2941709e+08 | C12: =LOG(A12) -> -2.3621404 | D12: =LOG(B12) -> 8.1119916 | E12: =D12-$H$8-$H$6*C12 -> -0.010163354
A13: 0.0043645908 | B13: 1.2886427e+08 | C13: =LOG(A13) -> -2.3600565 | D13: =LOG(B13) -> 8.1101325 | E13: =D13-$H$8-$H$6*C13 -> -0.0057376734
A14: 0.0043855841 | B14: 1.283138e+08 | C14: =LOG(A14) -> -2.3579726 | D14: =LOG(B14) -> 8.1082734 | E14: =D14-$H$8-$H$6*C14 -> -0.0013119931
A15: 0.0044066784 | B15: 1.2776569e+08 | C15: =LOG(A15) -> -2.3558886 | D15: =LOG(B15) -> 8.1064142 | E15: =D15-$H$8-$H$6*C15 -> 0.0031136872
A16: 0.0044278741 | B16: 1.2721992e+08 | C16: =LOG(A16) -> -2.3538047 | D16: =LOG(B16) -> 8.1045551 | E16: =D16-$H$8-$H$6*C16 -> 0.0075393676
A17: 0.0044491718 | B17: 1.2667648e+08 | C17: =LOG(A17) -> -2.3517208 | D17: =LOG(B17) -> 8.102696 | E17: =D17-$H$8-$H$6*C17 -> 0.011965048
A18: 0.0044705719 | B18: 1.2613536e+08 | C18: =LOG(A18) -> -2.3496369 | D18: =LOG(B18) -> 8.1008369 | E18: =D18-$H$8-$H$6*C18 -> 0.016390728
A19: 0.004492075 | B19: 1.2559655e+08 | C19: =LOG(A19) -> -2.347553 | D19: =LOG(B19) -> 8.0989777 | E19: =D19-$H$8-$H$6*C19 -> 0.020816409
A20: 0.0045136815 | B20: 1.2506005e+08 | C20: =LOG(A20) -> -2.3454691 | D20: =LOG(B20) -> 8.0971186 | E20: =D20-$H$8-$H$6*C20 -> 0.025242089
A21: 0.0045353919 | B21: 1.2452584e+08 | C21: =LOG(A21) -> -2.3433852 | D21: =LOG(B21) -> 8.0952595 | E21: =D21-$H$8-$H$6*C21 -> 0.029667769
A22: 0.0045572068 | B22: 1.239939e+08 | C22: =LOG(A22) -> -2.3413013 | D22: =LOG(B22) -> 8.0934003 | E22: =D22-$H$8-$H$6*C22 -> 0.03409345
... A1001: 0.49985981 | B1001: 84.216393 | C1001: =LOG(A1001) -> -0.30115178 | D1001: =LOG(B1001) -> 1.9253966 | E1001: =D1001-$H$8-$H$6*C1001 -> 0.018919191

Sheet efbm_H0.5Mach1_2
A1: k | B1: P(k) | C1: log(k) | D1: log(P(k)) | E1: Residuos | F1: Archivo | G1: H | H1: Mach | I1: beta | J1: beta_err | K1: intercept | L1: intercept_err
A2: 0.0041401922 | B2: 88494705 | C2: =LOG(A2) -> -2.3829795 | D2: =LOG(B2) -> 7.9469173 | E2: =D2-$H$8-$H$6*C2 -> 0.22672762 | F2: efbm_H0.5Mach1_2.fits | G2: 0.5 | H2: 1 | I2: -2.9607421 | J2: 0.015745287 | K2: 0.79324502 | L2: 0.21834425
A3: 0.0041601062 | B3: 84206687 | C3: =LOG(A3) -> -2.3808956 | D3: =LOG(B3) -> 7.9253466 | E3: =D3-$H$8-$H$6*C3 -> 0.2110697
A4: 0.0041801159 | B4: 80126446 | C4: =LOG(A4) -> -2.3788117 | D4: =LOG(B4) -> 7.9037759 | E4: =D4-$H$8-$H$6*C4 -> 0.19541178 | H4: Ajuste: log P(k)=a+b log(k)
A5: 0.0042002219 | B5: 76243913 | C5: =LOG(A5) -> -2.3767278 | D5: =LOG(B5) -> 7.8822052 | E5: =D5-$H$8-$H$6*C5 -> 0.17975385 | H5: Pendiente (b)
A6: 0.0042204246 | B6: 72549508 | C6: =LOG(A6) -> -2.3746439 | D6: =LOG(B6) -> 7.8606345 | E6: =D6-$H$8-$H$6*C6 -> 0.16409593 | H6: =SLOPE(D2:D1001,C2:C1001) -> -2.8373476
A7: 0.0042407245 | B7: 69034116 | C7: =LOG(A7) -> -2.3725599 | D7: =LOG(B7) -> 7.8390638 | E7: =D7-$H$8-$H$6*C7 -> 0.14843801 | H7: Intersección eje y (a)
A8: 0.004261122 | B8: 65689062 | C8: =LOG(A8) -> -2.370476 | D8: =LOG(B8) -> 7.8174931 | E8: =D8-$H$8-$H$6*C8 -> 0.13278009 | H8: =INTERCEPT(D2:D1001,C2:C1001) -> 0.95884855
A9: 0.0042816177 | B9: 62506094 | C9: =LOG(A9) -> -2.3683921 | D9: =LOG(B9) -> 7.7959224 | E9: =D9-$H$8-$H$6*C9 -> 0.11712216 | H9: R2
A10: 0.0043022119 | B10: 59477356 | C10: =LOG(A10) -> -2.3663082 | D10: =LOG(B10) -> 7.7743517 | E10: =D10-$H$8-$H$6*C10 -> 0.10146424 | H10: =CORREL(C2:C1001,D2:D1001)^2 -> 0.98573409
A11: 0.0043229052 | B11: 56595376 | C11: =LOG(A11) -> -2.3642243 | D11: =LOG(B11) -> 7.7527809 | E11: =D11-$H$8-$H$6*C11 -> 0.085806318
A12: 0.004343698 | B12: 53853043 | C12: =LOG(A12) -> -2.3621404 | D12: =LOG(B12) -> 7.7312102 | E12: =D12-$H$8-$H$6*C12 -> 0.070148396
A13: 0.0043645908 | B13: 51243589 | C13: =LOG(A13) -> -2.3600565 | D13: =LOG(B13) -> 7.7096395 | E13: =D13-$H$8-$H$6*C13 -> 0.054490473
A14: 0.0043855841 | B14: 48760577 | C14: =LOG(A14) -> -2.3579726 | D14: =LOG(B14) -> 7.6880688 | E14: =D14-$H$8-$H$6*C14 -> 0.03883255
A15: 0.0044066784 | B15: 46397879 | C15: =LOG(A15) -> -2.3558886 | D15: =LOG(B15) -> 7.6664981 | E15: =D15-$H$8-$H$6*C15 -> 0.023174627
A16: 0.0044278741 | B16: 44149666 | C16: =LOG(A16) -> -2.3538047 | D16: =LOG(B16) -> 7.6449274 | E16: =D16-$H$8-$H$6*C16 -> 0.0075167047
A17: 0.0044491718 | B17: 42010391 | C17: =LOG(A17) -> -2.3517208 | D17: =LOG(B17) -> 7.6233567 | E17: =D17-$H$8-$H$6*C17 -> -0.0081412181
A18: 0.0044705719 | B18: 39974774 | C18: =LOG(A18) -> -2.3496369 | D18: =LOG(B18) -> 7.601786 | E18: =D18-$H$8-$H$6*C18 -> -0.023799141
A19: 0.004492075 | B19: 38037793 | C19: =LOG(A19) -> -2.347553 | D19: =LOG(B19) -> 7.5802153 | E19: =D19-$H$8-$H$6*C19 -> -0.039457064
A20: 0.0045136815 | B20: 36194669 | C20: =LOG(A20) -> -2.3454691 | D20: =LOG(B20) -> 7.5586446 | E20: =D20-$H$8-$H$6*C20 -> -0.055114986
A21: 0.0045353919 | B21: 34440853 | C21: =LOG(A21) -> -2.3433852 | D21: =LOG(B21) -> 7.5370739 | E21: =D21-$H$8-$H$6*C21 -> -0.070772909
A22: 0.0045572068 | B22: 32772019 | C22: =LOG(A22) -> -2.3413013 | D22: =LOG(B22) -> 7.5155032 | E22: =D22-$H$8-$H$6*C22 -> -0.086430832
... A1001: 0.49985981 | B1001: 31.687499 | C1001: =LOG(A1001) -> -0.30115178 | D1001: =LOG(B1001) -> 1.500888 | E1001: =D1001-$H$8-$H$6*C1001 -> -0.31243287

Sheet efbm_H0.5Mach1_3
A1: k | B1: P(k) | C1: log(k) | D1: log(P(k)) | E1: Residuos | F1: Archivo | G1: H | H1: Mach | I1: beta | J1: beta_err | K1: intercept | L1: intercept_err
A2: 0.0041401922 | B2: 1.9060196e+08 | C2: =LOG(A2) -> -2.3829795 | D2: =LOG(B2) -> 8.2801274 | E2: =D2-$H$8-$H$6*C2 -> 0.25950854 | F2: efbm_H0.5Mach1_3.fits | G2: 0.5 | H2: 1 | I2: -2.9932244 | J2: 0.017679049 | K2: 0.67824271 | L2: 0.21601983
A3: 0.0041601062 | B3: 1.8575517e+08 | C3: =LOG(A3) -> -2.3808956 | D3: =LOG(B3) -> 8.2689409 | E3: =D3-$H$8-$H$6*C3 -> 0.25497929
A4: 0.0041801159 | B4: 1.8103162e+08 | C4: =LOG(A4) -> -2.3788117 | D4: =LOG(B4) -> 8.2577544 | E4: =D4-$H$8-$H$6*C4 -> 0.25045004 | H4: Ajuste: log P(k)=a+b log(k)
A5: 0.0042002219 | B5: 1.764282e+08 | C5: =LOG(A5) -> -2.3767278 | D5: =LOG(B5) -> 8.246568 | E5: =D5-$H$8-$H$6*C5 -> 0.24592079 | H5: Pendiente (b)
A6: 0.0042204246 | B6: 1.7194183e+08 | C6: =LOG(A6) -> -2.3746439 | D6: =LOG(B6) -> 8.2353815 | E6: =D6-$H$8-$H$6*C6 -> 0.24139155 | H6: =SLOPE(D2:D1001,C2:C1001) -> -3.1945703
A7: 0.0042407245 | B7: 1.6756955e+08 | C7: =LOG(A7) -> -2.3725599 | D7: =LOG(B7) -> 8.2241951 | E7: =D7-$H$8-$H$6*C7 -> 0.2368623 | H7: Intersección eje y (a)
A8: 0.004261122 | B8: 1.6330844e+08 | C8: =LOG(A8) -> -2.370476 | D8: =LOG(B8) -> 8.2130086 | E8: =D8-$H$8-$H$6*C8 -> 0.23233305 | H8: =INTERCEPT(D2:D1001,C2:C1001) -> 0.4080232
A9: 0.0042816177 | B9: 1.591557e+08 | C9: =LOG(A9) -> -2.3683921 | D9: =LOG(B9) -> 8.2018222 | E9: =D9-$H$8-$H$6*C9 -> 0.2278038 | H9: R2
A10: 0.0043022119 | B10: 1.5510855e+08 | C10: =LOG(A10) -> -2.3663082 | D10: =LOG(B10) -> 8.1906357 | E10: =D10-$H$8-$H$6*C10 -> 0.22327455 | H10: =CORREL(C2:C1001,D2:D1001)^2 -> 0.99141158
A11: 0.0043229052 | B11: 1.5116432e+08 | C11: =LOG(A11) -> -2.3642243 | D11: =LOG(B11) -> 8.1794493 | E11: =D11-$H$8-$H$6*C11 -> 0.2187453
A12: 0.004343698 | B12: 1.4732038e+08 | C12: =LOG(A12) -> -2.3621404 | D12: =LOG(B12) -> 8.1682628 | E12: =D12-$H$8-$H$6*C12 -> 0.21421605
A13: 0.0043645908 | B13: 1.4357419e+08 | C13: =LOG(A13) -> -2.3600565 | D13: =LOG(B13) -> 8.1570764 | E13: =D13-$H$8-$H$6*C13 -> 0.2096868
A14: 0.0043855841 | B14: 1.3992327e+08 | C14: =LOG(A14) -> -2.3579726 | D14: =LOG(B14) -> 8.1458899 | E14: =D14-$H$8-$H$6*C14 -> 0.20515755
A15: 0.0044066784 | B15: 1.3636518e+08 | C15: =LOG(A15) -> -2.3558886 | D15: =LOG(B15) -> 8.1347035 | E15: =D15-$H$8-$H$6*C15 -> 0.2006283
A16: 0.0044278741 | B16: 1.3289757e+08 | C16: =LOG(A16) -> -2.3538047 | D16: =LOG(B16) -> 8.123517 | E16: =D16-$H$8-$H$6*C16 -> 0.19609905
A17: 0.0044491718 | B17: 1.2951813e+08 | C17: =LOG(A17) -> -2.3517208 | D17: =LOG(B17) -> 8.1123306 | E17: =D17-$H$8-$H$6*C17 -> 0.19156981
A18: 0.0044705719 | B18: 1.2622464e+08 | C18: =LOG(A18) -> -2.3496369 | D18: =LOG(B18) -> 8.1011441 | E18: =D18-$H$8-$H$6*C18 -> 0.18704056
A19: 0.004492075 | B19: 1.2301489e+08 | C19: =LOG(A19) -> -2.347553 | D19: =LOG(B19) -> 8.0899577 | E19: =D19-$H$8-$H$6*C19 -> 0.18251131
A20: 0.0045136815 | B20: 1.1988676e+08 | C20: =LOG(A20) -> -2.3454691 | D20: =LOG(B20) -> 8.0787712 | E20: =D20-$H$8-$H$6*C20 -> 0.17798206
A21: 0.0045353919 | B21: 1.1683818e+08 | C21: =LOG(A21) -> -2.3433852 | D21: =LOG(B21) -> 8.0675848 | E21: =D21-$H$8-$H$6*C21 -> 0.17345281
A22: 0.0045572068 | B22: 1.1386712e+08 | C22: =LOG(A22) -> -2.3413013 | D22: =LOG(B22) -> 8.0563983 | E22: =D22-$H$8-$H$6*C22 -> 0.16892356
... A1001: 0.49985981 | B1001: 26.450444 | C1001: =LOG(A1001) -> -0.30115178 | D1001: =LOG(B1001) -> 1.422433 | E1001: =D1001-$H$8-$H$6*C1001 -> 0.052359209

Sheet efbm_H0.5Mach1_4
A1: k | B1: P(k) | C1: log(k) | D1: log(P(k)) | E1: Residuos | F1: Archivo | G1: H | H1: Mach | I1: beta | J1: beta_err | K1: intercept | L1: intercept_err
A2: 0.0041401922 | B2: 35411496 | C2: =LOG(A2) -> -2.3829795 | D2: =LOG(B2) -> 7.5491443 | E2: =D2-$H$8-$H$6*C2 -> -0.26084745 | F2: efbm_H0.5Mach1_4.fits | G2: 0.5 | H2: 1 | I2: -2.9449439 | J2: 0.02030184 | K2: 0.92734805 | L2: 0.22835505
A3: 0.0041601062 | B3: 35428732 | C3: =LOG(A3) -> -2.3808956 | D3: =LOG(B3) -> 7.5493556 | E3: =D3-$H$8-$H$6*C3 -> -0.25476958
A4: 0.0041801159 | B4: 35445976 | C4: =LOG(A4) -> -2.3788117 | D4: =LOG(B4) -> 7.5495669 | E4: =D4-$H$8-$H$6*C4 -> -0.24869171 | H4: Ajuste: log P(k)=a+b log(k)
A5: 0.0042002219 | B5: 35463229 | C5: =LOG(A5) -> -2.3767278 | D5: =LOG(B5) -> 7.5497783 | E5: =D5-$H$8-$H$6*C5 -> -0.24261384 | H5: Pendiente (b)
A6: 0.0042204246 | B6: 35480490 | C6: =LOG(A6) -> -2.3746439 | D6: =LOG(B6) -> 7.5499896 | E6: =D6-$H$8-$H$6*C6 -> -0.23653597 | H6: =SLOPE(D2:D1001,C2:C1001) -> -2.8151567
A7: 0.0042407245 | B7: 35497759 | C7: =LOG(A7) -> -2.3725599 | D7: =LOG(B7) -> 7.5502009 | E7: =D7-$H$8-$H$6*C7 -> -0.2304581 | H7: Intersección eje y (a)
A8: 0.004261122 | B8: 35515037 | C8: =LOG(A8) -> -2.370476 | D8: =LOG(B8) -> 7.5504123 | E8: =D8-$H$8-$H$6*C8 -> -0.22438023 | H8: =INTERCEPT(D2:D1001,C2:C1001) -> 1.101531
A9: 0.0042816177 | B9: 35532323 | C9: =LOG(A9) -> -2.3683921 | D9: =LOG(B9) -> 7.5506236 | E9: =D9-$H$8-$H$6*C9 -> -0.21830236 | H9: R2
A10: 0.0043022119 | B10: 35549618 | C10: =LOG(A10) -> -2.3663082 | D10: =LOG(B10) -> 7.5508349 | E10: =D10-$H$8-$H$6*C10 -> -0.2122245 | H10: =CORREL(C2:C1001,D2:D1001)^2 -> 0.98419733
A11: 0.0043229052 | B11: 35566921 | C11: =LOG(A11) -> -2.3642243 | D11: =LOG(B11) -> 7.5510463 | E11: =D11-$H$8-$H$6*C11 -> -0.20614663
A12: 0.004343698 | B12: 35584232 | C12: =LOG(A12) -> -2.3621404 | D12: =LOG(B12) -> 7.5512576 | E12: =D12-$H$8-$H$6*C12 -> -0.20006876
A13: 0.0043645908 | B13: 35601552 | C13: =LOG(A13) -> -2.3600565 | D13: =LOG(B13) -> 7.5514689 | E13: =D13-$H$8-$H$6*C13 -> -0.19399089
A14: 0.0043855841 | B14: 35618880 | C14: =LOG(A14) -> -2.3579726 | D14: =LOG(B14) -> 7.5516803 | E14: =D14-$H$8-$H$6*C14 -> -0.18791302
A15: 0.0044066784 | B15: 35636217 | C15: =LOG(A15) -> -2.3558886 | D15: =LOG(B15) -> 7.5518916 | E15: =D15-$H$8-$H$6*C15 -> -0.18183515
A16: 0.0044278741 | B16: 35653562 | C16: =LOG(A16) -> -2.3538047 | D16: =LOG(B16) -> 7.5521029 | E16: =D16-$H$8-$H$6*C16 -> -0.17575728
A17: 0.0044491718 | B17: 35670916 | C17: =LOG(A17) -> -2.3517208 | D17: =LOG(B17) -> 7.5523143 | E17: =D17-$H$8-$H$6*C17 -> -0.16967941
A18: 0.0044705719 | B18: 35688278 | C18: =LOG(A18) -> -2.3496369 | D18: =LOG(B18) -> 7.5525256 | E18: =D18-$H$8-$H$6*C18 -> -0.16360154
A19: 0.004492075 | B19: 35705648 | C19: =LOG(A19) -> -2.347553 | D19: =LOG(B19) -> 7.5527369 | E19: =D19-$H$8-$H$6*C19 -> -0.15752367
A20: 0.0045136815 | B20: 35723027 | C20: =LOG(A20) -> -2.3454691 | D20: =LOG(B20) -> 7.5529483 | E20: =D20-$H$8-$H$6*C20 -> -0.1514458
A21: 0.0045353919 | B21: 35740414 | C21: =LOG(A21) -> -2.3433852 | D21: =LOG(B21) -> 7.5531596 | E21: =D21-$H$8-$H$6*C21 -> -0.14536793
A22: 0.0045572068 | B22: 35757810 | C22: =LOG(A22) -> -2.3413013 | D22: =LOG(B22) -> 7.5533709 | E22: =D22-$H$8-$H$6*C22 -> -0.13929006
... A1001: 0.49985981 | B1001: 84.995744 | C1001: =LOG(A1001) -> -0.30115178 | D1001: =LOG(B1001) -> 1.9293972 | E1001: =D1001-$H$8-$H$6*C1001 -> -0.019923289

Sheet efbm_H0.5Mach1_5
A1: k | B1: P(k) | C1: log(k) | D1: log(P(k)) | E1: Residuos | F1: Archivo | G1: H | H1: Mach | I1: beta | J1: beta_err | K1: intercept | L1: intercept_err
A2: 0.0041401922 | B2: 87293787 | C2: =LOG(A2) -> -2.3829795 | D2: =LOG(B2) -> 7.9409833 | E2: =D2-$H$8-$H$6*C2 -> -0.38940439 | F2: efbm_H0.5Mach1_5.fits | G2: 0.5 | H2: 1 | I2: -3.0014579 | J2: 0.016474653 | K2: 1.1498045 | L2: 0.153808
A3: 0.0041601062 | B3: 87204636 | C3: =LOG(A3) -> -2.3808956 | D3: =LOG(B3) -> 7.9405396 | E3: =D3-$H$8-$H$6*C3 -> -0.38353697
A4: 0.0041801159 | B4: 87115577 | C4: =LOG(A4) -> -2.3788117 | D4: =LOG(B4) -> 7.9400958 | E4: =D4-$H$8-$H$6*C4 -> -0.37766956 | H4: Ajuste: log P(k)=a+b log(k)
A5: 0.0042002219 | B5: 87026608 | C5: =LOG(A5) -> -2.3767278 | D5: =LOG(B5) -> 7.9396521 | E5: =D5-$H$8-$H$6*C5 -> -0.37180215 | H5: Pendiente (b)
A6: 0.0042204246 | B6: 86937730 | C6: =LOG(A6) -> -2.3746439 | D6: =LOG(B6) -> 7.9392083 | E6: =D6-$H$8-$H$6*C6 -> -0.36593474 | H6: =SLOPE(D2:D1001,C2:C1001) -> -3.0285212
A7: 0.0042407245 | B7: 86848943 | C7: =LOG(A7) -> -2.3725599 | D7: =LOG(B7) -> 7.9387645 | E7: =D7-$H$8-$H$6*C7 -> -0.36006733 | H7: Intersección eje y (a)
A8: 0.004261122 | B8: 86760247 | C8: =LOG(A8) -> -2.370476 | D8: =LOG(B8) -> 7.9383208 | E8: =D8-$H$8-$H$6*C8 -> -0.35419992 | H8: =INTERCEPT(D2:D1001,C2:C1001) -> 1.1134838
A9: 0.0042816177 | B9: 86671641 | C9: =LOG(A9) -> -2.3683921 | D9: =LOG(B9) -> 7.937877 | E9: =D9-$H$8-$H$6*C9 -> -0.34833251 | H9: R2
A10: 0.0043022119 | B10: 86583126 | C10: =LOG(A10) -> -2.3663082 | D10: =LOG(B10) -> 7.9374333 | E10: =D10-$H$8-$H$6*C10 -> -0.34246509 | H10: =CORREL(C2:C1001,D2:D1001)^2 -> 0.99300196
A11: 0.0043229052 | B11: 86494701 | C11: =LOG(A11) -> -2.3642243 | D11: =LOG(B11) -> 7.9369895 | E11: =D11-$H$8-$H$6*C11 -> -0.33659768
A12: 0.004343698 | B12: 86406367 | C12: =LOG(A12) -> -2.3621404 | D12: =LOG(B12) -> 7.9365457 | E12: =D12-$H$8-$H$6*C12 -> -0.33073027
A13: 0.0043645908 | B13: 86318122 | C13: =LOG(A13) -> -2.3600565 | D13: =LOG(B13) -> 7.936102 | E13: =D13-$H$8-$H$6*C13 -> -0.32486286
A14: 0.0043855841 | B14: 86229968 | C14: =LOG(A14) -> -2.3579726 | D14: =LOG(B14) -> 7.9356582 | E14: =D14-$H$8-$H$6*C14 -> -0.31899545
A15: 0.0044066784 | B15: 86141904 | C15: =LOG(A15) -> -2.3558886 | D15: =LOG(B15) -> 7.9352145 | E15: =D15-$H$8-$H$6*C15 -> -0.31312804
A16: 0.0044278741 | B16: 86053930 | C16: =LOG(A16) -> -2.3538047 | D16: =LOG(B16) -> 7.9347707 | E16: =D16-$H$8-$H$6*C16 -> -0.30726063
A17: 0.0044491718 | B17: 85966045 | C17: =LOG(A17) -> -2.3517208 | D17: =LOG(B17) -> 7.9343269 | E17: =D17-$H$8-$H$6*C17 -> -0.30139321
A18: 0.0044705719 | B18: 85878251 | C18: =LOG(A18) -> -2.3496369 | D18: =LOG(B18) -> 7.9338832 | E18: =D18-$H$8-$H$6*C18 -> -0.2955258
A19: 0.004492075 | B19: 85790546 | C19: =LOG(A19) -> -2.347553 | D19: =LOG(B19) -> 7.9334394 | E19: =D19-$H$8-$H$6*C19 -> -0.28965839
A20: 0.0045136815 | B20: 85702930 | C20: =LOG(A20) -> -2.3454691 | D20: =LOG(B20) -> 7.9329957 | E20: =D20-$H$8-$H$6*C20 -> -0.28379098
A21: 0.0045353919 | B21: 85615404 | C21: =LOG(A21) -> -2.3433852 | D21: =LOG(B21) -> 7.9325519 | E21: =D21-$H$8-$H$6*C21 -> -0.27792357
A22: 0.0045572068 | B22: 85527968 | C22: =LOG(A22) -> -2.3413013 | D22: =LOG(B22) -> 7.9321082 | E22: =D22-$H$8-$H$6*C22 -> -0.27205616
... A1001: 0.49985981 | B1001: 170.99754 | C1001: =LOG(A1001) -> -0.30115178 | D1001: =LOG(B1001) -> 2.2329899 | E1001: =D1001-$H$8-$H$6*C1001 -> 0.20746147

Sheet efbm_H0.5Mach1_6
A1: k | B1: P(k) | C1: log(k) | D1: log(P(k)) | E1: Residuos | F1: Archivo | G1: H | H1: Mach | I1: beta | J1: beta_err | K1: intercept | L1: intercept_err
A2: 0.0041401922 | B2: 55902444 | C2: =LOG(A2) -> -2.3829795 | D2: =LOG(B2) -> 7.7474308 | E2: =D2-$H$8-$H$6*C2 -> 0.27486356 | F2: efbm_H0.5Mach1_6.fits | G2: 0.5 | H2: 1 | I2: -2.8967884 | J2: 0.017491058 | K2: 0.5954459 | L2: 0.17000046
A3: 0.0041601062 | B3: 53744664 | C3: =LOG(A3) -> -2.3808956 | D3: =LOG(B3) -> 7.7303354 | E3: =D3-$H$8-$H$6*C3 -> 0.26375299
A4: 0.0041801159 | B4: 51670173 | C4: =LOG(A4) -> -2.3788117 | D4: =LOG(B4) -> 7.7132399 | E4: =D4-$H$8-$H$6*C4 -> 0.25264242 | H4: Ajuste: log P(k)=a+b log(k)
A5: 0.0042002219 | B5: 49675755 | C5: =LOG(A5) -> -2.3767278 | D5: =LOG(B5) -> 7.6961445 | E5: =D5-$H$8-$H$6*C5 -> 0.24153184 | H5: Pendiente (b)
A6: 0.0042204246 | B6: 47758320 | C6: =LOG(A6) -> -2.3746439 | D6: =LOG(B6) -> 7.679049 | E6: =D6-$H$8-$H$6*C6 -> 0.23042127 | H6: =SLOPE(D2:D1001,C2:C1001) -> -2.871939
A7: 0.0042407245 | B7: 45914895 | C7: =LOG(A7) -> -2.3725599 | D7: =LOG(B7) -> 7.6619536 | E7: =D7-$H$8-$H$6*C7 -> 0.2193107 | H7: Intersección eje y (a)
A8: 0.004261122 | B8: 44142625 | C8: =LOG(A8) -> -2.370476 | D8: =LOG(B8) -> 7.6448582 | E8: =D8-$H$8-$H$6*C8 -> 0.20820013 | H8: =INTERCEPT(D2:D1001,C2:C1001) -> 0.62879549
A9: 0.0042816177 | B9: 42438763 | C9: =LOG(A9) -> -2.3683921 | D9: =LOG(B9) -> 7.6277627 | E9: =D9-$H$8-$H$6*C9 -> 0.19708956 | H9: R2
A10: 0.0043022119 | B10: 40800669 | C10: =LOG(A10) -> -2.3663082 | D10: =LOG(B10) -> 7.6106673 | E10: =D10-$H$8-$H$6*C10 -> 0.18597898 | H10: =CORREL(C2:C1001,D2:D1001)^2 -> 0.99048411
A11: 0.0043229052 | B11: 39225803 | C11: =LOG(A11) -> -2.3642243 | D11: =LOG(B11) -> 7.5935718 | E11: =D11-$H$8-$H$6*C11 -> 0.17486841
A12: 0.004343698 | B12: 37711726 | C12: =LOG(A12) -> -2.3621404 | D12: =LOG(B12) -> 7.5764764 | E12: =D12-$H$8-$H$6*C12 -> 0.16375784
A13: 0.0043645908 | B13: 36256090 | C13: =LOG(A13) -> -2.3600565 | D13: =LOG(B13) -> 7.559381 | E13: =D13-$H$8-$H$6*C13 -> 0.15264727
A14: 0.0043855841 | B14: 34856640 | C14: =LOG(A14) -> -2.3579726 | D14: =LOG(B14) -> 7.5422855 | E14: =D14-$H$8-$H$6*C14 -> 0.1415367
A15: 0.0044066784 | B15: 33511208 | C15: =LOG(A15) -> -2.3558886 | D15: =LOG(B15) -> 7.5251901 | E15: =D15-$H$8-$H$6*C15 -> 0.13042613
A16: 0.0044278741 | B16: 32217709 | C16: =LOG(A16) -> -2.3538047 | D16: =LOG(B16) -> 7.5080946 | E16: =D16-$H$8-$H$6*C16 -> 0.11931555
A17: 0.0044491718 | B17: 30974137 | C17: =LOG(A17) -> -2.3517208 | D17: =LOG(B17) -> 7.4909992 | E17: =D17-$H$8-$H$6*C17 -> 0.10820498
A18: 0.0044705719 | B18: 29778565 | C18: =LOG(A18) -> -2.3496369 | D18: =LOG(B18) -> 7.4739038 | E18: =D18-$H$8-$H$6*C18 -> 0.097094409
A19: 0.004492075 | B19: 28629142 | C19: =LOG(A19) -> -2.347553 | D19: =LOG(B19) -> 7.4568083 | E19: =D19-$H$8-$H$6*C19 -> 0.085983838
A20: 0.0045136815 | B20: 27524085 | C20: =LOG(A20) -> -2.3454691 | D20: =LOG(B20) -> 7.4397129 | E20: =D20-$H$8-$H$6*C20 -> 0.074873266
A21: 0.0045353919 | B21: 26461682 | C21: =LOG(A21) -> -2.3433852 | D21: =LOG(B21) -> 7.4226175 | E21: =D21-$H$8-$H$6*C21 -> 0.063762694
A22: 0.0045572068 | B22: 25440288 | C22: =LOG(A22) -> -2.3413013 | D22: =LOG(B22) -> 7.405522 | E22: =D22-$H$8-$H$6*C22 -> 0.052652122
... A1001: 0.49985981 | B1001: 31.766367 | C1001: =LOG(A1001) -> -0.30115178 | D1001: =LOG(B1001) -> 1.5019675 | E1001: =D1001-$H$8-$H$6*C1001 -> 0.0082825046

Sheet efbm_H0.5Mach1_7
A1: k | B1: P(k) | C1: log(k) | D1: log(P(k)) | E1: Residuos | F1: Archivo | G1: H | H1: Mach | I1: beta | J1: beta_err | K1: intercept | L1: intercept_err
A2: 0.0041401922 | B2: 88300413 | C2: =LOG(A2) -> -2.3829795 | D2: =LOG(B2) -> 7.9459627 | E2: =D2-$H$8-$H$6*C2 -> 0.29183448 | F2: efbm_H0.5Mach1_7.fits | G2: 0.5 | H2: 1 | I2: -2.9693994 | J2: 0.016961234 | K2: 0.49081303 | L2: 0.16961988
A3: 0.0041601062 | B3: 86775167 | C3: =LOG(A3) -> -2.3808956 | D3: =LOG(B3) -> 7.9383955 | E3: =D3-$H$8-$H$6*C3 -> 0.29062994
A4: 0.0041801159 | B4: 85276267 | C4: =LOG(A4) -> -2.3788117 | D4: =LOG(B4) -> 7.9308282 | E4: =D4-$H$8-$H$6*C4 -> 0.2894254 | H4: Ajuste: log P(k)=a+b log(k)
A5: 0.0042002219 | B5: 83803258 | C5: =LOG(A5) -> -2.3767278 | D5: =LOG(B5) -> 7.9232609 | E5: =D5-$H$8-$H$6*C5 -> 0.28822086 | H5: Pendiente (b)
A6: 0.0042204246 | B6: 82355694 | C6: =LOG(A6) -> -2.3746439 | D6: =LOG(B6) -> 7.9156936 | E6: =D6-$H$8-$H$6*C6 -> 0.28701632 | H6: =SLOPE(D2:D1001,C2:C1001) -> -3.0532654
A7: 0.0042407245 | B7: 80933133 | C7: =LOG(A7) -> -2.3725599 | D7: =LOG(B7) -> 7.9081264 | E7: =D7-$H$8-$H$6*C7 -> 0.28581178 | H7: Intersección eje y (a)
A8: 0.004261122 | B8: 79535145 | C8: =LOG(A8) -> -2.370476 | D8: =LOG(B8) -> 7.9005591 | E8: =D8-$H$8-$H$6*C8 -> 0.28460724 | H8: =INTERCEPT(D2:D1001,C2:C1001) -> 0.37825941
A9: 0.0042816177 | B9: 78161305 | C9: =LOG(A9) -> -2.3683921 | D9: =LOG(B9) -> 7.8929918 | E9: =D9-$H$8-$H$6*C9 -> 0.2834027 | H9: R2
A10: 0.0043022119 | B10: 76811195 | C10: =LOG(A10) -> -2.3663082 | D10: =LOG(B10) -> 7.8854245 | E10: =D10-$H$8-$H$6*C10 -> 0.28219816 | H10: =CORREL(C2:C1001,D2:D1001)^2 -> 0.99228643
A11: 0.0043229052 | B11: 75484407 | C11: =LOG(A11) -> -2.3642243 | D11: =LOG(B11) -> 7.8778572 | E11: =D11-$H$8-$H$6*C11 -> 0.28099361
A12: 0.004343698 | B12: 74180537 | C12: =LOG(A12) -> -2.3621404 | D12: =LOG(B12) -> 7.87029 | E12: =D12-$H$8-$H$6*C12 -> 0.27978907
A13: 0.0043645908 | B13: 72899189 | C13: =LOG(A13) -> -2.3600565 | D13: =LOG(B13) -> 7.8627227 | E13: =D13-$H$8-$H$6*C13 -> 0.27858453
A14: 0.0043855841 | B14: 71639974 | C14: =LOG(A14) -> -2.3579726 | D14: =LOG(B14) -> 7.8551554 | E14: =D14-$H$8-$H$6*C14 -> 0.27737999
A15: 0.0044066784 | B15: 70402510 | C15: =LOG(A15) -> -2.3558886 | D15: =LOG(B15) -> 7.8475881 | E15: =D15-$H$8-$H$6*C15 -> 0.27617545
A16: 0.0044278741 | B16: 69186421 | C16: =LOG(A16) -> -2.3538047 | D16: =LOG(B16) -> 7.8400209 | E16: =D16-$H$8-$H$6*C16 -> 0.27497091
A17: 0.0044491718 | B17: 67991339 | C17: =LOG(A17) -> -2.3517208 | D17: =LOG(B17) -> 7.8324536 | E17: =D17-$H$8-$H$6*C17 -> 0.27376637
A18: 0.0044705719 | B18: 66816899 | C18: =LOG(A18) -> -2.3496369 | D18: =LOG(B18) -> 7.8248863 | E18: =D18-$H$8-$H$6*C18 -> 0.27256183
A19: 0.004492075 | B19: 65662746 | C19: =LOG(A19) -> -2.347553 | D19: =LOG(B19) -> 7.817319 | E19: =D19-$H$8-$H$6*C19 -> 0.27135729
A20: 0.0045136815 | B20: 64528529 | C20: =LOG(A20) -> -2.3454691 | D20: =LOG(B20) -> 7.8097518 | E20: =D20-$H$8-$H$6*C20 -> 0.27015275
A21: 0.0045353919 | B21: 63413903 | C21: =LOG(A21) -> -2.3433852 | D21: =LOG(B21) -> 7.8021845 | E21: =D21-$H$8-$H$6*C21 -> 0.26894821
A22: 0.0045572068 | B22: 62318531 | C22: =LOG(A22) -> -2.3413013 | D22: =LOG(B22) -> 7.7946172 | E22: =D22-$H$8-$H$6*C22 -> 0.26774366
... A1001: 0.49985981 | B1001: 22.411211 | C1001: =LOG(A1001) -> -0.30115178 | D1001: =LOG(B1001) -> 1.3504653 | E1001: =D1001-$H$8-$H$6*C1001 -> 0.052709596

Sheet efbm_H0.5Mach1_8
A1: k | B1: P(k) | C1: log(k) | D1: log(P(k)) | E1: Residuos | F1: Archivo | G1: H | H1: Mach | I1: beta | J1: beta_err | K1: intercept | L1: intercept_err
A2: 0.0041401922 | B2: 85973995 | C2: =LOG(A2) -> -2.3829795 | D2: =LOG(B2) -> 7.9343671 | E2: =D2-$H$8-$H$6*C2 -> -0.042077933 | F2: efbm_H0.5Mach1_8.fits | G2: 0.5 | H2: 1 | I2: -2.9600783 | J2: 0.018723808 | K2: 0.71198553 | L2: 0.24413229
A3: 0.0041601062 | B3: 86135750 | C3: =LOG(A3) -> -2.3808956 | D3: =LOG(B3) -> 7.9351834 | E3: =D3-$H$8-$H$6*C3 -> -0.034671333
A4: 0.0041801159 | B4: 86297809 | C4: =LOG(A4) -> -2.3788117 | D4: =LOG(B4) -> 7.9359998 | E4: =D4-$H$8-$H$6*C4 -> -0.027264733 | H4: Ajuste: log P(k)=a+b log(k)
A5: 0.0042002219 | B5: 86460173 | C5: =LOG(A5) -> -2.3767278 | D5: =LOG(B5) -> 7.9368161 | E5: =D5-$H$8-$H$6*C5 -> -0.019858132 | H5: Pendiente (b)
A6: 0.0042204246 | B6: 86622842 | C6: =LOG(A6) -> -2.3746439 | D6: =LOG(B6) -> 7.9376324 | E6: =D6-$H$8-$H$6*C6 -> -0.012451532 | H6: =SLOPE(D2:D1001,C2:C1001) -> -3.162452
A7: 0.0042407245 | B7: 86785817 | C7: =LOG(A7) -> -2.3725599 | D7: =LOG(B7) -> 7.9384488 | E7: =D7-$H$8-$H$6*C7 -> -0.0050449319 | H7: Intersección eje y (a)
A8: 0.004261122 | B8: 86949099 | C8: =LOG(A8) -> -2.370476 | D8: =LOG(B8) -> 7.9392651 | E8: =D8-$H$8-$H$6*C8 -> 0.0023616683 | H8: =INTERCEPT(D2:D1001,C2:C1001) -> 0.44038665
A9: 0.0042816177 | B9: 87112689 | C9: =LOG(A9) -> -2.3683921 | D9: =LOG(B9) -> 7.9400814 | E9: =D9-$H$8-$H$6*C9 -> 0.0097682685 | H9: R2
A10: 0.0043022119 | B10: 87276585 | C10: =LOG(A10) -> -2.3663082 | D10: =LOG(B10) -> 7.9408977 | E10: =D10-$H$8-$H$6*C10 -> 0.017174869 | H10: =CORREL(C2:C1001,D2:D1001)^2 -> 0.98777884
A11: 0.0043229052 | B11: 87440791 | C11: =LOG(A11) -> -2.3642243 | D11: =LOG(B11) -> 7.9417141 | E11: =D11-$H$8-$H$6*C11 -> 0.024581469
A12: 0.004343698 | B12: 87605305 | C12: =LOG(A12) -> -2.3621404 | D12: =LOG(B12) -> 7.9425304 | E12: =D12-$H$8-$H$6*C12 -> 0.031988069
A13: 0.0043645908 | B13: 87770129 | C13: =LOG(A13) -> -2.3600565 | D13: =LOG(B13) -> 7.9433467 | E13: =D13-$H$8-$H$6*C13 -> 0.039394669
A14: 0.0043855841 | B14: 87935263 | C14: =LOG(A14) -> -2.3579726 | D14: =LOG(B14) -> 7.9441631 | E14: =D14-$H$8-$H$6*C14 -> 0.04680127
A15: 0.0044066784 | B15: 88100707 | C15: =LOG(A15) -> -2.3558886 | D15: =LOG(B15) -> 7.9449794 | E15: =D15-$H$8-$H$6*C15 -> 0.05420787
A16: 0.0044278741 | B16: 88266463 | C16: =LOG(A16) -> -2.3538047 | D16: =LOG(B16) -> 7.9457957 | E16: =D16-$H$8-$H$6*C16 -> 0.06161447
A17: 0.0044491718 | B17: 88432531 | C17: =LOG(A17) -> -2.3517208 | D17: =LOG(B17) -> 7.9466121 | E17: =D17-$H$8-$H$6*C17 -> 0.06902107
A18: 0.0044705719 | B18: 88598911 | C18: =LOG(A18) -> -2.3496369 | D18: =LOG(B18) -> 7.9474284 | E18: =D18-$H$8-$H$6*C18 -> 0.07642767
A19: 0.004492075 | B19: 88765604 | C19: =LOG(A19) -> -2.347553 | D19: =LOG(B19) -> 7.9482447 | E19: =D19-$H$8-$H$6*C19 -> 0.083834271
A20: 0.0045136815 | B20: 88932611 | C20: =LOG(A20) -> -2.3454691 | D20: =LOG(B20) -> 7.949061 | E20: =D20-$H$8-$H$6*C20 -> 0.091240871
A21: 0.0045353919 | B21: 89099932 | C21: =LOG(A21) -> -2.3433852 | D21: =LOG(B21) -> 7.9498774 | E21: =D21-$H$8-$H$6*C21 -> 0.098647471
A22: 0.0045572068 | B22: 89267568 | C22: =LOG(A22) -> -2.3413013 | D22: =LOG(B22) -> 7.9506937 | E22: =D22-$H$8-$H$6*C22 -> 0.10605407
... A1001: 0.49985981 | B1001: 20.833902 | C1001: =LOG(A1001) -> -0.30115178 | D1001: =LOG(B1001) -> 1.3187706 | E1001: =D1001-$H$8-$H$6*C1001 -> -0.07399411

Sheet efbm_H0.5Mach1_9
A1: k | B1: P(k) | C1: log(k) | D1: log(P(k)) | E1: Residuos | F1: Archivo | G1: H | H1: Mach | I1: beta | J1: beta_err | K1: intercept | L1: intercept_err
A2: 0.0041401922 | B2: 54805852 | C2: =LOG(A2) -> -2.3829795 | D2: =LOG(B2) -> 7.7388269 | E2: =D2-$H$8-$H$6*C2 -> 0.075467043 | F2: efbm_H0.5Mach1_9.fits | G2: 0.5 | H2: 1 | I2: -2.9688803 | J2: 0.017073641 | K2: 0.42032099 | L2: 0.20040143
A3: 0.0041601062 | B3: 54682520 | C3: =LOG(A3) -> -2.3808956 | D3: =LOG(B3) -> 7.7378485 | E3: =D3-$H$8-$H$6*C3 -> 0.08101237
A4: 0.0041801159 | B4: 54559466 | C4: =LOG(A4) -> -2.3788117 | D4: =LOG(B4) -> 7.7368701 | E4: =D4-$H$8-$H$6*C4 -> 0.086557697 | H4: Ajuste: log P(k)=a+b log(k)
A5: 0.0042002219 | B5: 54436689 | C5: =LOG(A5) -> -2.3767278 | D5: =LOG(B5) -> 7.7358917 | E5: =D5-$H$8-$H$6*C5 -> 0.092103023 | H5: Pendiente (b)
A6: 0.0042204246 | B6: 54314188 | C6: =LOG(A6) -> -2.3746439 | D6: =LOG(B6) -> 7.7349133 | E6: =D6-$H$8-$H$6*C6 -> 0.09764835 | H6: =SLOPE(D2:D1001,C2:C1001) -> -3.1305248
A7: 0.0042407245 | B7: 54191963 | C7: =LOG(A7) -> -2.3725599 | D7: =LOG(B7) -> 7.7339349 | E7: =D7-$H$8-$H$6*C7 -> 0.10319368 | H7: Intersección eje y (a)
A8: 0.004261122 | B8: 54070012 | C8: =LOG(A8) -> -2.370476 | D8: =LOG(B8) -> 7.7329565 | E8: =D8-$H$8-$H$6*C8 -> 0.108739 | H8: =INTERCEPT(D2:D1001,C2:C1001) -> 0.20338343
A9: 0.0042816177 | B9: 53948337 | C9: =LOG(A9) -> -2.3683921 | D9: =LOG(B9) -> 7.7319781 | E9: =D9-$H$8-$H$6*C9 -> 0.11428433 | H9: R2
A10: 0.0043022119 | B10: 53826935 | C10: =LOG(A10) -> -2.3663082 | D10: =LOG(B10) -> 7.7309996 | E10: =D10-$H$8-$H$6*C10 -> 0.11982966 | H10: =CORREL(C2:C1001,D2:D1001)^2 -> 0.99141673
A11: 0.0043229052 | B11: 53705806 | C11: =LOG(A11) -> -2.3642243 | D11: =LOG(B11) -> 7.7300212 | E11: =D11-$H$8-$H$6*C11 -> 0.12537498
A12: 0.004343698 | B12: 53584950 | C12: =LOG(A12) -> -2.3621404 | D12: =LOG(B12) -> 7.7290428 | E12: =D12-$H$8-$H$6*C12 -> 0.13092031
A13: 0.0043645908 | B13: 53464366 | C13: =LOG(A13) -> -2.3600565 | D13: =LOG(B13) -> 7.7280644 | E13: =D13-$H$8-$H$6*C13 -> 0.13646564
A14: 0.0043855841 | B14: 53344053 | C14: =LOG(A14) -> -2.3579726 | D14: =LOG(B14) -> 7.727086 | E14: =D14-$H$8-$H$6*C14 -> 0.14201096
A15: 0.0044066784 | B15: 53224011 | C15: =LOG(A15) -> -2.3558886 | D15: =LOG(B15) -> 7.7261076 | E15: =D15-$H$8-$H$6*C15 -> 0.14755629
A16: 0.0044278741 | B16: 53104239 | C16: =LOG(A16) -> -2.3538047 | D16: =LOG(B16) -> 7.7251292 | E16: =D16-$H$8-$H$6*C16 -> 0.15310162
A17: 0.0044491718 | B17: 52984736 | C17: =LOG(A17) -> -2.3517208 | D17: =LOG(B17) -> 7.7241508 | E17: =D17-$H$8-$H$6*C17 -> 0.15864694
A18: 0.0044705719 | B18: 52865503 | C18: =LOG(A18) -> -2.3496369 | D18: =LOG(B18) -> 7.7231724 | E18: =D18-$H$8-$H$6*C18 -> 0.16419227
A19: 0.004492075 | B19: 52746537 | C19: =LOG(A19) -> -2.347553 | D19: =LOG(B19) -> 7.722194 | E19: =D19-$H$8-$H$6*C19 -> 0.1697376
A20: 0.0045136815 | B20: 52627840 | C20: =LOG(A20) -> -2.3454691 | D20: =LOG(B20) -> 7.7212155 | E20: =D20-$H$8-$H$6*C20 -> 0.17528292
A21: 0.0045353919 | B21: 52509410 | C21: =LOG(A21) -> -2.3433852 | D21: =LOG(B21) -> 7.7202371 | E21: =D21-$H$8-$H$6*C21 -> 0.18082825
A22: 0.0045572068 | B22: 52391246 | C22: =LOG(A22) -> -2.3413013 | D22: =LOG(B22) -> 7.7192587 | E22: =D22-$H$8-$H$6*C22 -> 0.18637358
... A1001: 0.49985981 | B1001: 20.091775 | C1001: =LOG(A1001) -> -0.30115178 | D1001: =LOG(B1001) -> 1.3030183 | E1001: =D1001-$H$8-$H$6*C1001 -> 0.15687174

Sheet efbm_H0.5Mach2.5_0
A1: k | B1: P(k) | C1: log(k) | D1: log(P(k)) | E1: Residuos | F1: Archivo | G1: H | H1: Mach | I1: beta | J1: beta_err | K1: intercept | L1: intercept_err
A2: 0.0041401922 | B2: 2.5291809e+08 | C2: =LOG(A2) -> -2.3829795 | D2: =LOG(B2) -> 8.4029799 | E2: =D2-$H$8-$H$6*C2 -> -0.1778727 | F2: efbm_H0.5Mach2.5_0.fits | G2: 0.5 | H2: 2.5 | I2: -2.9213403 | J2: 0.019334893 | K2: 1.7236637 | L2: 0.18148902
A3: 0.0041601062 | B3: 2.5051961e+08 | C3: =LOG(A3) -> -2.3808956 | D3: =LOG(B3) -> 8.3988417 | E3: =D3-$H$8-$H$6*C3 -> -0.17613188
A4: 0.0041801159 | B4: 2.4814387e+08 | C4: =LOG(A4) -> -2.3788117 | D4: =LOG(B4) -> 8.3947035 | E4: =D4-$H$8-$H$6*C4 -> -0.17439106 | H4: Ajuste: log P(k)=a+b log(k)
A5: 0.0042002219 | B5: 2.4579066e+08 | C5: =LOG(A5) -> -2.3767278 | D5: =LOG(B5) -> 8.3905654 | E5: =D5-$H$8-$H$6*C5 -> -0.17265024 | H5: Pendiente (b)
A6: 0.0042204246 | B6: 2.4345976e+08 | C6: =LOG(A6) -> -2.3746439 | D6: =LOG(B6) -> 8.3864272 | E6: =D6-$H$8-$H$6*C6 -> -0.17090942 | H6: =SLOPE(D2:D1001,C2:C1001) -> -2.8211349
A7: 0.0042407245 | B7: 2.4115097e+08 | C7: =LOG(A7) -> -2.3725599 | D7: =LOG(B7) -> 8.382289 | E7: =D7-$H$8-$H$6*C7 -> -0.1691686 | H7: Intersección eje y (a)
A8: 0.004261122 | B8: 2.3886408e+08 | C8: =LOG(A8) -> -2.370476 | D8: =LOG(B8) -> 8.3781508 | E8: =D8-$H$8-$H$6*C8 -> -0.16742778 | H8: =INTERCEPT(D2:D1001,C2:C1001) -> 1.858146
A9: 0.0042816177 | B9: 2.3659887e+08 | C9: =LOG(A9) -> -2.3683921 | D9: =LOG(B9) -> 8.3740127 | E9: =D9-$H$8-$H$6*C9 -> -0.16568696 | H9: R2
A10: 0.0043022119 | B10: 2.3435515e+08 | C10: =LOG(A10) -> -2.3663082 | D10: =LOG(B10) -> 8.3698745 | E10: =D10-$H$8-$H$6*C10 -> -0.16394613 | H10: =CORREL(C2:C1001,D2:D1001)^2 -> 0.98992806
A11: 0.0043229052 | B11: 2.321327e+08 | C11: =LOG(A11) -> -2.3642243 | D11: =LOG(B11) -> 8.3657363 | E11: =D11-$H$8-$H$6*C11 -> -0.16220531
A12: 0.004343698 | B12: 2.2993133e+08 | C12: =LOG(A12) -> -2.3621404 | D12: =LOG(B12) -> 8.3615981 | E12: =D12-$H$8-$H$6*C12 -> -0.16046449
A13: 0.0043645908 | B13: 2.2775083e+08 | C13: =LOG(A13) -> -2.3600565 | D13: =LOG(B13) -> 8.35746 | E13: =D13-$H$8-$H$6*C13 -> -0.15872367
A14: 0.0043855841 | B14: 2.2559101e+08 | C14: =LOG(A14) -> -2.3579726 | D14: =LOG(B14) -> 8.3533218 | E14: =D14-$H$8-$H$6*C14 -> -0.15698285
A15: 0.0044066784 | B15: 2.2345168e+08 | C15: =LOG(A15) -> -2.3558886 | D15: =LOG(B15) -> 8.3491836 | E15: =D15-$H$8-$H$6*C15 -> -0.15524203
A16: 0.0044278741 | B16: 2.2133263e+08 | C16: =LOG(A16) -> -2.3538047 | D16: =LOG(B16) -> 8.3450454 | E16: =D16-$H$8-$H$6*C16 -> -0.15350121
A17: 0.0044491718 | B17: 2.1923368e+08 | C17: =LOG(A17) -> -2.3517208 | D17: =LOG(B17) -> 8.3409073 | E17: =D17-$H$8-$H$6*C17 -> -0.15176039
A18: 0.0044705719 | B18: 2.1715463e+08 | C18: =LOG(A18) -> -2.3496369 | D18: =LOG(B18) -> 8.3367691 | E18: =D18-$H$8-$H$6*C18 -> -0.15001957
A19: 0.004492075 | B19: 2.150953e+08 | C19: =LOG(A19) -> -2.347553 | D19: =LOG(B19) -> 8.3326309 | E19: =D19-$H$8-$H$6*C19 -> -0.14827875
A20: 0.0045136815 | B20: 2.130555e+08 | C20: =LOG(A20) -> -2.3454691 | D20: =LOG(B20) -> 8.3284927 | E20: =D20-$H$8-$H$6*C20 -> -0.14653793
A21: 0.0045353919 | B21: 2.1103504e+08 | C21: =LOG(A21) -> -2.3433852 | D21: =LOG(B21) -> 8.3243546 | E21: =D21-$H$8-$H$6*C21 -> -0.14479711
A22: 0.0045572068 | B22: 2.0903374e+08 | C22: =LOG(A22) -> -2.3413013 | D22: =LOG(B22) -> 8.3202164 | E22: =D22-$H$8-$H$6*C22 -> -0.14305629
... A1001: 0.49985981 | B1001: 301.67854 | C1001: =LOG(A1001) -> -0.30115178 | D1001: =LOG(B1001) -> 2.4795444 | E1001: =D1001-$H$8-$H$6*C1001 -> -0.22819137

Sheet efbm_H0.5Mach2.5_1
A1: k | B1: P(k) | C1: log(k) | D1: log(P(k)) | E1: Residuos | F1: Archivo | G1: H | H1: Mach | I1: beta | J1: beta_err | K1: intercept | L1: intercept_err
A2: 0.0041401922 | B2: 1.3339576e+09 | C2: =LOG(A2) -> -2.3829795 | D2: =LOG(B2) -> 9.125142 | E2: =D2-$H$8-$H$6*C2 -> -0.20268267 | F2: efbm_H0.5Mach2.5_1.fits | G2: 0.5 | H2: 2.5 | I2: -2.9559903 | J2: 0.015195697 | K2: 2.3354318 | L2: 0.13299286
A3: 0.0041601062 | B3: 1.3298957e+09 | C3: =LOG(A3) -> -2.3808956 | D3: =LOG(B3) -> 9.1238176 | E3: =D3-$H$8-$H$6*C3 -> -0.19795055
A4: 0.0041801159 | B4: 1.3258461e+09 | C4: =LOG(A4) -> -2.3788117 | D4: =LOG(B4) -> 9.1224931 | E4: =D4-$H$8-$H$6*C4 -> -0.19321842 | H4: Ajuste: log P(k)=a+b log(k)
A5: 0.0042002219 | B5: 1.3218089e+09 | C5: =LOG(A5) -> -2.3767278 | D5: =LOG(B5) -> 9.1211687 | E5: =D5-$H$8-$H$6*C5 -> -0.18848629 | H5: Pendiente (b)
A6: 0.0042204246 | B6: 1.317784e+09 | C6: =LOG(A6) -> -2.3746439 | D6: =LOG(B6) -> 9.1198442 | E6: =D6-$H$8-$H$6*C6 -> -0.18375417 | H6: =SLOPE(D2:D1001,C2:C1001) -> -2.9063499
A7: 0.0042407245 | B7: 1.3137713e+09 | C7: =LOG(A7) -> -2.3725599 | D7: =LOG(B7) -> 9.1185198 | E7: =D7-$H$8-$H$6*C7 -> -0.17902204 | H7: Intersección eje y (a)
A8: 0.004261122 | B8: 1.3097708e+09 | C8: =LOG(A8) -> -2.370476 | D8: =LOG(B8) -> 9.1171953 | E8: =D8-$H$8-$H$6*C8 -> -0.17428991 | H8: =INTERCEPT(D2:D1001,C2:C1001) -> 2.4020524
A9: 0.0042816177 | B9: 1.3057826e+09 | C9: =LOG(A9) -> -2.3683921 | D9: =LOG(B9) -> 9.1158709 | E9: =D9-$H$8-$H$6*C9 -> -0.16955779 | H9: R2
A10: 0.0043022119 | B10: 1.3018065e+09 | C10: =LOG(A10) -> -2.3663082 | D10: =LOG(B10) -> 9.1145464 | E10: =D10-$H$8-$H$6*C10 -> -0.16482566 | H10: =CORREL(C2:C1001,D2:D1001)^2 -> 0.99453567
A11: 0.0043229052 | B11: 1.2978424e+09 | C11: =LOG(A11) -> -2.3642243 | D11: =LOG(B11) -> 9.113222 | E11: =D11-$H$8-$H$6*C11 -> -0.16009353
A12: 0.004343698 | B12: 1.2938905e+09 | C12: =LOG(A12) -> -2.3621404 | D12: =LOG(B12) -> 9.1118975 | E12: =D12-$H$8-$H$6*C12 -> -0.15536141
A13: 0.0043645908 | B13: 1.2899506e+09 | C13: =LOG(A13) -> -2.3600565 | D13: =LOG(B13) -> 9.1105731 | E13: =D13-$H$8-$H$6*C13 -> -0.15062928
A14: 0.0043855841 | B14: 1.2860227e+09 | C14: =LOG(A14) -> -2.3579726 | D14: =LOG(B14) -> 9.1092486 | E14: =D14-$H$8-$H$6*C14 -> -0.14589715
A15: 0.0044066784 | B15: 1.2821067e+09 | C15: =LOG(A15) -> -2.3558886 | D15: =LOG(B15) -> 9.1079242 | E15: =D15-$H$8-$H$6*C15 -> -0.14116503
A16: 0.0044278741 | B16: 1.2782027e+09 | C16: =LOG(A16) -> -2.3538047 | D16: =LOG(B16) -> 9.1065997 | E16: =D16-$H$8-$H$6*C16 -> -0.1364329
A17: 0.0044491718 | B17: 1.2743105e+09 | C17: =LOG(A17) -> -2.3517208 | D17: =LOG(B17) -> 9.1052753 | E17: =D17-$H$8-$H$6*C17 -> -0.13170077
A18: 0.0044705719 | B18: 1.2704302e+09 | C18: =LOG(A18) -> -2.3496369 | D18: =LOG(B18) -> 9.1039508 | E18: =D18-$H$8-$H$6*C18 -> -0.12696865
A19: 0.004492075 | B19: 1.2665618e+09 | C19: =LOG(A19) -> -2.347553 | D19: =LOG(B19) -> 9.1026264 | E19: =D19-$H$8-$H$6*C19 -> -0.12223652
A20: 0.0045136815 | B20: 1.2627051e+09 | C20: =LOG(A20) -> -2.3454691 | D20: =LOG(B20) -> 9.1013019 | E20: =D20-$H$8-$H$6*C20 -> -0.11750439
A21: 0.0045353919 | B21: 1.2588601e+09 | C21: =LOG(A21) -> -2.3433852 | D21: =LOG(B21) -> 9.0999775 | E21: =D21-$H$8-$H$6*C21 -> -0.11277226
A22: 0.0045572068 | B22: 1.2550269e+09 | C22: =LOG(A22) -> -2.3413013 | D22: =LOG(B22) -> 9.098653 | E22: =D22-$H$8-$H$6*C22 -> -0.10804014
... A1001: 0.49985981 | B1001: 1609.9699 | C1001: =LOG(A1001) -> -0.30115178 | D1001: =LOG(B1001) -> 3.2068178 | E1001: =D1001-$H$8-$H$6*C1001 -> -0.070487063

Sheet efbm_H0.5Mach2.5_2
A1: k | B1: P(k) | C1: log(k) | D1: log(P(k)) | E1: Residuos | F1: Archivo | G1: H | H1: Mach | I1: beta | J1: beta_err | K1: intercept | L1: intercept_err
A2: 0.0041401922 | B2: 4.0250829e+08 | C2: =LOG(A2) -> -2.3829795 | D2: =LOG(B2) -> 8.6047748 | E2: =D2-$H$8-$H$6*C2 -> 0.095091047 | F2: efbm_H0.5Mach2.5_2.fits | G2: 0.5 | H2: 2.5 | I2: -2.9400591 | J2: 0.016266867 | K2: 1.7400073 | L2: 0.26454638
A3: 0.0041601062 | B3: 3.8527429e+08 | C3: =LOG(A3) -> -2.3808956 | D3: =LOG(B3) -> 8.58577 | E3: =D3-$H$8-$H$6*C3 -> 0.08173975
A4: 0.0041801159 | B4: 3.6877819e+08 | C4: =LOG(A4) -> -2.3788117 | D4: =LOG(B4) -> 8.5667652 | E4: =D4-$H$8-$H$6*C4 -> 0.068388453 | H4: Ajuste: log P(k)=a+b log(k)
A5: 0.0042002219 | B5: 3.529884e+08 | C5: =LOG(A5) -> -2.3767278 | D5: =LOG(B5) -> 8.5477604 | E5: =D5-$H$8-$H$6*C5 -> 0.055037156 | H5: Pendiente (b)
A6: 0.0042204246 | B6: 3.3787467e+08 | C6: =LOG(A6) -> -2.3746439 | D6: =LOG(B6) -> 8.5287556 | E6: =D6-$H$8-$H$6*C6 -> 0.041685859 | H6: =SLOPE(D2:D1001,C2:C1001) -> -2.7129278
A7: 0.0042407245 | B7: 3.2340806e+08 | C7: =LOG(A7) -> -2.3725599 | D7: =LOG(B7) -> 8.5097508 | E7: =D7-$H$8-$H$6*C7 -> 0.028334563 | H7: Intersección eje y (a)
A8: 0.004261122 | B8: 3.0956086e+08 | C8: =LOG(A8) -> -2.370476 | D8: =LOG(B8) -> 8.490746 | E8: =D8-$H$8-$H$6*C8 -> 0.014983266 | H8: =INTERCEPT(D2:D1001,C2:C1001) -> 2.0448324
A9: 0.0042816177 | B9: 2.9630654e+08 | C9: =LOG(A9) -> -2.3683921 | D9: =LOG(B9) -> 8.4717412 | E9: =D9-$H$8-$H$6*C9 -> 0.0016319687 | H9: R2
A10: 0.0043022119 | B10: 2.8361973e+08 | C10: =LOG(A10) -> -2.3663082 | D10: =LOG(B10) -> 8.4527364 | E10: =D10-$H$8-$H$6*C10 -> -0.011719328 | H10: =CORREL(C2:C1001,D2:D1001)^2 -> 0.98109806
A11: 0.0043229052 | B11: 2.7147612e+08 | C11: =LOG(A11) -> -2.3642243 | D11: =LOG(B11) -> 8.4337316 | E11: =D11-$H$8-$H$6*C11 -> -0.025070625
A12: 0.004343698 | B12: 2.5985247e+08 | C12: =LOG(A12) -> -2.3621404 | D12: =LOG(B12) -> 8.4147268 | E12: =D12-$H$8-$H$6*C12 -> -0.038421922
A13: 0.0043645908 | B13: 2.4872649e+08 | C13: =LOG(A13) -> -2.3600565 | D13: =LOG(B13) -> 8.395722 | E13: =D13-$H$8-$H$6*C13 -> -0.051773219
A14: 0.0043855841 | B14: 2.3807689e+08 | C14: =LOG(A14) -> -2.3579726 | D14: =LOG(B14) -> 8.3767172 | E14: =D14-$H$8-$H$6*C14 -> -0.065124516
A15: 0.0044066784 | B15: 2.2788327e+08 | C15: =LOG(A15) -> -2.3558886 | D15: =LOG(B15) -> 8.3577124 | E15: =D15-$H$8-$H$6*C15 -> -0.078475813
A16: 0.0044278741 | B16: 2.1812611e+08 | C16: =LOG(A16) -> -2.3538047 | D16: =LOG(B16) -> 8.3387076 | E16: =D16-$H$8-$H$6*C16 -> -0.09182711
A17: 0.0044491718 | B17: 2.0878671e+08 | C17: =LOG(A17) -> -2.3517208 | D17: =LOG(B17) -> 8.3197028 | E17: =D17-$H$8-$H$6*C17 -> -0.10517841
A18: 0.0044705719 | B18: 1.9984719e+08 | C18: =LOG(A18) -> -2.3496369 | D18: =LOG(B18) -> 8.3006981 | E18: =D18-$H$8-$H$6*C18 -> -0.1185297
A19: 0.004492075 | B19: 1.9129043e+08 | C19: =LOG(A19) -> -2.347553 | D19: =LOG(B19) -> 8.2816933 | E19: =D19-$H$8-$H$6*C19 -> -0.131881
A20: 0.0045136815 | B20: 1.8310005e+08 | C20: =LOG(A20) -> -2.3454691 | D20: =LOG(B20) -> 8.2626885 | E20: =D20-$H$8-$H$6*C20 -> -0.1452323
A21: 0.0045353919 | B21: 1.7526034e+08 | C21: =LOG(A21) -> -2.3433852 | D21: =LOG(B21) -> 8.2436837 | E21: =D21-$H$8-$H$6*C21 -> -0.15858359
A22: 0.0045572068 | B22: 1.6775631e+08 | C22: =LOG(A22) -> -2.3413013 | D22: =LOG(B22) -> 8.2246789 | E22: =D22-$H$8-$H$6*C22 -> -0.17193489
... A1001: 0.49985981 | B1001: 294.26809 | C1001: =LOG(A1001) -> -0.30115178 | D1001: =LOG(B1001) -> 2.4687432 | E1001: =D1001-$H$8-$H$6*C1001 -> -0.39309231

Sheet efbm_H0.5Mach2.5_3
A1: k | B1: P(k) | C1: log(k) | D1: log(P(k)) | E1: Residuos | F1: Archivo | G1: H | H1: Mach | I1: beta | J1: beta_err | K1: intercept | L1: intercept_err
A2: 0.0041401922 | B2: 1.5190956e+09 | C2: =LOG(A2) -> -2.3829795 | D2: =LOG(B2) -> 9.1815851 | E2: =D2-$H$8-$H$6*C2 -> 0.022892557 | F2: efbm_H0.5Mach2.5_3.fits | G2: 0.5 | H2: 2.5 | I2: -3.0193451 | J2: 0.015309399 | K2: 1.8491343 | L2: 0.16483862
A3: 0.0041601062 | B3: 1.4911187e+09 | C3: =LOG(A3) -> -2.3808956 | D3: =LOG(B3) -> 9.1735122 | E3: =D3-$H$8-$H$6*C3 -> 0.021340993
A4: 0.0041801159 | B4: 1.4636571e+09 | C4: =LOG(A4) -> -2.3788117 | D4: =LOG(B4) -> 9.1654393 | E4: =D4-$H$8-$H$6*C4 -> 0.019789429 | H4: Ajuste: log P(k)=a+b log(k)
A5: 0.0042002219 | B5: 1.4367012e+09 | C5: =LOG(A5) -> -2.3767278 | D5: =LOG(B5) -> 9.1573664 | E5: =D5-$H$8-$H$6*C5 -> 0.018237865 | H5: Pendiente (b)
A6: 0.0042204246 | B6: 1.4102417e+09 | C6: =LOG(A6) -> -2.3746439 | D6: =LOG(B6) -> 9.1492936 | E6: =D6-$H$8-$H$6*C6 -> 0.016686301 | H6: =SLOPE(D2:D1001,C2:C1001) -> -3.1293645
A7: 0.0042407245 | B7: 1.3842696e+09 | C7: =LOG(A7) -> -2.3725599 | D7: =LOG(B7) -> 9.1412207 | E7: =D7-$H$8-$H$6*C7 -> 0.015134736 | H7: Intersección eje y (a)
A8: 0.004261122 | B8: 1.3587758e+09 | C8: =LOG(A8) -> -2.370476 | D8: =LOG(B8) -> 9.1331478 | E8: =D8-$H$8-$H$6*C8 -> 0.013583172 | H8: =INTERCEPT(D2:D1001,C2:C1001) -> 1.701481
A9: 0.0042816177 | B9: 1.3337515e+09 | C9: =LOG(A9) -> -2.3683921 | D9: =LOG(B9) -> 9.1250749 | E9: =D9-$H$8-$H$6*C9 -> 0.012031608 | H9: R2
A10: 0.0043022119 | B10: 1.3091881e+09 | C10: =LOG(A10) -> -2.3663082 | D10: =LOG(B10) -> 9.117002 | E10: =D10-$H$8-$H$6*C10 -> 0.010480044 | H10: =CORREL(C2:C1001,D2:D1001)^2 -> 0.99361006
A11: 0.0043229052 | B11: 1.285077e+09 | C11: =LOG(A11) -> -2.3642243 | D11: =LOG(B11) -> 9.1089291 | E11: =D11-$H$8-$H$6*C11 -> 0.0089284796
A12: 0.004343698 | B12: 1.26141e+09 | C12: =LOG(A12) -> -2.3621404 | D12: =LOG(B12) -> 9.1008563 | E12: =D12-$H$8-$H$6*C12 -> 0.0073769154
A13: 0.0043645908 | B13: 1.2381789e+09 | C13: =LOG(A13) -> -2.3600565 | D13: =LOG(B13) -> 9.0927834 | E13: =D13-$H$8-$H$6*C13 -> 0.0058253512
A14: 0.0043855841 | B14: 1.2153756e+09 | C14: =LOG(A14) -> -2.3579726 | D14: =LOG(B14) -> 9.0847105 | E14: =D14-$H$8-$H$6*C14 -> 0.004273787
A15: 0.0044066784 | B15: 1.1929922e+09 | C15: =LOG(A15) -> -2.3558886 | D15: =LOG(B15) -> 9.0766376 | E15: =D15-$H$8-$H$6*C15 -> 0.0027222228
A16: 0.0044278741 | B16: 1.1710211e+09 | C16: =LOG(A16) -> -2.3538047 | D16: =LOG(B16) -> 9.0685647 | E16: =D16-$H$8-$H$6*C16 -> 0.0011706586
A17: 0.0044491718 | B17: 1.1494547e+09 | C17: =LOG(A17) -> -2.3517208 | D17: =LOG(B17) -> 9.0604918 | E17: =D17-$H$8-$H$6*C17 -> -0.00038090563
A18: 0.0044705719 | B18: 1.1282854e+09 | C18: =LOG(A18) -> -2.3496369 | D18: =LOG(B18) -> 9.052419 | E18: =D18-$H$8-$H$6*C18 -> -0.0019324698
A19: 0.004492075 | B19: 1.107506e+09 | C19: =LOG(A19) -> -2.347553 | D19: =LOG(B19) -> 9.0443461 | E19: =D19-$H$8-$H$6*C19 -> -0.003484034
A20: 0.0045136815 | B20: 1.0871093e+09 | C20: =LOG(A20) -> -2.3454691 | D20: =LOG(B20) -> 9.0362732 | E20: =D20-$H$8-$H$6*C20 -> -0.0050355982
A21: 0.0045353919 | B21: 1.0670882e+09 | C21: =LOG(A21) -> -2.3433852 | D21: =LOG(B21) -> 9.0282003 | E21: =D21-$H$8-$H$6*C21 -> -0.0065871624
A22: 0.0045572068 | B22: 1.0474358e+09 | C22: =LOG(A22) -> -2.3413013 | D22: =LOG(B22) -> 9.0201274 | E22: =D22-$H$8-$H$6*C22 -> -0.0081387266
... A1001: 0.49985981 | B1001: 419.10964 | C1001: =LOG(A1001) -> -0.30115178 | D1001: =LOG(B1001) -> 2.6223276 | E1001: =D1001-$H$8-$H$6*C1001 -> -0.021567052

Sheet efbm_H0.5Mach2.5_4
A1: k | B1: P(k) | C1: log(k) | D1: log(P(k)) | E1: Residuos | F1: Archivo | G1: H | H1: Mach | I1: beta | J1: beta_err | K1: intercept | L1: intercept_err
A2: 0.0041401922 | B2: 1.4435359e+08 | C2: =LOG(A2) -> -2.3829795 | D2: =LOG(B2) -> 8.1594276 | E2: =D2-$H$8-$H$6*C2 -> -0.44031524 | F2: efbm_H0.5Mach2.5_4.fits | G2: 0.5 | H2: 2.5 | I2: -2.9131087 | J2: 0.019656978 | K2: 1.8922333 | L2: 0.25905465
A3: 0.0041601062 | B3: 1.4468102e+08 | C3: =LOG(A3) -> -2.3808956 | D3: =LOG(B3) -> 8.1604116 | E3: =D3-$H$8-$H$6*C3 -> -0.43372982
A4: 0.0041801159 | B4: 1.4500919e+08 | C4: =LOG(A4) -> -2.3788117 | D4: =LOG(B4) -> 8.1613955 | E4: =D4-$H$8-$H$6*C4 -> -0.42714441 | H4: Ajuste: log P(k)=a+b log(k)
A5: 0.0042002219 | B5: 1.453381e+08 | C5: =LOG(A5) -> -2.3767278 | D5: =LOG(B5) -> 8.1623795 | E5: =D5-$H$8-$H$6*C5 -> -0.42055899 | H5: Pendiente (b)
A6: 0.0042204246 | B6: 1.4566776e+08 | C6: =LOG(A6) -> -2.3746439 | D6: =LOG(B6) -> 8.1633634 | E6: =D6-$H$8-$H$6*C6 -> -0.41397357 | H6: =SLOPE(D2:D1001,C2:C1001) -> -2.6879519
A7: 0.0042407245 | B7: 1.4599817e+08 | C7: =LOG(A7) -> -2.3725599 | D7: =LOG(B7) -> 8.1643474 | E7: =D7-$H$8-$H$6*C7 -> -0.40738816 | H7: Intersección eje y (a)
A8: 0.004261122 | B8: 1.4632932e+08 | C8: =LOG(A8) -> -2.370476 | D8: =LOG(B8) -> 8.1653314 | E8: =D8-$H$8-$H$6*C8 -> -0.40080274 | H8: =INTERCEPT(D2:D1001,C2:C1001) -> 2.1944086
A9: 0.0042816177 | B9: 1.4666123e+08 | C9: =LOG(A9) -> -2.3683921 | D9: =LOG(B9) -> 8.1663153 | E9: =D9-$H$8-$H$6*C9 -> -0.39421733 | H9: R2
A10: 0.0043022119 | B10: 1.4699389e+08 | C10: =LOG(A10) -> -2.3663082 | D10: =LOG(B10) -> 8.1672993 | E10: =D10-$H$8-$H$6*C10 -> -0.38763191 | H10: =CORREL(C2:C1001,D2:D1001)^2 -> 0.98169177
A11: 0.0043229052 | B11: 1.4732731e+08 | C11: =LOG(A11) -> -2.3642243 | D11: =LOG(B11) -> 8.1682833 | E11: =D11-$H$8-$H$6*C11 -> -0.3810465
A12: 0.004343698 | B12: 1.4766148e+08 | C12: =LOG(A12) -> -2.3621404 | D12: =LOG(B12) -> 8.1692672 | E12: =D12-$H$8-$H$6*C12 -> -0.37446108
